{"type": "open", "side": "sell", "price": "452.99000000", "order_id": "6847bcbb-1062-4772-b9f2-959c8f13f40c", "remaining_size": "6.79438000", "product_id": "ETH-USD", "sequence": 4179035759, "time": "2018-07-02T05:24:06.997000Z"}
{"type": "received", "order_id": "ef5e0e3f-fafa-4f35-ad2b-cd9e9fca9247", "order_type": "limit", "size": "0.01000000", "price": "452.25000000", "side": "sell", "client_oid": "909935c3-86cb-418e-8000-00cb17afb53c", "product_id": "ETH-USD", "sequence": 4179036937, "time": "2018-07-02T05:24:20.326000Z"}
{"type": "open", "side": "sell", "price": "452.25000000", "order_id": "ef5e0e3f-fafa-4f35-ad2b-cd9e9fca9247", "remaining_size": "0.01000000", "product_id": "ETH-USD", "sequence": 4179036938, "time": "2018-07-02T05:24:20.326000Z"}
{"type": "received", "order_id": "96d2981a-a84a-4c06-80a9-0490225efef9", "order_type": "limit", "size": "0.01000000", "price": "453.25000000", "side": "sell", "client_oid": "6c284416-3ecc-492f-8000-00b0a2ab44e2", "product_id": "ETH-USD", "sequence": 4179036939, "time": "2018-07-02T05:24:20.329000Z"}
{"type": "open", "side": "sell", "price": "453.25000000", "order_id": "96d2981a-a84a-4c06-80a9-0490225efef9", "remaining_size": "0.01000000", "product_id": "ETH-USD", "sequence": 4179036940, "time": "2018-07-02T05:24:20.329000Z"}
{"type": "received", "order_id": "2027b87e-2085-4684-a964-97e730716c89", "order_type": "limit", "size": "0.01000000", "price": "454.25000000", "side": "sell", "client_oid": "794a8f25-2ca3-413a-8000-005a5a623edc", "product_id": "ETH-USD", "sequence": 4179036941, "time": "2018-07-02T05:24:20.360000Z"}
{"type": "open", "side": "sell", "price": "454.25000000", "order_id": "2027b87e-2085-4684-a964-97e730716c89", "remaining_size": "0.01000000", "product_id": "ETH-USD", "sequence": 4179036942, "time": "2018-07-02T05:24:20.360000Z"}
{"type": "received", "order_id": "2ca9802b-0cc6-4afa-9607-afcc7c49be32", "order_type": "limit", "size": "0.01057000", "price": "447.17000000", "side": "sell", "client_oid": "2c312db4-7db8-11e8-874f-16be7828d23e", "product_id": "ETH-USD", "sequence": 4179036943, "time": "2018-07-02T05:24:20.371000Z"}
{"type": "open", "side": "sell", "price": "447.17000000", "order_id": "2ca9802b-0cc6-4afa-9607-afcc7c49be32", "remaining_size": "0.01057000", "product_id": "ETH-USD", "sequence": 4179036944, "time": "2018-07-02T05:24:20.371000Z"}
{"type": "done", "side": "sell", "order_id": "682543fe-41cf-42c5-a440-459c0cc62f93", "reason": "canceled", "product_id": "BTC-USD", "price": "6311.97000000", "remaining_size": "0.25000000", "sequence": 6227079242, "time": "2018-07-02T05:24:20.381000Z"}
{"type": "received", "order_id": "96954014-233e-41be-8599-66f4176ea214", "order_type": "limit", "size": "0.25000000", "price": "6311.46000000", "side": "sell", "client_oid": "0c443528-2de6-4b10-92b5-a8a03a21dbb4", "product_id": "BTC-USD", "sequence": 6227079243, "time": "2018-07-02T05:24:20.395000Z"}
{"type": "open", "side": "sell", "price": "6311.46000000", "order_id": "96954014-233e-41be-8599-66f4176ea214", "remaining_size": "0.25000000", "product_id": "BTC-USD", "sequence": 6227079244, "time": "2018-07-02T05:24:20.395000Z"}
{"type": "received", "order_id": "db7cc5ea-3bd7-4599-8d4f-b39921291dfe", "order_type": "limit", "size": "0.00100000", "price": "6300.55000000", "side": "sell", "client_oid": "f324efb8-24ed-405a-8000-008141f59bb4", "product_id": "BTC-USD", "sequence": 6227079245, "time": "2018-07-02T05:24:20.404000Z"}
{"type": "open", "side": "sell", "price": "6300.55000000", "order_id": "db7cc5ea-3bd7-4599-8d4f-b39921291dfe", "remaining_size": "0.00100000", "product_id": "BTC-USD", "sequence": 6227079246, "time": "2018-07-02T05:24:20.404000Z"}
{"type": "received", "order_id": "94b46aa9-fa38-46df-97b1-3a05a4c915a2", "order_type": "limit", "size": "0.00100000", "price": "6301.55000000", "side": "sell", "client_oid": "e856debe-c571-42ee-8000-00a67cf7e1ac", "product_id": "BTC-USD", "sequence": 6227079247, "time": "2018-07-02T05:24:20.445000Z"}
{"type": "open", "side": "sell", "price": "6301.55000000", "order_id": "94b46aa9-fa38-46df-97b1-3a05a4c915a2", "remaining_size": "0.00100000", "product_id": "BTC-USD", "sequence": 6227079248, "time": "2018-07-02T05:24:20.445000Z"}
{"type": "received", "order_id": "1c9e0b9c-c77d-4097-bf5c-fe4d4697f2c9", "order_type": "limit", "size": "0.06000000", "price": "446.71000000", "side": "buy", "client_oid": "b02807c0-0680-4913-8351-5c548c1e34d0", "product_id": "ETH-USD", "sequence": 4179036945, "time": "2018-07-02T05:24:20.463000Z"}
{"type": "open", "side": "buy", "price": "446.71000000", "order_id": "1c9e0b9c-c77d-4097-bf5c-fe4d4697f2c9", "remaining_size": "0.06000000", "product_id": "ETH-USD", "sequence": 4179036946, "time": "2018-07-02T05:24:20.463000Z"}
{"type": "done", "side": "sell", "order_id": "dbdd3468-e294-4332-b520-9c609766d303", "reason": "canceled", "product_id": "BTC-USD", "price": "6303.83000000", "remaining_size": "0.01500000", "sequence": 6227079249, "time": "2018-07-02T05:24:20.493000Z"}
{"type": "received", "order_id": "06389eb1-4451-429c-a04b-f014c7af0a4c", "order_type": "limit", "size": "0.01500000", "price": "6303.96000000", "side": "sell", "client_oid": "d0569bb8-e0d1-4147-a3b6-6857fe64ff8f", "product_id": "BTC-USD", "sequence": 6227079250, "time": "2018-07-02T05:24:20.497000Z"}
{"type": "open", "side": "sell", "price": "6303.96000000", "order_id": "06389eb1-4451-429c-a04b-f014c7af0a4c", "remaining_size": "0.01500000", "product_id": "BTC-USD", "sequence": 6227079251, "time": "2018-07-02T05:24:20.497000Z"}
{"type": "done", "side": "sell", "order_id": "9f59ddcc-6122-4f9a-9fa3-0536de87f211", "reason": "canceled", "product_id": "BTC-USD", "price": "6346.98000000", "remaining_size": "0.25868000", "sequence": 6227079252, "time": "2018-07-02T05:24:20.500000Z"}
{"type": "done", "side": "sell", "order_id": "e07a636a-8bde-4c82-bca3-ceaffc71b8b5", "reason": "canceled", "product_id": "ETH-USD", "price": "450.36000000", "remaining_size": "6.79438000", "sequence": 4179036947, "time": "2018-07-02T05:24:20.504000Z"}
{"type": "received", "order_id": "0bd79c1c-8bec-4782-b0b5-20c5f315a8f3", "order_type": "limit", "size": "0.25868000", "price": "6382.20000000", "side": "sell", "client_oid": "a18c56ef-8a77-477d-b8cd-ea507e67c2b0", "product_id": "BTC-USD", "sequence": 6227079253, "time": "2018-07-02T05:24:20.514000Z"}
{"type": "open", "side": "sell", "price": "6382.20000000", "order_id": "0bd79c1c-8bec-4782-b0b5-20c5f315a8f3", "remaining_size": "0.25868000", "product_id": "BTC-USD", "sequence": 6227079254, "time": "2018-07-02T05:24:20.514000Z"}
{"type": "received", "order_id": "090fc2b8-90b3-4fdc-bd03-a15a37a64e07", "order_type": "limit", "size": "6.79438000", "price": "452.99000000", "side": "sell", "client_oid": "49e384b7-1d50-41f6-8f88-4e46faa25e47", "product_id": "ETH-USD", "sequence": 4179036948, "time": "2018-07-02T05:24:20.518000Z"}
{"type": "open", "side": "sell", "price": "452.99000000", "order_id": "090fc2b8-90b3-4fdc-bd03-a15a37a64e07", "remaining_size": "6.79438000", "product_id": "ETH-USD", "sequence": 4179036949, "time": "2018-07-02T05:24:20.518000Z"}
{"type": "done", "side": "buy", "order_id": "4eb8ca6f-ec52-4da1-b602-6b80351aa9da", "reason": "canceled", "product_id": "ETH-USD", "price": "446.01000000", "remaining_size": "0.01000000", "sequence": 4179036950, "time": "2018-07-02T05:24:20.552000Z"}
{"type": "received", "order_id": "4a560b78-9771-421e-979b-b632651b95af", "order_type": "limit", "size": "0.01000000", "price": "446.03000000", "side": "buy", "client_oid": "c20ff000-0000-4e42-a040-000000e42a04", "product_id": "ETH-USD", "sequence": 4179036951, "time": "2018-07-02T05:24:20.558000Z"}
{"type": "open", "side": "buy", "price": "446.03000000", "order_id": "4a560b78-9771-421e-979b-b632651b95af", "remaining_size": "0.01000000", "product_id": "ETH-USD", "sequence": 4179036952, "time": "2018-07-02T05:24:20.558000Z"}
{"type": "done", "side": "buy", "order_id": "4a560b78-9771-421e-979b-b632651b95af", "reason": "canceled", "product_id": "ETH-USD", "price": "446.03000000", "remaining_size": "0.01000000", "sequence": 4179036953, "time": "2018-07-02T05:24:20.651000Z"}
{"type": "done", "side": "sell", "order_id": "dca64e82-78e8-4598-a34d-2f33ccca1272", "reason": "canceled", "product_id": "BTC-USD", "price": "6390.00000000", "remaining_size": "0.50125314", "sequence": 6227079255, "time": "2018-07-02T05:24:20.656000Z"}
{"type": "received", "order_id": "efb843d8-5610-4125-8675-47493edc6177", "order_type": "limit", "size": "0.01000000", "price": "446.03000000", "side": "buy", "client_oid": "49393300-0000-4d7c-96b5-000000d7cd6b", "product_id": "ETH-USD", "sequence": 4179036954, "time": "2018-07-02T05:24:20.658000Z"}
{"type": "open", "side": "buy", "price": "446.03000000", "order_id": "efb843d8-5610-4125-8675-47493edc6177", "remaining_size": "0.01000000", "product_id": "ETH-USD", "sequence": 4179036955, "time": "2018-07-02T05:24:20.658000Z"}
{"type": "done", "side": "sell", "order_id": "c56b963e-ca2b-4ce7-ac63-2beec58593dc", "reason": "canceled", "product_id": "ETH-USD", "price": "447.17000000", "remaining_size": "0.02000000", "sequence": 4179036956, "time": "2018-07-02T05:24:20.688000Z"}
{"type": "done", "side": "sell", "order_id": "0bd79c1c-8bec-4782-b0b5-20c5f315a8f3", "reason": "canceled", "product_id": "BTC-USD", "price": "6382.20000000", "remaining_size": "0.25868000", "sequence": 6227079256, "time": "2018-07-02T05:24:20.710000Z"}
{"type": "done", "side": "sell", "order_id": "090fc2b8-90b3-4fdc-bd03-a15a37a64e07", "reason": "canceled", "product_id": "ETH-USD", "price": "452.99000000", "remaining_size": "6.79438000", "sequence": 4179036957, "time": "2018-07-02T05:24:20.712000Z"}
{"type": "received", "order_id": "854b8e75-ff26-45a2-bb76-bd29ff1d2069", "order_type": "limit", "size": "0.25868000", "price": "6346.98000000", "side": "sell", "client_oid": "a475eee9-29a7-49ff-8e9b-8239d8123c8c", "product_id": "BTC-USD", "sequence": 6227079257, "time": "2018-07-02T05:24:20.723000Z"}
{"type": "open", "side": "sell", "price": "6346.98000000", "order_id": "854b8e75-ff26-45a2-bb76-bd29ff1d2069", "remaining_size": "0.25868000", "product_id": "BTC-USD", "sequence": 6227079258, "time": "2018-07-02T05:24:20.723000Z"}
{"type": "received", "order_id": "d2daee60-7041-4e17-9b64-5c92eedaefc1", "order_type": "limit", "size": "6.79438000", "price": "450.36000000", "side": "sell", "client_oid": "5a5d07c7-55a5-4aa5-a18d-7a8088984c2a", "product_id": "ETH-USD", "sequence": 4179036958, "time": "2018-07-02T05:24:20.725000Z"}
{"type": "open", "side": "sell", "price": "450.36000000", "order_id": "d2daee60-7041-4e17-9b64-5c92eedaefc1", "remaining_size": "6.79438000", "product_id": "ETH-USD", "sequence": 4179036959, "time": "2018-07-02T05:24:20.725000Z"}
{"type": "done", "side": "sell", "order_id": "11d77513-85f2-4def-98a6-e43b9361ebeb", "reason": "canceled", "product_id": "ETH-USD", "price": "447.17000000", "remaining_size": "0.01000000", "sequence": 4179036960, "time": "2018-07-02T05:24:20.729000Z"}
{"type": "done", "side": "buy", "order_id": "efb843d8-5610-4125-8675-47493edc6177", "reason": "canceled", "product_id": "ETH-USD", "price": "446.03000000", "remaining_size": "0.01000000", "sequence": 4179036961, "time": "2018-07-02T05:24:20.749000Z"}
{"type": "done", "side": "sell", "order_id": "96954014-233e-41be-8599-66f4176ea214", "reason": "canceled", "product_id": "BTC-USD", "price": "6311.46000000", "remaining_size": "0.25000000", "sequence": 6227079259, "time": "2018-07-02T05:24:20.756000Z"}
{"type": "received", "order_id": "392a7ed2-b7e2-45b5-a059-fd8fdf4a8089", "order_type": "limit", "size": "0.01000000", "price": "446.03000000", "side": "buy", "client_oid": "5ae1b000-000a-4768-bc00-0000a768fc00", "product_id": "ETH-USD", "sequence": 4179036962, "time": "2018-07-02T05:24:20.755000Z"}
{"type": "open", "side": "buy", "price": "446.03000000", "order_id": "392a7ed2-b7e2-45b5-a059-fd8fdf4a8089", "remaining_size": "0.01000000", "product_id": "ETH-USD", "sequence": 4179036963, "time": "2018-07-02T05:24:20.755000Z"}
{"type": "done", "side": "sell", "order_id": "144ace74-31d3-4d64-8ec6-0253210a5dff", "reason": "canceled", "product_id": "ETH-USD", "price": "474.70000000", "remaining_size": "0.01000000", "sequence": 4179036964, "time": "2018-07-02T05:24:20.790000Z"}
{"type": "done", "side": "buy", "order_id": "5ad5e122-ca72-4bd6-ba42-7301c8b53894", "reason": "canceled", "product_id": "ETH-USD", "price": "446.73000000", "remaining_size": "0.48000000", "sequence": 4179036965, "time": "2018-07-02T05:24:20.801000Z"}
{"type": "received", "order_id": "6c26253a-d4c1-478a-bfe4-68c168afe6b5", "order_type": "limit", "size": "0.00100000", "price": "6302.55000000", "side": "sell", "client_oid": "1393ae65-a16a-403b-8000-001ac8c65b81", "product_id": "BTC-USD", "sequence": 6227079260, "time": "2018-07-02T05:24:20.814000Z"}
{"type": "open", "side": "sell", "price": "6302.55000000", "order_id": "6c26253a-d4c1-478a-bfe4-68c168afe6b5", "remaining_size": "0.00100000", "product_id": "BTC-USD", "sequence": 6227079261, "time": "2018-07-02T05:24:20.814000Z"}
{"type": "received", "order_id": "636df6a9-768b-4f68-9500-4964d3e7cd5b", "order_type": "limit", "size": "0.01000000", "price": "470.67000000", "side": "sell", "client_oid": "c0f27169-bc1a-4226-8000-006a3ab0967e", "product_id": "ETH-USD", "sequence": 4179036966, "time": "2018-07-02T05:24:20.825000Z"}
{"type": "open", "side": "sell", "price": "470.67000000", "order_id": "636df6a9-768b-4f68-9500-4964d3e7cd5b", "remaining_size": "0.01000000", "product_id": "ETH-USD", "sequence": 4179036967, "time": "2018-07-02T05:24:20.825000Z"}
{"type": "received", "order_id": "16739955-35eb-40d0-8fd1-161490485f21", "order_type": "limit", "size": "0.25000000", "price": "6311.43000000", "side": "sell", "client_oid": "ad5f9393-e87c-4c4d-a16d-32ad3018e54f", "product_id": "BTC-USD", "sequence": 6227079262, "time": "2018-07-02T05:24:20.833000Z"}
{"type": "open", "side": "sell", "price": "6311.43000000", "order_id": "16739955-35eb-40d0-8fd1-161490485f21", "remaining_size": "0.25000000", "product_id": "BTC-USD", "sequence": 6227079263, "time": "2018-07-02T05:24:20.833000Z"}
{"type": "done", "side": "buy", "order_id": "aa79405d-e9aa-421b-9376-b5cc89413f92", "reason": "canceled", "product_id": "BTC-USD", "price": "6020.01000000", "remaining_size": "0.00150000", "sequence": 6227079264, "time": "2018-07-02T05:24:20.837000Z"}
{"type": "received", "order_id": "92553375-c4aa-4d36-a177-0f0ff7d16716", "order_type": "limit", "size": "0.00150000", "price": "6144.61000000", "side": "buy", "client_oid": "884edb51-2d4c-4c52-8000-00f243962bb0", "product_id": "BTC-USD", "sequence": 6227079265, "time": "2018-07-02T05:24:20.843000Z"}
{"type": "open", "side": "buy", "price": "6144.61000000", "order_id": "92553375-c4aa-4d36-a177-0f0ff7d16716", "remaining_size": "0.00150000", "product_id": "BTC-USD", "sequence": 6227079266, "time": "2018-07-02T05:24:20.843000Z"}
{"type": "done", "side": "buy", "order_id": "392a7ed2-b7e2-45b5-a059-fd8fdf4a8089", "reason": "canceled", "product_id": "ETH-USD", "price": "446.03000000", "remaining_size": "0.01000000", "sequence": 4179036968, "time": "2018-07-02T05:24:20.844000Z"}
{"type": "done", "side": "sell", "order_id": "abb0545a-2fb9-4b40-bb08-67b3f08a78ee", "reason": "canceled", "product_id": "ETH-USD", "price": "455.25000000", "remaining_size": "0.01000000", "sequence": 4179036969, "time": "2018-07-02T05:24:20.847000Z"}
{"type": "done", "side": "buy", "order_id": "4aa73379-3278-4686-8b29-d9b089e5b298", "reason": "canceled", "product_id": "ETH-USD", "price": "445.48000000", "remaining_size": "5.68644300", "sequence": 4179036970, "time": "2018-07-02T05:24:20.849000Z"}
{"type": "done", "side": "buy", "order_id": "f45e83a6-57b7-4507-a3cc-202459be3e0d", "reason": "canceled", "product_id": "ETH-USD", "price": "445.35000000", "remaining_size": "16.92060100", "sequence": 4179036971, "time": "2018-07-02T05:24:20.851000Z"}
{"type": "received", "order_id": "6d228a2c-4a02-4a88-a19e-b4ccc9f5b765", "order_type": "limit", "size": "0.01000000", "price": "446.03000000", "side": "buy", "client_oid": "a8fb4100-000f-480d-a440-00000f80da44", "product_id": "ETH-USD", "sequence": 4179036972, "time": "2018-07-02T05:24:20.852000Z"}
{"type": "open", "side": "buy", "price": "446.03000000", "order_id": "6d228a2c-4a02-4a88-a19e-b4ccc9f5b765", "remaining_size": "0.01000000", "product_id": "ETH-USD", "sequence": 4179036973, "time": "2018-07-02T05:24:20.852000Z"}
{"type": "done", "side": "sell", "order_id": "16739955-35eb-40d0-8fd1-161490485f21", "reason": "canceled", "product_id": "BTC-USD", "price": "6311.43000000", "remaining_size": "0.25000000", "sequence": 6227079267, "time": "2018-07-02T05:24:20.865000Z"}
{"type": "received", "order_id": "fad716d6-bf71-4e63-ac41-08b4197784e2", "order_type": "limit", "size": "0.48000000", "price": "446.69000000", "side": "buy", "client_oid": "37589a9b-af36-4876-b605-1a504278c19b", "product_id": "ETH-USD", "sequence": 4179036974, "time": "2018-07-02T05:24:20.872000Z"}
{"type": "open", "side": "buy", "price": "446.69000000", "order_id": "fad716d6-bf71-4e63-ac41-08b4197784e2", "remaining_size": "0.48000000", "product_id": "ETH-USD", "sequence": 4179036975, "time": "2018-07-02T05:24:20.872000Z"}
{"type": "received", "order_id": "7ee12323-425d-4521-b042-3d4a342f02db", "order_type": "limit", "size": "0.25000000", "price": "6311.27000000", "side": "sell", "client_oid": "12abe8b6-9585-4c76-acec-756540766e20", "product_id": "BTC-USD", "sequence": 6227079268, "time": "2018-07-02T05:24:20.882000Z"}
{"type": "received", "order_id": "40d54d70-8bcd-4b18-a5d4-9cbb3a1ffb4f", "order_type": "limit", "size": "2.61338600", "price": "445.48000000", "side": "buy", "client_oid": "5849c192-9cbc-43a1-8b23-e4fc175e9f70", "product_id": "ETH-USD", "sequence": 4179036976, "time": "2018-07-02T05:24:20.881000Z"}
{"type": "open", "side": "sell", "price": "6311.27000000", "order_id": "7ee12323-425d-4521-b042-3d4a342f02db", "remaining_size": "0.25000000", "product_id": "BTC-USD", "sequence": 6227079269, "time": "2018-07-02T05:24:20.882000Z"}
{"type": "open", "side": "buy", "price": "445.48000000", "order_id": "40d54d70-8bcd-4b18-a5d4-9cbb3a1ffb4f", "remaining_size": "2.61338600", "product_id": "ETH-USD", "sequence": 4179036977, "time": "2018-07-02T05:24:20.881000Z"}
{"type": "received", "order_id": "eebbe5e3-449f-499c-9ff8-400751057da9", "order_type": "limit", "size": "8.10882300", "price": "445.35000000", "side": "buy", "client_oid": "a27e7b7d-f4ab-42ad-abb1-e2409fe53dcf", "product_id": "ETH-USD", "sequence": 4179036978, "time": "2018-07-02T05:24:20.890000Z"}
{"type": "open", "side": "buy", "price": "445.35000000", "order_id": "eebbe5e3-449f-499c-9ff8-400751057da9", "remaining_size": "8.10882300", "product_id": "ETH-USD", "sequence": 4179036979, "time": "2018-07-02T05:24:20.890000Z"}
{"type": "received", "order_id": "4201d0b8-12b7-4e51-a1d8-210dca0b4ec8", "order_type": "limit", "size": "6.32147800", "price": "445.09000000", "side": "buy", "client_oid": "6a143728-9832-4f51-be97-fc1bf676192f", "product_id": "ETH-USD", "sequence": 4179036980, "time": "2018-07-02T05:24:20.899000Z"}
{"type": "open", "side": "buy", "price": "445.09000000", "order_id": "4201d0b8-12b7-4e51-a1d8-210dca0b4ec8", "remaining_size": "6.32147800", "product_id": "ETH-USD", "sequence": 4179036981, "time": "2018-07-02T05:24:20.899000Z"}
{"type": "received", "order_id": "cbf530f7-eb6a-4218-9b1e-f7cf1e319348", "order_type": "limit", "size": "2.14962400", "price": "443.92000000", "side": "buy", "client_oid": "abbf44a8-f6a5-4dca-908f-d05749a3b02c", "product_id": "ETH-USD", "sequence": 4179036982, "time": "2018-07-02T05:24:20.908000Z"}
{"type": "open", "side": "buy", "price": "443.92000000", "order_id": "cbf530f7-eb6a-4218-9b1e-f7cf1e319348", "remaining_size": "2.14962400", "product_id": "ETH-USD", "sequence": 4179036983, "time": "2018-07-02T05:24:20.908000Z"}
{"type": "received", "order_id": "d165017b-404c-4734-9d2f-4d2dc1db2030", "order_type": "limit", "size": "2.34888900", "price": "443.79000000", "side": "buy", "client_oid": "c6661df2-f50d-4331-a542-0db85da4b923", "product_id": "ETH-USD", "sequence": 4179036984, "time": "2018-07-02T05:24:20.917000Z"}
{"type": "open", "side": "buy", "price": "443.79000000", "order_id": "d165017b-404c-4734-9d2f-4d2dc1db2030", "remaining_size": "2.34888900", "product_id": "ETH-USD", "sequence": 4179036985, "time": "2018-07-02T05:24:20.917000Z"}
{"type": "received", "order_id": "ff9899f6-a8e1-4a10-914f-9c86d6a2f8ba", "order_type": "limit", "size": "1.08869100", "price": "443.66000000", "side": "buy", "client_oid": "542a3214-04a4-47ec-b56f-8d148a34391e", "product_id": "ETH-USD", "sequence": 4179036986, "time": "2018-07-02T05:24:20.926000Z"}
{"type": "open", "side": "buy", "price": "443.66000000", "order_id": "ff9899f6-a8e1-4a10-914f-9c86d6a2f8ba", "remaining_size": "1.08869100", "product_id": "ETH-USD", "sequence": 4179036987, "time": "2018-07-02T05:24:20.926000Z"}
{"type": "done", "side": "buy", "order_id": "6d228a2c-4a02-4a88-a19e-b4ccc9f5b765", "reason": "canceled", "product_id": "ETH-USD", "price": "446.03000000", "remaining_size": "0.01000000", "sequence": 4179036988, "time": "2018-07-02T05:24:20.943000Z"}
{"type": "received", "order_id": "55410c9e-585f-4ac4-ac6d-1c2dbfb597e3", "order_type": "limit", "size": "0.01000000", "price": "446.01000000", "side": "buy", "client_oid": "0d57e000-0002-4bf9-bd00-00002bf97d00", "product_id": "ETH-USD", "sequence": 4179036989, "time": "2018-07-02T05:24:20.959000Z"}
{"type": "open", "side": "buy", "price": "446.01000000", "order_id": "55410c9e-585f-4ac4-ac6d-1c2dbfb597e3", "remaining_size": "0.01000000", "product_id": "ETH-USD", "sequence": 4179036990, "time": "2018-07-02T05:24:20.959000Z"}
{"type": "done", "side": "sell", "order_id": "7ee12323-425d-4521-b042-3d4a342f02db", "reason": "canceled", "product_id": "BTC-USD", "price": "6311.27000000", "remaining_size": "0.25000000", "sequence": 6227079270, "time": "2018-07-02T05:24:21.007000Z"}
{"type": "received", "order_id": "7f180d08-40b6-4066-a1b3-666e5d44ab21", "order_type": "limit", "size": "57.00000000", "price": "447.17000000", "side": "sell", "client_oid": "663e38a1-be71-46e6-bfd4-a7def05fe38a", "product_id": "ETH-USD", "sequence": 4179036991, "time": "2018-07-02T05:24:21.013000Z"}
{"type": "open", "side": "sell", "price": "447.17000000", "order_id": "7f180d08-40b6-4066-a1b3-666e5d44ab21", "remaining_size": "57.00000000", "product_id": "ETH-USD", "sequence": 4179036992, "time": "2018-07-02T05:24:21.013000Z"}
{"type": "received", "order_id": "7fcba6e2-2a38-4739-8e2c-1a703724eb96", "order_type": "limit", "size": "0.25000000", "price": "6311.44000000", "side": "sell", "client_oid": "f1505ac2-7ca7-4c60-9790-373d255e4632", "product_id": "BTC-USD", "sequence": 6227079271, "time": "2018-07-02T05:24:21.022000Z"}
{"type": "open", "side": "sell", "price": "6311.44000000", "order_id": "7fcba6e2-2a38-4739-8e2c-1a703724eb96", "remaining_size": "0.25000000", "product_id": "BTC-USD", "sequence": 6227079272, "time": "2018-07-02T05:24:21.022000Z"}
{"type": "done", "side": "sell", "order_id": "7fcba6e2-2a38-4739-8e2c-1a703724eb96", "reason": "canceled", "product_id": "BTC-USD", "price": "6311.44000000", "remaining_size": "0.25000000", "sequence": 6227079273, "time": "2018-07-02T05:24:21.030000Z"}
{"type": "received", "order_id": "cec1f9ee-059f-4e6a-a640-f1d7e5c9b7db", "order_type": "limit", "size": "0.25000000", "price": "6313.32000000", "side": "sell", "client_oid": "c5e8fce7-e7ba-40a9-add0-539ed0441006", "product_id": "BTC-USD", "sequence": 6227079274, "time": "2018-07-02T05:24:21.044000Z"}
{"type": "open", "side": "sell", "price": "6313.32000000", "order_id": "cec1f9ee-059f-4e6a-a640-f1d7e5c9b7db", "remaining_size": "0.25000000", "product_id": "BTC-USD", "sequence": 6227079275, "time": "2018-07-02T05:24:21.044000Z"}
{"type": "received", "order_id": "63bc29f5-7864-4aaf-95e1-443cf5ed33c1", "order_type": "limit", "size": "0.01000000", "price": "447.25000000", "side": "sell", "client_oid": "f5e704c5-c10b-4fda-8000-008e584a2324", "product_id": "ETH-USD", "sequence": 4179036993, "time": "2018-07-02T05:24:21.052000Z"}
{"type": "open", "side": "sell", "price": "447.25000000", "order_id": "63bc29f5-7864-4aaf-95e1-443cf5ed33c1", "remaining_size": "0.01000000", "product_id": "ETH-USD", "sequence": 4179036994, "time": "2018-07-02T05:24:21.052000Z"}
{"type": "done", "side": "buy", "order_id": "55410c9e-585f-4ac4-ac6d-1c2dbfb597e3", "reason": "canceled", "product_id": "ETH-USD", "price": "446.01000000", "remaining_size": "0.01000000", "sequence": 4179036995, "time": "2018-07-02T05:24:21.064000Z"}
{"type": "received", "order_id": "9e655ae2-953b-4f31-8a3f-54fc03a401a0", "order_type": "limit", "size": "0.01000000", "price": "446.03000000", "side": "buy", "client_oid": "9a8cc000-0009-4d06-9f00-00009d065f00", "product_id": "ETH-USD", "sequence": 4179036996, "time": "2018-07-02T05:24:21.071000Z"}
{"type": "open", "side": "buy", "price": "446.03000000", "order_id": "9e655ae2-953b-4f31-8a3f-54fc03a401a0", "remaining_size": "0.01000000", "product_id": "ETH-USD", "sequence": 4179036997, "time": "2018-07-02T05:24:21.071000Z"}
{"type": "done", "side": "sell", "order_id": "7f180d08-40b6-4066-a1b3-666e5d44ab21", "reason": "canceled", "product_id": "ETH-USD", "price": "447.17000000", "remaining_size": "57.00000000", "sequence": 4179036998, "time": "2018-07-02T05:24:21.081000Z"}
{"type": "done", "side": "sell", "order_id": "ef5e0e3f-fafa-4f35-ad2b-cd9e9fca9247", "reason": "canceled", "product_id": "ETH-USD", "price": "452.25000000", "remaining_size": "0.01000000", "sequence": 4179036999, "time": "2018-07-02T05:24:21.088000Z"}
{"type": "received", "order_id": "8cf406df-6e2d-418a-bf2b-43230eb46ff4", "order_type": "limit", "size": "0.01000000", "price": "448.25000000", "side": "sell", "client_oid": "3643b003-08b1-4bd4-8000-00560981b9c1", "product_id": "ETH-USD", "sequence": 4179037000, "time": "2018-07-02T05:24:21.094000Z"}
{"type": "open", "side": "sell", "price": "448.25000000", "order_id": "8cf406df-6e2d-418a-bf2b-43230eb46ff4", "remaining_size": "0.01000000", "product_id": "ETH-USD", "sequence": 4179037001, "time": "2018-07-02T05:24:21.094000Z"}
{"type": "done", "side": "sell", "order_id": "4ceccfa4-a829-4d36-b390-ccd0d3d68804", "reason": "canceled", "product_id": "ETH-USD", "price": "448.13000000", "remaining_size": "14.24999000", "sequence": 4179037002, "time": "2018-07-02T05:24:21.099000Z"}
{"type": "done", "side": "buy", "order_id": "9e655ae2-953b-4f31-8a3f-54fc03a401a0", "reason": "canceled", "product_id": "ETH-USD", "price": "446.03000000", "remaining_size": "0.01000000", "sequence": 4179037003, "time": "2018-07-02T05:24:21.160000Z"}
{"type": "received", "order_id": "324e7611-f27a-4b6d-8fc9-998876a4fcc9", "order_type": "limit", "size": "0.01000000", "price": "446.03000000", "side": "buy", "client_oid": "29f99500-0000-4563-a061-00000563e061", "product_id": "ETH-USD", "sequence": 4179037004, "time": "2018-07-02T05:24:21.166000Z"}
{"type": "open", "side": "buy", "price": "446.03000000", "order_id": "324e7611-f27a-4b6d-8fc9-998876a4fcc9", "remaining_size": "0.01000000", "product_id": "ETH-USD", "sequence": 4179037005, "time": "2018-07-02T05:24:21.166000Z"}
{"type": "received", "order_id": "6e40c8dc-cd17-4054-877f-23f1b84988dd", "order_type": "limit", "size": "0.00100000", "price": "6303.55000000", "side": "sell", "client_oid": "b79a3069-b606-47fb-8000-00449c3a79e5", "product_id": "BTC-USD", "sequence": 6227079276, "time": "2018-07-02T05:24:21.182000Z"}
{"type": "open", "side": "sell", "price": "6303.55000000", "order_id": "6e40c8dc-cd17-4054-877f-23f1b84988dd", "remaining_size": "0.00100000", "product_id": "BTC-USD", "sequence": 6227079277, "time": "2018-07-02T05:24:21.183000Z"}
{"type": "done", "side": "buy", "order_id": "260af8fb-245c-41ed-9114-5f564ed53902", "reason": "canceled", "product_id": "BTC-USD", "price": "6298.26000000", "remaining_size": "0.25000000", "sequence": 6227079278, "time": "2018-07-02T05:24:21.185000Z"}
{"type": "done", "side": "sell", "order_id": "767cb6ec-ff71-40c3-babe-5f0fa1cff1e9", "reason": "canceled", "product_id": "ETH-USD", "price": "448.25000000", "remaining_size": "8.82388000", "sequence": 4179037006, "time": "2018-07-02T05:24:21.183000Z"}
{"type": "received", "order_id": "0cdff36c-4239-4f56-999b-15df7f68aefd", "order_type": "limit", "size": "0.25000000", "price": "6298.26000000", "side": "buy", "client_oid": "d311dcc1-8f53-4abb-a03c-464fb1d7519f", "product_id": "BTC-USD", "sequence": 6227079279, "time": "2018-07-02T05:24:21.199000Z"}
{"type": "open", "side": "buy", "price": "6298.26000000", "order_id": "0cdff36c-4239-4f56-999b-15df7f68aefd", "remaining_size": "0.25000000", "product_id": "BTC-USD", "sequence": 6227079280, "time": "2018-07-02T05:24:21.199000Z"}
{"type": "done", "side": "buy", "order_id": "24e967e9-8967-4ff3-8d73-8f2a9ed4dd30", "reason": "canceled", "product_id": "BTC-USD", "price": "6298.26000000", "remaining_size": "3.96900000", "sequence": 6227079281, "time": "2018-07-02T05:24:21.200000Z"}
{"type": "done", "side": "buy", "order_id": "27cd7680-ef8f-4e00-b378-985db603a076", "reason": "canceled", "product_id": "BTC-USD", "price": "6298.26000000", "remaining_size": "0.00200000", "sequence": 6227079282, "time": "2018-07-02T05:24:21.203000Z"}
{"type": "done", "side": "buy", "order_id": "324e7611-f27a-4b6d-8fc9-998876a4fcc9", "reason": "canceled", "product_id": "ETH-USD", "price": "446.03000000", "remaining_size": "0.01000000", "sequence": 4179037007, "time": "2018-07-02T05:24:21.258000Z"}
{"type": "received", "order_id": "2c47fd91-475c-4641-8432-e1e089e60e91", "order_type": "limit", "size": "0.01000000", "price": "449.25000000", "side": "sell", "client_oid": "4c901c7f-dd7a-442e-8000-00c68c55219a", "product_id": "ETH-USD", "sequence": 4179037008, "time": "2018-07-02T05:24:21.261000Z"}
{"type": "open", "side": "sell", "price": "449.25000000", "order_id": "2c47fd91-475c-4641-8432-e1e089e60e91", "remaining_size": "0.01000000", "product_id": "ETH-USD", "sequence": 4179037009, "time": "2018-07-02T05:24:21.261000Z"}
{"type": "received", "order_id": "de3e1d81-ee38-44c2-b28b-ec3c3d3fcd20", "order_type": "limit", "size": "8.82388000", "price": "448.37000000", "side": "sell", "client_oid": "ba6c30df-b8dc-4c8b-8076-8a498dc82e55", "product_id": "ETH-USD", "sequence": 4179037010, "time": "2018-07-02T05:24:21.261000Z"}
{"type": "open", "side": "sell", "price": "448.37000000", "order_id": "de3e1d81-ee38-44c2-b28b-ec3c3d3fcd20", "remaining_size": "8.82388000", "product_id": "ETH-USD", "sequence": 4179037011, "time": "2018-07-02T05:24:21.261000Z"}
{"type": "received", "order_id": "092185ba-85ab-47d3-a775-24ee02971a4f", "order_type": "limit", "size": "0.01000000", "price": "446.03000000", "side": "buy", "client_oid": "b665a000-000d-46b4-ba00-0000d6b4fa00", "product_id": "ETH-USD", "sequence": 4179037012, "time": "2018-07-02T05:24:21.263000Z"}
{"type": "open", "side": "buy", "price": "446.03000000", "order_id": "092185ba-85ab-47d3-a775-24ee02971a4f", "remaining_size": "0.01000000", "product_id": "ETH-USD", "sequence": 4179037013, "time": "2018-07-02T05:24:21.263000Z"}
{"type": "received", "order_id": "6f19fce8-0373-4528-8da5-b7b1f1438832", "order_type": "limit", "size": "14.24999000", "price": "448.12000000", "side": "sell", "client_oid": "2d2248db-a215-42e0-87f8-e24ebb4b42e5", "product_id": "ETH-USD", "sequence": 4179037014, "time": "2018-07-02T05:24:21.273000Z"}
{"type": "open", "side": "sell", "price": "448.12000000", "order_id": "6f19fce8-0373-4528-8da5-b7b1f1438832", "remaining_size": "14.24999000", "product_id": "ETH-USD", "sequence": 4179037015, "time": "2018-07-02T05:24:21.273000Z"}
{"type": "done", "side": "sell", "order_id": "8cf406df-6e2d-418a-bf2b-43230eb46ff4", "reason": "canceled", "product_id": "ETH-USD", "price": "448.25000000", "remaining_size": "0.01000000", "sequence": 4179037016, "time": "2018-07-02T05:24:21.295000Z"}
{"type": "done", "side": "sell", "order_id": "63bc29f5-7864-4aaf-95e1-443cf5ed33c1", "reason": "canceled", "product_id": "ETH-USD", "price": "447.25000000", "remaining_size": "0.01000000", "sequence": 4179037017, "time": "2018-07-02T05:24:21.297000Z"}
{"type": "received", "order_id": "3636cff1-d3d1-46e1-b4a7-4d37e1d9521e", "order_type": "limit", "size": "0.01000000", "price": "450.25000000", "side": "sell", "client_oid": "5e0b530c-3839-4dcd-8000-0088ec7e79e7", "product_id": "ETH-USD", "sequence": 4179037018, "time": "2018-07-02T05:24:21.303000Z"}
{"type": "open", "side": "sell", "price": "450.25000000", "order_id": "3636cff1-d3d1-46e1-b4a7-4d37e1d9521e", "remaining_size": "0.01000000", "product_id": "ETH-USD", "sequence": 4179037019, "time": "2018-07-02T05:24:21.303000Z"}
{"type": "received", "order_id": "e932eacf-c0ce-4832-9c19-3a4c9cd7e300", "order_type": "limit", "size": "0.01000000", "price": "451.25000000", "side": "sell", "client_oid": "ed7ace36-9601-4a2c-8000-00b6cd1d8cb1", "product_id": "ETH-USD", "sequence": 4179037020, "time": "2018-07-02T05:24:21.309000Z"}
{"type": "open", "side": "sell", "price": "451.25000000", "order_id": "e932eacf-c0ce-4832-9c19-3a4c9cd7e300", "remaining_size": "0.01000000", "product_id": "ETH-USD", "sequence": 4179037021, "time": "2018-07-02T05:24:21.309000Z"}
{"type": "received", "order_id": "f21355fc-d61b-441d-ba48-a739baeb557f", "order_type": "limit", "size": "2.68391400", "price": "447.17000000", "side": "sell", "product_id": "ETH-USD", "sequence": 4179037022, "time": "2018-07-02T05:24:21.329000Z"}
{"type": "open", "side": "sell", "price": "447.17000000", "order_id": "f21355fc-d61b-441d-ba48-a739baeb557f", "remaining_size": "2.68391400", "product_id": "ETH-USD", "sequence": 4179037023, "time": "2018-07-02T05:24:21.329000Z"}
{"type": "done", "side": "buy", "order_id": "092185ba-85ab-47d3-a775-24ee02971a4f", "reason": "canceled", "product_id": "ETH-USD", "price": "446.03000000", "remaining_size": "0.01000000", "sequence": 4179037024, "time": "2018-07-02T05:24:21.349000Z"}
{"type": "received", "order_id": "f05764c7-828c-415c-9287-424f786f20c6", "order_type": "limit", "size": "0.01000000", "price": "446.03000000", "side": "buy", "client_oid": "68b07500-0000-40ee-b5a0-000000ee35a0", "product_id": "ETH-USD", "sequence": 4179037025, "time": "2018-07-02T05:24:21.354000Z"}
{"type": "open", "side": "buy", "price": "446.03000000", "order_id": "f05764c7-828c-415c-9287-424f786f20c6", "remaining_size": "0.01000000", "product_id": "ETH-USD", "sequence": 4179037026, "time": "2018-07-02T05:24:21.354000Z"}
{"type": "done", "side": "buy", "order_id": "f05764c7-828c-415c-9287-424f786f20c6", "reason": "canceled", "product_id": "ETH-USD", "price": "446.03000000", "remaining_size": "0.01000000", "sequence": 4179037027, "time": "2018-07-02T05:24:21.444000Z"}
{"type": "received", "order_id": "6eda1dc2-8c8d-4e03-a7e4-c63ab2c82e25", "order_type": "limit", "size": "0.01000000", "price": "446.03000000", "side": "buy", "client_oid": "084ac000-000a-4664-9610-0000a664d610", "product_id": "ETH-USD", "sequence": 4179037028, "time": "2018-07-02T05:24:21.451000Z"}
{"type": "open", "side": "buy", "price": "446.03000000", "order_id": "6eda1dc2-8c8d-4e03-a7e4-c63ab2c82e25", "remaining_size": "0.01000000", "product_id": "ETH-USD", "sequence": 4179037029, "time": "2018-07-02T05:24:21.451000Z"}
{"type": "done", "side": "sell", "order_id": "2c47fd91-475c-4641-8432-e1e089e60e91", "reason": "canceled", "product_id": "ETH-USD", "price": "449.25000000", "remaining_size": "0.01000000", "sequence": 4179037030, "time": "2018-07-02T05:24:21.457000Z"}
{"type": "received", "order_id": "dfaad9ca-ce83-4f31-89b8-c522b0ababe8", "order_type": "limit", "size": "0.01000000", "price": "452.25000000", "side": "sell", "client_oid": "ebcd760a-4977-42ab-8000-004d32b10bc2", "product_id": "ETH-USD", "sequence": 4179037031, "time": "2018-07-02T05:24:21.464000Z"}
{"type": "open", "side": "sell", "price": "452.25000000", "order_id": "dfaad9ca-ce83-4f31-89b8-c522b0ababe8", "remaining_size": "0.01000000", "product_id": "ETH-USD", "sequence": 4179037032, "time": "2018-07-02T05:24:21.464000Z"}
{"type": "received", "order_id": "c7d87df5-7907-4880-b038-3a4a777bd5d1", "order_type": "limit", "size": "0.01000000", "price": "449.53000000", "side": "sell", "client_oid": "94175fcf-c856-40cb-a752-b64517077878", "product_id": "ETH-USD", "sequence": 4179037033, "time": "2018-07-02T05:24:21.472000Z"}
{"type": "open", "side": "sell", "price": "449.53000000", "order_id": "c7d87df5-7907-4880-b038-3a4a777bd5d1", "remaining_size": "0.01000000", "product_id": "ETH-USD", "sequence": 4179037034, "time": "2018-07-02T05:24:21.472000Z"}
{"type": "received", "order_id": "0f290426-28c0-4acf-b4d2-a3a06aabe8f7", "order_type": "limit", "size": "0.00200000", "price": "6298.26000000", "side": "buy", "product_id": "BTC-USD", "sequence": 6227079283, "time": "2018-07-02T05:24:21.478000Z"}
{"type": "open", "side": "buy", "price": "6298.26000000", "order_id": "0f290426-28c0-4acf-b4d2-a3a06aabe8f7", "remaining_size": "0.00200000", "product_id": "BTC-USD", "sequence": 6227079284, "time": "2018-07-02T05:24:21.478000Z"}
{"type": "done", "side": "sell", "order_id": "06389eb1-4451-429c-a04b-f014c7af0a4c", "reason": "canceled", "product_id": "BTC-USD", "price": "6303.96000000", "remaining_size": "0.01500000", "sequence": 6227079285, "time": "2018-07-02T05:24:21.495000Z"}
{"type": "received", "order_id": "882f4e3b-f08a-4e71-806c-716996ed2e0b", "order_type": "limit", "size": "0.01500000", "price": "6304.02000000", "side": "sell", "client_oid": "b7b776cc-f0bd-4e77-8025-4b6358251589", "product_id": "BTC-USD", "sequence": 6227079286, "time": "2018-07-02T05:24:21.498000Z"}
{"type": "open", "side": "sell", "price": "6304.02000000", "order_id": "882f4e3b-f08a-4e71-806c-716996ed2e0b", "remaining_size": "0.01500000", "product_id": "BTC-USD", "sequence": 6227079287, "time": "2018-07-02T05:24:21.498000Z"}
{"type": "received", "order_id": "1bb24510-9984-453b-86cc-ff89717fa6cd", "order_type": "limit", "size": "0.00100000", "price": "6304.55000000", "side": "sell", "client_oid": "b8e7bd91-f79e-464c-8000-00c34ac57ff9", "product_id": "BTC-USD", "sequence": 6227079288, "time": "2018-07-02T05:24:21.508000Z"}
{"type": "open", "side": "sell", "price": "6304.55000000", "order_id": "1bb24510-9984-453b-86cc-ff89717fa6cd", "remaining_size": "0.00100000", "product_id": "BTC-USD", "sequence": 6227079289, "time": "2018-07-02T05:24:21.508000Z"}
{"type": "done", "side": "buy", "order_id": "6eda1dc2-8c8d-4e03-a7e4-c63ab2c82e25", "reason": "canceled", "product_id": "ETH-USD", "price": "446.03000000", "remaining_size": "0.01000000", "sequence": 4179037035, "time": "2018-07-02T05:24:21.540000Z"}
{"type": "received", "order_id": "f040007a-7bee-4907-8abf-ef7f6d3b1508", "order_type": "limit", "size": "0.01000000", "price": "446.03000000", "side": "buy", "client_oid": "2cffa000-000a-41d8-bd00-0000a1d87d00", "product_id": "ETH-USD", "sequence": 4179037036, "time": "2018-07-02T05:24:21.548000Z"}
{"type": "open", "side": "buy", "price": "446.03000000", "order_id": "f040007a-7bee-4907-8abf-ef7f6d3b1508", "remaining_size": "0.01000000", "product_id": "ETH-USD", "sequence": 4179037037, "time": "2018-07-02T05:24:21.548000Z"}
{"type": "done", "side": "sell", "order_id": "3636cff1-d3d1-46e1-b4a7-4d37e1d9521e", "reason": "canceled", "product_id": "ETH-USD", "price": "450.25000000", "remaining_size": "0.01000000", "sequence": 4179037038, "time": "2018-07-02T05:24:21.845000Z"}
{"type": "done", "side": "sell", "order_id": "e932eacf-c0ce-4832-9c19-3a4c9cd7e300", "reason": "canceled", "product_id": "ETH-USD", "price": "451.25000000", "remaining_size": "0.01000000", "sequence": 4179037039, "time": "2018-07-02T05:24:21.858000Z"}
{"type": "done", "side": "sell", "order_id": "dfaad9ca-ce83-4f31-89b8-c522b0ababe8", "reason": "canceled", "product_id": "ETH-USD", "price": "452.25000000", "remaining_size": "0.01000000", "sequence": 4179037040, "time": "2018-07-02T05:24:21.860000Z"}
{"type": "done", "side": "sell", "order_id": "2027b87e-2085-4684-a964-97e730716c89", "reason": "canceled", "product_id": "ETH-USD", "price": "454.25000000", "remaining_size": "0.01000000", "sequence": 4179037041, "time": "2018-07-02T05:24:21.861000Z"}
{"type": "done", "side": "buy", "order_id": "40d54d70-8bcd-4b18-a5d4-9cbb3a1ffb4f", "reason": "canceled", "product_id": "ETH-USD", "price": "445.48000000", "remaining_size": "2.61338600", "sequence": 4179037042, "time": "2018-07-02T05:24:21.861000Z"}
{"type": "received", "order_id": "3905aeda-fdaa-453d-8821-95ff83e262d8", "order_type": "limit", "size": "0.01000000", "price": "455.25000000", "side": "sell", "client_oid": "c987f894-a456-4749-8000-0050ae44fe64", "product_id": "ETH-USD", "sequence": 4179037043, "time": "2018-07-02T05:24:21.863000Z"}
{"type": "open", "side": "sell", "price": "455.25000000", "order_id": "3905aeda-fdaa-453d-8821-95ff83e262d8", "remaining_size": "0.01000000", "product_id": "ETH-USD", "sequence": 4179037044, "time": "2018-07-02T05:24:21.863000Z"}
{"type": "done", "side": "sell", "order_id": "96d2981a-a84a-4c06-80a9-0490225efef9", "reason": "canceled", "product_id": "ETH-USD", "price": "453.25000000", "remaining_size": "0.01000000", "sequence": 4179037045, "time": "2018-07-02T05:24:21.864000Z"}
{"type": "done", "side": "buy", "order_id": "eebbe5e3-449f-499c-9ff8-400751057da9", "reason": "canceled", "product_id": "ETH-USD", "price": "445.35000000", "remaining_size": "8.10882300", "sequence": 4179037046, "time": "2018-07-02T05:24:21.865000Z"}
{"type": "done", "side": "buy", "order_id": "4201d0b8-12b7-4e51-a1d8-210dca0b4ec8", "reason": "canceled", "product_id": "ETH-USD", "price": "445.09000000", "remaining_size": "6.32147800", "sequence": 4179037047, "time": "2018-07-02T05:24:21.868000Z"}
{"type": "done", "side": "buy", "order_id": "cbf530f7-eb6a-4218-9b1e-f7cf1e319348", "reason": "canceled", "product_id": "ETH-USD", "price": "443.92000000", "remaining_size": "2.14962400", "sequence": 4179037048, "time": "2018-07-02T05:24:21.870000Z"}
{"type": "done", "side": "buy", "order_id": "d165017b-404c-4734-9d2f-4d2dc1db2030", "reason": "canceled", "product_id": "ETH-USD", "price": "443.79000000", "remaining_size": "2.34888900", "sequence": 4179037049, "time": "2018-07-02T05:24:21.872000Z"}
{"type": "done", "side": "buy", "order_id": "ff9899f6-a8e1-4a10-914f-9c86d6a2f8ba", "reason": "canceled", "product_id": "ETH-USD", "price": "443.66000000", "remaining_size": "1.08869100", "sequence": 4179037050, "time": "2018-07-02T05:24:21.880000Z"}
{"type": "done", "side": "sell", "order_id": "cec1f9ee-059f-4e6a-a640-f1d7e5c9b7db", "reason": "canceled", "product_id": "BTC-USD", "price": "6313.32000000", "remaining_size": "0.25000000", "sequence": 6227079290, "time": "2018-07-02T05:24:21.907000Z"}
{"type": "received", "order_id": "4ebce167-81ad-4ae3-b57b-3900cb755d86", "order_type": "limit", "size": "2.26610200", "price": "445.48000000", "side": "buy", "client_oid": "006319c1-9642-4033-b1f4-9ced18ebbb95", "product_id": "ETH-USD", "sequence": 4179037051, "time": "2018-07-02T05:24:21.909000Z"}
{"type": "open", "side": "buy", "price": "445.48000000", "order_id": "4ebce167-81ad-4ae3-b57b-3900cb755d86", "remaining_size": "2.26610200", "product_id": "ETH-USD", "sequence": 4179037052, "time": "2018-07-02T05:24:21.909000Z"}
{"type": "done", "side": "buy", "order_id": "582c7858-5e41-4da5-be49-3e7a38f93e08", "reason": "canceled", "product_id": "ETH-USD", "price": "442.61000000", "remaining_size": "1.00534000", "sequence": 4179037053, "time": "2018-07-02T05:24:21.919000Z"}
{"type": "received", "order_id": "ae1df128-4194-47d8-a00d-75cbdef92f85", "order_type": "limit", "size": "0.25000000", "price": "6311.42000000", "side": "sell", "client_oid": "8acb6ef3-91f6-484f-ae83-18c0a077fb65", "product_id": "BTC-USD", "sequence": 6227079291, "time": "2018-07-02T05:24:21.922000Z"}
{"type": "received", "order_id": "d884f5c5-d1ab-454f-a9eb-2657ce57c96c", "order_type": "limit", "size": "7.97241500", "price": "445.35000000", "side": "buy", "client_oid": "ad0eebe0-2743-4810-b415-90b561fbdca1", "product_id": "ETH-USD", "sequence": 4179037054, "time": "2018-07-02T05:24:21.920000Z"}
{"type": "open", "side": "buy", "price": "445.35000000", "order_id": "d884f5c5-d1ab-454f-a9eb-2657ce57c96c", "remaining_size": "7.97241500", "product_id": "ETH-USD", "sequence": 4179037055, "time": "2018-07-02T05:24:21.920000Z"}
{"type": "open", "side": "sell", "price": "6311.42000000", "order_id": "ae1df128-4194-47d8-a00d-75cbdef92f85", "remaining_size": "0.25000000", "product_id": "BTC-USD", "sequence": 6227079292, "time": "2018-07-02T05:24:21.922000Z"}
{"type": "received", "order_id": "44a55de8-f40e-4524-be40-8e92f864a1f4", "order_type": "limit", "size": "6.08299000", "price": "445.09000000", "side": "buy", "client_oid": "791768dc-99b1-48a9-a50e-81c6e8827385", "product_id": "ETH-USD", "sequence": 4179037056, "time": "2018-07-02T05:24:21.931000Z"}
{"type": "open", "side": "buy", "price": "445.09000000", "order_id": "44a55de8-f40e-4524-be40-8e92f864a1f4", "remaining_size": "6.08299000", "product_id": "ETH-USD", "sequence": 4179037057, "time": "2018-07-02T05:24:21.931000Z"}
{"type": "received", "order_id": "bd765151-6495-4a0d-a3e8-a19eb3978e0c", "order_type": "limit", "size": "2.25161800", "price": "443.92000000", "side": "buy", "client_oid": "62bf5e34-a652-498a-b1f3-875481ec3cc0", "product_id": "ETH-USD", "sequence": 4179037058, "time": "2018-07-02T05:24:21.942000Z"}
{"type": "open", "side": "buy", "price": "443.92000000", "order_id": "bd765151-6495-4a0d-a3e8-a19eb3978e0c", "remaining_size": "2.25161800", "product_id": "ETH-USD", "sequence": 4179037059, "time": "2018-07-02T05:24:21.942000Z"}
{"type": "received", "order_id": "936548c7-2a0d-410a-84d5-a19b0663b77b", "order_type": "limit", "size": "2.33596800", "price": "443.79000000", "side": "buy", "client_oid": "1f58a979-b6fa-4f43-bf4e-2ac5540cd88a", "product_id": "ETH-USD", "sequence": 4179037060, "time": "2018-07-02T05:24:21.952000Z"}
{"type": "open", "side": "buy", "price": "443.79000000", "order_id": "936548c7-2a0d-410a-84d5-a19b0663b77b", "remaining_size": "2.33596800", "product_id": "ETH-USD", "sequence": 4179037061, "time": "2018-07-02T05:24:21.952000Z"}
{"type": "received", "order_id": "cb8b395c-87e4-4b4a-9b1e-99d187ccbeb5", "order_type": "limit", "size": "1.72445700", "price": "443.66000000", "side": "buy", "client_oid": "9fd6c7cf-b041-49be-bd07-497b74090143", "product_id": "ETH-USD", "sequence": 4179037062, "time": "2018-07-02T05:24:21.961000Z"}
{"type": "open", "side": "buy", "price": "443.66000000", "order_id": "cb8b395c-87e4-4b4a-9b1e-99d187ccbeb5", "remaining_size": "1.72445700", "product_id": "ETH-USD", "sequence": 4179037063, "time": "2018-07-02T05:24:21.961000Z"}
{"type": "received", "order_id": "2e874a92-0eb5-4da1-a68d-2c99526d45a0", "order_type": "limit", "size": "93.00000000", "price": "447.17000000", "side": "sell", "client_oid": "8bea7831-817f-429a-95d9-e51785ab695d", "product_id": "ETH-USD", "sequence": 4179037064, "time": "2018-07-02T05:24:22.001000Z"}
{"type": "open", "side": "sell", "price": "447.17000000", "order_id": "2e874a92-0eb5-4da1-a68d-2c99526d45a0", "remaining_size": "93.00000000", "product_id": "ETH-USD", "sequence": 4179037065, "time": "2018-07-02T05:24:22.001000Z"}
{"type": "done", "side": "sell", "order_id": "ae1df128-4194-47d8-a00d-75cbdef92f85", "reason": "canceled", "product_id": "BTC-USD", "price": "6311.42000000", "remaining_size": "0.25000000", "sequence": 6227079293, "time": "2018-07-02T05:24:22.028000Z"}
{"type": "received", "order_id": "7a6d2ff9-6310-41a1-9294-045ba03402bd", "order_type": "limit", "size": "0.25000000", "price": "6313.30000000", "side": "sell", "client_oid": "56be0b54-7682-4752-bd0c-70ab32f2af90", "product_id": "BTC-USD", "sequence": 6227079294, "time": "2018-07-02T05:24:22.043000Z"}
{"type": "open", "side": "sell", "price": "6313.30000000", "order_id": "7a6d2ff9-6310-41a1-9294-045ba03402bd", "remaining_size": "0.25000000", "product_id": "BTC-USD", "sequence": 6227079295, "time": "2018-07-02T05:24:22.044000Z"}
{"type": "done", "side": "buy", "order_id": "f040007a-7bee-4907-8abf-ef7f6d3b1508", "reason": "canceled", "product_id": "ETH-USD", "price": "446.03000000", "remaining_size": "0.01000000", "sequence": 4179037066, "time": "2018-07-02T05:24:22.073000Z"}
{"type": "received", "order_id": "702586c4-e868-4902-922b-961ca0c9fc64", "order_type": "limit", "size": "0.01000000", "price": "446.03000000", "side": "buy", "client_oid": "f314e500-0000-483f-9014-00000083f501", "product_id": "ETH-USD", "sequence": 4179037067, "time": "2018-07-02T05:24:22.084000Z"}
{"type": "open", "side": "buy", "price": "446.03000000", "order_id": "702586c4-e868-4902-922b-961ca0c9fc64", "remaining_size": "0.01000000", "product_id": "ETH-USD", "sequence": 4179037068, "time": "2018-07-02T05:24:22.084000Z"}
{"type": "done", "side": "sell", "order_id": "636df6a9-768b-4f68-9500-4964d3e7cd5b", "reason": "canceled", "product_id": "ETH-USD", "price": "470.67000000", "remaining_size": "0.01000000", "sequence": 4179037069, "time": "2018-07-02T05:24:22.087000Z"}
{"type": "done", "side": "sell", "order_id": "7a6d2ff9-6310-41a1-9294-045ba03402bd", "reason": "canceled", "product_id": "BTC-USD", "price": "6313.30000000", "remaining_size": "0.25000000", "sequence": 6227079296, "time": "2018-07-02T05:24:22.107000Z"}
{"type": "done", "side": "buy", "order_id": "92553375-c4aa-4d36-a177-0f0ff7d16716", "reason": "canceled", "product_id": "BTC-USD", "price": "6144.61000000", "remaining_size": "0.00150000", "sequence": 6227079297, "time": "2018-07-02T05:24:22.110000Z"}
{"type": "received", "order_id": "6f5a1fb0-eecc-46e7-b2db-43534dc9c147", "order_type": "limit", "size": "0.00150000", "price": "6116.50000000", "side": "buy", "client_oid": "e8100181-635e-4f2d-8000-00cd667e9b93", "product_id": "BTC-USD", "sequence": 6227079298, "time": "2018-07-02T05:24:22.116000Z"}
{"type": "open", "side": "buy", "price": "6116.50000000", "order_id": "6f5a1fb0-eecc-46e7-b2db-43534dc9c147", "remaining_size": "0.00150000", "product_id": "BTC-USD", "sequence": 6227079299, "time": "2018-07-02T05:24:22.116000Z"}
{"type": "received", "order_id": "c893695c-0ee9-4ea3-a784-878d01bd6801", "order_type": "limit", "size": "0.01000000", "price": "472.67000000", "side": "sell", "client_oid": "870d2ea2-253e-4965-8000-0033b49ecdce", "product_id": "ETH-USD", "sequence": 4179037070, "time": "2018-07-02T05:24:22.119000Z"}
{"type": "open", "side": "sell", "price": "472.67000000", "order_id": "c893695c-0ee9-4ea3-a784-878d01bd6801", "remaining_size": "0.01000000", "product_id": "ETH-USD", "sequence": 4179037071, "time": "2018-07-02T05:24:22.119000Z"}
{"type": "received", "order_id": "49280993-6cfd-44cb-a6a8-f3a86eb7e2f3", "order_type": "limit", "size": "0.25000000", "price": "6311.40000000", "side": "sell", "client_oid": "28231d95-b100-464c-ae67-6fb9e1c8bd1a", "product_id": "BTC-USD", "sequence": 6227079300, "time": "2018-07-02T05:24:22.124000Z"}
{"type": "open", "side": "sell", "price": "6311.40000000", "order_id": "49280993-6cfd-44cb-a6a8-f3a86eb7e2f3", "remaining_size": "0.25000000", "product_id": "BTC-USD", "sequence": 6227079301, "time": "2018-07-02T05:24:22.124000Z"}
{"type": "done", "side": "sell", "order_id": "2ca9802b-0cc6-4afa-9607-afcc7c49be32", "reason": "canceled", "product_id": "ETH-USD", "price": "447.17000000", "remaining_size": "0.01057000", "sequence": 4179037072, "time": "2018-07-02T05:24:22.125000Z"}
{"type": "received", "order_id": "62d3815d-cdbd-4548-9bb6-cfd1aa03fed9", "order_type": "limit", "size": "0.01023000", "price": "447.17000000", "side": "sell", "client_oid": "2d3d96c0-7db8-11e8-874f-16be7828d23e", "product_id": "ETH-USD", "sequence": 4179037073, "time": "2018-07-02T05:24:22.134000Z"}
{"type": "open", "side": "sell", "price": "447.17000000", "order_id": "62d3815d-cdbd-4548-9bb6-cfd1aa03fed9", "remaining_size": "0.01023000", "product_id": "ETH-USD", "sequence": 4179037074, "time": "2018-07-02T05:24:22.134000Z"}
{"type": "done", "side": "sell", "order_id": "49280993-6cfd-44cb-a6a8-f3a86eb7e2f3", "reason": "canceled", "product_id": "BTC-USD", "price": "6311.40000000", "remaining_size": "0.25000000", "sequence": 6227079302, "time": "2018-07-02T05:24:22.166000Z"}
{"type": "done", "side": "buy", "order_id": "702586c4-e868-4902-922b-961ca0c9fc64", "reason": "canceled", "product_id": "ETH-USD", "price": "446.03000000", "remaining_size": "0.01000000", "sequence": 4179037075, "time": "2018-07-02T05:24:22.174000Z"}
{"type": "received", "order_id": "3d597912-d6f0-4179-8c09-f3a6d0267aa7", "order_type": "limit", "size": "0.25000000", "price": "6311.37000000", "side": "sell", "client_oid": "cd60ce5a-b2ec-46c9-b551-00a5094a1aad", "product_id": "BTC-USD", "sequence": 6227079303, "time": "2018-07-02T05:24:22.180000Z"}
{"type": "open", "side": "sell", "price": "6311.37000000", "order_id": "3d597912-d6f0-4179-8c09-f3a6d0267aa7", "remaining_size": "0.25000000", "product_id": "BTC-USD", "sequence": 6227079304, "time": "2018-07-02T05:24:22.180000Z"}
{"type": "done", "side": "buy", "order_id": "49d7e91e-1ea8-49e0-9175-d3afa3800f25", "reason": "canceled", "product_id": "ETH-USD", "price": "446.34000000", "remaining_size": "13.00000000", "sequence": 4179037076, "time": "2018-07-02T05:24:22.180000Z"}
{"type": "received", "order_id": "17ef1946-8505-415e-ab4b-7fca29c38cdf", "order_type": "limit", "size": "0.01000000", "price": "446.03000000", "side": "buy", "client_oid": "13bf3500-0000-492b-9425-00000092b542", "product_id": "ETH-USD", "sequence": 4179037077, "time": "2018-07-02T05:24:22.181000Z"}
{"type": "open", "side": "buy", "price": "446.03000000", "order_id": "17ef1946-8505-415e-ab4b-7fca29c38cdf", "remaining_size": "0.01000000", "product_id": "ETH-USD", "sequence": 4179037078, "time": "2018-07-02T05:24:22.181000Z"}
{"type": "done", "side": "sell", "order_id": "3905aeda-fdaa-453d-8821-95ff83e262d8", "reason": "canceled", "product_id": "ETH-USD", "price": "455.25000000", "remaining_size": "0.01000000", "sequence": 4179037079, "time": "2018-07-02T05:24:22.196000Z"}
{"type": "done", "side": "buy", "order_id": "1c9e0b9c-c77d-4097-bf5c-fe4d4697f2c9", "reason": "canceled", "product_id": "ETH-USD", "price": "446.71000000", "remaining_size": "0.06000000", "sequence": 4179037080, "time": "2018-07-02T05:24:22.197000Z"}
{"type": "received", "order_id": "88d5ca16-aec9-478e-b9bc-ed7300c7a785", "order_type": "limit", "size": "13.00000000", "price": "445.81000000", "side": "buy", "client_oid": "559a084b-a210-46bb-bcbb-3862db0edb31", "product_id": "ETH-USD", "sequence": 4179037081, "time": "2018-07-02T05:24:22.211000Z"}
{"type": "open", "side": "buy", "price": "445.81000000", "order_id": "88d5ca16-aec9-478e-b9bc-ed7300c7a785", "remaining_size": "13.00000000", "product_id": "ETH-USD", "sequence": 4179037082, "time": "2018-07-02T05:24:22.211000Z"}
{"type": "received", "order_id": "ddbca297-58ed-4987-9f6b-39616cb8415d", "order_type": "limit", "size": "0.01000000", "price": "447.17000000", "side": "sell", "client_oid": "3ab36717-d993-4b4b-8b8b-31b17c678ef1", "product_id": "ETH-USD", "sequence": 4179037083, "time": "2018-07-02T05:24:22.212000Z"}
{"type": "open", "side": "sell", "price": "447.17000000", "order_id": "ddbca297-58ed-4987-9f6b-39616cb8415d", "remaining_size": "0.01000000", "product_id": "ETH-USD", "sequence": 4179037084, "time": "2018-07-02T05:24:22.212000Z"}
{"type": "done", "side": "buy", "order_id": "17ef1946-8505-415e-ab4b-7fca29c38cdf", "reason": "canceled", "product_id": "ETH-USD", "price": "446.03000000", "remaining_size": "0.01000000", "sequence": 4179037085, "time": "2018-07-02T05:24:22.311000Z"}
{"type": "received", "order_id": "5502b694-af82-43b7-9c6d-4320d4fa88bb", "order_type": "limit", "size": "0.01000000", "price": "446.03000000", "side": "buy", "client_oid": "b81a9000-0003-497b-a420-0000397b2420", "product_id": "ETH-USD", "sequence": 4179037086, "time": "2018-07-02T05:24:22.317000Z"}
{"type": "open", "side": "buy", "price": "446.03000000", "order_id": "5502b694-af82-43b7-9c6d-4320d4fa88bb", "remaining_size": "0.01000000", "product_id": "ETH-USD", "sequence": 4179037087, "time": "2018-07-02T05:24:22.317000Z"}
{"type": "received", "order_id": "d46109a5-23eb-4994-818c-cbb904e8198a", "order_type": "market", "size": "1.33180000", "side": "buy", "funds": "595.5410060000000000", "product_id": "ETH-USD", "sequence": 4179037088, "time": "2018-07-02T05:24:22.325000Z"}
{"type": "match", "trade_id": 36819235, "maker_order_id": "53556bf5-8025-4ff8-9535-31dd5a1408e8", "taker_order_id": "d46109a5-23eb-4994-818c-cbb904e8198a", "side": "sell", "size": "0.11000000", "price": "447.17000000", "product_id": "ETH-USD", "sequence": 4179037089, "time": "2018-07-02T05:24:22.325000Z"}
{"type": "done", "side": "sell", "order_id": "53556bf5-8025-4ff8-9535-31dd5a1408e8", "reason": "filled", "product_id": "ETH-USD", "price": "447.17000000", "remaining_size": "0.00000000", "sequence": 4179037090, "time": "2018-07-02T05:24:22.325000Z"}
{"type": "match", "trade_id": 36819236, "maker_order_id": "0b44ffa9-2626-4012-87ef-19450071be1b", "taker_order_id": "d46109a5-23eb-4994-818c-cbb904e8198a", "side": "sell", "size": "0.19433648", "price": "447.17000000", "product_id": "ETH-USD", "sequence": 4179037091, "time": "2018-07-02T05:24:22.325000Z"}
{"type": "done", "side": "sell", "order_id": "0b44ffa9-2626-4012-87ef-19450071be1b", "reason": "filled", "product_id": "ETH-USD", "price": "447.17000000", "remaining_size": "0.00000000", "sequence": 4179037092, "time": "2018-07-02T05:24:22.325000Z"}
{"type": "match", "trade_id": 36819237, "maker_order_id": "7f025f87-6525-4e65-bbe6-03a85eaa9332", "taker_order_id": "d46109a5-23eb-4994-818c-cbb904e8198a", "side": "sell", "size": "0.01795211", "price": "447.17000000", "product_id": "ETH-USD", "sequence": 4179037093, "time": "2018-07-02T05:24:22.325000Z"}
{"type": "done", "side": "sell", "order_id": "7f025f87-6525-4e65-bbe6-03a85eaa9332", "reason": "filled", "product_id": "ETH-USD", "price": "447.17000000", "remaining_size": "0.00000000", "sequence": 4179037094, "time": "2018-07-02T05:24:22.325000Z"}
{"type": "match", "trade_id": 36819238, "maker_order_id": "ae6d8782-220c-49d6-8a60-4a69408a5184", "taker_order_id": "d46109a5-23eb-4994-818c-cbb904e8198a", "side": "sell", "size": "0.01000000", "price": "447.17000000", "product_id": "ETH-USD", "sequence": 4179037095, "time": "2018-07-02T05:24:22.325000Z"}
{"type": "done", "side": "sell", "order_id": "ae6d8782-220c-49d6-8a60-4a69408a5184", "reason": "filled", "product_id": "ETH-USD", "price": "447.17000000", "remaining_size": "0.00000000", "sequence": 4179037096, "time": "2018-07-02T05:24:22.325000Z"}
{"type": "match", "trade_id": 36819239, "maker_order_id": "c817e185-6625-4456-a12b-a1deb6760e5e", "taker_order_id": "d46109a5-23eb-4994-818c-cbb904e8198a", "side": "sell", "size": "0.01000000", "price": "447.17000000", "product_id": "ETH-USD", "sequence": 4179037097, "time": "2018-07-02T05:24:22.325000Z"}
{"type": "done", "side": "sell", "order_id": "c817e185-6625-4456-a12b-a1deb6760e5e", "reason": "filled", "product_id": "ETH-USD", "price": "447.17000000", "remaining_size": "0.00000000", "sequence": 4179037098, "time": "2018-07-02T05:24:22.325000Z"}
{"type": "match", "trade_id": 36819240, "maker_order_id": "3e17f0e2-3976-46cb-ab2b-355ee3a55a2c", "taker_order_id": "d46109a5-23eb-4994-818c-cbb904e8198a", "side": "sell", "size": "0.01000000", "price": "447.17000000", "product_id": "ETH-USD", "sequence": 4179037099, "time": "2018-07-02T05:24:22.325000Z"}
{"type": "done", "side": "sell", "order_id": "3e17f0e2-3976-46cb-ab2b-355ee3a55a2c", "reason": "filled", "product_id": "ETH-USD", "price": "447.17000000", "remaining_size": "0.00000000", "sequence": 4179037100, "time": "2018-07-02T05:24:22.325000Z"}
{"type": "match", "trade_id": 36819241, "maker_order_id": "7f952836-6256-4af2-8d58-389176fc172f", "taker_order_id": "d46109a5-23eb-4994-818c-cbb904e8198a", "side": "sell", "size": "0.01000000", "price": "447.17000000", "product_id": "ETH-USD", "sequence": 4179037101, "time": "2018-07-02T05:24:22.325000Z"}
{"type": "done", "side": "sell", "order_id": "7f952836-6256-4af2-8d58-389176fc172f", "reason": "filled", "product_id": "ETH-USD", "price": "447.17000000", "remaining_size": "0.00000000", "sequence": 4179037102, "time": "2018-07-02T05:24:22.325000Z"}
{"type": "match", "trade_id": 36819242, "maker_order_id": "cbaa8bfe-c296-427c-aaed-5f16d599186d", "taker_order_id": "d46109a5-23eb-4994-818c-cbb904e8198a", "side": "sell", "size": "0.01000000", "price": "447.17000000", "product_id": "ETH-USD", "sequence": 4179037103, "time": "2018-07-02T05:24:22.325000Z"}
{"type": "done", "side": "sell", "order_id": "cbaa8bfe-c296-427c-aaed-5f16d599186d", "reason": "filled", "product_id": "ETH-USD", "price": "447.17000000", "remaining_size": "0.00000000", "sequence": 4179037104, "time": "2018-07-02T05:24:22.325000Z"}
{"type": "match", "trade_id": 36819243, "maker_order_id": "504b1e9f-9b2b-410a-b0ed-96fcf0cc74aa", "taker_order_id": "d46109a5-23eb-4994-818c-cbb904e8198a", "side": "sell", "size": "0.01000000", "price": "447.17000000", "product_id": "ETH-USD", "sequence": 4179037105, "time": "2018-07-02T05:24:22.325000Z"}
{"type": "done", "side": "sell", "order_id": "504b1e9f-9b2b-410a-b0ed-96fcf0cc74aa", "reason": "filled", "product_id": "ETH-USD", "price": "447.17000000", "remaining_size": "0.00000000", "sequence": 4179037106, "time": "2018-07-02T05:24:22.325000Z"}
{"type": "match", "trade_id": 36819244, "maker_order_id": "b021670e-6b2a-4bba-9a26-638b64a45365", "taker_order_id": "d46109a5-23eb-4994-818c-cbb904e8198a", "side": "sell", "size": "0.14000000", "price": "447.17000000", "product_id": "ETH-USD", "sequence": 4179037107, "time": "2018-07-02T05:24:22.325000Z"}
{"type": "done", "side": "sell", "order_id": "b021670e-6b2a-4bba-9a26-638b64a45365", "reason": "filled", "product_id": "ETH-USD", "price": "447.17000000", "remaining_size": "0.00000000", "sequence": 4179037108, "time": "2018-07-02T05:24:22.325000Z"}
{"type": "match", "trade_id": 36819245, "maker_order_id": "2876399b-0dd5-417a-9b4c-c0844f7b18a1", "taker_order_id": "d46109a5-23eb-4994-818c-cbb904e8198a", "side": "sell", "size": "0.01000000", "price": "447.17000000", "product_id": "ETH-USD", "sequence": 4179037109, "time": "2018-07-02T05:24:22.325000Z"}
{"type": "done", "side": "sell", "order_id": "2876399b-0dd5-417a-9b4c-c0844f7b18a1", "reason": "filled", "product_id": "ETH-USD", "price": "447.17000000", "remaining_size": "0.00000000", "sequence": 4179037110, "time": "2018-07-02T05:24:22.325000Z"}
{"type": "match", "trade_id": 36819246, "maker_order_id": "bf683695-b772-4743-836f-09c0c004a62a", "taker_order_id": "d46109a5-23eb-4994-818c-cbb904e8198a", "side": "sell", "size": "0.79951141", "price": "447.17000000", "product_id": "ETH-USD", "sequence": 4179037111, "time": "2018-07-02T05:24:22.325000Z"}
{"type": "done", "side": "buy", "order_id": "d46109a5-23eb-4994-818c-cbb904e8198a", "reason": "filled", "product_id": "ETH-USD", "remaining_size": "0.00000000", "sequence": 4179037112, "time": "2018-07-02T05:24:22.325000Z"}
{"type": "done", "side": "sell", "order_id": "f21355fc-d61b-441d-ba48-a739baeb557f", "reason": "canceled", "product_id": "ETH-USD", "price": "447.17000000", "remaining_size": "2.68391400", "sequence": 4179037113, "time": "2018-07-02T05:24:22.328000Z"}
{"type": "received", "order_id": "3422c29a-af8a-4a03-ac9d-b6a4da695aa8", "order_type": "limit", "size": "0.01000000", "price": "447.25000000", "side": "sell", "client_oid": "a1684a30-ec69-4db6-8000-00fd84a130bb", "product_id": "ETH-USD", "sequence": 4179037114, "time": "2018-07-02T05:24:22.338000Z"}
{"type": "open", "side": "sell", "price": "447.25000000", "order_id": "3422c29a-af8a-4a03-ac9d-b6a4da695aa8", "remaining_size": "0.01000000", "product_id": "ETH-USD", "sequence": 4179037115, "time": "2018-07-02T05:24:22.338000Z"}
{"type": "received", "order_id": "b4c4fcc2-4277-4305-9c67-86e58fd27878", "order_type": "limit", "size": "0.96891000", "price": "442.62000000", "side": "buy", "product_id": "ETH-USD", "sequence": 4179037116, "time": "2018-07-02T05:24:22.345000Z"}
{"type": "open", "side": "buy", "price": "442.62000000", "order_id": "b4c4fcc2-4277-4305-9c67-86e58fd27878", "remaining_size": "0.96891000", "product_id": "ETH-USD", "sequence": 4179037117, "time": "2018-07-02T05:24:22.345000Z"}
{"type": "done", "side": "sell", "order_id": "bf683695-b772-4743-836f-09c0c004a62a", "reason": "canceled", "product_id": "ETH-USD", "price": "447.17000000", "remaining_size": "10.38048859", "sequence": 4179037118, "time": "2018-07-02T05:24:22.357000Z"}
{"type": "done", "side": "sell", "order_id": "1d517bbf-1c7b-4697-b57a-fa3c278ad742", "reason": "canceled", "product_id": "ETH-USD", "price": "447.17000000", "remaining_size": "4.00000000", "sequence": 4179037119, "time": "2018-07-02T05:24:22.365000Z"}
{"type": "received", "order_id": "2aa4e794-8274-4775-be3b-152995de5217", "order_type": "limit", "size": "0.12000000", "price": "446.67000000", "side": "buy", "client_oid": "14be677c-4f0b-4718-9858-aec3a02e9a7b", "product_id": "ETH-USD", "sequence": 4179037120, "time": "2018-07-02T05:24:22.379000Z"}
{"type": "open", "side": "buy", "price": "446.67000000", "order_id": "2aa4e794-8274-4775-be3b-152995de5217", "remaining_size": "0.12000000", "product_id": "ETH-USD", "sequence": 4179037121, "time": "2018-07-02T05:24:22.379000Z"}
{"type": "received", "order_id": "c1ec74e2-789f-4fb8-bf13-b6add700ff8d", "order_type": "limit", "size": "0.10000000", "price": "447.17000000", "side": "sell", "client_oid": "ad0b05f8-6950-4b3f-8ffd-0eba2ecb7773", "product_id": "ETH-USD", "sequence": 4179037122, "time": "2018-07-02T05:24:22.383000Z"}
{"type": "open", "side": "sell", "price": "447.17000000", "order_id": "c1ec74e2-789f-4fb8-bf13-b6add700ff8d", "remaining_size": "0.10000000", "product_id": "ETH-USD", "sequence": 4179037123, "time": "2018-07-02T05:24:22.383000Z"}
{"type": "received", "order_id": "ed30355c-671e-4fd2-93ec-f612b51da28f", "order_type": "limit", "size": "0.00100000", "price": "6392.64000000", "side": "sell", "client_oid": "4429a684-5c95-4a9f-85b1-ece4d7c6f85f", "product_id": "BTC-USD", "sequence": 6227079305, "time": "2018-07-02T05:24:22.429000Z"}
{"type": "open", "side": "sell", "price": "6392.64000000", "order_id": "ed30355c-671e-4fd2-93ec-f612b51da28f", "remaining_size": "0.00100000", "product_id": "BTC-USD", "sequence": 6227079306, "time": "2018-07-02T05:24:22.429000Z"}
{"type": "done", "side": "buy", "order_id": "9db78cec-1e1b-4486-a577-0d9aa1a0b8fd", "reason": "canceled", "product_id": "ETH-USD", "price": "442.61000000", "remaining_size": "0.86565000", "sequence": 4179037124, "time": "2018-07-02T05:24:22.436000Z"}
{"type": "done", "side": "buy", "order_id": "5502b694-af82-43b7-9c6d-4320d4fa88bb", "reason": "canceled", "product_id": "ETH-USD", "price": "446.03000000", "remaining_size": "0.01000000", "sequence": 4179037125, "time": "2018-07-02T05:24:22.444000Z"}
{"type": "done", "side": "sell", "order_id": "3d597912-d6f0-4179-8c09-f3a6d0267aa7", "reason": "canceled", "product_id": "BTC-USD", "price": "6311.37000000", "remaining_size": "0.25000000", "sequence": 6227079307, "time": "2018-07-02T05:24:22.447000Z"}
{"type": "received", "order_id": "fa21e215-ec3b-4d78-a112-b22346423ab8", "order_type": "limit", "size": "0.86560000", "price": "442.63000000", "side": "buy", "client_oid": "c104826a-532e-4685-9a4a-60c3881396c1", "product_id": "ETH-USD", "sequence": 4179037126, "time": "2018-07-02T05:24:22.447000Z"}
{"type": "open", "side": "buy", "price": "442.63000000", "order_id": "fa21e215-ec3b-4d78-a112-b22346423ab8", "remaining_size": "0.86560000", "product_id": "ETH-USD", "sequence": 4179037127, "time": "2018-07-02T05:24:22.447000Z"}
{"type": "received", "order_id": "09a9dedc-0d11-4ea5-a02e-13132056630b", "order_type": "limit", "size": "0.01000000", "price": "445.96000000", "side": "buy", "client_oid": "987b7400-0000-4ff0-b4b0-00000ff0f4b0", "product_id": "ETH-USD", "sequence": 4179037128, "time": "2018-07-02T05:24:22.450000Z"}
{"type": "open", "side": "buy", "price": "445.96000000", "order_id": "09a9dedc-0d11-4ea5-a02e-13132056630b", "remaining_size": "0.01000000", "product_id": "ETH-USD", "sequence": 4179037129, "time": "2018-07-02T05:24:22.450000Z"}
{"type": "received", "order_id": "15b5b665-b9b4-493f-8238-54c2f860ff32", "order_type": "limit", "size": "4.00000000", "price": "447.43000000", "side": "sell", "client_oid": "997d24c3-f94d-48d5-a428-3871a634b0ad", "product_id": "ETH-USD", "sequence": 4179037130, "time": "2018-07-02T05:24:22.459000Z"}
{"type": "open", "side": "sell", "price": "447.43000000", "order_id": "15b5b665-b9b4-493f-8238-54c2f860ff32", "remaining_size": "4.00000000", "product_id": "ETH-USD", "sequence": 4179037131, "time": "2018-07-02T05:24:22.459000Z"}
{"type": "received", "order_id": "78da27e1-5a33-4d34-a74d-ea7aa12d5cd3", "order_type": "limit", "size": "0.25000000", "price": "6313.32000000", "side": "sell", "client_oid": "2975384d-c36c-45df-8b1f-cd76143c6c40", "product_id": "BTC-USD", "sequence": 6227079308, "time": "2018-07-02T05:24:22.463000Z"}
{"type": "open", "side": "sell", "price": "6313.32000000", "order_id": "78da27e1-5a33-4d34-a74d-ea7aa12d5cd3", "remaining_size": "0.25000000", "product_id": "BTC-USD", "sequence": 6227079309, "time": "2018-07-02T05:24:22.463000Z"}
{"type": "done", "side": "sell", "order_id": "882f4e3b-f08a-4e71-806c-716996ed2e0b", "reason": "canceled", "product_id": "BTC-USD", "price": "6304.02000000", "remaining_size": "0.01500000", "sequence": 6227079310, "time": "2018-07-02T05:24:22.496000Z"}
{"type": "received", "order_id": "9df23cec-7482-41e7-b5ed-68a5b3f248b9", "order_type": "limit", "size": "0.01500000", "price": "6304.01000000", "side": "sell", "client_oid": "5dfb5988-82c0-46ec-9d72-6a9a84d8930d", "product_id": "BTC-USD", "sequence": 6227079311, "time": "2018-07-02T05:24:22.502000Z"}
{"type": "open", "side": "sell", "price": "6304.01000000", "order_id": "9df23cec-7482-41e7-b5ed-68a5b3f248b9", "remaining_size": "0.01500000", "product_id": "BTC-USD", "sequence": 6227079312, "time": "2018-07-02T05:24:22.502000Z"}
{"type": "done", "side": "sell", "order_id": "78da27e1-5a33-4d34-a74d-ea7aa12d5cd3", "reason": "canceled", "product_id": "BTC-USD", "price": "6313.32000000", "remaining_size": "0.25000000", "sequence": 6227079313, "time": "2018-07-02T05:24:22.508000Z"}
{"type": "received", "order_id": "115412a4-c585-4310-80c3-dfb066197362", "order_type": "limit", "size": "0.25000000", "price": "6311.34000000", "side": "sell", "client_oid": "8f4c0bdc-a05b-483e-add3-2fcbf5c8b84e", "product_id": "BTC-USD", "sequence": 6227079314, "time": "2018-07-02T05:24:22.522000Z"}
{"type": "open", "side": "sell", "price": "6311.34000000", "order_id": "115412a4-c585-4310-80c3-dfb066197362", "remaining_size": "0.25000000", "product_id": "BTC-USD", "sequence": 6227079315, "time": "2018-07-02T05:24:22.522000Z"}
{"type": "done", "side": "buy", "order_id": "09a9dedc-0d11-4ea5-a02e-13132056630b", "reason": "canceled", "product_id": "ETH-USD", "price": "445.96000000", "remaining_size": "0.01000000", "sequence": 4179037132, "time": "2018-07-02T05:24:22.553000Z"}
{"type": "received", "order_id": "97e8fda7-b240-40c9-8a0f-44d1c2c892d0", "order_type": "limit", "size": "0.01000000", "price": "446.01000000", "side": "buy", "client_oid": "93b5a000-0006-4a27-b900-00006a27b900", "product_id": "ETH-USD", "sequence": 4179037133, "time": "2018-07-02T05:24:22.559000Z"}
{"type": "open", "side": "buy", "price": "446.01000000", "order_id": "97e8fda7-b240-40c9-8a0f-44d1c2c892d0", "remaining_size": "0.01000000", "product_id": "ETH-USD", "sequence": 4179037134, "time": "2018-07-02T05:24:22.559000Z"}
{"type": "received", "order_id": "c399dc71-25b4-42a7-a5b4-284361d52fee", "order_type": "limit", "size": "0.01000000", "price": "448.25000000", "side": "sell", "client_oid": "0603a1d1-e7e6-4f79-8000-002a01008697", "product_id": "ETH-USD", "sequence": 4179037135, "time": "2018-07-02T05:24:22.570000Z"}
{"type": "open", "side": "sell", "price": "448.25000000", "order_id": "c399dc71-25b4-42a7-a5b4-284361d52fee", "remaining_size": "0.01000000", "product_id": "ETH-USD", "sequence": 4179037136, "time": "2018-07-02T05:24:22.570000Z"}
{"type": "done", "side": "sell", "order_id": "3422c29a-af8a-4a03-ac9d-b6a4da695aa8", "reason": "canceled", "product_id": "ETH-USD", "price": "447.25000000", "remaining_size": "0.01000000", "sequence": 4179037137, "time": "2018-07-02T05:24:22.605000Z"}
{"type": "received", "order_id": "c008c2a6-6fe5-43b5-887c-f60e3eb4a347", "order_type": "limit", "size": "0.01000000", "price": "449.25000000", "side": "sell", "client_oid": "75afd181-d126-4ca1-8000-0a753ce50540", "product_id": "ETH-USD", "sequence": 4179037138, "time": "2018-07-02T05:24:22.612000Z"}
{"type": "open", "side": "sell", "price": "449.25000000", "order_id": "c008c2a6-6fe5-43b5-887c-f60e3eb4a347", "remaining_size": "0.01000000", "product_id": "ETH-USD", "sequence": 4179037139, "time": "2018-07-02T05:24:22.612000Z"}
{"type": "done", "side": "buy", "order_id": "e69191db-1003-4ce0-93b6-a77ca6a666fa", "reason": "canceled", "product_id": "ETH-USD", "price": "447.09000000", "remaining_size": "0.01000000", "sequence": 4179037661, "time": "2018-07-02T05:24:28.498000Z"}
{"type": "done", "side": "sell", "order_id": "47bb652b-a631-4240-b1ac-cc779270f01f", "reason": "canceled", "product_id": "BTC-USD", "price": "6303.95000000", "remaining_size": "0.01500000", "sequence": 6227079475, "time": "2018-07-02T05:24:28.504000Z"}
{"type": "received", "order_id": "14e108e3-5ce1-4fdd-8274-d0e6dbe8be7e", "order_type": "limit", "size": "0.01500000", "price": "6303.93000000", "side": "sell", "client_oid": "f9320c80-5810-4ae7-b3df-e8c4365ac1ca", "product_id": "BTC-USD", "sequence": 6227079476, "time": "2018-07-02T05:24:28.511000Z"}
{"type": "open", "side": "sell", "price": "6303.93000000", "order_id": "14e108e3-5ce1-4fdd-8274-d0e6dbe8be7e", "remaining_size": "0.01500000", "product_id": "BTC-USD", "sequence": 6227079477, "time": "2018-07-02T05:24:28.511000Z"}
{"type": "done", "side": "sell", "order_id": "2667752d-dc0d-4005-8084-163d92363b89", "reason": "canceled", "product_id": "ETH-USD", "price": "447.25000000", "remaining_size": "0.01000000", "sequence": 4179037662, "time": "2018-07-02T05:24:28.582000Z"}
{"type": "done", "side": "sell", "order_id": "df714e5a-50ee-4fe3-8aa4-b5c2d68af259", "reason": "canceled", "product_id": "ETH-USD", "price": "449.25000000", "remaining_size": "0.01000000", "sequence": 4179037663, "time": "2018-07-02T05:24:28.585000Z"}
{"type": "done", "side": "sell", "order_id": "e2248b6b-5ff5-4bc6-b4a7-56bb32603f23", "reason": "canceled", "product_id": "ETH-USD", "price": "448.25000000", "remaining_size": "0.01000000", "sequence": 4179037664, "time": "2018-07-02T05:24:28.587000Z"}
{"type": "received", "order_id": "12d9ae80-f1b6-43ef-b2f1-3471faa5b9df", "order_type": "limit", "size": "0.01000000", "price": "451.25000000", "side": "sell", "client_oid": "7c07f926-4b64-474d-8000-001962173fef", "product_id": "ETH-USD", "sequence": 4179037665, "time": "2018-07-02T05:24:28.590000Z"}
{"type": "open", "side": "sell", "price": "451.25000000", "order_id": "12d9ae80-f1b6-43ef-b2f1-3471faa5b9df", "remaining_size": "0.01000000", "product_id": "ETH-USD", "sequence": 4179037666, "time": "2018-07-02T05:24:28.590000Z"}
{"type": "done", "side": "sell", "order_id": "cb19b976-b4b2-42d9-994c-ee58ddc51457", "reason": "canceled", "product_id": "ETH-USD", "price": "447.73000000", "remaining_size": "4.98000000", "sequence": 4179037667, "time": "2018-07-02T05:24:28.596000Z"}
{"type": "received", "order_id": "053ad1b9-2a23-4d29-bf1c-56809c6c913f", "order_type": "limit", "size": "0.01000000", "price": "450.25000000", "side": "sell", "client_oid": "40731fc2-c112-4458-8000-00232a0ee248", "product_id": "ETH-USD", "sequence": 4179037668, "time": "2018-07-02T05:24:28.596000Z"}
{"type": "open", "side": "sell", "price": "450.25000000", "order_id": "053ad1b9-2a23-4d29-bf1c-56809c6c913f", "remaining_size": "0.01000000", "product_id": "ETH-USD", "sequence": 4179037669, "time": "2018-07-02T05:24:28.596000Z"}
{"type": "done", "side": "buy", "order_id": "98a854ce-c188-448f-85e8-a58a66f9f014", "reason": "canceled", "product_id": "ETH-USD", "price": "444.82000000", "remaining_size": "1.03000000", "sequence": 4179037670, "time": "2018-07-02T05:24:28.600000Z"}
{"type": "done", "side": "buy", "order_id": "5dcd7059-4d66-494d-80ca-8e0424e7f7e5", "reason": "canceled", "product_id": "ETH-USD", "price": "446.03000000", "remaining_size": "0.01000000", "sequence": 4179037671, "time": "2018-07-02T05:24:28.613000Z"}
{"type": "received", "order_id": "9b95921b-d27e-495a-abf7-a25548e6f758", "order_type": "limit", "size": "0.01000000", "price": "446.03000000", "side": "buy", "client_oid": "9c1ab000-0000-4ad2-b520-00000ad23520", "product_id": "ETH-USD", "sequence": 4179037672, "time": "2018-07-02T05:24:28.634000Z"}
{"type": "open", "side": "buy", "price": "446.03000000", "order_id": "9b95921b-d27e-495a-abf7-a25548e6f758", "remaining_size": "0.01000000", "product_id": "ETH-USD", "sequence": 4179037673, "time": "2018-07-02T05:24:28.634000Z"}
{"type": "received", "order_id": "4e55fa20-2c29-4bf9-a348-d1d6504d8a82", "order_type": "limit", "size": "0.00200000", "price": "6298.26000000", "side": "buy", "product_id": "BTC-USD", "sequence": 6227079478, "time": "2018-07-02T05:24:28.664000Z"}
{"type": "open", "side": "buy", "price": "6298.26000000", "order_id": "4e55fa20-2c29-4bf9-a348-d1d6504d8a82", "remaining_size": "0.00200000", "product_id": "BTC-USD", "sequence": 6227079479, "time": "2018-07-02T05:24:28.664000Z"}
{"type": "received", "order_id": "735d1f9d-f1b8-4a04-bc80-7e1ebb39f805", "order_type": "limit", "size": "0.01000000", "price": "452.25000000", "side": "sell", "client_oid": "30ac9a95-16b8-4c52-8000-0fcb6ccd02d0", "product_id": "ETH-USD", "sequence": 4179037674, "time": "2018-07-02T05:24:28.711000Z"}
{"type": "open", "side": "sell", "price": "452.25000000", "order_id": "735d1f9d-f1b8-4a04-bc80-7e1ebb39f805", "remaining_size": "0.01000000", "product_id": "ETH-USD", "sequence": 4179037675, "time": "2018-07-02T05:24:28.711000Z"}
{"type": "done", "side": "buy", "order_id": "9b95921b-d27e-495a-abf7-a25548e6f758", "reason": "canceled", "product_id": "ETH-USD", "price": "446.03000000", "remaining_size": "0.01000000", "sequence": 4179037676, "time": "2018-07-02T05:24:28.722000Z"}
{"type": "received", "order_id": "02da473f-70e1-4acc-bb81-b9758a8060db", "order_type": "limit", "size": "0.01000000", "price": "446.03000000", "side": "buy", "client_oid": "3f1eb000-0005-4d25-8010-00005d250010", "product_id": "ETH-USD", "sequence": 4179037677, "time": "2018-07-02T05:24:28.728000Z"}
{"type": "open", "side": "buy", "price": "446.03000000", "order_id": "02da473f-70e1-4acc-bb81-b9758a8060db", "remaining_size": "0.01000000", "product_id": "ETH-USD", "sequence": 4179037678, "time": "2018-07-02T05:24:28.728000Z"}
{"type": "received", "order_id": "99a88527-7449-4bac-aaec-a7cdc8b9aa71", "order_type": "limit", "size": "0.09200000", "price": "444.59000000", "side": "buy", "product_id": "ETH-USD", "sequence": 4179037679, "time": "2018-07-02T05:24:28.757000Z"}
{"type": "open", "side": "buy", "price": "444.59000000", "order_id": "99a88527-7449-4bac-aaec-a7cdc8b9aa71", "remaining_size": "0.09200000", "product_id": "ETH-USD", "sequence": 4179037680, "time": "2018-07-02T05:24:28.757000Z"}
{"type": "received", "order_id": "be8f100d-14f3-4faa-b0e2-e34a2ef5d31a", "order_type": "limit", "size": "0.02000000", "price": "444.03000000", "side": "buy", "client_oid": "4f3462a2-0225-48b1-bd90-868621921abc", "product_id": "ETH-USD", "sequence": 4179037681, "time": "2018-07-02T05:24:28.802000Z"}
{"type": "open", "side": "buy", "price": "444.03000000", "order_id": "be8f100d-14f3-4faa-b0e2-e34a2ef5d31a", "remaining_size": "0.02000000", "product_id": "ETH-USD", "sequence": 4179037682, "time": "2018-07-02T05:24:28.802000Z"}
{"type": "done", "side": "buy", "order_id": "02da473f-70e1-4acc-bb81-b9758a8060db", "reason": "canceled", "product_id": "ETH-USD", "price": "446.03000000", "remaining_size": "0.01000000", "sequence": 4179037683, "time": "2018-07-02T05:24:28.818000Z"}
{"type": "received", "order_id": "bc4e63fc-f093-4df5-b1c7-795957f8afad", "order_type": "limit", "size": "0.01000000", "price": "446.03000000", "side": "buy", "client_oid": "80940300-0000-4893-a773-000000893677", "product_id": "ETH-USD", "sequence": 4179037684, "time": "2018-07-02T05:24:28.823000Z"}
{"type": "open", "side": "buy", "price": "446.03000000", "order_id": "bc4e63fc-f093-4df5-b1c7-795957f8afad", "remaining_size": "0.01000000", "product_id": "ETH-USD", "sequence": 4179037685, "time": "2018-07-02T05:24:28.823000Z"}
{"type": "done", "side": "buy", "order_id": "bc4e63fc-f093-4df5-b1c7-795957f8afad", "reason": "canceled", "product_id": "ETH-USD", "price": "446.03000000", "remaining_size": "0.01000000", "sequence": 4179037686, "time": "2018-07-02T05:24:28.911000Z"}
{"type": "received", "order_id": "5c1ba9f7-09cb-4b48-b8ad-dc9beb3913aa", "order_type": "limit", "size": "0.01000000", "price": "446.03000000", "side": "buy", "client_oid": "2c97a000-000b-4056-8d00-0000b056cd00", "product_id": "ETH-USD", "sequence": 4179037687, "time": "2018-07-02T05:24:28.918000Z"}
{"type": "open", "side": "buy", "price": "446.03000000", "order_id": "5c1ba9f7-09cb-4b48-b8ad-dc9beb3913aa", "remaining_size": "0.01000000", "product_id": "ETH-USD", "sequence": 4179037688, "time": "2018-07-02T05:24:28.918000Z"}
{"type": "done", "side": "buy", "order_id": "830381f2-1e5c-44d0-be78-3479fcfacc5b", "reason": "canceled", "product_id": "ETH-USD", "price": "445.35000000", "remaining_size": "2.75029700", "sequence": 4179037689, "time": "2018-07-02T05:24:28.979000Z"}
{"type": "done", "side": "buy", "order_id": "adad85f9-798e-4e59-80a8-103f39600516", "reason": "canceled", "product_id": "ETH-USD", "price": "445.09000000", "remaining_size": "2.30056100", "sequence": 4179037690, "time": "2018-07-02T05:24:28.983000Z"}
{"type": "done", "side": "buy", "order_id": "1015e05b-56aa-4588-8ee9-7ff3ffed5cdc", "reason": "canceled", "product_id": "ETH-USD", "price": "443.66000000", "remaining_size": "1.78592200", "sequence": 4179037691, "time": "2018-07-02T05:24:28.986000Z"}
{"type": "done", "side": "buy", "order_id": "6fa005f3-0cce-4180-99dd-c1d169eb4108", "reason": "canceled", "product_id": "ETH-USD", "price": "443.14000000", "remaining_size": "1.81993200", "sequence": 4179037692, "time": "2018-07-02T05:24:28.994000Z"}
{"type": "done", "side": "buy", "order_id": "717d2805-1adf-436a-9f1a-eb1fcf5ab298", "reason": "canceled", "product_id": "ETH-USD", "price": "443.01000000", "remaining_size": "14.04292900", "sequence": 4179037693, "time": "2018-07-02T05:24:28.997000Z"}
{"type": "done", "side": "buy", "order_id": "933a7ffe-dc5a-4463-a13f-7fc0d621fa12", "reason": "canceled", "product_id": "ETH-USD", "price": "444.47000000", "remaining_size": "0.01000000", "sequence": 4179037694, "time": "2018-07-02T05:24:29.005000Z"}
{"type": "done", "side": "buy", "order_id": "5c1ba9f7-09cb-4b48-b8ad-dc9beb3913aa", "reason": "canceled", "product_id": "ETH-USD", "price": "446.03000000", "remaining_size": "0.01000000", "sequence": 4179037695, "time": "2018-07-02T05:24:29.005000Z"}
{"type": "received", "order_id": "38353ead-c26e-409c-88d7-0342680d5184", "order_type": "limit", "size": "0.01000000", "price": "446.03000000", "side": "buy", "client_oid": "66243400-0000-4a5c-8f01-00000a5c0f01", "product_id": "ETH-USD", "sequence": 4179037696, "time": "2018-07-02T05:24:29.011000Z"}
{"type": "open", "side": "buy", "price": "446.03000000", "order_id": "38353ead-c26e-409c-88d7-0342680d5184", "remaining_size": "0.01000000", "product_id": "ETH-USD", "sequence": 4179037697, "time": "2018-07-02T05:24:29.011000Z"}
{"type": "received", "order_id": "6c663c72-24ad-4d33-98a4-5631a987c4ce", "order_type": "limit", "size": "2.80365200", "price": "445.35000000", "side": "buy", "client_oid": "58e95b52-b697-4ebb-a5c5-230eeb3eb54c", "product_id": "ETH-USD", "sequence": 4179037698, "time": "2018-07-02T05:24:29.025000Z"}
{"type": "open", "side": "buy", "price": "445.35000000", "order_id": "6c663c72-24ad-4d33-98a4-5631a987c4ce", "remaining_size": "2.80365200", "product_id": "ETH-USD", "sequence": 4179037699, "time": "2018-07-02T05:24:29.025000Z"}
{"type": "received", "order_id": "ed5818cf-d808-4a6e-a251-847a223bf77e", "order_type": "limit", "size": "2.33273900", "price": "445.09000000", "side": "buy", "client_oid": "0e570482-2e89-4709-80be-b0014e72084a", "product_id": "ETH-USD", "sequence": 4179037700, "time": "2018-07-02T05:24:29.034000Z"}
{"type": "open", "side": "buy", "price": "445.09000000", "order_id": "ed5818cf-d808-4a6e-a251-847a223bf77e", "remaining_size": "2.33273900", "product_id": "ETH-USD", "sequence": 4179037701, "time": "2018-07-02T05:24:29.034000Z"}
{"type": "received", "order_id": "20f685db-bf92-49af-94fb-1ee2fe12f1b0", "order_type": "limit", "size": "1.81678200", "price": "443.66000000", "side": "buy", "client_oid": "3467c3f4-80d7-454c-b050-388a02a60f81", "product_id": "ETH-USD", "sequence": 4179037702, "time": "2018-07-02T05:24:29.042000Z"}
{"type": "open", "side": "buy", "price": "443.66000000", "order_id": "20f685db-bf92-49af-94fb-1ee2fe12f1b0", "remaining_size": "1.81678200", "product_id": "ETH-USD", "sequence": 4179037703, "time": "2018-07-02T05:24:29.042000Z"}
{"type": "received", "order_id": "f598adb4-0815-4a3a-afa9-e1158dca5df3", "order_type": "limit", "size": "1.91409000", "price": "443.14000000", "side": "buy", "client_oid": "18381b43-2eff-44ec-8eed-394d0204680e", "product_id": "ETH-USD", "sequence": 4179037704, "time": "2018-07-02T05:24:29.051000Z"}
{"type": "open", "side": "buy", "price": "443.14000000", "order_id": "f598adb4-0815-4a3a-afa9-e1158dca5df3", "remaining_size": "1.91409000", "product_id": "ETH-USD", "sequence": 4179037705, "time": "2018-07-02T05:24:29.051000Z"}
{"type": "received", "order_id": "5031ddfa-7316-43af-92be-25ac46ed920f", "order_type": "limit", "size": "0.09100000", "price": "448.99000000", "side": "sell", "product_id": "ETH-USD", "sequence": 4179037706, "time": "2018-07-02T05:24:29.051000Z"}
{"type": "open", "side": "sell", "price": "448.99000000", "order_id": "5031ddfa-7316-43af-92be-25ac46ed920f", "remaining_size": "0.09100000", "product_id": "ETH-USD", "sequence": 4179037707, "time": "2018-07-02T05:24:29.051000Z"}
{"type": "received", "order_id": "02e48ac9-63c6-411d-b037-4b98cafbbe2e", "order_type": "limit", "size": "13.83187200", "price": "443.01000000", "side": "buy", "client_oid": "516f0d38-99fe-44e8-9b33-cd9f3c9d1616", "product_id": "ETH-USD", "sequence": 4179037708, "time": "2018-07-02T05:24:29.062000Z"}
{"type": "open", "side": "buy", "price": "443.01000000", "order_id": "02e48ac9-63c6-411d-b037-4b98cafbbe2e", "remaining_size": "13.83187200", "product_id": "ETH-USD", "sequence": 4179037709, "time": "2018-07-02T05:24:29.062000Z"}
{"type": "received", "order_id": "f9c3e25b-5715-4cd4-86dd-7aac2754f85a", "order_type": "limit", "size": "0.01000000", "price": "444.47000000", "side": "buy", "client_oid": "e4aaf4c7-8481-4eea-b355-cac15afa3aaa", "product_id": "ETH-USD", "sequence": 4179037710, "time": "2018-07-02T05:24:29.065000Z"}
{"type": "open", "side": "buy", "price": "444.47000000", "order_id": "f9c3e25b-5715-4cd4-86dd-7aac2754f85a", "remaining_size": "0.01000000", "product_id": "ETH-USD", "sequence": 4179037711, "time": "2018-07-02T05:24:29.065000Z"}
{"type": "done", "side": "buy", "order_id": "38353ead-c26e-409c-88d7-0342680d5184", "reason": "canceled", "product_id": "ETH-USD", "price": "446.03000000", "remaining_size": "0.01000000", "sequence": 4179037712, "time": "2018-07-02T05:24:29.098000Z"}
{"type": "received", "order_id": "9ae4f871-3fb2-4e32-ac46-412943a338eb", "order_type": "limit", "size": "0.01000000", "price": "446.03000000", "side": "buy", "client_oid": "36e1c200-000e-4560-af00-0000e5606f00", "product_id": "ETH-USD", "sequence": 4179037713, "time": "2018-07-02T05:24:29.112000Z"}
{"type": "open", "side": "buy", "price": "446.03000000", "order_id": "9ae4f871-3fb2-4e32-ac46-412943a338eb", "remaining_size": "0.01000000", "product_id": "ETH-USD", "sequence": 4179037714, "time": "2018-07-02T05:24:29.112000Z"}
{"type": "done", "side": "sell", "order_id": "3db1b9d1-f84a-436d-a568-9366e3bf64dc", "reason": "canceled", "product_id": "ETH-USD", "price": "448.07000000", "remaining_size": "14.24999000", "sequence": 4179037715, "time": "2018-07-02T05:24:29.134000Z"}
{"type": "done", "side": "buy", "order_id": "9ae4f871-3fb2-4e32-ac46-412943a338eb", "reason": "canceled", "product_id": "ETH-USD", "price": "446.03000000", "remaining_size": "0.01000000", "sequence": 4179037716, "time": "2018-07-02T05:24:29.201000Z"}
{"type": "received", "order_id": "8d078c58-2610-4177-b1ae-e5cdba099a20", "order_type": "limit", "size": "0.01000000", "price": "446.03000000", "side": "buy", "client_oid": "dba9c400-0000-47d2-a8f0-000007d2e8f0", "product_id": "ETH-USD", "sequence": 4179037717, "time": "2018-07-02T05:24:29.208000Z"}
{"type": "open", "side": "buy", "price": "446.03000000", "order_id": "8d078c58-2610-4177-b1ae-e5cdba099a20", "remaining_size": "0.01000000", "product_id": "ETH-USD", "sequence": 4179037718, "time": "2018-07-02T05:24:29.208000Z"}
{"type": "received", "order_id": "7ac47d82-5098-4bcb-b269-fad4cfecef68", "order_type": "limit", "size": "14.24999000", "price": "448.04000000", "side": "sell", "client_oid": "e9649d33-b5d7-421e-8d69-90393f61ecbc", "product_id": "ETH-USD", "sequence": 4179037719, "time": "2018-07-02T05:24:29.222000Z"}
{"type": "open", "side": "sell", "price": "448.04000000", "order_id": "7ac47d82-5098-4bcb-b269-fad4cfecef68", "remaining_size": "14.24999000", "product_id": "ETH-USD", "sequence": 4179037720, "time": "2018-07-02T05:24:29.222000Z"}
{"type": "done", "side": "sell", "order_id": "053ad1b9-2a23-4d29-bf1c-56809c6c913f", "reason": "canceled", "product_id": "ETH-USD", "price": "450.25000000", "remaining_size": "0.01000000", "sequence": 4179037721, "time": "2018-07-02T05:24:29.233000Z"}
{"type": "done", "side": "sell", "order_id": "735d1f9d-f1b8-4a04-bc80-7e1ebb39f805", "reason": "canceled", "product_id": "ETH-USD", "price": "452.25000000", "remaining_size": "0.01000000", "sequence": 4179037722, "time": "2018-07-02T05:24:29.236000Z"}
{"type": "done", "side": "sell", "order_id": "12d9ae80-f1b6-43ef-b2f1-3471faa5b9df", "reason": "canceled", "product_id": "ETH-USD", "price": "451.25000000", "remaining_size": "0.01000000", "sequence": 4179037723, "time": "2018-07-02T05:24:29.238000Z"}
{"type": "received", "order_id": "02429c7c-1598-4b3a-b280-b09f53b52350", "order_type": "limit", "size": "0.01000000", "price": "453.25000000", "side": "sell", "client_oid": "cd8f1b6f-7e8b-4b02-8000-0e4c5799f030", "product_id": "ETH-USD", "sequence": 4179037724, "time": "2018-07-02T05:24:29.251000Z"}
{"type": "open", "side": "sell", "price": "453.25000000", "order_id": "02429c7c-1598-4b3a-b280-b09f53b52350", "remaining_size": "0.01000000", "product_id": "ETH-USD", "sequence": 4179037725, "time": "2018-07-02T05:24:29.251000Z"}
{"type": "received", "order_id": "02b6caa2-5e99-4bc2-ac8d-1fd14fe1590a", "order_type": "limit", "size": "0.78027907", "price": "6330.00000000", "side": "sell", "client_oid": "7b0bb68d-1db8-43e3-a590-5edfe1385d9e", "product_id": "BTC-USD", "sequence": 6227079480, "time": "2018-07-02T05:24:29.274000Z"}
{"type": "open", "side": "sell", "price": "6330.00000000", "order_id": "02b6caa2-5e99-4bc2-ac8d-1fd14fe1590a", "remaining_size": "0.78027907", "product_id": "BTC-USD", "sequence": 6227079481, "time": "2018-07-02T05:24:29.274000Z"}
{"type": "done", "side": "buy", "order_id": "8d078c58-2610-4177-b1ae-e5cdba099a20", "reason": "canceled", "product_id": "ETH-USD", "price": "446.03000000", "remaining_size": "0.01000000", "sequence": 4179037726, "time": "2018-07-02T05:24:29.295000Z"}
{"type": "received", "order_id": "86bef408-a557-4cff-8e76-e3fcf4eacc16", "order_type": "limit", "size": "0.01000000", "price": "446.03000000", "side": "buy", "client_oid": "b27ab500-0000-4646-bce1-00000646fce1", "product_id": "ETH-USD", "sequence": 4179037727, "time": "2018-07-02T05:24:29.302000Z"}
{"type": "open", "side": "buy", "price": "446.03000000", "order_id": "86bef408-a557-4cff-8e76-e3fcf4eacc16", "remaining_size": "0.01000000", "product_id": "ETH-USD", "sequence": 4179037728, "time": "2018-07-02T05:24:29.302000Z"}
{"type": "received", "order_id": "2f13cfad-b2de-47d6-abe4-62d1f4f8d8f7", "order_type": "limit", "size": "0.01000000", "price": "454.25000000", "side": "sell", "client_oid": "2597d0a6-3178-4e62-8000-057eb3ae3340", "product_id": "ETH-USD", "sequence": 4179037729, "time": "2018-07-02T05:24:29.322000Z"}
{"type": "open", "side": "sell", "price": "454.25000000", "order_id": "2f13cfad-b2de-47d6-abe4-62d1f4f8d8f7", "remaining_size": "0.01000000", "product_id": "ETH-USD", "sequence": 4179037730, "time": "2018-07-02T05:24:29.322000Z"}
{"type": "received", "order_id": "61adc293-355e-4c27-9660-519bb48ab0c5", "order_type": "limit", "size": "0.44580000", "price": "6319.22000000", "side": "sell", "client_oid": "3198ebc0-7db8-11e8-9045-3c52826c840b", "product_id": "BTC-USD", "sequence": 6227079482, "time": "2018-07-02T05:24:29.383000Z"}
{"type": "open", "side": "sell", "price": "6319.22000000", "order_id": "61adc293-355e-4c27-9660-519bb48ab0c5", "remaining_size": "0.44580000", "product_id": "BTC-USD", "sequence": 6227079483, "time": "2018-07-02T05:24:29.383000Z"}
{"type": "done", "side": "buy", "order_id": "86bef408-a557-4cff-8e76-e3fcf4eacc16", "reason": "canceled", "product_id": "ETH-USD", "price": "446.03000000", "remaining_size": "0.01000000", "sequence": 4179037731, "time": "2018-07-02T05:24:29.390000Z"}
{"type": "received", "order_id": "7907a191-1daf-4955-b03a-03ca988421e2", "order_type": "limit", "size": "4.98000000", "price": "447.73000000", "side": "sell", "product_id": "ETH-USD", "sequence": 4179037732, "time": "2018-07-02T05:24:29.398000Z"}
{"type": "open", "side": "sell", "price": "447.73000000", "order_id": "7907a191-1daf-4955-b03a-03ca988421e2", "remaining_size": "4.98000000", "product_id": "ETH-USD", "sequence": 4179037733, "time": "2018-07-02T05:24:29.398000Z"}
{"type": "received", "order_id": "97b5a469-75e2-47ff-aab0-bff4d58e00a0", "order_type": "limit", "size": "0.01000000", "price": "446.03000000", "side": "buy", "client_oid": "9756c500-0000-44ad-b821-000004ad3821", "product_id": "ETH-USD", "sequence": 4179037734, "time": "2018-07-02T05:24:29.403000Z"}
{"type": "open", "side": "buy", "price": "446.03000000", "order_id": "97b5a469-75e2-47ff-aab0-bff4d58e00a0", "remaining_size": "0.01000000", "product_id": "ETH-USD", "sequence": 4179037735, "time": "2018-07-02T05:24:29.403000Z"}
{"type": "received", "order_id": "7ee41141-c403-41ea-9afd-eb9977eb0295", "order_type": "limit", "size": "2.68391400", "price": "447.17000000", "side": "sell", "product_id": "ETH-USD", "sequence": 4179037736, "time": "2018-07-02T05:24:29.408000Z"}
{"type": "open", "side": "sell", "price": "447.17000000", "order_id": "7ee41141-c403-41ea-9afd-eb9977eb0295", "remaining_size": "2.68391400", "product_id": "ETH-USD", "sequence": 4179037737, "time": "2018-07-02T05:24:29.408000Z"}
{"type": "done", "side": "buy", "order_id": "97b5a469-75e2-47ff-aab0-bff4d58e00a0", "reason": "canceled", "product_id": "ETH-USD", "price": "446.03000000", "remaining_size": "0.01000000", "sequence": 4179037738, "time": "2018-07-02T05:24:29.491000Z"}
{"type": "received", "order_id": "971d1ecb-2da1-4b66-be5e-d50785b1d2b1", "order_type": "limit", "size": "0.01000000", "price": "446.03000000", "side": "buy", "client_oid": "6a07c000-000d-4864-ac00-0000d864ac00", "product_id": "ETH-USD", "sequence": 4179037739, "time": "2018-07-02T05:24:29.499000Z"}
{"type": "open", "side": "buy", "price": "446.03000000", "order_id": "971d1ecb-2da1-4b66-be5e-d50785b1d2b1", "remaining_size": "0.01000000", "product_id": "ETH-USD", "sequence": 4179037740, "time": "2018-07-02T05:24:29.499000Z"}
{"type": "done", "side": "sell", "order_id": "14e108e3-5ce1-4fdd-8274-d0e6dbe8be7e", "reason": "canceled", "product_id": "BTC-USD", "price": "6303.93000000", "remaining_size": "0.01500000", "sequence": 6227079484, "time": "2018-07-02T05:24:29.504000Z"}
{"type": "received", "order_id": "335ff166-22b2-4b6a-b76b-c76d6be7a84d", "order_type": "limit", "size": "0.01500000", "price": "6303.98000000", "side": "sell", "client_oid": "65f44f59-1521-4a3c-add0-22f2c7e8524d", "product_id": "BTC-USD", "sequence": 6227079485, "time": "2018-07-02T05:24:29.508000Z"}
{"type": "open", "side": "sell", "price": "6303.98000000", "order_id": "335ff166-22b2-4b6a-b76b-c76d6be7a84d", "remaining_size": "0.01500000", "product_id": "BTC-USD", "sequence": 6227079486, "time": "2018-07-02T05:24:29.508000Z"}
{"type": "received", "order_id": "6defc46e-b517-4f95-9094-da0bd958814d", "order_type": "limit", "size": "0.01000000", "price": "455.25000000", "side": "sell", "client_oid": "c7901df7-f40d-4af6-8000-00f83226893a", "product_id": "ETH-USD", "sequence": 4179037741, "time": "2018-07-02T05:24:29.530000Z"}
{"type": "open", "side": "sell", "price": "455.25000000", "order_id": "6defc46e-b517-4f95-9094-da0bd958814d", "remaining_size": "0.01000000", "product_id": "ETH-USD", "sequence": 4179037742, "time": "2018-07-02T05:24:29.530000Z"}
{"type": "done", "side": "buy", "order_id": "62d8dba2-12db-4b57-a84b-db63d05e6889", "reason": "canceled", "product_id": "BTC-USD", "price": "6116.50000000", "remaining_size": "0.00150000", "sequence": 6227079487, "time": "2018-07-02T05:24:29.536000Z"}
{"type": "received", "order_id": "c243aa5a-a228-40ea-ada3-cca343179307", "order_type": "limit", "size": "0.00150000", "price": "6085.89000000", "side": "buy", "client_oid": "c789b082-5196-44dc-8000-006711f81c79", "product_id": "BTC-USD", "sequence": 6227079488, "time": "2018-07-02T05:24:29.541000Z"}
{"type": "open", "side": "buy", "price": "6085.89000000", "order_id": "c243aa5a-a228-40ea-ada3-cca343179307", "remaining_size": "0.00150000", "product_id": "BTC-USD", "sequence": 6227079489, "time": "2018-07-02T05:24:29.541000Z"}
{"type": "done", "side": "sell", "order_id": "c7da8291-4b8e-4e66-ba6f-937ad106dc46", "reason": "canceled", "product_id": "ETH-USD", "price": "470.67000000", "remaining_size": "0.01000000", "sequence": 4179037743, "time": "2018-07-02T05:24:29.556000Z"}
{"type": "received", "order_id": "f41e6e00-ba35-45e1-b997-a1542a3e94cd", "order_type": "limit", "size": "0.01000000", "price": "472.67000000", "side": "sell", "client_oid": "b15e9080-4938-45db-8000-0094fceb3bd9", "product_id": "ETH-USD", "sequence": 4179037744, "time": "2018-07-02T05:24:29.561000Z"}
{"type": "open", "side": "sell", "price": "472.67000000", "order_id": "f41e6e00-ba35-45e1-b997-a1542a3e94cd", "remaining_size": "0.01000000", "product_id": "ETH-USD", "sequence": 4179037745, "time": "2018-07-02T05:24:29.561000Z"}
{"type": "received", "order_id": "81750105-6e78-4b40-824e-11a68e9e5c97", "order_type": "limit", "size": "0.01000000", "price": "446.96000000", "side": "buy", "client_oid": "31ac2ffa-7db8-11e8-874f-16be7828d23e", "product_id": "ETH-USD", "sequence": 4179037746, "time": "2018-07-02T05:24:29.567000Z"}
{"type": "done", "side": "buy", "order_id": "81750105-6e78-4b40-824e-11a68e9e5c97", "reason": "canceled", "product_id": "ETH-USD", "price": "446.96000000", "remaining_size": "0.01000000", "sequence": 4179037747, "time": "2018-07-02T05:24:29.567000Z"}
{"type": "done", "side": "sell", "order_id": "0b54546b-462f-4cb0-aa1e-5595d685f640", "reason": "canceled", "product_id": "ETH-USD", "price": "450.36000000", "remaining_size": "6.79438000", "sequence": 4179037748, "time": "2018-07-02T05:24:29.576000Z"}
{"type": "done", "side": "sell", "order_id": "e5dfa63e-1d31-424b-8e7f-f4306db0f197", "reason": "canceled", "product_id": "ETH-USD", "price": "449.70000000", "remaining_size": "6.79438000", "sequence": 4179037749, "time": "2018-07-02T05:24:29.580000Z"}
{"type": "done", "side": "buy", "order_id": "971d1ecb-2da1-4b66-be5e-d50785b1d2b1", "reason": "canceled", "product_id": "ETH-USD", "price": "446.03000000", "remaining_size": "0.01000000", "sequence": 4179037750, "time": "2018-07-02T05:24:29.587000Z"}
{"type": "received", "order_id": "e35e5921-4b40-4c8f-a4f7-1e504aa82023", "order_type": "limit", "size": "6.79438000", "price": "452.99000000", "side": "sell", "client_oid": "6e964048-f6d1-4fe0-a31b-3a71c735135b", "product_id": "ETH-USD", "sequence": 4179037751, "time": "2018-07-02T05:24:29.587000Z"}
{"type": "open", "side": "sell", "price": "452.99000000", "order_id": "e35e5921-4b40-4c8f-a4f7-1e504aa82023", "remaining_size": "6.79438000", "product_id": "ETH-USD", "sequence": 4179037752, "time": "2018-07-02T05:24:29.587000Z"}
{"type": "received", "order_id": "b0273035-f7df-4444-b45a-275280ae185c", "order_type": "limit", "size": "6.79438000", "price": "452.79000000", "side": "sell", "client_oid": "19543fc4-e776-4c61-858a-46f28cafc0bf", "product_id": "ETH-USD", "sequence": 4179037753, "time": "2018-07-02T05:24:29.591000Z"}
{"type": "open", "side": "sell", "price": "452.79000000", "order_id": "b0273035-f7df-4444-b45a-275280ae185c", "remaining_size": "6.79438000", "product_id": "ETH-USD", "sequence": 4179037754, "time": "2018-07-02T05:24:29.591000Z"}
{"type": "received", "order_id": "6d72e766-876e-4e9d-b6d5-2e4d53f39879", "order_type": "limit", "size": "0.01000000", "price": "446.03000000", "side": "buy", "client_oid": "92b09400-0000-4d8f-90a0-00000d8fd0a0", "product_id": "ETH-USD", "sequence": 4179037755, "time": "2018-07-02T05:24:29.593000Z"}
{"type": "open", "side": "buy", "price": "446.03000000", "order_id": "6d72e766-876e-4e9d-b6d5-2e4d53f39879", "remaining_size": "0.01000000", "product_id": "ETH-USD", "sequence": 4179037756, "time": "2018-07-02T05:24:29.593000Z"}
{"type": "done", "side": "sell", "order_id": "02429c7c-1598-4b3a-b280-b09f53b52350", "reason": "canceled", "product_id": "ETH-USD", "price": "453.25000000", "remaining_size": "0.01000000", "sequence": 4179037757, "time": "2018-07-02T05:24:29.644000Z"}
{"type": "done", "side": "buy", "order_id": "6d72e766-876e-4e9d-b6d5-2e4d53f39879", "reason": "canceled", "product_id": "ETH-USD", "price": "446.03000000", "remaining_size": "0.01000000", "sequence": 4179037758, "time": "2018-07-02T05:24:29.687000Z"}
{"type": "received", "order_id": "45dc9f47-e700-4120-ae38-d688b275e3f4", "order_type": "limit", "size": "0.01000000", "price": "446.03000000", "side": "buy", "client_oid": "6cb8e000-0004-4b97-a230-000004b97623", "product_id": "ETH-USD", "sequence": 4179037759, "time": "2018-07-02T05:24:29.697000Z"}
{"type": "open", "side": "buy", "price": "446.03000000", "order_id": "45dc9f47-e700-4120-ae38-d688b275e3f4", "remaining_size": "0.01000000", "product_id": "ETH-USD", "sequence": 4179037760, "time": "2018-07-02T05:24:29.697000Z"}
{"type": "done", "side": "buy", "order_id": "9d38335c-7dc9-48c0-aa2b-a97b25fcc051", "reason": "canceled", "product_id": "ETH-USD", "price": "446.41000000", "remaining_size": "11.00000000", "sequence": 4179037761, "time": "2018-07-02T05:24:29.736000Z"}
{"type": "received", "order_id": "7b9429d0-e9ad-4c9e-9c1a-48d076a0793e", "order_type": "limit", "size": "11.00000000", "price": "446.46000000", "side": "buy", "client_oid": "532c3a26-d4aa-4567-b3c4-0752ceb79681", "product_id": "ETH-USD", "sequence": 4179037762, "time": "2018-07-02T05:24:29.769000Z"}
{"type": "open", "side": "buy", "price": "446.46000000", "order_id": "7b9429d0-e9ad-4c9e-9c1a-48d076a0793e", "remaining_size": "11.00000000", "product_id": "ETH-USD", "sequence": 4179037763, "time": "2018-07-02T05:24:29.769000Z"}
{"type": "received", "order_id": "f449a401-f828-4fac-9845-5046e363d671", "order_type": "limit", "size": "0.01000000", "price": "447.25000000", "side": "sell", "client_oid": "c3db815f-0b0c-4b3e-8000-00a34a101658", "product_id": "ETH-USD", "sequence": 4179037764, "time": "2018-07-02T05:24:29.775000Z"}
{"type": "open", "side": "sell", "price": "447.25000000", "order_id": "f449a401-f828-4fac-9845-5046e363d671", "remaining_size": "0.01000000", "product_id": "ETH-USD", "sequence": 4179037765, "time": "2018-07-02T05:24:29.775000Z"}
{"type": "done", "side": "buy", "order_id": "45dc9f47-e700-4120-ae38-d688b275e3f4", "reason": "canceled", "product_id": "ETH-USD", "price": "446.03000000", "remaining_size": "0.01000000", "sequence": 4179037766, "time": "2018-07-02T05:24:29.785000Z"}
{"type": "received", "order_id": "b145a308-419c-4d9a-88b8-91c997c1f103", "order_type": "limit", "size": "0.01000000", "price": "446.03000000", "side": "buy", "client_oid": "e61a4100-0005-4c0c-a110-00005c0c2110", "product_id": "ETH-USD", "sequence": 4179037767, "time": "2018-07-02T05:24:29.792000Z"}
{"type": "open", "side": "buy", "price": "446.03000000", "order_id": "b145a308-419c-4d9a-88b8-91c997c1f103", "remaining_size": "0.01000000", "product_id": "ETH-USD", "sequence": 4179037768, "time": "2018-07-02T05:24:29.792000Z"}
{"type": "done", "side": "buy", "order_id": "dea7af33-00b6-4807-895e-122c91b4bf3f", "reason": "canceled", "product_id": "BTC-USD", "price": "6286.00000000", "remaining_size": "0.05000000", "sequence": 6227079490, "time": "2018-07-02T05:24:29.840000Z"}
{"type": "done", "side": "sell", "order_id": "e35e5921-4b40-4c8f-a4f7-1e504aa82023", "reason": "canceled", "product_id": "ETH-USD", "price": "452.99000000", "remaining_size": "6.79438000", "sequence": 4179037769, "time": "2018-07-02T05:24:29.877000Z"}
{"type": "done", "side": "sell", "order_id": "b0273035-f7df-4444-b45a-275280ae185c", "reason": "canceled", "product_id": "ETH-USD", "price": "452.79000000", "remaining_size": "6.79438000", "sequence": 4179037770, "time": "2018-07-02T05:24:29.881000Z"}
{"type": "received", "order_id": "7bb61785-7428-4b9e-99b4-7392e2955159", "order_type": "limit", "size": "14.92161000", "price": "454.83000000", "side": "sell", "product_id": "ETH-USD", "sequence": 4179037771, "time": "2018-07-02T05:24:29.884000Z"}
{"type": "open", "side": "sell", "price": "454.83000000", "order_id": "7bb61785-7428-4b9e-99b4-7392e2955159", "remaining_size": "14.92161000", "product_id": "ETH-USD", "sequence": 4179037772, "time": "2018-07-02T05:24:29.884000Z"}
{"type": "done", "side": "buy", "order_id": "b145a308-419c-4d9a-88b8-91c997c1f103", "reason": "canceled", "product_id": "ETH-USD", "price": "446.03000000", "remaining_size": "0.01000000", "sequence": 4179037773, "time": "2018-07-02T05:24:29.886000Z"}
{"type": "received", "order_id": "df9ca783-b0a1-4acb-ad3c-f3f28e2a64c3", "order_type": "limit", "size": "6.79438000", "price": "450.36000000", "side": "sell", "client_oid": "053937ed-4653-48ab-bdfd-8b3efe524b38", "product_id": "ETH-USD", "sequence": 4179037774, "time": "2018-07-02T05:24:29.891000Z"}
{"type": "open", "side": "sell", "price": "450.36000000", "order_id": "df9ca783-b0a1-4acb-ad3c-f3f28e2a64c3", "remaining_size": "6.79438000", "product_id": "ETH-USD", "sequence": 4179037775, "time": "2018-07-02T05:24:29.891000Z"}
{"type": "received", "order_id": "86f90889-ca5c-4aa5-b487-ed7492e5e9b1", "order_type": "limit", "size": "0.01000000", "price": "446.01000000", "side": "buy", "client_oid": "ae93f400-0000-4605-b211-00000605f211", "product_id": "ETH-USD", "sequence": 4179037776, "time": "2018-07-02T05:24:29.892000Z"}
{"type": "open", "side": "buy", "price": "446.01000000", "order_id": "86f90889-ca5c-4aa5-b487-ed7492e5e9b1", "remaining_size": "0.01000000", "product_id": "ETH-USD", "sequence": 4179037777, "time": "2018-07-02T05:24:29.892000Z"}
{"type": "received", "order_id": "5fb8cd30-340e-4c55-a2b8-826e32e737a2", "order_type": "limit", "size": "6.79438000", "price": "449.70000000", "side": "sell", "client_oid": "e6eae85c-ec81-41ec-b1d5-d2d35ea3c2ce", "product_id": "ETH-USD", "sequence": 4179037778, "time": "2018-07-02T05:24:29.895000Z"}
{"type": "open", "side": "sell", "price": "449.70000000", "order_id": "5fb8cd30-340e-4c55-a2b8-826e32e737a2", "remaining_size": "6.79438000", "product_id": "ETH-USD", "sequence": 4179037779, "time": "2018-07-02T05:24:29.895000Z"}
{"type": "done", "side": "sell", "order_id": "967aa3b8-721c-4efb-a95a-6b5fb3c8db7f", "reason": "canceled", "product_id": "BTC-USD", "price": "6319.20000000", "remaining_size": "0.50030000", "sequence": 6227079491, "time": "2018-07-02T05:24:29.913000Z"}
{"type": "done", "side": "sell", "order_id": "f4288fe8-ccc0-45c5-a8e5-4bf87198ed01", "reason": "canceled", "product_id": "ETH-USD", "price": "453.82000000", "remaining_size": "15.54951000", "sequence": 4179037780, "time": "2018-07-02T05:24:29.920000Z"}
{"type": "done", "side": "sell", "order_id": "f449a401-f828-4fac-9845-5046e363d671", "reason": "canceled", "product_id": "ETH-USD", "price": "447.25000000", "remaining_size": "0.01000000", "sequence": 4179037781, "time": "2018-07-02T05:24:29.972000Z"}
{"type": "done", "side": "buy", "order_id": "2ce97817-e8a4-4252-8e7c-558babb5f2fd", "reason": "canceled", "product_id": "BTC-USD", "price": "6298.26000000", "remaining_size": "0.00200000", "sequence": 6227079492, "time": "2018-07-02T05:24:29.977000Z"}
{"type": "received", "order_id": "68b66ae6-cf73-4418-99fb-aa4ce94f0dbe", "order_type": "limit", "size": "0.01000000", "price": "448.25000000", "side": "sell", "client_oid": "25395ff8-06c7-4e3a-8000-00bc9a82df3b", "product_id": "ETH-USD", "sequence": 4179037782, "time": "2018-07-02T05:24:29.981000Z"}
{"type": "open", "side": "sell", "price": "448.25000000", "order_id": "68b66ae6-cf73-4418-99fb-aa4ce94f0dbe", "remaining_size": "0.01000000", "product_id": "ETH-USD", "sequence": 4179037783, "time": "2018-07-02T05:24:29.981000Z"}
{"type": "done", "side": "buy", "order_id": "6c663c72-24ad-4d33-98a4-5631a987c4ce", "reason": "canceled", "product_id": "ETH-USD", "price": "445.35000000", "remaining_size": "2.80365200", "sequence": 4179037784, "time": "2018-07-02T05:24:29.988000Z"}
{"type": "done", "side": "buy", "order_id": "ed5818cf-d808-4a6e-a251-847a223bf77e", "reason": "canceled", "product_id": "ETH-USD", "price": "445.09000000", "remaining_size": "2.33273900", "sequence": 4179037785, "time": "2018-07-02T05:24:29.990000Z"}
{"type": "done", "side": "buy", "order_id": "20f685db-bf92-49af-94fb-1ee2fe12f1b0", "reason": "canceled", "product_id": "ETH-USD", "price": "443.66000000", "remaining_size": "1.81678200", "sequence": 4179037786, "time": "2018-07-02T05:24:29.993000Z"}
{"type": "done", "side": "sell", "order_id": "4fed13d4-21d3-40f6-9819-1e14e903bf74", "reason": "canceled", "product_id": "BTC-USD", "price": "6309.93000000", "remaining_size": "0.25000000", "sequence": 6227079493, "time": "2018-07-02T05:24:30.000000Z"}
{"type": "done", "side": "buy", "order_id": "f598adb4-0815-4a3a-afa9-e1158dca5df3", "reason": "canceled", "product_id": "ETH-USD", "price": "443.14000000", "remaining_size": "1.91409000", "sequence": 4179037787, "time": "2018-07-02T05:24:29.999000Z"}
{"type": "done", "side": "buy", "order_id": "dc1c06f1-83b3-4d18-bae6-8e83b70a59db", "reason": "canceled", "product_id": "ETH-USD", "price": "444.32000000", "remaining_size": "10.12783579", "sequence": 4179037788, "time": "2018-07-02T05:24:30.002000Z"}
{"type": "done", "side": "buy", "order_id": "2f71dac7-78a5-43e7-a6f9-0f99f793659f", "reason": "canceled", "product_id": "ETH-USD", "price": "445.26000000", "remaining_size": "6.73763644", "sequence": 4179037789, "time": "2018-07-02T05:24:30.002000Z"}
{"type": "done", "side": "buy", "order_id": "02e48ac9-63c6-411d-b037-4b98cafbbe2e", "reason": "canceled", "product_id": "ETH-USD", "price": "443.01000000", "remaining_size": "13.83187200", "sequence": 4179037790, "time": "2018-07-02T05:24:30.002000Z"}
{"type": "received", "order_id": "be8ec75e-6b9d-4de3-bcdb-d5498455dd10", "order_type": "limit", "size": "0.25000000", "price": "6310.46000000", "side": "sell", "client_oid": "1db4e7d9-bccb-42f5-a441-518d9b7169dc", "product_id": "BTC-USD", "sequence": 6227079494, "time": "2018-07-02T05:24:30.017000Z"}
{"type": "open", "side": "sell", "price": "6310.46000000", "order_id": "be8ec75e-6b9d-4de3-bcdb-d5498455dd10", "remaining_size": "0.25000000", "product_id": "BTC-USD", "sequence": 6227079495, "time": "2018-07-02T05:24:30.017000Z"}
{"type": "received", "order_id": "2ad5dbe9-1fc7-4347-8693-27467223f03c", "order_type": "limit", "size": "3.08770400", "price": "445.35000000", "side": "buy", "client_oid": "3b6efc0b-83c7-461e-b88c-8cb292248da0", "product_id": "ETH-USD", "sequence": 4179037791, "time": "2018-07-02T05:24:30.037000Z"}
{"type": "open", "side": "buy", "price": "445.35000000", "order_id": "2ad5dbe9-1fc7-4347-8693-27467223f03c", "remaining_size": "3.08770400", "product_id": "ETH-USD", "sequence": 4179037792, "time": "2018-07-02T05:24:30.037000Z"}
{"type": "done", "side": "sell", "order_id": "be8ec75e-6b9d-4de3-bcdb-d5498455dd10", "reason": "canceled", "product_id": "BTC-USD", "price": "6310.46000000", "remaining_size": "0.25000000", "sequence": 6227079496, "time": "2018-07-02T05:24:30.042000Z"}
{"type": "received", "order_id": "e70a92f7-ead4-4896-8ef7-ea86963b29c2", "order_type": "limit", "size": "2.57122200", "price": "445.09000000", "side": "buy", "client_oid": "395c7c69-d6c3-44c9-9a71-86f831f06cf3", "product_id": "ETH-USD", "sequence": 4179037793, "time": "2018-07-02T05:24:30.048000Z"}
{"type": "open", "side": "buy", "price": "445.09000000", "order_id": "e70a92f7-ead4-4896-8ef7-ea86963b29c2", "remaining_size": "2.57122200", "product_id": "ETH-USD", "sequence": 4179037794, "time": "2018-07-02T05:24:30.048000Z"}
{"type": "received", "order_id": "a1ab5260-22f5-4dc2-a622-ff1e5686ea02", "order_type": "limit", "size": "0.25000000", "price": "6313.32000000", "side": "sell", "client_oid": "d3f4c999-b345-40f0-8c4e-e6af26738bb4", "product_id": "BTC-USD", "sequence": 6227079497, "time": "2018-07-02T05:24:30.056000Z"}
{"type": "open", "side": "sell", "price": "6313.32000000", "order_id": "a1ab5260-22f5-4dc2-a622-ff1e5686ea02", "remaining_size": "0.25000000", "product_id": "BTC-USD", "sequence": 6227079498, "time": "2018-07-02T05:24:30.056000Z"}
{"type": "received", "order_id": "a406aeee-8559-466a-a4c7-2a4191ccf173", "order_type": "limit", "size": "2.00631500", "price": "443.66000000", "side": "buy", "client_oid": "970c0183-778d-4614-8fea-9389310cb4f3", "product_id": "ETH-USD", "sequence": 4179037795, "time": "2018-07-02T05:24:30.056000Z"}
{"type": "open", "side": "buy", "price": "443.66000000", "order_id": "a406aeee-8559-466a-a4c7-2a4191ccf173", "remaining_size": "2.00631500", "product_id": "ETH-USD", "sequence": 4179037796, "time": "2018-07-02T05:24:30.056000Z"}
{"type": "done", "side": "sell", "order_id": "a1ab5260-22f5-4dc2-a622-ff1e5686ea02", "reason": "canceled", "product_id": "BTC-USD", "price": "6313.32000000", "remaining_size": "0.25000000", "sequence": 6227079499, "time": "2018-07-02T05:24:30.064000Z"}
{"type": "received", "order_id": "7965bf6a-3cf7-4341-89c0-529b1269aa5f", "order_type": "limit", "size": "2.07569800", "price": "443.14000000", "side": "buy", "client_oid": "23eb8c25-c702-4eb6-8db9-2f2c1996bf1a", "product_id": "ETH-USD", "sequence": 4179037797, "time": "2018-07-02T05:24:30.066000Z"}
{"type": "open", "side": "buy", "price": "443.14000000", "order_id": "7965bf6a-3cf7-4341-89c0-529b1269aa5f", "remaining_size": "2.07569800", "product_id": "ETH-USD", "sequence": 4179037798, "time": "2018-07-02T05:24:30.066000Z"}
{"type": "received", "order_id": "32b80887-614a-439f-bc9a-57b77aa771cc", "order_type": "limit", "size": "12.95525100", "price": "443.01000000", "side": "buy", "client_oid": "26a2e683-a407-414b-bf17-7b93b7f9aae0", "product_id": "ETH-USD", "sequence": 4179037799, "time": "2018-07-02T05:24:30.074000Z"}
{"type": "open", "side": "buy", "price": "443.01000000", "order_id": "32b80887-614a-439f-bc9a-57b77aa771cc", "remaining_size": "12.95525100", "product_id": "ETH-USD", "sequence": 4179037800, "time": "2018-07-02T05:24:30.074000Z"}
{"type": "received", "order_id": "3e6c1092-5bf8-44c5-b5c1-cd3ca9ac5a01", "order_type": "limit", "size": "0.25000000", "price": "6310.50000000", "side": "sell", "client_oid": "095684ce-0e3c-4a55-b68b-e1e4c172fb8f", "product_id": "BTC-USD", "sequence": 6227079500, "time": "2018-07-02T05:24:30.079000Z"}
{"type": "open", "side": "sell", "price": "6310.50000000", "order_id": "3e6c1092-5bf8-44c5-b5c1-cd3ca9ac5a01", "remaining_size": "0.25000000", "product_id": "BTC-USD", "sequence": 6227079501, "time": "2018-07-02T05:24:30.079000Z"}
{"type": "done", "side": "sell", "order_id": "3e6c1092-5bf8-44c5-b5c1-cd3ca9ac5a01", "reason": "canceled", "product_id": "BTC-USD", "price": "6310.50000000", "remaining_size": "0.25000000", "sequence": 6227079502, "time": "2018-07-02T05:24:30.102000Z"}
{"type": "received", "order_id": "0fb9f9a8-306d-44cc-8025-7d9f32da0ec8", "order_type": "limit", "size": "0.01000000", "price": "449.25000000", "side": "sell", "client_oid": "05499a7c-27f4-4a6e-8000-0042c87ada23", "product_id": "ETH-USD", "sequence": 4179037801, "time": "2018-07-02T05:24:30.100000Z"}
{"type": "open", "side": "sell", "price": "449.25000000", "order_id": "0fb9f9a8-306d-44cc-8025-7d9f32da0ec8", "remaining_size": "0.01000000", "product_id": "ETH-USD", "sequence": 4179037802, "time": "2018-07-02T05:24:30.100000Z"}
{"type": "done", "side": "sell", "order_id": "c8d5309e-8fe6-40ef-8854-b56ee10e911a", "reason": "canceled", "product_id": "ETH-USD", "price": "448.12000000", "remaining_size": "11.74997000", "sequence": 4179037803, "time": "2018-07-02T05:24:30.111000Z"}
{"type": "received", "order_id": "dd7f8522-101a-4da6-8c9e-8d10e95c20d0", "order_type": "limit", "size": "0.25000000", "price": "6310.29000000", "side": "sell", "client_oid": "d54c73ba-1adf-45a8-a5af-a3f3bc71964b", "product_id": "BTC-USD", "sequence": 6227079503, "time": "2018-07-02T05:24:30.116000Z"}
{"type": "open", "side": "sell", "price": "6310.29000000", "order_id": "dd7f8522-101a-4da6-8c9e-8d10e95c20d0", "remaining_size": "0.25000000", "product_id": "BTC-USD", "sequence": 6227079504, "time": "2018-07-02T05:24:30.116000Z"}
{"type": "done", "side": "sell", "order_id": "7ac47d82-5098-4bcb-b269-fad4cfecef68", "reason": "canceled", "product_id": "ETH-USD", "price": "448.04000000", "remaining_size": "14.24999000", "sequence": 4179037804, "time": "2018-07-02T05:24:30.149000Z"}
{"type": "received", "order_id": "d281aa8d-dd0b-4977-ad2f-c4244d599422", "order_type": "limit", "size": "11.74997000", "price": "448.08000000", "side": "sell", "client_oid": "cdbfedf1-dd3d-4fc6-98d0-739f7a011c50", "product_id": "ETH-USD", "sequence": 4179037805, "time": "2018-07-02T05:24:30.186000Z"}
{"type": "open", "side": "sell", "price": "448.08000000", "order_id": "d281aa8d-dd0b-4977-ad2f-c4244d599422", "remaining_size": "11.74997000", "product_id": "ETH-USD", "sequence": 4179037806, "time": "2018-07-02T05:24:30.186000Z"}
{"type": "done", "side": "sell", "order_id": "dd7f8522-101a-4da6-8c9e-8d10e95c20d0", "reason": "canceled", "product_id": "BTC-USD", "price": "6310.29000000", "remaining_size": "0.25000000", "sequence": 6227079505, "time": "2018-07-02T05:24:30.206000Z"}
{"type": "received", "order_id": "1e510685-340f-480f-ab6d-4d6feffb46ad", "order_type": "limit", "size": "0.25000000", "price": "6313.32000000", "side": "sell", "client_oid": "62910b4b-3619-4236-aa42-909cfde596d2", "product_id": "BTC-USD", "sequence": 6227079506, "time": "2018-07-02T05:24:30.220000Z"}
{"type": "open", "side": "sell", "price": "6313.32000000", "order_id": "1e510685-340f-480f-ab6d-4d6feffb46ad", "remaining_size": "0.25000000", "product_id": "BTC-USD", "sequence": 6227079507, "time": "2018-07-02T05:24:30.220000Z"}
{"type": "received", "order_id": "2cacf5ce-b287-4bb6-bc2a-5dd037cdff0d", "order_type": "limit", "size": "14.24999000", "price": "448.03000000", "side": "sell", "client_oid": "07d36f17-2ed7-4c3a-ab2e-a6568156f017", "product_id": "ETH-USD", "sequence": 4179037807, "time": "2018-07-02T05:24:30.220000Z"}
{"type": "open", "side": "sell", "price": "448.03000000", "order_id": "2cacf5ce-b287-4bb6-bc2a-5dd037cdff0d", "remaining_size": "14.24999000", "product_id": "ETH-USD", "sequence": 4179037808, "time": "2018-07-02T05:24:30.220000Z"}
{"type": "received", "order_id": "bfa30a96-a5dc-4ba1-932c-c9e7c5f4981f", "order_type": "limit", "size": "10.12783579", "price": "444.32000000", "side": "buy", "product_id": "ETH-USD", "sequence": 4179037809, "time": "2018-07-02T05:24:30.231000Z"}
{"type": "open", "side": "buy", "price": "444.32000000", "order_id": "bfa30a96-a5dc-4ba1-932c-c9e7c5f4981f", "remaining_size": "10.12783579", "product_id": "ETH-USD", "sequence": 4179037810, "time": "2018-07-02T05:24:30.231000Z"}
{"type": "received", "order_id": "76c456ce-401c-4601-90ea-3e3a0e131aef", "order_type": "limit", "size": "6.73763644", "price": "445.26000000", "side": "buy", "product_id": "ETH-USD", "sequence": 4179037811, "time": "2018-07-02T05:24:30.234000Z"}
{"type": "open", "side": "buy", "price": "445.26000000", "order_id": "76c456ce-401c-4601-90ea-3e3a0e131aef", "remaining_size": "6.73763644", "product_id": "ETH-USD", "sequence": 4179037812, "time": "2018-07-02T05:24:30.234000Z"}
{"type": "done", "side": "sell", "order_id": "1e510685-340f-480f-ab6d-4d6feffb46ad", "reason": "canceled", "product_id": "BTC-USD", "price": "6313.32000000", "remaining_size": "0.25000000", "sequence": 6227079508, "time": "2018-07-02T05:24:30.301000Z"}
{"type": "received", "order_id": "8e336e39-5fbf-48aa-9422-7449f8813138", "order_type": "limit", "size": "0.01000000", "price": "450.25000000", "side": "sell", "client_oid": "6a774fba-acff-484f-8000-00e7d97dd7e9", "product_id": "ETH-USD", "sequence": 4179037813, "time": "2018-07-02T05:24:30.305000Z"}
{"type": "open", "side": "sell", "price": "450.25000000", "order_id": "8e336e39-5fbf-48aa-9422-7449f8813138", "remaining_size": "0.01000000", "product_id": "ETH-USD", "sequence": 4179037814, "time": "2018-07-02T05:24:30.305000Z"}
{"type": "received", "order_id": "ba94f72b-3511-444c-ba78-b66f05390091", "order_type": "limit", "size": "0.25000000", "price": "6310.46000000", "side": "sell", "client_oid": "7d744cc2-f7d7-49da-beb3-c83306b8d22b", "product_id": "BTC-USD", "sequence": 6227079509, "time": "2018-07-02T05:24:30.315000Z"}
{"type": "open", "side": "sell", "price": "6310.46000000", "order_id": "ba94f72b-3511-444c-ba78-b66f05390091", "remaining_size": "0.25000000", "product_id": "BTC-USD", "sequence": 6227079510, "time": "2018-07-02T05:24:30.315000Z"}
{"type": "done", "side": "sell", "order_id": "97a14d4f-adb9-4d48-9362-d22a946befa0", "reason": "canceled", "product_id": "BTC-USD", "price": "6299.55000000", "remaining_size": "0.00100000", "sequence": 6227079511, "time": "2018-07-02T05:24:30.387000Z"}
{"type": "done", "side": "sell", "order_id": "7ee41141-c403-41ea-9afd-eb9977eb0295", "reason": "canceled", "product_id": "ETH-USD", "price": "447.17000000", "remaining_size": "2.68391400", "sequence": 4179037815, "time": "2018-07-02T05:24:30.417000Z"}
{"type": "done", "side": "sell", "order_id": "ba94f72b-3511-444c-ba78-b66f05390091", "reason": "canceled", "product_id": "BTC-USD", "price": "6310.46000000", "remaining_size": "0.25000000", "sequence": 6227079512, "time": "2018-07-02T05:24:30.421000Z"}
{"type": "done", "side": "sell", "order_id": "68b66ae6-cf73-4418-99fb-aa4ce94f0dbe", "reason": "canceled", "product_id": "ETH-USD", "price": "448.25000000", "remaining_size": "0.01000000", "sequence": 4179037816, "time": "2018-07-02T05:24:30.423000Z"}
{"type": "done", "side": "sell", "order_id": "db7cc5ea-3bd7-4599-8d4f-b39921291dfe", "reason": "canceled", "product_id": "BTC-USD", "price": "6300.55000000", "remaining_size": "0.00100000", "sequence": 6227079513, "time": "2018-07-02T05:24:30.426000Z"}
{"type": "done", "side": "sell", "order_id": "6c26253a-d4c1-478a-bfe4-68c168afe6b5", "reason": "canceled", "product_id": "BTC-USD", "price": "6302.55000000", "remaining_size": "0.00100000", "sequence": 6227079514, "time": "2018-07-02T05:24:30.429000Z"}
{"type": "done", "side": "sell", "order_id": "94b46aa9-fa38-46df-97b1-3a05a4c915a2", "reason": "canceled", "product_id": "BTC-USD", "price": "6301.55000000", "remaining_size": "0.00100000", "sequence": 6227079515, "time": "2018-07-02T05:24:30.429000Z"}
{"type": "done", "side": "sell", "order_id": "1bb24510-9984-453b-86cc-ff89717fa6cd", "reason": "canceled", "product_id": "BTC-USD", "price": "6304.55000000", "remaining_size": "0.00100000", "sequence": 6227079516, "time": "2018-07-02T05:24:30.431000Z"}
{"type": "done", "side": "sell", "order_id": "6e40c8dc-cd17-4054-877f-23f1b84988dd", "reason": "canceled", "product_id": "BTC-USD", "price": "6303.55000000", "remaining_size": "0.00100000", "sequence": 6227079517, "time": "2018-07-02T05:24:30.431000Z"}
{"type": "done", "side": "sell", "order_id": "d9b24879-ed7c-4dba-aa33-63c02c158bd1", "reason": "canceled", "product_id": "BTC-USD", "price": "6298.55000000", "remaining_size": "0.00100000", "sequence": 6227079518, "time": "2018-07-02T05:24:30.433000Z"}
{"type": "received", "order_id": "18a6f5ea-cfe3-4e98-91cc-f6310e147194", "order_type": "limit", "size": "0.00100000", "price": "6305.55000000", "side": "sell", "client_oid": "9ba80d10-cfbb-4c9a-8000-008e32e9edb7", "product_id": "BTC-USD", "sequence": 6227079519, "time": "2018-07-02T05:24:30.434000Z"}
{"type": "open", "side": "sell", "price": "6305.55000000", "order_id": "18a6f5ea-cfe3-4e98-91cc-f6310e147194", "remaining_size": "0.00100000", "product_id": "BTC-USD", "sequence": 6227079520, "time": "2018-07-02T05:24:30.434000Z"}
{"type": "received", "order_id": "ae8c3c34-e782-41e0-9c9d-aea353d9442b", "order_type": "limit", "size": "0.25000000", "price": "6313.29000000", "side": "sell", "client_oid": "0b3dcd81-cb5a-4f6d-a1db-b267455fbf44", "product_id": "BTC-USD", "sequence": 6227079521, "time": "2018-07-02T05:24:30.441000Z"}
{"type": "open", "side": "sell", "price": "6313.29000000", "order_id": "ae8c3c34-e782-41e0-9c9d-aea353d9442b", "remaining_size": "0.25000000", "product_id": "BTC-USD", "sequence": 6227079522, "time": "2018-07-02T05:24:30.441000Z"}
{"type": "done", "side": "buy", "order_id": "88d5ca16-aec9-478e-b9bc-ed7300c7a785", "reason": "canceled", "product_id": "ETH-USD", "price": "445.81000000", "remaining_size": "13.00000000", "sequence": 4179037817, "time": "2018-07-02T05:24:30.445000Z"}
{"type": "done", "side": "sell", "order_id": "ae8c3c34-e782-41e0-9c9d-aea353d9442b", "reason": "canceled", "product_id": "BTC-USD", "price": "6313.29000000", "remaining_size": "0.25000000", "sequence": 6227079523, "time": "2018-07-02T05:24:30.449000Z"}
{"type": "received", "order_id": "7a17a56e-61e4-4259-ad9e-2e09941a566b", "order_type": "limit", "size": "0.25000000", "price": "6313.32000000", "side": "sell", "client_oid": "12fd7742-ad50-420a-a721-ce8b5ca5840b", "product_id": "BTC-USD", "sequence": 6227079524, "time": "2018-07-02T05:24:30.464000Z"}
{"type": "done", "side": "sell", "order_id": "0fb9f9a8-306d-44cc-8025-7d9f32da0ec8", "reason": "canceled", "product_id": "ETH-USD", "price": "449.25000000", "remaining_size": "0.01000000", "sequence": 4179037818, "time": "2018-07-02T05:24:30.463000Z"}
{"type": "open", "side": "sell", "price": "6313.32000000", "order_id": "7a17a56e-61e4-4259-ad9e-2e09941a566b", "remaining_size": "0.25000000", "product_id": "BTC-USD", "sequence": 6227079525, "time": "2018-07-02T05:24:30.464000Z"}
{"type": "received", "order_id": "03bf8bdd-3338-47a2-9084-0ca25ab6782d", "order_type": "limit", "size": "0.00200000", "price": "6298.26000000", "side": "buy", "product_id": "BTC-USD", "sequence": 6227079526, "time": "2018-07-02T05:24:30.467000Z"}
{"type": "open", "side": "buy", "price": "6298.26000000", "order_id": "03bf8bdd-3338-47a2-9084-0ca25ab6782d", "remaining_size": "0.00200000", "product_id": "BTC-USD", "sequence": 6227079527, "time": "2018-07-02T05:24:30.467000Z"}
{"type": "received", "order_id": "6bf9fc49-a46e-4d2c-b455-7542820024f2", "order_type": "limit", "size": "0.01000000", "price": "451.25000000", "side": "sell", "client_oid": "1e408316-5df0-46ec-8000-00d6a79938c2", "product_id": "ETH-USD", "sequence": 4179037819, "time": "2018-07-02T05:24:30.470000Z"}
{"type": "open", "side": "sell", "price": "451.25000000", "order_id": "6bf9fc49-a46e-4d2c-b455-7542820024f2", "remaining_size": "0.01000000", "product_id": "ETH-USD", "sequence": 4179037820, "time": "2018-07-02T05:24:30.470000Z"}
{"type": "received", "order_id": "544d8834-1382-4d70-8740-bd564da2e411", "order_type": "limit", "size": "13.00000000", "price": "446.19000000", "side": "buy", "client_oid": "85b47992-a7b5-4ef3-baac-6f9a1c16a4f7", "product_id": "ETH-USD", "sequence": 4179037821, "time": "2018-07-02T05:24:30.478000Z"}
{"type": "open", "side": "buy", "price": "446.19000000", "order_id": "544d8834-1382-4d70-8740-bd564da2e411", "remaining_size": "13.00000000", "product_id": "ETH-USD", "sequence": 4179037822, "time": "2018-07-02T05:24:30.478000Z"}
{"type": "done", "side": "sell", "order_id": "7a17a56e-61e4-4259-ad9e-2e09941a566b", "reason": "canceled", "product_id": "BTC-USD", "price": "6313.32000000", "remaining_size": "0.25000000", "sequence": 6227079528, "time": "2018-07-02T05:24:30.502000Z"}
{"type": "done", "side": "sell", "order_id": "335ff166-22b2-4b6a-b76b-c76d6be7a84d", "reason": "canceled", "product_id": "BTC-USD", "price": "6303.98000000", "remaining_size": "0.01500000", "sequence": 6227079529, "time": "2018-07-02T05:24:30.505000Z"}
{"type": "received", "order_id": "1eff1dca-4279-4aba-8b40-c353c53c7e74", "order_type": "limit", "size": "0.01500000", "price": "6304.05000000", "side": "sell", "client_oid": "71285b42-501f-4e37-b1bd-482634984f0c", "product_id": "BTC-USD", "sequence": 6227079530, "time": "2018-07-02T05:24:30.510000Z"}
{"type": "open", "side": "sell", "price": "6304.05000000", "order_id": "1eff1dca-4279-4aba-8b40-c353c53c7e74", "remaining_size": "0.01500000", "product_id": "BTC-USD", "sequence": 6227079531, "time": "2018-07-02T05:24:30.510000Z"}
{"type": "received", "order_id": "793840f1-ac54-4fcf-9edc-280c166a5612", "order_type": "limit", "size": "0.25000000", "price": "6310.44000000", "side": "sell", "client_oid": "07b75139-d479-41a2-a027-59ac8c48d8e8", "product_id": "BTC-USD", "sequence": 6227079532, "time": "2018-07-02T05:24:30.519000Z"}
{"type": "open", "side": "sell", "price": "6310.44000000", "order_id": "793840f1-ac54-4fcf-9edc-280c166a5612", "remaining_size": "0.25000000", "product_id": "BTC-USD", "sequence": 6227079533, "time": "2018-07-02T05:24:30.519000Z"}
{"type": "done", "side": "buy", "order_id": "86f90889-ca5c-4aa5-b487-ed7492e5e9b1", "reason": "canceled", "product_id": "ETH-USD", "price": "446.01000000", "remaining_size": "0.01000000", "sequence": 4179037823, "time": "2018-07-02T05:24:30.581000Z"}
{"type": "received", "order_id": "533c4688-3838-417e-956a-e586fa1984bc", "order_type": "limit", "size": "0.01000000", "price": "446.03000000", "side": "buy", "client_oid": "fa2de200-0007-427d-8020-0000727d0020", "product_id": "ETH-USD", "sequence": 4179037824, "time": "2018-07-02T05:24:30.589000Z"}
{"type": "open", "side": "buy", "price": "446.03000000", "order_id": "533c4688-3838-417e-956a-e586fa1984bc", "remaining_size": "0.01000000", "product_id": "ETH-USD", "sequence": 4179037825, "time": "2018-07-02T05:24:30.589000Z"}
{"type": "received", "order_id": "b12b758e-d00d-408e-af12-a0b31705942d", "order_type": "limit", "size": "0.09300000", "price": "442.39000000", "side": "buy", "product_id": "ETH-USD", "sequence": 4179037826, "time": "2018-07-02T05:24:30.596000Z"}
{"type": "open", "side": "buy", "price": "442.39000000", "order_id": "b12b758e-d00d-408e-af12-a0b31705942d", "remaining_size": "0.09300000", "product_id": "ETH-USD", "sequence": 4179037827, "time": "2018-07-02T05:24:30.596000Z"}
{"type": "received", "order_id": "25dc5246-eda8-4afc-834e-8fad3b5c5d62", "order_type": "limit", "size": "1.00000000", "price": "6283.90000000", "side": "buy", "product_id": "BTC-USD", "sequence": 6227079534, "time": "2018-07-02T05:24:30.599000Z"}
{"type": "open", "side": "buy", "price": "6283.90000000", "order_id": "25dc5246-eda8-4afc-834e-8fad3b5c5d62", "remaining_size": "1.00000000", "product_id": "BTC-USD", "sequence": 6227079535, "time": "2018-07-02T05:24:30.599000Z"}
{"type": "done", "side": "sell", "order_id": "793840f1-ac54-4fcf-9edc-280c166a5612", "reason": "canceled", "product_id": "BTC-USD", "price": "6310.44000000", "remaining_size": "0.25000000", "sequence": 6227079536, "time": "2018-07-02T05:24:30.600000Z"}
{"type": "received", "order_id": "1a51b602-0c88-4d47-958b-8e01becb9a9a", "order_type": "limit", "size": "0.25000000", "price": "6313.32000000", "side": "sell", "client_oid": "442109e3-194f-4ce4-a44e-b215a2d9387a", "product_id": "BTC-USD", "sequence": 6227079537, "time": "2018-07-02T05:24:30.617000Z"}
{"type": "open", "side": "sell", "price": "6313.32000000", "order_id": "1a51b602-0c88-4d47-958b-8e01becb9a9a", "remaining_size": "0.25000000", "product_id": "BTC-USD", "sequence": 6227079538, "time": "2018-07-02T05:24:30.617000Z"}
{"type": "received", "order_id": "c2e34268-3719-4030-be54-d125f35d4f85", "order_type": "limit", "size": "1.40600000", "price": "6298.26000000", "side": "buy", "product_id": "BTC-USD", "sequence": 6227079539, "time": "2018-07-02T05:24:30.652000Z"}
{"type": "open", "side": "buy", "price": "6298.26000000", "order_id": "c2e34268-3719-4030-be54-d125f35d4f85", "remaining_size": "1.40600000", "product_id": "BTC-USD", "sequence": 6227079540, "time": "2018-07-02T05:24:30.652000Z"}
{"type": "done", "side": "buy", "order_id": "23b6fccb-bd65-4172-8daf-41e0b2442800", "reason": "canceled", "product_id": "BTC-USD", "price": "6298.26000000", "remaining_size": "0.00134000", "sequence": 6227079541, "time": "2018-07-02T05:24:30.661000Z"}
{"type": "received", "order_id": "5e63bd1d-5579-41da-a134-dc96e3565998", "order_type": "limit", "size": "0.00111000", "price": "6298.26000000", "side": "buy", "client_oid": "3253ac6c-7db8-11e8-874f-16be7828d23e", "product_id": "BTC-USD", "sequence": 6227079542, "time": "2018-07-02T05:24:30.668000Z"}
{"type": "open", "side": "buy", "price": "6298.26000000", "order_id": "5e63bd1d-5579-41da-a134-dc96e3565998", "remaining_size": "0.00111000", "product_id": "BTC-USD", "sequence": 6227079543, "time": "2018-07-02T05:24:30.668000Z"}
{"type": "done", "side": "buy", "order_id": "533c4688-3838-417e-956a-e586fa1984bc", "reason": "canceled", "product_id": "ETH-USD", "price": "446.03000000", "remaining_size": "0.01000000", "sequence": 4179037828, "time": "2018-07-02T05:24:30.681000Z"}
{"type": "received", "order_id": "7504156c-660d-487e-858d-0870992ffb19", "order_type": "limit", "size": "0.01000000", "price": "452.25000000", "side": "sell", "client_oid": "d5de6af9-0dfb-4866-8000-00fdc0c9139f", "product_id": "ETH-USD", "sequence": 4179037829, "time": "2018-07-02T05:24:30.684000Z"}
{"type": "open", "side": "sell", "price": "452.25000000", "order_id": "7504156c-660d-487e-858d-0870992ffb19", "remaining_size": "0.01000000", "product_id": "ETH-USD", "sequence": 4179037830, "time": "2018-07-02T05:24:30.684000Z"}
{"type": "received", "order_id": "c1bb1539-89b5-4dbd-8a99-ee8ffc474945", "order_type": "limit", "size": "0.01000000", "price": "446.03000000", "side": "buy", "client_oid": "17e66200-000e-417c-b840-00000e17cf84", "product_id": "ETH-USD", "sequence": 4179037831, "time": "2018-07-02T05:24:30.696000Z"}
{"type": "open", "side": "buy", "price": "446.03000000", "order_id": "c1bb1539-89b5-4dbd-8a99-ee8ffc474945", "remaining_size": "0.01000000", "product_id": "ETH-USD", "sequence": 4179037832, "time": "2018-07-02T05:24:30.696000Z"}
{"type": "done", "side": "sell", "order_id": "1a51b602-0c88-4d47-958b-8e01becb9a9a", "reason": "canceled", "product_id": "BTC-USD", "price": "6313.32000000", "remaining_size": "0.25000000", "sequence": 6227079544, "time": "2018-07-02T05:24:30.701000Z"}
{"type": "done", "side": "sell", "order_id": "6bf9fc49-a46e-4d2c-b455-7542820024f2", "reason": "canceled", "product_id": "ETH-USD", "price": "451.25000000", "remaining_size": "0.01000000", "sequence": 4179037833, "time": "2018-07-02T05:24:30.706000Z"}
{"type": "done", "side": "sell", "order_id": "8e336e39-5fbf-48aa-9422-7449f8813138", "reason": "canceled", "product_id": "ETH-USD", "price": "450.25000000", "remaining_size": "0.01000000", "sequence": 4179037834, "time": "2018-07-02T05:24:30.707000Z"}
{"type": "received", "order_id": "fe78eede-717c-42f7-b16c-6b3e0bca45f9", "order_type": "limit", "size": "0.25000000", "price": "6310.43000000", "side": "sell", "client_oid": "ffd7d4a1-35c8-4b01-b881-7bd617c4e309", "product_id": "BTC-USD", "sequence": 6227079545, "time": "2018-07-02T05:24:30.715000Z"}
{"type": "received", "order_id": "ea588591-c03b-4d22-8fca-9b898da79bef", "order_type": "limit", "size": "0.01000000", "price": "453.25000000", "side": "sell", "client_oid": "42f77b7b-a947-47e0-8000-071d8d9d8e10", "product_id": "ETH-USD", "sequence": 4179037835, "time": "2018-07-02T05:24:30.713000Z"}
{"type": "open", "side": "sell", "price": "453.25000000", "order_id": "ea588591-c03b-4d22-8fca-9b898da79bef", "remaining_size": "0.01000000", "product_id": "ETH-USD", "sequence": 4179037836, "time": "2018-07-02T05:24:30.713000Z"}
{"type": "open", "side": "sell", "price": "6310.43000000", "order_id": "fe78eede-717c-42f7-b16c-6b3e0bca45f9", "remaining_size": "0.25000000", "product_id": "BTC-USD", "sequence": 6227079546, "time": "2018-07-02T05:24:30.715000Z"}
{"type": "done", "side": "buy", "order_id": "c243aa5a-a228-40ea-ada3-cca343179307", "reason": "canceled", "product_id": "BTC-USD", "price": "6085.89000000", "remaining_size": "0.00150000", "sequence": 6227079547, "time": "2018-07-02T05:24:30.765000Z"}
{"type": "done", "side": "sell", "order_id": "f41e6e00-ba35-45e1-b997-a1542a3e94cd", "reason": "canceled", "product_id": "ETH-USD", "price": "472.67000000", "remaining_size": "0.01000000", "sequence": 4179037837, "time": "2018-07-02T05:24:30.767000Z"}
{"type": "received", "order_id": "7da0ff6d-ca49-424e-9a02-b10907cc0e9c", "order_type": "limit", "size": "0.00150000", "price": "6051.91000000", "side": "buy", "client_oid": "dfe95b3d-460f-4aa7-8000-0020ac1f4b79", "product_id": "BTC-USD", "sequence": 6227079548, "time": "2018-07-02T05:24:30.771000Z"}
{"type": "open", "side": "buy", "price": "6051.91000000", "order_id": "7da0ff6d-ca49-424e-9a02-b10907cc0e9c", "remaining_size": "0.00150000", "product_id": "BTC-USD", "sequence": 6227079549, "time": "2018-07-02T05:24:30.771000Z"}
{"type": "received", "order_id": "d495e330-6ea7-4eb9-a11f-d2ad2eaf864c", "order_type": "limit", "size": "0.01000000", "price": "474.70000000", "side": "sell", "client_oid": "8b328bc5-546c-4d0e-8000-00367d643d8f", "product_id": "ETH-USD", "sequence": 4179037838, "time": "2018-07-02T05:24:30.790000Z"}
{"type": "open", "side": "sell", "price": "474.70000000", "order_id": "d495e330-6ea7-4eb9-a11f-d2ad2eaf864c", "remaining_size": "0.01000000", "product_id": "ETH-USD", "sequence": 4179037839, "time": "2018-07-02T05:24:30.790000Z"}
{"type": "done", "side": "buy", "order_id": "c1bb1539-89b5-4dbd-8a99-ee8ffc474945", "reason": "canceled", "product_id": "ETH-USD", "price": "446.03000000", "remaining_size": "0.01000000", "sequence": 4179037840, "time": "2018-07-02T05:24:30.801000Z"}
{"type": "received", "order_id": "8f51ed0e-a929-4530-b339-b989246f767a", "order_type": "limit", "size": "0.01000000", "price": "446.03000000", "side": "buy", "client_oid": "ba3fc000-0003-41ed-8130-0000031ed813", "product_id": "ETH-USD", "sequence": 4179037841, "time": "2018-07-02T05:24:30.808000Z"}
{"type": "open", "side": "buy", "price": "446.03000000", "order_id": "8f51ed0e-a929-4530-b339-b989246f767a", "remaining_size": "0.01000000", "product_id": "ETH-USD", "sequence": 4179037842, "time": "2018-07-02T05:24:30.808000Z"}
