{"type": "done", "side": "sell", "order_id": "f8c2ae0a-e888-4dfb-9563-d45498701ce9", "reason": "canceled", "product_id": "BTC-USD", "price": "6302.70000000", "remaining_size": "0.01500000", "sequence": 6227073848, "time": "2018-07-02T05:20:58.248000Z"}{"type": "done", "side": "buy", "order_id": "cd6e11e6-e818-481c-b4f7-6118356b43fa", "reason": "canceled", "product_id": "BTC-USD", "price": "6297.82000000", "remaining_size": "0.25000000", "sequence": 6227074756, "time": "2018-07-02T05:21:23.986000Z"}
{"type": "received", "order_id": "46849c0d-2f82-44b9-b085-823fe226b837", "order_type": "limit", "size": "6.87320969", "price": "446.69000000", "side": "buy", "client_oid": "3b5c30f8-4db5-c10e-4afb-16dc18a9784b", "product_id": "ETH-USD", "sequence": 4179023944, "time": "2018-07-02T05:21:44.895000Z"}
{"type": "open", "side": "buy", "price": "446.69000000", "order_id": "46849c0d-2f82-44b9-b085-823fe226b837", "remaining_size": "6.87320969", "product_id": "ETH-USD", "sequence": 4179023945, "time": "2018-07-02T05:21:44.895000Z"}
{"type": "done", "side": "sell", "order_id": "9c432d4c-9638-49a4-b67e-a1003aa6379d", "reason": "canceled", "product_id": "ETH-USD", "price": "447.80000000", "remaining_size": "6.00000000", "sequence": 4179023946, "time": "2018-07-02T05:21:44.898000Z"}
{"type": "done", "side": "sell", "order_id": "062c56ee-0d5c-4873-8afd-7277eaf1ff92", "reason": "canceled", "product_id": "ETH-USD", "price": "447.84000000", "remaining_size": "6.00000000", "sequence": 4179023947, "time": "2018-07-02T05:21:44.900000Z"}
{"type": "done", "side": "sell", "order_id": "1417cb37-0d1b-41e5-8098-a992826805a0", "reason": "canceled", "product_id": "ETH-USD", "price": "447.94000000", "remaining_size": "9.00000000", "sequence": 4179023948, "time": "2018-07-02T05:21:44.902000Z"}
{"type": "done", "side": "sell", "order_id": "f38d8d77-b60a-49ae-ade5-9440d62629f4", "reason": "canceled", "product_id": "ETH-USD", "price": "447.84000000", "remaining_size": "9.00000000", "sequence": 4179023949, "time": "2018-07-02T05:21:44.904000Z"}
{"type": "received", "order_id": "0c1f4346-8678-466a-9383-9f655481703d", "order_type": "limit", "size": "6.00000000", "price": "447.73000000", "side": "sell", "client_oid": "823c3040-1d09-4a4d-a881-300285bd4c34", "product_id": "ETH-USD", "sequence": 4179023950, "time": "2018-07-02T05:21:44.904000Z"}
{"type": "open", "side": "sell", "price": "447.73000000", "order_id": "0c1f4346-8678-466a-9383-9f655481703d", "remaining_size": "6.00000000", "product_id": "ETH-USD", "sequence": 4179023951, "time": "2018-07-02T05:21:44.904000Z"}
{"type": "done", "side": "buy", "order_id": "f70d2ad9-62be-4fa1-8ab6-434ab89affa3", "reason": "canceled", "product_id": "ETH-USD", "price": "446.14000000", "remaining_size": "0.01000000", "sequence": 4179023952, "time": "2018-07-02T05:21:44.906000Z"}
{"type": "received", "order_id": "848465bc-1684-4b0d-b9a7-a968649b418b", "order_type": "limit", "size": "9.00000000", "price": "447.87000000", "side": "sell", "client_oid": "bd093f06-cb9b-4559-8c27-fde5a0e41679", "product_id": "ETH-USD", "sequence": 4179023953, "time": "2018-07-02T05:21:44.907000Z"}
{"type": "open", "side": "sell", "price": "447.87000000", "order_id": "848465bc-1684-4b0d-b9a7-a968649b418b", "remaining_size": "9.00000000", "product_id": "ETH-USD", "sequence": 4179023954, "time": "2018-07-02T05:21:44.907000Z"}
{"type": "received", "order_id": "72f8d002-1f6b-4234-813a-8c0798a39ef0", "order_type": "limit", "size": "6.00000000", "price": "447.77000000", "side": "sell", "client_oid": "7e97e0ac-a0cc-480b-aceb-b9a7943532be", "product_id": "ETH-USD", "sequence": 4179023955, "time": "2018-07-02T05:21:44.908000Z"}
{"type": "open", "side": "sell", "price": "447.77000000", "order_id": "72f8d002-1f6b-4234-813a-8c0798a39ef0", "remaining_size": "6.00000000", "product_id": "ETH-USD", "sequence": 4179023956, "time": "2018-07-02T05:21:44.908000Z"}
{"type": "done", "side": "sell", "order_id": "0c1f4346-8678-466a-9383-9f655481703d", "reason": "canceled", "product_id": "ETH-USD", "price": "447.73000000", "remaining_size": "6.00000000", "sequence": 4179023957, "time": "2018-07-02T05:21:44.908000Z"}
{"type": "received", "order_id": "13022158-b58e-4b19-aba2-fdde462d668f", "order_type": "limit", "size": "9.00000000", "price": "447.77000000", "side": "sell", "client_oid": "8d06e221-f153-4222-907a-b8f8247f9bf5", "product_id": "ETH-USD", "sequence": 4179023958, "time": "2018-07-02T05:21:44.911000Z"}
{"type": "open", "side": "sell", "price": "447.77000000", "order_id": "13022158-b58e-4b19-aba2-fdde462d668f", "remaining_size": "9.00000000", "product_id": "ETH-USD", "sequence": 4179023959, "time": "2018-07-02T05:21:44.911000Z"}
{"type": "done", "side": "sell", "order_id": "72f8d002-1f6b-4234-813a-8c0798a39ef0", "reason": "canceled", "product_id": "ETH-USD", "price": "447.77000000", "remaining_size": "6.00000000", "sequence": 4179023960, "time": "2018-07-02T05:21:44.911000Z"}
{"type": "received", "order_id": "62da52b4-47c9-4c9b-9aa1-cfe015357d9f", "order_type": "limit", "size": "0.01000000", "price": "446.19000000", "side": "buy", "client_oid": "30b21200-000a-4440-8540-00000a440854", "product_id": "ETH-USD", "sequence": 4179023961, "time": "2018-07-02T05:21:44.913000Z"}
{"type": "open", "side": "buy", "price": "446.19000000", "order_id": "62da52b4-47c9-4c9b-9aa1-cfe015357d9f", "remaining_size": "0.01000000", "product_id": "ETH-USD", "sequence": 4179023962, "time": "2018-07-02T05:21:44.913000Z"}
{"type": "done", "side": "sell", "order_id": "848465bc-1684-4b0d-b9a7-a968649b418b", "reason": "canceled", "product_id": "ETH-USD", "price": "447.87000000", "remaining_size": "9.00000000", "sequence": 4179023963, "time": "2018-07-02T05:21:44.914000Z"}
{"type": "done", "side": "sell", "order_id": "13022158-b58e-4b19-aba2-fdde462d668f", "reason": "canceled", "product_id": "ETH-USD", "price": "447.77000000", "remaining_size": "9.00000000", "sequence": 4179023964, "time": "2018-07-02T05:21:44.915000Z"}
{"type": "received", "order_id": "47afa418-c6ba-4dac-b411-3acb6ed1c5d2", "order_type": "limit", "size": "6.00000000", "price": "447.80000000", "side": "sell", "client_oid": "0b1eeb8b-e0a1-42f2-b99c-bcbf6d77f354", "product_id": "ETH-USD", "sequence": 4179023965, "time": "2018-07-02T05:21:44.919000Z"}
{"type": "open", "side": "sell", "price": "447.80000000", "order_id": "47afa418-c6ba-4dac-b411-3acb6ed1c5d2", "remaining_size": "6.00000000", "product_id": "ETH-USD", "sequence": 4179023966, "time": "2018-07-02T05:21:44.919000Z"}
{"type": "received", "order_id": "ea416d1c-2131-41ca-aeed-9f2874e57fa2", "order_type": "limit", "size": "9.00000000", "price": "447.84000000", "side": "sell", "client_oid": "08fe9b39-fba5-41a4-82f3-a8d7d088f157", "product_id": "ETH-USD", "sequence": 4179023967, "time": "2018-07-02T05:21:44.921000Z"}
{"type": "open", "side": "sell", "price": "447.84000000", "order_id": "ea416d1c-2131-41ca-aeed-9f2874e57fa2", "remaining_size": "9.00000000", "product_id": "ETH-USD", "sequence": 4179023968, "time": "2018-07-02T05:21:44.921000Z"}
{"type": "received", "order_id": "5d02cb17-7e43-4a5f-a65e-7206a91a0b80", "order_type": "limit", "size": "6.00000000", "price": "447.84000000", "side": "sell", "client_oid": "c2a6de5f-4f4b-4f47-8efe-5028f7063d10", "product_id": "ETH-USD", "sequence": 4179023969, "time": "2018-07-02T05:21:44.922000Z"}
{"type": "open", "side": "sell", "price": "447.84000000", "order_id": "5d02cb17-7e43-4a5f-a65e-7206a91a0b80", "remaining_size": "6.00000000", "product_id": "ETH-USD", "sequence": 4179023970, "time": "2018-07-02T05:21:44.922000Z"}
{"type": "received", "order_id": "89ae4350-9987-4932-875f-a9e934c8457e", "order_type": "limit", "size": "9.00000000", "price": "447.94000000", "side": "sell", "client_oid": "130d44c4-701e-4730-95ae-f27fcc758ada", "product_id": "ETH-USD", "sequence": 4179023971, "time": "2018-07-02T05:21:44.924000Z"}
{"type": "open", "side": "sell", "price": "447.94000000", "order_id": "89ae4350-9987-4932-875f-a9e934c8457e", "remaining_size": "9.00000000", "product_id": "ETH-USD", "sequence": 4179023972, "time": "2018-07-02T05:21:44.924000Z"}
{"type": "done", "side": "buy", "order_id": "ec494729-a530-48a6-9af4-e533cdadb979", "reason": "canceled", "product_id": "ETH-USD", "price": "446.68000000", "remaining_size": "0.01000000", "sequence": 4179023973, "time": "2018-07-02T05:21:44.924000Z"}
{"type": "done", "side": "buy", "order_id": "46849c0d-2f82-44b9-b085-823fe226b837", "reason": "canceled", "product_id": "ETH-USD", "price": "446.69000000", "remaining_size": "6.87320969", "sequence": 4179023974, "time": "2018-07-02T05:21:44.932000Z"}
{"type": "done", "side": "sell", "order_id": "cfb05c2e-14ec-4619-aee4-0545e02236fd", "reason": "canceled", "product_id": "ETH-USD", "price": "447.17000000", "remaining_size": "4.00000000", "sequence": 4179023975, "time": "2018-07-02T05:21:44.934000Z"}
{"type": "received", "order_id": "60db5adb-bbfa-412c-a945-62ed1befc184", "order_type": "limit", "size": "6.87320969", "price": "446.66000000", "side": "buy", "client_oid": "cc4c463f-7fdf-a72b-dca7-d64bb3835088", "product_id": "ETH-USD", "sequence": 4179023976, "time": "2018-07-02T05:21:44.938000Z"}
{"type": "open", "side": "buy", "price": "446.66000000", "order_id": "60db5adb-bbfa-412c-a945-62ed1befc184", "remaining_size": "6.87320969", "product_id": "ETH-USD", "sequence": 4179023977, "time": "2018-07-02T05:21:44.938000Z"}
{"type": "done", "side": "sell", "order_id": "5d02cb17-7e43-4a5f-a65e-7206a91a0b80", "reason": "canceled", "product_id": "ETH-USD", "price": "447.84000000", "remaining_size": "6.00000000", "sequence": 4179023978, "time": "2018-07-02T05:21:44.938000Z"}
{"type": "done", "side": "sell", "order_id": "47afa418-c6ba-4dac-b411-3acb6ed1c5d2", "reason": "canceled", "product_id": "ETH-USD", "price": "447.80000000", "remaining_size": "6.00000000", "sequence": 4179023979, "time": "2018-07-02T05:21:44.939000Z"}
{"type": "done", "side": "sell", "order_id": "ea416d1c-2131-41ca-aeed-9f2874e57fa2", "reason": "canceled", "product_id": "ETH-USD", "price": "447.84000000", "remaining_size": "9.00000000", "sequence": 4179023980, "time": "2018-07-02T05:21:44.940000Z"}
{"type": "done", "side": "sell", "order_id": "89ae4350-9987-4932-875f-a9e934c8457e", "reason": "canceled", "product_id": "ETH-USD", "price": "447.94000000", "remaining_size": "9.00000000", "sequence": 4179023981, "time": "2018-07-02T05:21:44.941000Z"}
{"type": "received", "order_id": "7938bc8b-014d-491f-856b-d12a5390e5b6", "order_type": "limit", "size": "6.00000000", "price": "447.73000000", "side": "sell", "client_oid": "806c716c-49ab-41a1-933e-70ce7c890635", "product_id": "ETH-USD", "sequence": 4179023982, "time": "2018-07-02T05:21:44.945000Z"}
{"type": "open", "side": "sell", "price": "447.73000000", "order_id": "7938bc8b-014d-491f-856b-d12a5390e5b6", "remaining_size": "6.00000000", "product_id": "ETH-USD", "sequence": 4179023983, "time": "2018-07-02T05:21:44.945000Z"}
{"type": "done", "side": "buy", "order_id": "524a9bbe-eed7-4c10-b566-45a3f671ae72", "reason": "canceled", "product_id": "ETH-USD", "price": "446.68000000", "remaining_size": "0.03000000", "sequence": 4179023984, "time": "2018-07-02T05:21:44.946000Z"}
{"type": "received", "order_id": "7a3fb00b-02cf-4c3f-8a6e-73b82cfd367c", "order_type": "limit", "size": "9.00000000", "price": "447.87000000", "side": "sell", "client_oid": "41071a4f-0098-4a8a-b170-f926d4fbbd91", "product_id": "ETH-USD", "sequence": 4179023985, "time": "2018-07-02T05:21:44.947000Z"}
{"type": "open", "side": "sell", "price": "447.87000000", "order_id": "7a3fb00b-02cf-4c3f-8a6e-73b82cfd367c", "remaining_size": "9.00000000", "product_id": "ETH-USD", "sequence": 4179023986, "time": "2018-07-02T05:21:44.947000Z"}
{"type": "received", "order_id": "1fefe9e9-7224-4f54-bd15-8c03d57b76db", "order_type": "limit", "size": "6.00000000", "price": "447.77000000", "side": "sell", "client_oid": "a8b40f7b-ea99-45f2-8538-a8afe5b5a202", "product_id": "ETH-USD", "sequence": 4179023987, "time": "2018-07-02T05:21:44.948000Z"}
{"type": "open", "side": "sell", "price": "447.77000000", "order_id": "1fefe9e9-7224-4f54-bd15-8c03d57b76db", "remaining_size": "6.00000000", "product_id": "ETH-USD", "sequence": 4179023988, "time": "2018-07-02T05:21:44.948000Z"}
{"type": "done", "side": "sell", "order_id": "7938bc8b-014d-491f-856b-d12a5390e5b6", "reason": "canceled", "product_id": "ETH-USD", "price": "447.73000000", "remaining_size": "6.00000000", "sequence": 4179023989, "time": "2018-07-02T05:21:44.948000Z"}
{"type": "done", "side": "sell", "order_id": "7a3fb00b-02cf-4c3f-8a6e-73b82cfd367c", "reason": "canceled", "product_id": "ETH-USD", "price": "447.87000000", "remaining_size": "9.00000000", "sequence": 4179023990, "time": "2018-07-02T05:21:44.951000Z"}
{"type": "received", "order_id": "c162ab73-cd94-43c1-b416-93fa87c7fe7e", "order_type": "limit", "size": "9.00000000", "price": "447.77000000", "side": "sell", "client_oid": "3b59e056-f7ec-4eac-8bf8-bb22e5b81d76", "product_id": "ETH-USD", "sequence": 4179023991, "time": "2018-07-02T05:21:44.951000Z"}
{"type": "open", "side": "sell", "price": "447.77000000", "order_id": "c162ab73-cd94-43c1-b416-93fa87c7fe7e", "remaining_size": "9.00000000", "product_id": "ETH-USD", "sequence": 4179023992, "time": "2018-07-02T05:21:44.951000Z"}
{"type": "done", "side": "sell", "order_id": "1fefe9e9-7224-4f54-bd15-8c03d57b76db", "reason": "canceled", "product_id": "ETH-USD", "price": "447.77000000", "remaining_size": "6.00000000", "sequence": 4179023993, "time": "2018-07-02T05:21:44.953000Z"}
{"type": "done", "side": "sell", "order_id": "c162ab73-cd94-43c1-b416-93fa87c7fe7e", "reason": "canceled", "product_id": "ETH-USD", "price": "447.77000000", "remaining_size": "9.00000000", "sequence": 4179023994, "time": "2018-07-02T05:21:44.955000Z"}
{"type": "received", "order_id": "af77c354-8f72-4f91-a7d0-a598f030df44", "order_type": "limit", "size": "6.00000000", "price": "447.84000000", "side": "sell", "client_oid": "0a737e9f-4156-4002-b03b-8dd8ae58277a", "product_id": "ETH-USD", "sequence": 4179023995, "time": "2018-07-02T05:21:44.958000Z"}
{"type": "open", "side": "sell", "price": "447.84000000", "order_id": "af77c354-8f72-4f91-a7d0-a598f030df44", "remaining_size": "6.00000000", "product_id": "ETH-USD", "sequence": 4179023996, "time": "2018-07-02T05:21:44.958000Z"}
{"type": "received", "order_id": "b9d5e748-b03a-41a6-be58-75f09853c1af", "order_type": "limit", "size": "9.00000000", "price": "447.94000000", "side": "sell", "client_oid": "b5c8f4be-28c3-4172-a6ef-92bea0838c6f", "product_id": "ETH-USD", "sequence": 4179023997, "time": "2018-07-02T05:21:44.959000Z"}
{"type": "open", "side": "sell", "price": "447.94000000", "order_id": "b9d5e748-b03a-41a6-be58-75f09853c1af", "remaining_size": "9.00000000", "product_id": "ETH-USD", "sequence": 4179023998, "time": "2018-07-02T05:21:44.959000Z"}
{"type": "received", "order_id": "b8f02504-ad16-4e5c-ad4f-d0f3a13cbb0c", "order_type": "limit", "size": "9.00000000", "price": "447.84000000", "side": "sell", "client_oid": "cb220201-c2c4-455d-bab4-1c526f2088fd", "product_id": "ETH-USD", "sequence": 4179023999, "time": "2018-07-02T05:21:44.965000Z"}
{"type": "open", "side": "sell", "price": "447.84000000", "order_id": "b8f02504-ad16-4e5c-ad4f-d0f3a13cbb0c", "remaining_size": "9.00000000", "product_id": "ETH-USD", "sequence": 4179024000, "time": "2018-07-02T05:21:44.965000Z"}
{"type": "received", "order_id": "b83f5dfd-c702-4770-a90f-ea2d5c7a98f1", "order_type": "limit", "size": "0.04000000", "price": "446.68000000", "side": "buy", "client_oid": "112fde0d-e8a3-4419-a6bc-f69ec588ca5c", "product_id": "ETH-USD", "sequence": 4179024001, "time": "2018-07-02T05:21:44.975000Z"}
{"type": "open", "side": "buy", "price": "446.68000000", "order_id": "b83f5dfd-c702-4770-a90f-ea2d5c7a98f1", "remaining_size": "0.04000000", "product_id": "ETH-USD", "sequence": 4179024002, "time": "2018-07-02T05:21:44.975000Z"}
{"type": "done", "side": "sell", "order_id": "d8ec9d51-806f-4962-b0ab-d00923871ab5", "reason": "canceled", "product_id": "ETH-USD", "price": "453.25000000", "remaining_size": "0.01000000", "sequence": 4179024003, "time": "2018-07-02T05:21:44.989000Z"}
{"type": "received", "order_id": "bc777d18-1b3a-4726-9a20-45fec620e64a", "order_type": "limit", "size": "4.00000000", "price": "447.24000000", "side": "sell", "client_oid": "12a77da9-99f5-44c4-9354-405886b7238f", "product_id": "ETH-USD", "sequence": 4179024004, "time": "2018-07-02T05:21:45.000000Z"}
{"type": "open", "side": "sell", "price": "447.24000000", "order_id": "bc777d18-1b3a-4726-9a20-45fec620e64a", "remaining_size": "4.00000000", "product_id": "ETH-USD", "sequence": 4179024005, "time": "2018-07-02T05:21:45.000000Z"}
{"type": "done", "side": "buy", "order_id": "ea1a1c39-d88a-4dba-9408-b2bf30ff5d46", "reason": "canceled", "product_id": "ETH-USD", "price": "446.50000000", "remaining_size": "40.00000000", "sequence": 4179024006, "time": "2018-07-02T05:21:45.000000Z"}
{"type": "done", "side": "buy", "order_id": "60db5adb-bbfa-412c-a945-62ed1befc184", "reason": "canceled", "product_id": "ETH-USD", "price": "446.66000000", "remaining_size": "6.87320969", "sequence": 4179024007, "time": "2018-07-02T05:21:45.006000Z"}
{"type": "received", "order_id": "57049958-9c05-4be6-8f4e-ee839df0400e", "order_type": "limit", "size": "6.00000000", "price": "447.80000000", "side": "sell", "client_oid": "525bdd04-5114-489a-ab58-2bb959f5f0c2", "product_id": "ETH-USD", "sequence": 4179024008, "time": "2018-07-02T05:21:45.008000Z"}
{"type": "open", "side": "sell", "price": "447.80000000", "order_id": "57049958-9c05-4be6-8f4e-ee839df0400e", "remaining_size": "6.00000000", "product_id": "ETH-USD", "sequence": 4179024009, "time": "2018-07-02T05:21:45.008000Z"}
{"type": "done", "side": "sell", "order_id": "a39553b9-1f49-4a0b-b965-4bc454ac97d3", "reason": "canceled", "product_id": "ETH-USD", "price": "447.17000000", "remaining_size": "0.02000000", "sequence": 4179024010, "time": "2018-07-02T05:21:45.010000Z"}
{"type": "received", "order_id": "828f7cb9-6b63-4d38-a991-5961f7658d3c", "order_type": "limit", "size": "6.87320969", "price": "446.69000000", "side": "buy", "client_oid": "a13b9b5b-7d69-d6df-2b66-9f94cde8f39a", "product_id": "ETH-USD", "sequence": 4179024011, "time": "2018-07-02T05:21:45.013000Z"}
{"type": "open", "side": "buy", "price": "446.69000000", "order_id": "828f7cb9-6b63-4d38-a991-5961f7658d3c", "remaining_size": "6.87320969", "product_id": "ETH-USD", "sequence": 4179024012, "time": "2018-07-02T05:21:45.013000Z"}
{"type": "done", "side": "sell", "order_id": "b8f02504-ad16-4e5c-ad4f-d0f3a13cbb0c", "reason": "canceled", "product_id": "ETH-USD", "price": "447.84000000", "remaining_size": "9.00000000", "sequence": 4179024013, "time": "2018-07-02T05:21:45.015000Z"}
{"type": "done", "side": "sell", "order_id": "b9d5e748-b03a-41a6-be58-75f09853c1af", "reason": "canceled", "product_id": "ETH-USD", "price": "447.94000000", "remaining_size": "9.00000000", "sequence": 4179024014, "time": "2018-07-02T05:21:45.016000Z"}
{"type": "received", "order_id": "ec2d9838-cbbf-495f-9ead-795b904084b7", "order_type": "limit", "size": "0.10000000", "price": "446.68000000", "side": "buy", "client_oid": "d17ec0df-1e30-42a3-a3d2-88136b6ef9e0", "product_id": "ETH-USD", "sequence": 4179024015, "time": "2018-07-02T05:21:45.016000Z"}
{"type": "open", "side": "buy", "price": "446.68000000", "order_id": "ec2d9838-cbbf-495f-9ead-795b904084b7", "remaining_size": "0.10000000", "product_id": "ETH-USD", "sequence": 4179024016, "time": "2018-07-02T05:21:45.016000Z"}
{"type": "done", "side": "sell", "order_id": "57049958-9c05-4be6-8f4e-ee839df0400e", "reason": "canceled", "product_id": "ETH-USD", "price": "447.80000000", "remaining_size": "6.00000000", "sequence": 4179024017, "time": "2018-07-02T05:21:45.020000Z"}
{"type": "done", "side": "sell", "order_id": "af77c354-8f72-4f91-a7d0-a598f030df44", "reason": "canceled", "product_id": "ETH-USD", "price": "447.84000000", "remaining_size": "6.00000000", "sequence": 4179024018, "time": "2018-07-02T05:21:45.021000Z"}
{"type": "received", "order_id": "df3fdab8-e68e-428c-88ec-394baf5915d7", "order_type": "limit", "size": "9.00000000", "price": "447.87000000", "side": "sell", "client_oid": "4df2c7f3-0458-4570-b031-87c1adbd45c6", "product_id": "ETH-USD", "sequence": 4179024019, "time": "2018-07-02T05:21:45.023000Z"}
{"type": "open", "side": "sell", "price": "447.87000000", "order_id": "df3fdab8-e68e-428c-88ec-394baf5915d7", "remaining_size": "9.00000000", "product_id": "ETH-USD", "sequence": 4179024020, "time": "2018-07-02T05:21:45.023000Z"}
{"type": "received", "order_id": "cf9ae488-31ac-4eea-8b0f-1d5912b5c7d2", "order_type": "limit", "size": "9.00000000", "price": "447.76000000", "side": "sell", "client_oid": "edd45c03-9cca-4625-b889-95a2c70da83a", "product_id": "ETH-USD", "sequence": 4179024021, "time": "2018-07-02T05:21:45.026000Z"}
{"type": "open", "side": "sell", "price": "447.76000000", "order_id": "cf9ae488-31ac-4eea-8b0f-1d5912b5c7d2", "remaining_size": "9.00000000", "product_id": "ETH-USD", "sequence": 4179024022, "time": "2018-07-02T05:21:45.026000Z"}
{"type": "done", "side": "sell", "order_id": "df3fdab8-e68e-428c-88ec-394baf5915d7", "reason": "canceled", "product_id": "ETH-USD", "price": "447.87000000", "remaining_size": "9.00000000", "sequence": 4179024023, "time": "2018-07-02T05:21:45.026000Z"}
{"type": "received", "order_id": "0afb2455-0499-4180-89f6-7f448821b67f", "order_type": "limit", "size": "48.54000000", "price": "446.50000000", "side": "buy", "client_oid": "28c3bf27-5c58-440c-ba06-6fd9a81380ce", "product_id": "ETH-USD", "sequence": 4179024024, "time": "2018-07-02T05:21:45.026000Z"}
{"type": "open", "side": "buy", "price": "446.50000000", "order_id": "0afb2455-0499-4180-89f6-7f448821b67f", "remaining_size": "48.54000000", "product_id": "ETH-USD", "sequence": 4179024025, "time": "2018-07-02T05:21:45.026000Z"}
{"type": "received", "order_id": "0fd7d7bf-9796-42c0-a9c0-bf339641597c", "order_type": "limit", "size": "6.00000000", "price": "447.72000000", "side": "sell", "client_oid": "f8c1ceb6-b0d6-4ee9-a05f-30cf234b3c12", "product_id": "ETH-USD", "sequence": 4179024026, "time": "2018-07-02T05:21:45.026000Z"}
{"type": "open", "side": "sell", "price": "447.72000000", "order_id": "0fd7d7bf-9796-42c0-a9c0-bf339641597c", "remaining_size": "6.00000000", "product_id": "ETH-USD", "sequence": 4179024027, "time": "2018-07-02T05:21:45.026000Z"}
{"type": "received", "order_id": "9210b344-7415-4e34-a80a-6b7cc6b982bb", "order_type": "limit", "size": "6.00000000", "price": "447.76000000", "side": "sell", "client_oid": "878d4f3d-7748-402d-b774-eb30d13f44c6", "product_id": "ETH-USD", "sequence": 4179024028, "time": "2018-07-02T05:21:45.029000Z"}
{"type": "open", "side": "sell", "price": "447.76000000", "order_id": "9210b344-7415-4e34-a80a-6b7cc6b982bb", "remaining_size": "6.00000000", "product_id": "ETH-USD", "sequence": 4179024029, "time": "2018-07-02T05:21:45.029000Z"}
{"type": "done", "side": "sell", "order_id": "cf9ae488-31ac-4eea-8b0f-1d5912b5c7d2", "reason": "canceled", "product_id": "ETH-USD", "price": "447.76000000", "remaining_size": "9.00000000", "sequence": 4179024030, "time": "2018-07-02T05:21:45.029000Z"}
{"type": "done", "side": "sell", "order_id": "0fd7d7bf-9796-42c0-a9c0-bf339641597c", "reason": "canceled", "product_id": "ETH-USD", "price": "447.72000000", "remaining_size": "6.00000000", "sequence": 4179024031, "time": "2018-07-02T05:21:45.030000Z"}
{"type": "done", "side": "sell", "order_id": "9210b344-7415-4e34-a80a-6b7cc6b982bb", "reason": "canceled", "product_id": "ETH-USD", "price": "447.76000000", "remaining_size": "6.00000000", "sequence": 4179024032, "time": "2018-07-02T05:21:45.033000Z"}
{"type": "received", "order_id": "eaa4ae9a-1931-4742-a82b-9e9b741f62f5", "order_type": "limit", "size": "9.00000000", "price": "447.94000000", "side": "sell", "client_oid": "0451d208-3435-4626-ad48-160964794c4b", "product_id": "ETH-USD", "sequence": 4179024033, "time": "2018-07-02T05:21:45.035000Z"}
{"type": "open", "side": "sell", "price": "447.94000000", "order_id": "eaa4ae9a-1931-4742-a82b-9e9b741f62f5", "remaining_size": "9.00000000", "product_id": "ETH-USD", "sequence": 4179024034, "time": "2018-07-02T05:21:45.035000Z"}
{"type": "received", "order_id": "ea4ebedd-e93c-4474-8994-285b03291444", "order_type": "limit", "size": "9.00000000", "price": "447.84000000", "side": "sell", "client_oid": "96f32f75-0f5e-4d68-90b7-5fdaddd0d0b5", "product_id": "ETH-USD", "sequence": 4179024035, "time": "2018-07-02T05:21:45.039000Z"}
{"type": "open", "side": "sell", "price": "447.84000000", "order_id": "ea4ebedd-e93c-4474-8994-285b03291444", "remaining_size": "9.00000000", "product_id": "ETH-USD", "sequence": 4179024036, "time": "2018-07-02T05:21:45.039000Z"}
{"type": "received", "order_id": "72593312-9db2-41ab-ab81-9f75d49ec1be", "order_type": "limit", "size": "6.00000000", "price": "447.80000000", "side": "sell", "client_oid": "56e747c8-a029-4c56-a9fa-14d6bdde4cae", "product_id": "ETH-USD", "sequence": 4179024037, "time": "2018-07-02T05:21:45.040000Z"}
{"type": "open", "side": "sell", "price": "447.80000000", "order_id": "72593312-9db2-41ab-ab81-9f75d49ec1be", "remaining_size": "6.00000000", "product_id": "ETH-USD", "sequence": 4179024038, "time": "2018-07-02T05:21:45.040000Z"}
{"type": "received", "order_id": "65db800c-5492-4749-b60b-5d3d5f178d9c", "order_type": "limit", "size": "6.00000000", "price": "447.84000000", "side": "sell", "client_oid": "85654fe4-e2d3-4e6f-8ba5-1efdaff43b0e", "product_id": "ETH-USD", "sequence": 4179024039, "time": "2018-07-02T05:21:45.041000Z"}
{"type": "open", "side": "sell", "price": "447.84000000", "order_id": "65db800c-5492-4749-b60b-5d3d5f178d9c", "remaining_size": "6.00000000", "product_id": "ETH-USD", "sequence": 4179024040, "time": "2018-07-02T05:21:45.041000Z"}
{"type": "done", "side": "sell", "order_id": "bc777d18-1b3a-4726-9a20-45fec620e64a", "reason": "canceled", "product_id": "ETH-USD", "price": "447.24000000", "remaining_size": "4.00000000", "sequence": 4179024041, "time": "2018-07-02T05:21:45.053000Z"}
{"type": "done", "side": "buy", "order_id": "b83f5dfd-c702-4770-a90f-ea2d5c7a98f1", "reason": "canceled", "product_id": "ETH-USD", "price": "446.68000000", "remaining_size": "0.04000000", "sequence": 4179024042, "time": "2018-07-02T05:21:45.061000Z"}
{"type": "done", "side": "buy", "order_id": "62da52b4-47c9-4c9b-9aa1-cfe015357d9f", "reason": "canceled", "product_id": "ETH-USD", "price": "446.19000000", "remaining_size": "0.01000000", "sequence": 4179024043, "time": "2018-07-02T05:21:45.109000Z"}
{"type": "done", "side": "sell", "order_id": "acfda0bb-c9b8-493b-98b9-7065898cea5b", "reason": "canceled", "product_id": "ETH-USD", "price": "447.94000000", "remaining_size": "11.74997000", "sequence": 4179024044, "time": "2018-07-02T05:21:45.111000Z"}
{"type": "done", "side": "buy", "order_id": "ec2d9838-cbbf-495f-9ead-795b904084b7", "reason": "canceled", "product_id": "ETH-USD", "price": "446.68000000", "remaining_size": "0.10000000", "sequence": 4179024045, "time": "2018-07-02T05:21:45.117000Z"}
{"type": "done", "side": "buy", "order_id": "828f7cb9-6b63-4d38-a991-5961f7658d3c", "reason": "canceled", "product_id": "ETH-USD", "price": "446.69000000", "remaining_size": "6.87320969", "sequence": 4179024046, "time": "2018-07-02T05:21:45.123000Z"}
{"type": "done", "side": "sell", "order_id": "5110f4ae-5c25-47cb-8a55-e27f564bd813", "reason": "canceled", "product_id": "ETH-USD", "price": "448.06000000", "remaining_size": "9.51998000", "sequence": 4179024047, "time": "2018-07-02T05:21:45.125000Z"}
{"type": "received", "order_id": "57340fe3-fc8b-471b-aca1-1f1f580ac0ba", "order_type": "limit", "size": "0.01000000", "price": "446.14000000", "side": "buy", "client_oid": "419ba000-0000-4d84-b010-00000d84f010", "product_id": "ETH-USD", "sequence": 4179024048, "time": "2018-07-02T05:21:45.128000Z"}
{"type": "open", "side": "buy", "price": "446.14000000", "order_id": "57340fe3-fc8b-471b-aca1-1f1f580ac0ba", "remaining_size": "0.01000000", "product_id": "ETH-USD", "sequence": 4179024049, "time": "2018-07-02T05:21:45.128000Z"}
{"type": "received", "order_id": "bb58070e-a9a9-4321-95af-e1ea4bd6e6ae", "order_type": "limit", "size": "6.87320969", "price": "446.66000000", "side": "buy", "client_oid": "29eca073-6323-375e-9d0b-92473660205e", "product_id": "ETH-USD", "sequence": 4179024050, "time": "2018-07-02T05:21:45.129000Z"}
{"type": "open", "side": "buy", "price": "446.66000000", "order_id": "bb58070e-a9a9-4321-95af-e1ea4bd6e6ae", "remaining_size": "6.87320969", "product_id": "ETH-USD", "sequence": 4179024051, "time": "2018-07-02T05:21:45.129000Z"}
{"type": "done", "side": "sell", "order_id": "a1251ed6-97b9-4722-98a8-41ba9e66a1c5", "reason": "canceled", "product_id": "BTC-USD", "price": "6300.94000000", "remaining_size": "1.00000000", "sequence": 6227075381, "time": "2018-07-02T05:21:45.167000Z"}
{"type": "received", "order_id": "10ee1b43-ef9e-4b6d-8492-98e995f16171", "order_type": "limit", "size": "4.00000000", "price": "447.30000000", "side": "sell", "client_oid": "126bb8e9-f789-4e10-b40a-8b23b6137abb", "product_id": "ETH-USD", "sequence": 4179024052, "time": "2018-07-02T05:21:45.137000Z"}
{"type": "open", "side": "sell", "price": "447.30000000", "order_id": "10ee1b43-ef9e-4b6d-8492-98e995f16171", "remaining_size": "4.00000000", "product_id": "ETH-USD", "sequence": 4179024053, "time": "2018-07-02T05:21:45.137000Z"}
{"type": "done", "side": "sell", "order_id": "e38cdf93-3ee0-4269-89c3-eaa84cb840ae", "reason": "canceled", "product_id": "ETH-USD", "price": "454.25000000", "remaining_size": "0.01000000", "sequence": 4179024054, "time": "2018-07-02T05:21:45.151000Z"}
{"type": "received", "order_id": "a72b792a-e6f6-406e-8d8f-5a01ae8a24c6", "order_type": "limit", "size": "0.04000000", "price": "446.68000000", "side": "buy", "client_oid": "2ec8d03d-c634-4dee-b91f-37641f2a7831", "product_id": "ETH-USD", "sequence": 4179024055, "time": "2018-07-02T05:21:45.176000Z"}
{"type": "open", "side": "buy", "price": "446.68000000", "order_id": "a72b792a-e6f6-406e-8d8f-5a01ae8a24c6", "remaining_size": "0.04000000", "product_id": "ETH-USD", "sequence": 4179024056, "time": "2018-07-02T05:21:45.176000Z"}
{"type": "received", "order_id": "6756084f-3ff7-4a24-a935-738c36d47380", "order_type": "limit", "size": "0.01000000", "price": "447.25000000", "side": "sell", "client_oid": "36646a09-a9db-4e81-8000-0a3965ecd010", "product_id": "ETH-USD", "sequence": 4179024057, "time": "2018-07-02T05:21:45.195000Z"}
{"type": "open", "side": "sell", "price": "447.25000000", "order_id": "6756084f-3ff7-4a24-a935-738c36d47380", "remaining_size": "0.01000000", "product_id": "ETH-USD", "sequence": 4179024058, "time": "2018-07-02T05:21:45.195000Z"}
{"type": "received", "order_id": "8b654c83-e0b2-4c77-bd4d-448a89962fa1", "order_type": "limit", "size": "1.00000000", "price": "6300.74000000", "side": "sell", "client_oid": "7fdaa0cd-3a54-4761-8874-1ce53c677536", "product_id": "BTC-USD", "sequence": 6227075382, "time": "2018-07-02T05:21:45.201000Z"}
{"type": "open", "side": "sell", "price": "6300.74000000", "order_id": "8b654c83-e0b2-4c77-bd4d-448a89962fa1", "remaining_size": "1.00000000", "product_id": "BTC-USD", "sequence": 6227075383, "time": "2018-07-02T05:21:45.201000Z"}
{"type": "received", "order_id": "0f645c98-3d9a-4e2c-add9-a41f63e39f1c", "order_type": "limit", "size": "9.51998000", "price": "448.02000000", "side": "sell", "client_oid": "5f95c826-e3bb-4a83-a9b1-47237931e855", "product_id": "ETH-USD", "sequence": 4179024059, "time": "2018-07-02T05:21:45.200000Z"}
{"type": "open", "side": "sell", "price": "448.02000000", "order_id": "0f645c98-3d9a-4e2c-add9-a41f63e39f1c", "remaining_size": "9.51998000", "product_id": "ETH-USD", "sequence": 4179024060, "time": "2018-07-02T05:21:45.200000Z"}
{"type": "done", "side": "sell", "order_id": "10ee1b43-ef9e-4b6d-8492-98e995f16171", "reason": "canceled", "product_id": "ETH-USD", "price": "447.30000000", "remaining_size": "4.00000000", "sequence": 4179024061, "time": "2018-07-02T05:21:45.200000Z"}
{"type": "done", "side": "buy", "order_id": "bb58070e-a9a9-4321-95af-e1ea4bd6e6ae", "reason": "canceled", "product_id": "ETH-USD", "price": "446.66000000", "remaining_size": "6.87320969", "sequence": 4179024062, "time": "2018-07-02T05:21:45.204000Z"}
{"type": "received", "order_id": "59cca263-8a01-4e80-8229-073fbfc375ef", "order_type": "limit", "size": "6.87320969", "price": "446.69000000", "side": "buy", "client_oid": "798f7b6d-eddc-0224-68d7-0637ca68af97", "product_id": "ETH-USD", "sequence": 4179024063, "time": "2018-07-02T05:21:45.211000Z"}
{"type": "open", "side": "buy", "price": "446.69000000", "order_id": "59cca263-8a01-4e80-8229-073fbfc375ef", "remaining_size": "6.87320969", "product_id": "ETH-USD", "sequence": 4179024064, "time": "2018-07-02T05:21:45.211000Z"}
{"type": "done", "side": "sell", "order_id": "ea4ebedd-e93c-4474-8994-285b03291444", "reason": "canceled", "product_id": "ETH-USD", "price": "447.84000000", "remaining_size": "9.00000000", "sequence": 4179024065, "time": "2018-07-02T05:21:45.213000Z"}
{"type": "done", "side": "sell", "order_id": "eaa4ae9a-1931-4742-a82b-9e9b741f62f5", "reason": "canceled", "product_id": "ETH-USD", "price": "447.94000000", "remaining_size": "9.00000000", "sequence": 4179024066, "time": "2018-07-02T05:21:45.213000Z"}
{"type": "received", "order_id": "301aedf8-b948-4f60-ae43-aa11fc04e50f", "order_type": "limit", "size": "9.00000000", "price": "447.88000000", "side": "sell", "client_oid": "67f5bfd2-9483-4e5d-a2d7-7273afc778bd", "product_id": "ETH-USD", "sequence": 4179024067, "time": "2018-07-02T05:21:45.219000Z"}
{"type": "open", "side": "sell", "price": "447.88000000", "order_id": "301aedf8-b948-4f60-ae43-aa11fc04e50f", "remaining_size": "9.00000000", "product_id": "ETH-USD", "sequence": 4179024068, "time": "2018-07-02T05:21:45.219000Z"}
{"type": "received", "order_id": "ff3f9ba8-9449-42f3-9523-b25fbf7b011c", "order_type": "limit", "size": "9.00000000", "price": "447.77000000", "side": "sell", "client_oid": "5455ee4c-a138-4d4c-9870-a4f0731054b0", "product_id": "ETH-USD", "sequence": 4179024069, "time": "2018-07-02T05:21:45.223000Z"}
{"type": "open", "side": "sell", "price": "447.77000000", "order_id": "ff3f9ba8-9449-42f3-9523-b25fbf7b011c", "remaining_size": "9.00000000", "product_id": "ETH-USD", "sequence": 4179024070, "time": "2018-07-02T05:21:45.223000Z"}
{"type": "done", "side": "sell", "order_id": "301aedf8-b948-4f60-ae43-aa11fc04e50f", "reason": "canceled", "product_id": "ETH-USD", "price": "447.88000000", "remaining_size": "9.00000000", "sequence": 4179024071, "time": "2018-07-02T05:21:45.223000Z"}
{"type": "done", "side": "sell", "order_id": "ff3f9ba8-9449-42f3-9523-b25fbf7b011c", "reason": "canceled", "product_id": "ETH-USD", "price": "447.77000000", "remaining_size": "9.00000000", "sequence": 4179024072, "time": "2018-07-02T05:21:45.226000Z"}
{"type": "received", "order_id": "d349b396-96b2-4ad9-b6ab-4b0404a0c243", "order_type": "limit", "size": "9.00000000", "price": "447.84000000", "side": "sell", "client_oid": "612173e2-6ca7-4d5e-bd08-3fecbd48e6cf", "product_id": "ETH-USD", "sequence": 4179024073, "time": "2018-07-02T05:21:45.233000Z"}
{"type": "open", "side": "sell", "price": "447.84000000", "order_id": "d349b396-96b2-4ad9-b6ab-4b0404a0c243", "remaining_size": "9.00000000", "product_id": "ETH-USD", "sequence": 4179024074, "time": "2018-07-02T05:21:45.233000Z"}
{"type": "received", "order_id": "b6d91d6e-bbc5-43ca-a5c0-655b3474c7a7", "order_type": "limit", "size": "9.00000000", "price": "447.94000000", "side": "sell", "client_oid": "49b166e0-7334-4dc2-8812-a64dad891486", "product_id": "ETH-USD", "sequence": 4179024075, "time": "2018-07-02T05:21:45.237000Z"}
{"type": "open", "side": "sell", "price": "447.94000000", "order_id": "b6d91d6e-bbc5-43ca-a5c0-655b3474c7a7", "remaining_size": "9.00000000", "product_id": "ETH-USD", "sequence": 4179024076, "time": "2018-07-02T05:21:45.237000Z"}
{"type": "received", "order_id": "bb8963bb-c878-48e5-b20e-d55ec4bf38b0", "order_type": "limit", "size": "0.01000000", "price": "448.25000000", "side": "sell", "client_oid": "bba30e55-b1ac-4ef6-8000-003cbdf799a1", "product_id": "ETH-USD", "sequence": 4179024077, "time": "2018-07-02T05:21:45.242000Z"}
{"type": "open", "side": "sell", "price": "448.25000000", "order_id": "bb8963bb-c878-48e5-b20e-d55ec4bf38b0", "remaining_size": "0.01000000", "product_id": "ETH-USD", "sequence": 4179024078, "time": "2018-07-02T05:21:45.242000Z"}
{"type": "received", "order_id": "7b315936-c4bf-442c-a7d2-8d989100edc6", "order_type": "limit", "size": "4.00000000", "price": "447.32000000", "side": "sell", "client_oid": "17db163f-5266-48f1-8348-6b06cfbea4e0", "product_id": "ETH-USD", "sequence": 4179024079, "time": "2018-07-02T05:21:45.254000Z"}
{"type": "open", "side": "sell", "price": "447.32000000", "order_id": "7b315936-c4bf-442c-a7d2-8d989100edc6", "remaining_size": "4.00000000", "product_id": "ETH-USD", "sequence": 4179024080, "time": "2018-07-02T05:21:45.254000Z"}
{"type": "done", "side": "buy", "order_id": "57340fe3-fc8b-471b-aca1-1f1f580ac0ba", "reason": "canceled", "product_id": "ETH-USD", "price": "446.14000000", "remaining_size": "0.01000000", "sequence": 4179024081, "time": "2018-07-02T05:21:45.266000Z"}
{"type": "received", "order_id": "9ea2ad6b-9ba1-45f4-af7f-975203b7e211", "order_type": "limit", "size": "0.01000000", "price": "446.19000000", "side": "buy", "client_oid": "a8644300-0000-4c7d-99d0-00000c7d59d0", "product_id": "ETH-USD", "sequence": 4179024082, "time": "2018-07-02T05:21:45.271000Z"}
{"type": "open", "side": "buy", "price": "446.19000000", "order_id": "9ea2ad6b-9ba1-45f4-af7f-975203b7e211", "remaining_size": "0.01000000", "product_id": "ETH-USD", "sequence": 4179024083, "time": "2018-07-02T05:21:45.271000Z"}
{"type": "done", "side": "buy", "order_id": "a72b792a-e6f6-406e-8d8f-5a01ae8a24c6", "reason": "canceled", "product_id": "ETH-USD", "price": "446.68000000", "remaining_size": "0.04000000", "sequence": 4179024084, "time": "2018-07-02T05:21:45.271000Z"}
{"type": "done", "side": "sell", "order_id": "6756084f-3ff7-4a24-a935-738c36d47380", "reason": "canceled", "product_id": "ETH-USD", "price": "447.25000000", "remaining_size": "0.01000000", "sequence": 4179024085, "time": "2018-07-02T05:21:45.274000Z"}
{"type": "received", "order_id": "4b5c54cf-ddf6-4916-8e97-e69226dbec4c", "order_type": "limit", "size": "0.01000000", "price": "449.25000000", "side": "sell", "client_oid": "ea86b1b3-aabd-42e0-8000-055c2f50da80", "product_id": "ETH-USD", "sequence": 4179024086, "time": "2018-07-02T05:21:45.284000Z"}
{"type": "open", "side": "sell", "price": "449.25000000", "order_id": "4b5c54cf-ddf6-4916-8e97-e69226dbec4c", "remaining_size": "0.01000000", "product_id": "ETH-USD", "sequence": 4179024087, "time": "2018-07-02T05:21:45.284000Z"}
{"type": "received", "order_id": "d32c45af-afbe-42dc-93b7-804d5e2bf7c0", "order_type": "limit", "size": "11.74997000", "price": "447.92000000", "side": "sell", "client_oid": "f637bdd7-cea8-4c13-851b-9950ee9d1970", "product_id": "ETH-USD", "sequence": 4179024088, "time": "2018-07-02T05:21:45.285000Z"}
{"type": "open", "side": "sell", "price": "447.92000000", "order_id": "d32c45af-afbe-42dc-93b7-804d5e2bf7c0", "remaining_size": "11.74997000", "product_id": "ETH-USD", "sequence": 4179024089, "time": "2018-07-02T05:21:45.285000Z"}
{"type": "done", "side": "buy", "order_id": "59cca263-8a01-4e80-8229-073fbfc375ef", "reason": "canceled", "product_id": "ETH-USD", "price": "446.69000000", "remaining_size": "6.87320969", "sequence": 4179024090, "time": "2018-07-02T05:21:45.306000Z"}
{"type": "done", "side": "sell", "order_id": "7b315936-c4bf-442c-a7d2-8d989100edc6", "reason": "canceled", "product_id": "ETH-USD", "price": "447.32000000", "remaining_size": "4.00000000", "sequence": 4179024091, "time": "2018-07-02T05:21:45.309000Z"}
{"type": "received", "order_id": "f7706b2f-ee41-4c5d-97d2-b690c47f0da5", "order_type": "limit", "size": "6.87320969", "price": "446.66000000", "side": "buy", "client_oid": "b95f445d-fc73-afdd-b4eb-dc25f27f5736", "product_id": "ETH-USD", "sequence": 4179024092, "time": "2018-07-02T05:21:45.312000Z"}
{"type": "open", "side": "buy", "price": "446.66000000", "order_id": "f7706b2f-ee41-4c5d-97d2-b690c47f0da5", "remaining_size": "6.87320969", "product_id": "ETH-USD", "sequence": 4179024093, "time": "2018-07-02T05:21:45.312000Z"}
{"type": "done", "side": "sell", "order_id": "72593312-9db2-41ab-ab81-9f75d49ec1be", "reason": "canceled", "product_id": "ETH-USD", "price": "447.80000000", "remaining_size": "6.00000000", "sequence": 4179024094, "time": "2018-07-02T05:21:45.313000Z"}
{"type": "done", "side": "sell", "order_id": "65db800c-5492-4749-b60b-5d3d5f178d9c", "reason": "canceled", "product_id": "ETH-USD", "price": "447.84000000", "remaining_size": "6.00000000", "sequence": 4179024095, "time": "2018-07-02T05:21:45.313000Z"}
{"type": "done", "side": "sell", "order_id": "d349b396-96b2-4ad9-b6ab-4b0404a0c243", "reason": "canceled", "product_id": "ETH-USD", "price": "447.84000000", "remaining_size": "9.00000000", "sequence": 4179024096, "time": "2018-07-02T05:21:45.314000Z"}
{"type": "received", "order_id": "30de4026-7294-42cc-8110-1c52eacd3150", "order_type": "limit", "size": "9.00000000", "price": "447.88000000", "side": "sell", "client_oid": "ca81b88a-69ae-462a-ba74-a87e6a8d3896", "product_id": "ETH-USD", "sequence": 4179024097, "time": "2018-07-02T05:21:45.320000Z"}
{"type": "open", "side": "sell", "price": "447.88000000", "order_id": "30de4026-7294-42cc-8110-1c52eacd3150", "remaining_size": "9.00000000", "product_id": "ETH-USD", "sequence": 4179024098, "time": "2018-07-02T05:21:45.320000Z"}
{"type": "received", "order_id": "0ae2e786-69fd-48d1-abca-1f42a521cfb9", "order_type": "limit", "size": "6.00000000", "price": "447.77000000", "side": "sell", "client_oid": "5b55fc82-d6b0-4531-a9c3-0afa29a9672a", "product_id": "ETH-USD", "sequence": 4179024099, "time": "2018-07-02T05:21:45.321000Z"}
{"type": "open", "side": "sell", "price": "447.77000000", "order_id": "0ae2e786-69fd-48d1-abca-1f42a521cfb9", "remaining_size": "6.00000000", "product_id": "ETH-USD", "sequence": 4179024100, "time": "2018-07-02T05:21:45.321000Z"}
{"type": "done", "side": "sell", "order_id": "30de4026-7294-42cc-8110-1c52eacd3150", "reason": "canceled", "product_id": "ETH-USD", "price": "447.88000000", "remaining_size": "9.00000000", "sequence": 4179024101, "time": "2018-07-02T05:21:45.323000Z"}
{"type": "received", "order_id": "66dae93e-7be7-442c-93c8-f58d4a6c3814", "order_type": "limit", "size": "6.00000000", "price": "447.73000000", "side": "sell", "client_oid": "d41d6045-2be6-456b-ae08-560669d511f1", "product_id": "ETH-USD", "sequence": 4179024102, "time": "2018-07-02T05:21:45.324000Z"}
{"type": "open", "side": "sell", "price": "447.73000000", "order_id": "66dae93e-7be7-442c-93c8-f58d4a6c3814", "remaining_size": "6.00000000", "product_id": "ETH-USD", "sequence": 4179024103, "time": "2018-07-02T05:21:45.324000Z"}
{"type": "done", "side": "sell", "order_id": "0ae2e786-69fd-48d1-abca-1f42a521cfb9", "reason": "canceled", "product_id": "ETH-USD", "price": "447.77000000", "remaining_size": "6.00000000", "sequence": 4179024104, "time": "2018-07-02T05:21:45.324000Z"}
{"type": "received", "order_id": "ecd423c0-7d5e-4ce0-88db-8191588b5772", "order_type": "limit", "size": "9.00000000", "price": "447.77000000", "side": "sell", "client_oid": "f0d681b6-3d61-4dd9-8c2b-89ff21516a3b", "product_id": "ETH-USD", "sequence": 4179024105, "time": "2018-07-02T05:21:45.325000Z"}
{"type": "open", "side": "sell", "price": "447.77000000", "order_id": "ecd423c0-7d5e-4ce0-88db-8191588b5772", "remaining_size": "9.00000000", "product_id": "ETH-USD", "sequence": 4179024106, "time": "2018-07-02T05:21:45.325000Z"}
{"type": "done", "side": "sell", "order_id": "66dae93e-7be7-442c-93c8-f58d4a6c3814", "reason": "canceled", "product_id": "ETH-USD", "price": "447.73000000", "remaining_size": "6.00000000", "sequence": 4179024107, "time": "2018-07-02T05:21:45.329000Z"}
{"type": "received", "order_id": "f2cb146e-bd93-4812-9bbf-a0f7804da679", "order_type": "limit", "size": "9.00000000", "price": "447.94000000", "side": "sell", "client_oid": "4a8515e9-da9f-4931-b44c-c56d33f86cb3", "product_id": "ETH-USD", "sequence": 4179024108, "time": "2018-07-02T05:21:45.330000Z"}
{"type": "open", "side": "sell", "price": "447.94000000", "order_id": "f2cb146e-bd93-4812-9bbf-a0f7804da679", "remaining_size": "9.00000000", "product_id": "ETH-USD", "sequence": 4179024109, "time": "2018-07-02T05:21:45.330000Z"}
{"type": "done", "side": "sell", "order_id": "ecd423c0-7d5e-4ce0-88db-8191588b5772", "reason": "canceled", "product_id": "ETH-USD", "price": "447.77000000", "remaining_size": "9.00000000", "sequence": 4179024110, "time": "2018-07-02T05:21:45.330000Z"}
{"type": "received", "order_id": "4250e2c4-8095-44d2-b2a9-22d73424fd27", "order_type": "limit", "size": "6.00000000", "price": "447.84000000", "side": "sell", "client_oid": "8aaf70f4-1efc-4cfc-aad2-a98cdb8282ef", "product_id": "ETH-USD", "sequence": 4179024111, "time": "2018-07-02T05:21:45.333000Z"}
{"type": "open", "side": "sell", "price": "447.84000000", "order_id": "4250e2c4-8095-44d2-b2a9-22d73424fd27", "remaining_size": "6.00000000", "product_id": "ETH-USD", "sequence": 4179024112, "time": "2018-07-02T05:21:45.333000Z"}
{"type": "received", "order_id": "cbf5054a-2625-4ea9-b708-753696d9d171", "order_type": "limit", "size": "9.00000000", "price": "447.84000000", "side": "sell", "client_oid": "52db00d8-b46c-45bc-b15d-cd297f8c99b0", "product_id": "ETH-USD", "sequence": 4179024113, "time": "2018-07-02T05:21:45.339000Z"}
{"type": "open", "side": "sell", "price": "447.84000000", "order_id": "cbf5054a-2625-4ea9-b708-753696d9d171", "remaining_size": "9.00000000", "product_id": "ETH-USD", "sequence": 4179024114, "time": "2018-07-02T05:21:45.339000Z"}
{"type": "received", "order_id": "ebc3b5b3-0dbf-4677-a506-0804ba2f7e0f", "order_type": "limit", "size": "6.00000000", "price": "447.80000000", "side": "sell", "client_oid": "f56fe930-bfc4-4b52-8554-d8f7567a651e", "product_id": "ETH-USD", "sequence": 4179024115, "time": "2018-07-02T05:21:45.340000Z"}
{"type": "open", "side": "sell", "price": "447.80000000", "order_id": "ebc3b5b3-0dbf-4677-a506-0804ba2f7e0f", "remaining_size": "6.00000000", "product_id": "ETH-USD", "sequence": 4179024116, "time": "2018-07-02T05:21:45.340000Z"}
{"type": "done", "side": "buy", "order_id": "943c7123-f7cb-4631-a681-135aa5772e3f", "reason": "canceled", "product_id": "BTC-USD", "price": "6286.16000000", "remaining_size": "0.17000000", "sequence": 6227075384, "time": "2018-07-02T05:21:45.345000Z"}
{"type": "done", "side": "sell", "order_id": "0b86938c-1958-4812-9ad7-1b67e03dceb2", "reason": "canceled", "product_id": "BTC-USD", "price": "6928.10000000", "remaining_size": "0.01000000", "sequence": 6227075385, "time": "2018-07-02T05:21:45.350000Z"}
{"type": "done", "side": "sell", "order_id": "b6d91d6e-bbc5-43ca-a5c0-655b3474c7a7", "reason": "canceled", "product_id": "ETH-USD", "price": "447.94000000", "remaining_size": "9.00000000", "sequence": 4179024117, "time": "2018-07-02T05:21:45.349000Z"}
{"type": "received", "order_id": "24a2b4aa-2eed-470f-a043-76fc95f601f7", "order_type": "limit", "size": "0.04000000", "price": "446.68000000", "side": "buy", "client_oid": "dc971392-d752-4029-82cf-d7903f628956", "product_id": "ETH-USD", "sequence": 4179024118, "time": "2018-07-02T05:21:45.350000Z"}
{"type": "open", "side": "buy", "price": "446.68000000", "order_id": "24a2b4aa-2eed-470f-a043-76fc95f601f7", "remaining_size": "0.04000000", "product_id": "ETH-USD", "sequence": 4179024119, "time": "2018-07-02T05:21:45.350000Z"}
{"type": "done", "side": "buy", "order_id": "1df1447a-0375-4357-b141-4e3c3b28a355", "reason": "canceled", "product_id": "BTC-USD", "price": "6298.26000000", "remaining_size": "0.00200000", "sequence": 6227075386, "time": "2018-07-02T05:21:45.365000Z"}
{"type": "done", "side": "sell", "order_id": "2a89ee5b-d8b8-4f4b-8d7e-c8c46c199008", "reason": "canceled", "product_id": "ETH-USD", "price": "472.67000000", "remaining_size": "0.01000000", "sequence": 4179024120, "time": "2018-07-02T05:21:45.370000Z"}
{"type": "done", "side": "buy", "order_id": "2290936f-ceaa-4a41-b9ab-1ed5ade8113c", "reason": "canceled", "product_id": "BTC-USD", "price": "6085.89000000", "remaining_size": "0.00150000", "sequence": 6227075387, "time": "2018-07-02T05:21:45.393000Z"}
{"type": "received", "order_id": "94ee1f37-07eb-4733-81d7-ab3db63ffead", "order_type": "limit", "size": "0.01000000", "price": "474.70000000", "side": "sell", "client_oid": "14e6ab7b-9e43-4c87-8000-0000564ef026", "product_id": "ETH-USD", "sequence": 4179024121, "time": "2018-07-02T05:21:45.391000Z"}
{"type": "open", "side": "sell", "price": "474.70000000", "order_id": "94ee1f37-07eb-4733-81d7-ab3db63ffead", "remaining_size": "0.01000000", "product_id": "ETH-USD", "sequence": 4179024122, "time": "2018-07-02T05:21:45.391000Z"}
{"type": "done", "side": "buy", "order_id": "9ea2ad6b-9ba1-45f4-af7f-975203b7e211", "reason": "canceled", "product_id": "ETH-USD", "price": "446.19000000", "remaining_size": "0.01000000", "sequence": 4179024123, "time": "2018-07-02T05:21:45.393000Z"}
{"type": "received", "order_id": "c4834fda-f64c-4e04-ab80-0b34958f2ae1", "order_type": "limit", "size": "0.00150000", "price": "6051.91000000", "side": "buy", "client_oid": "cd995788-dd2b-4aaf-8000-00c7a29fc085", "product_id": "BTC-USD", "sequence": 6227075388, "time": "2018-07-02T05:21:45.401000Z"}
{"type": "open", "side": "buy", "price": "6051.91000000", "order_id": "c4834fda-f64c-4e04-ab80-0b34958f2ae1", "remaining_size": "0.00150000", "product_id": "BTC-USD", "sequence": 6227075389, "time": "2018-07-02T05:21:45.401000Z"}
{"type": "received", "order_id": "447962e6-154d-46db-a333-7714a9b57c65", "order_type": "limit", "size": "0.00100000", "price": "6298.32000000", "side": "sell", "client_oid": "cfd2b6a0-7db7-11e8-874f-16be7828d23e", "product_id": "BTC-USD", "sequence": 6227075390, "time": "2018-07-02T05:21:45.403000Z"}
{"type": "done", "side": "sell", "order_id": "447962e6-154d-46db-a333-7714a9b57c65", "reason": "canceled", "product_id": "BTC-USD", "price": "6298.32000000", "remaining_size": "0.00100000", "sequence": 6227075391, "time": "2018-07-02T05:21:45.403000Z"}
{"type": "received", "order_id": "1c993e56-5ac6-4db1-9554-4c9791efe600", "order_type": "limit", "size": "0.01000000", "price": "450.25000000", "side": "sell", "client_oid": "89754748-7f5d-4563-8000-0032961fd3af", "product_id": "ETH-USD", "sequence": 4179024124, "time": "2018-07-02T05:21:45.407000Z"}
{"type": "open", "side": "sell", "price": "450.25000000", "order_id": "1c993e56-5ac6-4db1-9554-4c9791efe600", "remaining_size": "0.01000000", "product_id": "ETH-USD", "sequence": 4179024125, "time": "2018-07-02T05:21:45.407000Z"}
{"type": "received", "order_id": "2e5a7389-cb33-4cf2-8290-fd49b4b9f2f0", "order_type": "limit", "size": "0.01000000", "price": "446.14000000", "side": "buy", "client_oid": "edf29500-0000-4c5e-b701-00000c5ef701", "product_id": "ETH-USD", "sequence": 4179024126, "time": "2018-07-02T05:21:45.408000Z"}
{"type": "open", "side": "buy", "price": "446.14000000", "order_id": "2e5a7389-cb33-4cf2-8290-fd49b4b9f2f0", "remaining_size": "0.01000000", "product_id": "ETH-USD", "sequence": 4179024127, "time": "2018-07-02T05:21:45.408000Z"}
{"type": "done", "side": "buy", "order_id": "f7706b2f-ee41-4c5d-97d2-b690c47f0da5", "reason": "canceled", "product_id": "ETH-USD", "price": "446.66000000", "remaining_size": "6.87320969", "sequence": 4179024128, "time": "2018-07-02T05:21:45.411000Z"}
{"type": "received", "order_id": "25262f51-e8b5-41f6-aa6c-d5b2f4a49419", "order_type": "limit", "size": "6.87320969", "price": "446.69000000", "side": "buy", "client_oid": "b907a775-fdca-13d4-7dec-c1e7d047db36", "product_id": "ETH-USD", "sequence": 4179024129, "time": "2018-07-02T05:21:45.416000Z"}
{"type": "open", "side": "buy", "price": "446.69000000", "order_id": "25262f51-e8b5-41f6-aa6c-d5b2f4a49419", "remaining_size": "6.87320969", "product_id": "ETH-USD", "sequence": 4179024130, "time": "2018-07-02T05:21:45.416000Z"}
{"type": "done", "side": "sell", "order_id": "cbf5054a-2625-4ea9-b708-753696d9d171", "reason": "canceled", "product_id": "ETH-USD", "price": "447.84000000", "remaining_size": "9.00000000", "sequence": 4179024131, "time": "2018-07-02T05:21:45.420000Z"}
{"type": "done", "side": "sell", "order_id": "f2cb146e-bd93-4812-9bbf-a0f7804da679", "reason": "canceled", "product_id": "ETH-USD", "price": "447.94000000", "remaining_size": "9.00000000", "sequence": 4179024132, "time": "2018-07-02T05:21:45.420000Z"}
{"type": "received", "order_id": "02b6dc6a-3101-45a8-b1d4-d766ed43b89d", "order_type": "limit", "size": "9.00000000", "price": "447.77000000", "side": "sell", "client_oid": "b7aca097-d2af-42cb-8c46-28c4aaba516b", "product_id": "ETH-USD", "sequence": 4179024133, "time": "2018-07-02T05:21:45.426000Z"}
{"type": "open", "side": "sell", "price": "447.77000000", "order_id": "02b6dc6a-3101-45a8-b1d4-d766ed43b89d", "remaining_size": "9.00000000", "product_id": "ETH-USD", "sequence": 4179024134, "time": "2018-07-02T05:21:45.426000Z"}
{"type": "done", "side": "sell", "order_id": "02b6dc6a-3101-45a8-b1d4-d766ed43b89d", "reason": "canceled", "product_id": "ETH-USD", "price": "447.77000000", "remaining_size": "9.00000000", "sequence": 4179024135, "time": "2018-07-02T05:21:45.430000Z"}
{"type": "received", "order_id": "8fdf8503-7873-4bc0-ae0e-058a92db0f98", "order_type": "limit", "size": "9.00000000", "price": "447.88000000", "side": "sell", "client_oid": "ebc8f281-70b3-4af4-bf02-6889458fb8ce", "product_id": "ETH-USD", "sequence": 4179024136, "time": "2018-07-02T05:21:45.430000Z"}
{"type": "open", "side": "sell", "price": "447.88000000", "order_id": "8fdf8503-7873-4bc0-ae0e-058a92db0f98", "remaining_size": "9.00000000", "product_id": "ETH-USD", "sequence": 4179024137, "time": "2018-07-02T05:21:45.430000Z"}
{"type": "received", "order_id": "1ff10033-1a65-4493-858c-db9a2665d6a6", "order_type": "limit", "size": "0.11000000", "price": "446.68000000", "side": "buy", "client_oid": "ee27974d-6677-408f-90c4-c7361d721177", "product_id": "ETH-USD", "sequence": 4179024138, "time": "2018-07-02T05:21:45.433000Z"}
{"type": "open", "side": "buy", "price": "446.68000000", "order_id": "1ff10033-1a65-4493-858c-db9a2665d6a6", "remaining_size": "0.11000000", "product_id": "ETH-USD", "sequence": 4179024139, "time": "2018-07-02T05:21:45.433000Z"}
{"type": "done", "side": "sell", "order_id": "8fdf8503-7873-4bc0-ae0e-058a92db0f98", "reason": "canceled", "product_id": "ETH-USD", "price": "447.88000000", "remaining_size": "9.00000000", "sequence": 4179024140, "time": "2018-07-02T05:21:45.434000Z"}
{"type": "received", "order_id": "e98b50aa-f0c1-48f5-b491-59d9f89ce5fd", "order_type": "limit", "size": "4.00000000", "price": "447.28000000", "side": "sell", "client_oid": "f3a4c94e-b644-4691-b03a-732571f38ce7", "product_id": "ETH-USD", "sequence": 4179024141, "time": "2018-07-02T05:21:45.434000Z"}
{"type": "open", "side": "sell", "price": "447.28000000", "order_id": "e98b50aa-f0c1-48f5-b491-59d9f89ce5fd", "remaining_size": "4.00000000", "product_id": "ETH-USD", "sequence": 4179024142, "time": "2018-07-02T05:21:45.434000Z"}
{"type": "done", "side": "buy", "order_id": "24a2b4aa-2eed-470f-a043-76fc95f601f7", "reason": "canceled", "product_id": "ETH-USD", "price": "446.68000000", "remaining_size": "0.04000000", "sequence": 4179024143, "time": "2018-07-02T05:21:45.438000Z"}
{"type": "received", "order_id": "4ebbe091-b191-41c5-93f1-cd9d23ef0202", "order_type": "limit", "size": "9.00000000", "price": "447.94000000", "side": "sell", "client_oid": "9a054773-ea89-4912-8531-2d5140987465", "product_id": "ETH-USD", "sequence": 4179024144, "time": "2018-07-02T05:21:45.439000Z"}
{"type": "open", "side": "sell", "price": "447.94000000", "order_id": "4ebbe091-b191-41c5-93f1-cd9d23ef0202", "remaining_size": "9.00000000", "product_id": "ETH-USD", "sequence": 4179024145, "time": "2018-07-02T05:21:45.439000Z"}
{"type": "received", "order_id": "dd9656a3-ea81-4242-a4a3-41c20cf2fbc0", "order_type": "limit", "size": "9.00000000", "price": "447.84000000", "side": "sell", "client_oid": "bf347491-ded8-4ce1-b62e-fa05b117aea1", "product_id": "ETH-USD", "sequence": 4179024146, "time": "2018-07-02T05:21:45.439000Z"}
{"type": "open", "side": "sell", "price": "447.84000000", "order_id": "dd9656a3-ea81-4242-a4a3-41c20cf2fbc0", "remaining_size": "9.00000000", "product_id": "ETH-USD", "sequence": 4179024147, "time": "2018-07-02T05:21:45.439000Z"}
{"type": "received", "order_id": "568fd690-3200-4e9c-82eb-3393b961b4eb", "order_type": "limit", "size": "0.07000000", "price": "447.17000000", "side": "sell", "client_oid": "154f266a-c165-443c-8b7a-1b2d3f913f8b", "product_id": "ETH-USD", "sequence": 4179024148, "time": "2018-07-02T05:21:45.440000Z"}
{"type": "open", "side": "sell", "price": "447.17000000", "order_id": "568fd690-3200-4e9c-82eb-3393b961b4eb", "remaining_size": "0.07000000", "product_id": "ETH-USD", "sequence": 4179024149, "time": "2018-07-02T05:21:45.440000Z"}
{"type": "done", "side": "buy", "order_id": "0afb2455-0499-4180-89f6-7f448821b67f", "reason": "canceled", "product_id": "ETH-USD", "price": "446.50000000", "remaining_size": "48.54000000", "sequence": 4179024150, "time": "2018-07-02T05:21:45.490000Z"}
{"type": "done", "side": "buy", "order_id": "1ff10033-1a65-4493-858c-db9a2665d6a6", "reason": "canceled", "product_id": "ETH-USD", "price": "446.68000000", "remaining_size": "0.11000000", "sequence": 4179024151, "time": "2018-07-02T05:21:45.498000Z"}
{"type": "done", "side": "buy", "order_id": "2e5a7389-cb33-4cf2-8290-fd49b4b9f2f0", "reason": "canceled", "product_id": "ETH-USD", "price": "446.14000000", "remaining_size": "0.01000000", "sequence": 4179024152, "time": "2018-07-02T05:21:45.498000Z"}
{"type": "received", "order_id": "2d3a5d5f-7164-43fd-a935-5f38d45d7a67", "order_type": "limit", "size": "0.01000000", "price": "446.19000000", "side": "buy", "client_oid": "abc3a500-0000-4dee-a411-00000dee6411", "product_id": "ETH-USD", "sequence": 4179024153, "time": "2018-07-02T05:21:45.506000Z"}
{"type": "open", "side": "buy", "price": "446.19000000", "order_id": "2d3a5d5f-7164-43fd-a935-5f38d45d7a67", "remaining_size": "0.01000000", "product_id": "ETH-USD", "sequence": 4179024154, "time": "2018-07-02T05:21:45.506000Z"}
{"type": "done", "side": "sell", "order_id": "e98b50aa-f0c1-48f5-b491-59d9f89ce5fd", "reason": "canceled", "product_id": "ETH-USD", "price": "447.28000000", "remaining_size": "4.00000000", "sequence": 4179024155, "time": "2018-07-02T05:21:45.516000Z"}
{"type": "done", "side": "buy", "order_id": "25262f51-e8b5-41f6-aa6c-d5b2f4a49419", "reason": "canceled", "product_id": "ETH-USD", "price": "446.69000000", "remaining_size": "6.87320969", "sequence": 4179024156, "time": "2018-07-02T05:21:45.522000Z"}
{"type": "received", "order_id": "ca769f68-d905-4fc7-b3aa-09fb5ae97f17", "order_type": "limit", "size": "6.87320969", "price": "446.66000000", "side": "buy", "client_oid": "79adf208-d9ab-3881-ea84-87fa9a087e14", "product_id": "ETH-USD", "sequence": 4179024157, "time": "2018-07-02T05:21:45.527000Z"}
{"type": "open", "side": "buy", "price": "446.66000000", "order_id": "ca769f68-d905-4fc7-b3aa-09fb5ae97f17", "remaining_size": "6.87320969", "product_id": "ETH-USD", "sequence": 4179024158, "time": "2018-07-02T05:21:45.527000Z"}
{"type": "done", "side": "sell", "order_id": "dd9656a3-ea81-4242-a4a3-41c20cf2fbc0", "reason": "canceled", "product_id": "ETH-USD", "price": "447.84000000", "remaining_size": "9.00000000", "sequence": 4179024159, "time": "2018-07-02T05:21:45.531000Z"}
{"type": "done", "side": "sell", "order_id": "4ebbe091-b191-41c5-93f1-cd9d23ef0202", "reason": "canceled", "product_id": "ETH-USD", "price": "447.94000000", "remaining_size": "9.00000000", "sequence": 4179024160, "time": "2018-07-02T05:21:45.531000Z"}
{"type": "received", "order_id": "44b5b352-7c7e-4238-97b5-19f998cf5c13", "order_type": "limit", "size": "9.00000000", "price": "447.87000000", "side": "sell", "client_oid": "3cc4bf0d-e121-4382-b5a1-dd0b0042fa5d", "product_id": "ETH-USD", "sequence": 4179024161, "time": "2018-07-02T05:21:45.538000Z"}
{"type": "open", "side": "sell", "price": "447.87000000", "order_id": "44b5b352-7c7e-4238-97b5-19f998cf5c13", "remaining_size": "9.00000000", "product_id": "ETH-USD", "sequence": 4179024162, "time": "2018-07-02T05:21:45.538000Z"}
{"type": "done", "side": "sell", "order_id": "4b5c54cf-ddf6-4916-8e97-e69226dbec4c", "reason": "canceled", "product_id": "ETH-USD", "price": "449.25000000", "remaining_size": "0.01000000", "sequence": 4179024163, "time": "2018-07-02T05:21:45.542000Z"}
{"type": "done", "side": "sell", "order_id": "44b5b352-7c7e-4238-97b5-19f998cf5c13", "reason": "canceled", "product_id": "ETH-USD", "price": "447.87000000", "remaining_size": "9.00000000", "sequence": 4179024164, "time": "2018-07-02T05:21:45.543000Z"}
{"type": "received", "order_id": "ce986272-0bf1-4667-b283-72a72c3f7602", "order_type": "limit", "size": "9.00000000", "price": "447.76000000", "side": "sell", "client_oid": "590c4929-e715-487b-bc80-2e779f041b85", "product_id": "ETH-USD", "sequence": 4179024165, "time": "2018-07-02T05:21:45.552000Z"}
{"type": "open", "side": "sell", "price": "447.76000000", "order_id": "ce986272-0bf1-4667-b283-72a72c3f7602", "remaining_size": "9.00000000", "product_id": "ETH-USD", "sequence": 4179024166, "time": "2018-07-02T05:21:45.552000Z"}
{"type": "received", "order_id": "a6ebcc38-9032-4e80-adc1-2aca7c848c51", "order_type": "limit", "size": "9.00000000", "price": "447.94000000", "side": "sell", "client_oid": "d3fdc655-d698-42bf-8145-345460b93391", "product_id": "ETH-USD", "sequence": 4179024167, "time": "2018-07-02T05:21:45.553000Z"}
{"type": "open", "side": "sell", "price": "447.94000000", "order_id": "a6ebcc38-9032-4e80-adc1-2aca7c848c51", "remaining_size": "9.00000000", "product_id": "ETH-USD", "sequence": 4179024168, "time": "2018-07-02T05:21:45.553000Z"}
{"type": "done", "side": "sell", "order_id": "ce986272-0bf1-4667-b283-72a72c3f7602", "reason": "canceled", "product_id": "ETH-USD", "price": "447.76000000", "remaining_size": "9.00000000", "sequence": 4179024169, "time": "2018-07-02T05:21:45.556000Z"}
{"type": "done", "side": "sell", "order_id": "bb8963bb-c878-48e5-b20e-d55ec4bf38b0", "reason": "canceled", "product_id": "ETH-USD", "price": "448.25000000", "remaining_size": "0.01000000", "sequence": 4179024170, "time": "2018-07-02T05:21:45.559000Z"}
{"type": "done", "side": "sell", "order_id": "a63ac800-3b42-4c18-bfdf-d0e1ae03f888", "reason": "canceled", "product_id": "ETH-USD", "price": "447.56000000", "remaining_size": "5.54000000", "sequence": 4179024171, "time": "2018-07-02T05:21:45.562000Z"}
{"type": "received", "order_id": "c09c7bbb-89ff-41f9-9499-513f90aa0125", "order_type": "limit", "size": "9.00000000", "price": "447.84000000", "side": "sell", "client_oid": "d786075f-1a84-4e1b-993a-81cb5837eb23", "product_id": "ETH-USD", "sequence": 4179024172, "time": "2018-07-02T05:21:45.562000Z"}
{"type": "open", "side": "sell", "price": "447.84000000", "order_id": "c09c7bbb-89ff-41f9-9499-513f90aa0125", "remaining_size": "9.00000000", "product_id": "ETH-USD", "sequence": 4179024173, "time": "2018-07-02T05:21:45.562000Z"}
{"type": "received", "order_id": "fd9b73eb-31c4-4550-bdda-ed2e10d76154", "order_type": "limit", "size": "0.01000000", "price": "451.25000000", "side": "sell", "client_oid": "34b81769-2c29-4ba3-8000-00419cd46723", "product_id": "ETH-USD", "sequence": 4179024174, "time": "2018-07-02T05:21:45.566000Z"}
{"type": "open", "side": "sell", "price": "451.25000000", "order_id": "fd9b73eb-31c4-4550-bdda-ed2e10d76154", "remaining_size": "0.01000000", "product_id": "ETH-USD", "sequence": 4179024175, "time": "2018-07-02T05:21:45.566000Z"}
{"type": "received", "order_id": "49c72dd5-296b-490c-b6b9-373152ad5c38", "order_type": "limit", "size": "4.00000000", "price": "447.17000000", "side": "sell", "client_oid": "2afd03aa-559b-4a76-b7c9-6c596d4aa397", "product_id": "ETH-USD", "sequence": 4179024176, "time": "2018-07-02T05:21:45.571000Z"}
{"type": "open", "side": "sell", "price": "447.17000000", "order_id": "49c72dd5-296b-490c-b6b9-373152ad5c38", "remaining_size": "4.00000000", "product_id": "ETH-USD", "sequence": 4179024177, "time": "2018-07-02T05:21:45.571000Z"}
{"type": "done", "side": "buy", "order_id": "2d3a5d5f-7164-43fd-a935-5f38d45d7a67", "reason": "canceled", "product_id": "ETH-USD", "price": "446.19000000", "remaining_size": "0.01000000", "sequence": 4179024178, "time": "2018-07-02T05:21:45.601000Z"}
{"type": "received", "order_id": "59a847c5-81e7-44a3-9a5a-7ffb8402a80c", "order_type": "limit", "size": "0.01000000", "price": "446.15000000", "side": "buy", "client_oid": "a38be000-0002-4303-af00-00002303ef00", "product_id": "ETH-USD", "sequence": 4179024179, "time": "2018-07-02T05:21:45.615000Z"}
{"type": "open", "side": "buy", "price": "446.15000000", "order_id": "59a847c5-81e7-44a3-9a5a-7ffb8402a80c", "remaining_size": "0.01000000", "product_id": "ETH-USD", "sequence": 4179024180, "time": "2018-07-02T05:21:45.615000Z"}
{"type": "received", "order_id": "68483277-9a10-414f-83dd-43bbfc090be2", "order_type": "limit", "size": "58.87000000", "price": "446.50000000", "side": "buy", "client_oid": "58d5bed1-edaf-4d41-b414-7305b4f96cf7", "product_id": "ETH-USD", "sequence": 4179024181, "time": "2018-07-02T05:21:45.616000Z"}
{"type": "open", "side": "buy", "price": "446.50000000", "order_id": "68483277-9a10-414f-83dd-43bbfc090be2", "remaining_size": "58.87000000", "product_id": "ETH-USD", "sequence": 4179024182, "time": "2018-07-02T05:21:45.616000Z"}
{"type": "received", "order_id": "631359a6-b590-4e6d-ba49-d72dec72b2ce", "order_type": "limit", "size": "0.00200000", "price": "6298.26000000", "side": "buy", "product_id": "BTC-USD", "sequence": 6227075392, "time": "2018-07-02T05:21:45.626000Z"}
{"type": "open", "side": "buy", "price": "6298.26000000", "order_id": "631359a6-b590-4e6d-ba49-d72dec72b2ce", "remaining_size": "0.00200000", "product_id": "BTC-USD", "sequence": 6227075393, "time": "2018-07-02T05:21:45.626000Z"}
{"type": "received", "order_id": "609c0326-a8f6-4786-923f-bc6d54268b0d", "order_type": "limit", "size": "0.01250000", "price": "6298.26000000", "side": "buy", "product_id": "BTC-USD", "sequence": 6227075394, "time": "2018-07-02T05:21:45.678000Z"}
{"type": "open", "side": "buy", "price": "6298.26000000", "order_id": "609c0326-a8f6-4786-923f-bc6d54268b0d", "remaining_size": "0.01250000", "product_id": "BTC-USD", "sequence": 6227075395, "time": "2018-07-02T05:21:45.678000Z"}
{"type": "received", "order_id": "860a850d-c42f-4ef5-b653-7769e4e1e3cf", "order_type": "limit", "size": "0.01000000", "price": "452.25000000", "side": "sell", "client_oid": "94254e61-2afc-425e-8000-00a2abd24e8b", "product_id": "ETH-USD", "sequence": 4179024183, "time": "2018-07-02T05:21:45.689000Z"}
{"type": "open", "side": "sell", "price": "452.25000000", "order_id": "860a850d-c42f-4ef5-b653-7769e4e1e3cf", "remaining_size": "0.01000000", "product_id": "ETH-USD", "sequence": 4179024184, "time": "2018-07-02T05:21:45.689000Z"}
{"type": "done", "side": "buy", "order_id": "0aafb4bd-9033-4b29-8abd-c83173e1c00d", "reason": "canceled", "product_id": "ETH-USD", "price": "445.48000000", "remaining_size": "2.38224400", "sequence": 4179024185, "time": "2018-07-02T05:21:45.693000Z"}
{"type": "done", "side": "buy", "order_id": "c27f0c72-8e92-49fd-82c6-5e79eff1bf0f", "reason": "canceled", "product_id": "ETH-USD", "price": "445.35000000", "remaining_size": "5.20082500", "sequence": 4179024186, "time": "2018-07-02T05:21:45.696000Z"}
{"type": "done", "side": "buy", "order_id": "2fa5d0f5-1879-4e9d-830e-12d385d802db", "reason": "canceled", "product_id": "ETH-USD", "price": "445.09000000", "remaining_size": "3.22640800", "sequence": 4179024187, "time": "2018-07-02T05:21:45.698000Z"}
{"type": "done", "side": "buy", "order_id": "20b9e96d-8fd4-4b18-9965-e35f0ccddf11", "reason": "canceled", "product_id": "ETH-USD", "price": "444.31000000", "remaining_size": "2.52143800", "sequence": 4179024188, "time": "2018-07-02T05:21:45.700000Z"}
{"type": "done", "side": "buy", "order_id": "298617d2-85b7-4dc4-99cd-96b277767845", "reason": "canceled", "product_id": "ETH-USD", "price": "444.05000000", "remaining_size": "5.30600300", "sequence": 4179024189, "time": "2018-07-02T05:21:45.702000Z"}
{"type": "done", "side": "buy", "order_id": "59a847c5-81e7-44a3-9a5a-7ffb8402a80c", "reason": "canceled", "product_id": "ETH-USD", "price": "446.15000000", "remaining_size": "0.01000000", "sequence": 4179024190, "time": "2018-07-02T05:21:45.704000Z"}
{"type": "done", "side": "buy", "order_id": "df0ffaad-fd89-4982-8af6-712a0597e30b", "reason": "canceled", "product_id": "ETH-USD", "price": "443.92000000", "remaining_size": "2.45273700", "sequence": 4179024191, "time": "2018-07-02T05:21:45.706000Z"}
{"type": "done", "side": "buy", "order_id": "ab682dad-45ab-41d5-837b-3300ad898e38", "reason": "canceled", "product_id": "ETH-USD", "price": "443.66000000", "remaining_size": "1.55539000", "sequence": 4179024192, "time": "2018-07-02T05:21:45.708000Z"}
{"type": "received", "order_id": "9bfeb927-5b26-4ffe-bbdd-515df008a1b3", "order_type": "limit", "size": "0.01000000", "price": "446.14000000", "side": "buy", "client_oid": "2e800100-0002-4341-a950-000002341695", "product_id": "ETH-USD", "sequence": 4179024193, "time": "2018-07-02T05:21:45.709000Z"}
{"type": "open", "side": "buy", "price": "446.14000000", "order_id": "9bfeb927-5b26-4ffe-bbdd-515df008a1b3", "remaining_size": "0.01000000", "product_id": "ETH-USD", "sequence": 4179024194, "time": "2018-07-02T05:21:45.709000Z"}
{"type": "received", "order_id": "5e15b5ff-d2fa-47fe-8a19-cd8c1c0eef79", "order_type": "limit", "size": "0.03000000", "price": "446.68000000", "side": "buy", "client_oid": "c7f04943-65de-45bc-8e8d-4b00925d4d6b", "product_id": "ETH-USD", "sequence": 4179024195, "time": "2018-07-02T05:21:45.715000Z"}
{"type": "open", "side": "buy", "price": "446.68000000", "order_id": "5e15b5ff-d2fa-47fe-8a19-cd8c1c0eef79", "remaining_size": "0.03000000", "product_id": "ETH-USD", "sequence": 4179024196, "time": "2018-07-02T05:21:45.715000Z"}
{"type": "received", "order_id": "e0bc9729-245c-475b-9fa7-7c06a0ddcb4a", "order_type": "limit", "size": "2.60784800", "price": "445.48000000", "side": "buy", "client_oid": "3d3a5652-5ac9-412b-ae61-9ce36d191993", "product_id": "ETH-USD", "sequence": 4179024197, "time": "2018-07-02T05:21:45.737000Z"}
{"type": "open", "side": "buy", "price": "445.48000000", "order_id": "e0bc9729-245c-475b-9fa7-7c06a0ddcb4a", "remaining_size": "2.60784800", "product_id": "ETH-USD", "sequence": 4179024198, "time": "2018-07-02T05:21:45.737000Z"}
{"type": "received", "order_id": "d9f319f4-07a2-4b20-aae7-bd7cd0b20e56", "order_type": "limit", "size": "5.71932800", "price": "445.35000000", "side": "buy", "client_oid": "a1511f96-0a0e-4b26-9eae-99320698ff52", "product_id": "ETH-USD", "sequence": 4179024199, "time": "2018-07-02T05:21:45.745000Z"}
{"type": "open", "side": "buy", "price": "445.35000000", "order_id": "d9f319f4-07a2-4b20-aae7-bd7cd0b20e56", "remaining_size": "5.71932800", "product_id": "ETH-USD", "sequence": 4179024200, "time": "2018-07-02T05:21:45.745000Z"}
{"type": "received", "order_id": "c32e3433-43f8-4a99-97bb-29fc29b7da8f", "order_type": "limit", "size": "3.55678700", "price": "445.09000000", "side": "buy", "client_oid": "60d8dec3-9eae-49f3-8902-d92a9d98cc31", "product_id": "ETH-USD", "sequence": 4179024201, "time": "2018-07-02T05:21:45.755000Z"}
{"type": "open", "side": "buy", "price": "445.09000000", "order_id": "c32e3433-43f8-4a99-97bb-29fc29b7da8f", "remaining_size": "3.55678700", "product_id": "ETH-USD", "sequence": 4179024202, "time": "2018-07-02T05:21:45.755000Z"}
{"type": "done", "side": "buy", "order_id": "81a82689-02b4-4163-98d2-be26f271cf72", "reason": "canceled", "product_id": "ETH-USD", "price": "446.41000000", "remaining_size": "11.00000000", "sequence": 4179024203, "time": "2018-07-02T05:21:45.761000Z"}
{"type": "received", "order_id": "bf753b42-526b-49f3-b2ec-c7b383aca14a", "order_type": "limit", "size": "2.76799400", "price": "444.31000000", "side": "buy", "client_oid": "1741e39e-0dc9-4eb9-813b-7a76b4715e08", "product_id": "ETH-USD", "sequence": 4179024204, "time": "2018-07-02T05:21:45.765000Z"}
{"type": "open", "side": "buy", "price": "444.31000000", "order_id": "bf753b42-526b-49f3-b2ec-c7b383aca14a", "remaining_size": "2.76799400", "product_id": "ETH-USD", "sequence": 4179024205, "time": "2018-07-02T05:21:45.765000Z"}
{"type": "received", "order_id": "c330407c-549f-409b-90f8-7be1b311386a", "order_type": "limit", "size": "14.00000000", "price": "447.58000000", "side": "sell", "product_id": "ETH-USD", "sequence": 4179024206, "time": "2018-07-02T05:21:45.772000Z"}
{"type": "open", "side": "sell", "price": "447.58000000", "order_id": "c330407c-549f-409b-90f8-7be1b311386a", "remaining_size": "14.00000000", "product_id": "ETH-USD", "sequence": 4179024207, "time": "2018-07-02T05:21:45.772000Z"}
{"type": "received", "order_id": "eb3fd8d5-1a54-4aea-af90-b8b53599c600", "order_type": "limit", "size": "5.90497600", "price": "444.05000000", "side": "buy", "client_oid": "ea2c0c77-4714-4ab3-bf11-293ac84ef9f3", "product_id": "ETH-USD", "sequence": 4179024208, "time": "2018-07-02T05:21:45.773000Z"}
{"type": "open", "side": "buy", "price": "444.05000000", "order_id": "eb3fd8d5-1a54-4aea-af90-b8b53599c600", "remaining_size": "5.90497600", "product_id": "ETH-USD", "sequence": 4179024209, "time": "2018-07-02T05:21:45.773000Z"}
{"type": "received", "order_id": "8035b5b2-75ba-40b4-8230-d984c662e4ad", "order_type": "limit", "size": "2.08347600", "price": "443.92000000", "side": "buy", "client_oid": "fe601d45-b1a7-4e7f-a477-37a0f3c7b04e", "product_id": "ETH-USD", "sequence": 4179024210, "time": "2018-07-02T05:21:45.780000Z"}
{"type": "open", "side": "buy", "price": "443.92000000", "order_id": "8035b5b2-75ba-40b4-8230-d984c662e4ad", "remaining_size": "2.08347600", "product_id": "ETH-USD", "sequence": 4179024211, "time": "2018-07-02T05:21:45.780000Z"}
{"type": "received", "order_id": "9ce944d9-0e7b-4948-be94-b686a4ca9131", "order_type": "limit", "size": "2.42832700", "price": "447.81000000", "side": "sell", "client_oid": "e823ff9f-db8d-4032-a7e5-24300c3a80bd", "product_id": "ETH-USD", "sequence": 4179024212, "time": "2018-07-02T05:21:45.789000Z"}
{"type": "open", "side": "sell", "price": "447.81000000", "order_id": "9ce944d9-0e7b-4948-be94-b686a4ca9131", "remaining_size": "2.42832700", "product_id": "ETH-USD", "sequence": 4179024213, "time": "2018-07-02T05:21:45.789000Z"}
{"type": "received", "order_id": "69aaf2e2-b0df-4439-a94f-02aa15f06692", "order_type": "limit", "size": "11.00000000", "price": "446.40000000", "side": "buy", "client_oid": "90be25cd-c4be-4c19-a1d3-445aaafff9b4", "product_id": "ETH-USD", "sequence": 4179024214, "time": "2018-07-02T05:21:45.791000Z"}
{"type": "open", "side": "buy", "price": "446.40000000", "order_id": "69aaf2e2-b0df-4439-a94f-02aa15f06692", "remaining_size": "11.00000000", "product_id": "ETH-USD", "sequence": 4179024215, "time": "2018-07-02T05:21:45.791000Z"}
{"type": "received", "order_id": "ee78aa59-96cd-4cfb-95fc-f474092d4ae2", "order_type": "limit", "size": "3.45040900", "price": "447.94000000", "side": "sell", "client_oid": "35fb142c-a267-4edc-ac22-b1b7e0a2e07d", "product_id": "ETH-USD", "sequence": 4179024216, "time": "2018-07-02T05:21:45.797000Z"}
{"type": "open", "side": "sell", "price": "447.94000000", "order_id": "ee78aa59-96cd-4cfb-95fc-f474092d4ae2", "remaining_size": "3.45040900", "product_id": "ETH-USD", "sequence": 4179024217, "time": "2018-07-02T05:21:45.797000Z"}
{"type": "received", "order_id": "22d3454e-cedf-4a21-8634-c615be664469", "order_type": "limit", "size": "2.68391400", "price": "447.17000000", "side": "sell", "product_id": "ETH-USD", "sequence": 4179024218, "time": "2018-07-02T05:21:45.800000Z"}
{"type": "open", "side": "sell", "price": "447.17000000", "order_id": "22d3454e-cedf-4a21-8634-c615be664469", "remaining_size": "2.68391400", "product_id": "ETH-USD", "sequence": 4179024219, "time": "2018-07-02T05:21:45.800000Z"}
{"type": "done", "side": "buy", "order_id": "9bfeb927-5b26-4ffe-bbdd-515df008a1b3", "reason": "canceled", "product_id": "ETH-USD", "price": "446.14000000", "remaining_size": "0.01000000", "sequence": 4179024220, "time": "2018-07-02T05:21:45.802000Z"}
{"type": "received", "order_id": "f30d5687-5305-446c-8f2c-678f29b1fc8b", "order_type": "limit", "size": "3.32849100", "price": "448.72000000", "side": "sell", "client_oid": "9f36d197-b9e4-4c97-97e0-0d2d205d677f", "product_id": "ETH-USD", "sequence": 4179024221, "time": "2018-07-02T05:21:45.806000Z"}
{"type": "open", "side": "sell", "price": "448.72000000", "order_id": "f30d5687-5305-446c-8f2c-678f29b1fc8b", "remaining_size": "3.32849100", "product_id": "ETH-USD", "sequence": 4179024222, "time": "2018-07-02T05:21:45.806000Z"}
{"type": "received", "order_id": "1b92c8cc-9122-4c62-8919-b5d00c1928d2", "order_type": "limit", "size": "0.01000000", "price": "446.19000000", "side": "buy", "client_oid": "e2145100-000e-4c41-9750-00000ec41575", "product_id": "ETH-USD", "sequence": 4179024223, "time": "2018-07-02T05:21:45.811000Z"}
{"type": "open", "side": "buy", "price": "446.19000000", "order_id": "1b92c8cc-9122-4c62-8919-b5d00c1928d2", "remaining_size": "0.01000000", "product_id": "ETH-USD", "sequence": 4179024224, "time": "2018-07-02T05:21:45.811000Z"}
{"type": "received", "order_id": "bb6cd42a-84d3-4f10-863a-c5052afc31e9", "order_type": "limit", "size": "14.96044100", "price": "448.85000000", "side": "sell", "client_oid": "379913f6-d544-45bb-9bf3-c79440d6a003", "product_id": "ETH-USD", "sequence": 4179024225, "time": "2018-07-02T05:21:45.814000Z"}
{"type": "open", "side": "sell", "price": "448.85000000", "order_id": "bb6cd42a-84d3-4f10-863a-c5052afc31e9", "remaining_size": "14.96044100", "product_id": "ETH-USD", "sequence": 4179024226, "time": "2018-07-02T05:21:45.814000Z"}
{"type": "done", "side": "sell", "order_id": "9ce944d9-0e7b-4948-be94-b686a4ca9131", "reason": "canceled", "product_id": "ETH-USD", "price": "447.81000000", "remaining_size": "2.42832700", "sequence": 4179024227, "time": "2018-07-02T05:21:45.820000Z"}
{"type": "done", "side": "sell", "order_id": "ee78aa59-96cd-4cfb-95fc-f474092d4ae2", "reason": "canceled", "product_id": "ETH-USD", "price": "447.94000000", "remaining_size": "3.45040900", "sequence": 4179024228, "time": "2018-07-02T05:21:45.822000Z"}
{"type": "done", "side": "sell", "order_id": "f30d5687-5305-446c-8f2c-678f29b1fc8b", "reason": "canceled", "product_id": "ETH-USD", "price": "448.72000000", "remaining_size": "3.32849100", "sequence": 4179024229, "time": "2018-07-02T05:21:45.824000Z"}
{"type": "done", "side": "sell", "order_id": "bb6cd42a-84d3-4f10-863a-c5052afc31e9", "reason": "canceled", "product_id": "ETH-USD", "price": "448.85000000", "remaining_size": "14.96044100", "sequence": 4179024230, "time": "2018-07-02T05:21:45.826000Z"}
{"type": "done", "side": "buy", "order_id": "68483277-9a10-414f-83dd-43bbfc090be2", "reason": "canceled", "product_id": "ETH-USD", "price": "446.50000000", "remaining_size": "58.87000000", "sequence": 4179024231, "time": "2018-07-02T05:21:45.830000Z"}
{"type": "done", "side": "sell", "order_id": "1c993e56-5ac6-4db1-9554-4c9791efe600", "reason": "canceled", "product_id": "ETH-USD", "price": "450.25000000", "remaining_size": "0.01000000", "sequence": 4179024232, "time": "2018-07-02T05:21:45.847000Z"}
{"type": "done", "side": "sell", "order_id": "fd9b73eb-31c4-4550-bdda-ed2e10d76154", "reason": "canceled", "product_id": "ETH-USD", "price": "451.25000000", "remaining_size": "0.01000000", "sequence": 4179024233, "time": "2018-07-02T05:21:45.891000Z"}
{"type": "received", "order_id": "46844479-bc7a-4d7b-be8d-b213b9121359", "order_type": "limit", "size": "0.01000000", "price": "453.25000000", "side": "sell", "client_oid": "23528980-0857-4a53-8000-005231a5c3d1", "product_id": "ETH-USD", "sequence": 4179024234, "time": "2018-07-02T05:21:45.899000Z"}
{"type": "open", "side": "sell", "price": "453.25000000", "order_id": "46844479-bc7a-4d7b-be8d-b213b9121359", "remaining_size": "0.01000000", "product_id": "ETH-USD", "sequence": 4179024235, "time": "2018-07-02T05:21:45.899000Z"}
{"type": "received", "order_id": "a1908189-35aa-496a-95b5-9632ee30f4da", "order_type": "limit", "size": "0.01000000", "price": "454.25000000", "side": "sell", "client_oid": "dba791f3-8dbc-4d53-8000-00ddcaba227c", "product_id": "ETH-USD", "sequence": 4179024236, "time": "2018-07-02T05:21:45.902000Z"}
{"type": "open", "side": "sell", "price": "454.25000000", "order_id": "a1908189-35aa-496a-95b5-9632ee30f4da", "remaining_size": "0.01000000", "product_id": "ETH-USD", "sequence": 4179024237, "time": "2018-07-02T05:21:45.902000Z"}
{"type": "done", "side": "buy", "order_id": "69aaf2e2-b0df-4439-a94f-02aa15f06692", "reason": "canceled", "product_id": "ETH-USD", "price": "446.40000000", "remaining_size": "11.00000000", "sequence": 4179024238, "time": "2018-07-02T05:21:45.919000Z"}
{"type": "done", "side": "buy", "order_id": "1b92c8cc-9122-4c62-8919-b5d00c1928d2", "reason": "canceled", "product_id": "ETH-USD", "price": "446.19000000", "remaining_size": "0.01000000", "sequence": 4179024239, "time": "2018-07-02T05:21:45.927000Z"}
{"type": "received", "order_id": "ad0154ea-b337-4c0f-998f-e660800ed5c9", "order_type": "limit", "size": "0.01000000", "price": "446.14000000", "side": "buy", "client_oid": "440ef000-0005-4e0f-aa00-00005e0fea00", "product_id": "ETH-USD", "sequence": 4179024240, "time": "2018-07-02T05:21:45.933000Z"}
{"type": "open", "side": "buy", "price": "446.14000000", "order_id": "ad0154ea-b337-4c0f-998f-e660800ed5c9", "remaining_size": "0.01000000", "product_id": "ETH-USD", "sequence": 4179024241, "time": "2018-07-02T05:21:45.933000Z"}
{"type": "received", "order_id": "b0e85f8e-b535-4bf5-afcb-13afe8b4ee01", "order_type": "limit", "size": "11.00000000", "price": "446.34000000", "side": "buy", "client_oid": "ffd00a9f-cb00-4f46-8ef5-db68d9b389dd", "product_id": "ETH-USD", "sequence": 4179024242, "time": "2018-07-02T05:21:45.952000Z"}
{"type": "open", "side": "buy", "price": "446.34000000", "order_id": "b0e85f8e-b535-4bf5-afcb-13afe8b4ee01", "remaining_size": "11.00000000", "product_id": "ETH-USD", "sequence": 4179024243, "time": "2018-07-02T05:21:45.952000Z"}
{"type": "done", "side": "buy", "order_id": "ad0154ea-b337-4c0f-998f-e660800ed5c9", "reason": "canceled", "product_id": "ETH-USD", "price": "446.14000000", "remaining_size": "0.01000000", "sequence": 4179024244, "time": "2018-07-02T05:21:46.029000Z"}
{"type": "received", "order_id": "109396e9-0168-44ac-a0c8-4533ac6f9fd4", "order_type": "limit", "size": "0.01000000", "price": "446.03000000", "side": "buy", "client_oid": "0dc3b400-0000-4b6f-9ce3-000000b6f9ce", "product_id": "ETH-USD", "sequence": 4179024245, "time": "2018-07-02T05:21:46.036000Z"}
{"type": "open", "side": "buy", "price": "446.03000000", "order_id": "109396e9-0168-44ac-a0c8-4533ac6f9fd4", "remaining_size": "0.01000000", "product_id": "ETH-USD", "sequence": 4179024246, "time": "2018-07-02T05:21:46.036000Z"}
{"type": "received", "order_id": "76474bb1-b486-41c9-83af-198345754d36", "order_type": "limit", "size": "0.01250000", "price": "6298.26000000", "side": "buy", "product_id": "BTC-USD", "sequence": 6227075396, "time": "2018-07-02T05:21:46.085000Z"}
{"type": "open", "side": "buy", "price": "6298.26000000", "order_id": "76474bb1-b486-41c9-83af-198345754d36", "remaining_size": "0.01250000", "product_id": "BTC-USD", "sequence": 6227075397, "time": "2018-07-02T05:21:46.085000Z"}
{"type": "received", "order_id": "bbe4f523-0c4b-4041-b385-769f768a5dc9", "order_type": "limit", "size": "0.42000000", "price": "6285.26000000", "side": "buy", "product_id": "BTC-USD", "sequence": 6227075398, "time": "2018-07-02T05:21:46.105000Z"}
{"type": "open", "side": "buy", "price": "6285.26000000", "order_id": "bbe4f523-0c4b-4041-b385-769f768a5dc9", "remaining_size": "0.42000000", "product_id": "BTC-USD", "sequence": 6227075399, "time": "2018-07-02T05:21:46.105000Z"}
{"type": "done", "side": "buy", "order_id": "109396e9-0168-44ac-a0c8-4533ac6f9fd4", "reason": "canceled", "product_id": "ETH-USD", "price": "446.03000000", "remaining_size": "0.01000000", "sequence": 4179024247, "time": "2018-07-02T05:21:46.124000Z"}
{"type": "done", "side": "sell", "order_id": "0f645c98-3d9a-4e2c-add9-a41f63e39f1c", "reason": "canceled", "product_id": "ETH-USD", "price": "448.02000000", "remaining_size": "9.51998000", "sequence": 4179024248, "time": "2018-07-02T05:21:46.130000Z"}
{"type": "received", "order_id": "f20d2a3d-40c7-4025-b2b9-9ebbcda238a8", "order_type": "limit", "size": "0.01000000", "price": "446.14000000", "side": "buy", "client_oid": "56cc8300-0000-4b00-91d0-00000b0011d0", "product_id": "ETH-USD", "sequence": 4179024249, "time": "2018-07-02T05:21:46.131000Z"}
{"type": "open", "side": "buy", "price": "446.14000000", "order_id": "f20d2a3d-40c7-4025-b2b9-9ebbcda238a8", "remaining_size": "0.01000000", "product_id": "ETH-USD", "sequence": 4179024250, "time": "2018-07-02T05:21:46.131000Z"}
{"type": "done", "side": "sell", "order_id": "7fc2b461-428a-4260-8f6f-f367037e50cd", "reason": "canceled", "product_id": "ETH-USD", "price": "447.82000000", "remaining_size": "14.24999000", "sequence": 4179024251, "time": "2018-07-02T05:21:46.135000Z"}
{"type": "done", "side": "sell", "order_id": "eb946c35-3be2-4639-ba1d-56a0a7e8f5c4", "reason": "canceled", "product_id": "ETH-USD", "price": "448.39000000", "remaining_size": "8.82388000", "sequence": 4179024252, "time": "2018-07-02T05:21:46.168000Z"}
{"type": "done", "side": "sell", "order_id": "1ef23f99-de65-484d-8673-0f6eb38489f3", "reason": "canceled", "product_id": "BTC-USD", "price": "6310.20000000", "remaining_size": "0.25000000", "sequence": 6227075400, "time": "2018-07-02T05:21:46.193000Z"}
{"type": "received", "order_id": "52870485-c405-4f36-8968-077fd765f547", "order_type": "limit", "size": "0.25000000", "price": "6310.69000000", "side": "sell", "client_oid": "668896a3-8afa-4bd5-a995-8846cb1c59a2", "product_id": "BTC-USD", "sequence": 6227075401, "time": "2018-07-02T05:21:46.207000Z"}
{"type": "open", "side": "sell", "price": "6310.69000000", "order_id": "52870485-c405-4f36-8968-077fd765f547", "remaining_size": "0.25000000", "product_id": "BTC-USD", "sequence": 6227075402, "time": "2018-07-02T05:21:46.207000Z"}
{"type": "received", "order_id": "94313111-d07c-48c1-9adc-31787c745da8", "order_type": "limit", "size": "9.51998000", "price": "448.36000000", "side": "sell", "client_oid": "784c707a-c34a-40e1-b94b-bf1585aad8b8", "product_id": "ETH-USD", "sequence": 4179024253, "time": "2018-07-02T05:21:46.208000Z"}
{"type": "open", "side": "sell", "price": "448.36000000", "order_id": "94313111-d07c-48c1-9adc-31787c745da8", "remaining_size": "9.51998000", "product_id": "ETH-USD", "sequence": 4179024254, "time": "2018-07-02T05:21:46.208000Z"}
{"type": "received", "order_id": "2d962f69-bf14-4db7-8f64-fa6b3101fd9c", "order_type": "limit", "size": "0.01000000", "price": "446.68000000", "side": "buy", "client_oid": "ceb620df-e10e-468f-8821-bebf1ce8c825", "product_id": "ETH-USD", "sequence": 4179024255, "time": "2018-07-02T05:21:46.216000Z"}
{"type": "open", "side": "buy", "price": "446.68000000", "order_id": "2d962f69-bf14-4db7-8f64-fa6b3101fd9c", "remaining_size": "0.01000000", "product_id": "ETH-USD", "sequence": 4179024256, "time": "2018-07-02T05:21:46.216000Z"}
{"type": "done", "side": "buy", "order_id": "ca769f68-d905-4fc7-b3aa-09fb5ae97f17", "reason": "canceled", "product_id": "ETH-USD", "price": "446.66000000", "remaining_size": "6.87320969", "sequence": 4179024257, "time": "2018-07-02T05:21:46.224000Z"}
{"type": "received", "order_id": "c6ef438b-99d2-4b47-bff7-d94e957355ab", "order_type": "limit", "size": "6.87320969", "price": "446.69000000", "side": "buy", "client_oid": "1b5bb840-4295-1f80-967a-010a5b2a8ffd", "product_id": "ETH-USD", "sequence": 4179024258, "time": "2018-07-02T05:21:46.229000Z"}
{"type": "open", "side": "buy", "price": "446.69000000", "order_id": "c6ef438b-99d2-4b47-bff7-d94e957355ab", "remaining_size": "6.87320969", "product_id": "ETH-USD", "sequence": 4179024259, "time": "2018-07-02T05:21:46.229000Z"}
{"type": "received", "order_id": "c7b4e5d3-e6d9-420f-bf7b-2c59f61ff17b", "order_type": "limit", "size": "14.24999000", "price": "447.83000000", "side": "sell", "client_oid": "14ea6211-1324-4185-94b8-de3d457a7f24", "product_id": "ETH-USD", "sequence": 4179024260, "time": "2018-07-02T05:21:46.236000Z"}
{"type": "open", "side": "sell", "price": "447.83000000", "order_id": "c7b4e5d3-e6d9-420f-bf7b-2c59f61ff17b", "remaining_size": "14.24999000", "product_id": "ETH-USD", "sequence": 4179024261, "time": "2018-07-02T05:21:46.236000Z"}
{"type": "done", "side": "buy", "order_id": "2d962f69-bf14-4db7-8f64-fa6b3101fd9c", "reason": "canceled", "product_id": "ETH-USD", "price": "446.68000000", "remaining_size": "0.01000000", "sequence": 4179024262, "time": "2018-07-02T05:21:46.293000Z"}
{"type": "done", "side": "buy", "order_id": "c6ef438b-99d2-4b47-bff7-d94e957355ab", "reason": "canceled", "product_id": "ETH-USD", "price": "446.69000000", "remaining_size": "6.87320969", "sequence": 4179024263, "time": "2018-07-02T05:21:46.302000Z"}
{"type": "received", "order_id": "fc795d3a-5d6b-4627-93f8-e9a8576d591b", "order_type": "limit", "size": "6.87320969", "price": "446.66000000", "side": "buy", "client_oid": "19deebc5-7c1d-18a6-c642-31725722ee71", "product_id": "ETH-USD", "sequence": 4179024264, "time": "2018-07-02T05:21:46.307000Z"}
{"type": "open", "side": "buy", "price": "446.66000000", "order_id": "fc795d3a-5d6b-4627-93f8-e9a8576d591b", "remaining_size": "6.87320969", "product_id": "ETH-USD", "sequence": 4179024265, "time": "2018-07-02T05:21:46.307000Z"}
{"type": "done", "side": "sell", "order_id": "7008b4a8-d294-4731-b5b1-7a6a677ce2f5", "reason": "canceled", "product_id": "BTC-USD", "price": "6303.06000000", "remaining_size": "0.01500000", "sequence": 6227075403, "time": "2018-07-02T05:21:46.313000Z"}
{"type": "received", "order_id": "53073477-99e4-4c18-b082-d1a0e81e7952", "order_type": "limit", "size": "0.01500000", "price": "6303.05000000", "side": "sell", "client_oid": "4e3986f3-37ee-4889-9843-6c52e04e84bc", "product_id": "BTC-USD", "sequence": 6227075404, "time": "2018-07-02T05:21:46.317000Z"}
{"type": "open", "side": "sell", "price": "6303.05000000", "order_id": "53073477-99e4-4c18-b082-d1a0e81e7952", "remaining_size": "0.01500000", "product_id": "BTC-USD", "sequence": 6227075405, "time": "2018-07-02T05:21:46.317000Z"}
{"type": "done", "side": "sell", "order_id": "a1908189-35aa-496a-95b5-9632ee30f4da", "reason": "canceled", "product_id": "ETH-USD", "price": "454.25000000", "remaining_size": "0.01000000", "sequence": 4179024266, "time": "2018-07-02T05:21:46.339000Z"}
{"type": "received", "order_id": "09981548-8813-48d5-8b97-c0b1a42599ae", "order_type": "limit", "size": "8.82388000", "price": "448.40000000", "side": "sell", "client_oid": "93e7cdf5-3cd7-4e72-84ab-702f19494ff9", "product_id": "ETH-USD", "sequence": 4179024267, "time": "2018-07-02T05:21:46.346000Z"}
{"type": "open", "side": "sell", "price": "448.40000000", "order_id": "09981548-8813-48d5-8b97-c0b1a42599ae", "remaining_size": "8.82388000", "product_id": "ETH-USD", "sequence": 4179024268, "time": "2018-07-02T05:21:46.346000Z"}
{"type": "received", "order_id": "7ceb3255-2370-4e4f-955a-f39046937790", "order_type": "limit", "size": "0.01000000", "price": "446.68000000", "side": "buy", "client_oid": "fa85dd33-c620-4909-a87d-9c58421eb0a0", "product_id": "ETH-USD", "sequence": 4179024269, "time": "2018-07-02T05:21:46.425000Z"}
{"type": "open", "side": "buy", "price": "446.68000000", "order_id": "7ceb3255-2370-4e4f-955a-f39046937790", "remaining_size": "0.01000000", "product_id": "ETH-USD", "sequence": 4179024270, "time": "2018-07-02T05:21:46.425000Z"}
{"type": "done", "side": "buy", "order_id": "fc795d3a-5d6b-4627-93f8-e9a8576d591b", "reason": "canceled", "product_id": "ETH-USD", "price": "446.66000000", "remaining_size": "6.87320969", "sequence": 4179024271, "time": "2018-07-02T05:21:46.432000Z"}
{"type": "received", "order_id": "0cb14be9-6966-404a-b84c-a1d9354aa610", "order_type": "limit", "size": "6.87320969", "price": "446.69000000", "side": "buy", "client_oid": "0d081391-b530-7d15-70d6-c5ee0b0e5f31", "product_id": "ETH-USD", "sequence": 4179024272, "time": "2018-07-02T05:21:46.438000Z"}
{"type": "open", "side": "buy", "price": "446.69000000", "order_id": "0cb14be9-6966-404a-b84c-a1d9354aa610", "remaining_size": "6.87320969", "product_id": "ETH-USD", "sequence": 4179024273, "time": "2018-07-02T05:21:46.438000Z"}
{"type": "done", "side": "sell", "order_id": "a6ebcc38-9032-4e80-adc1-2aca7c848c51", "reason": "canceled", "product_id": "ETH-USD", "price": "447.94000000", "remaining_size": "9.00000000", "sequence": 4179024274, "time": "2018-07-02T05:21:46.441000Z"}
{"type": "done", "side": "sell", "order_id": "c09c7bbb-89ff-41f9-9499-513f90aa0125", "reason": "canceled", "product_id": "ETH-USD", "price": "447.84000000", "remaining_size": "9.00000000", "sequence": 4179024275, "time": "2018-07-02T05:21:46.441000Z"}
{"type": "received", "order_id": "279dee4f-3e38-48f4-93ed-c474405b6b1c", "order_type": "limit", "size": "0.01000000", "price": "447.30000000", "side": "sell", "client_oid": "d0716944-7db7-11e8-874f-16be7828d23e", "product_id": "ETH-USD", "sequence": 4179024276, "time": "2018-07-02T05:21:46.443000Z"}
{"type": "done", "side": "sell", "order_id": "279dee4f-3e38-48f4-93ed-c474405b6b1c", "reason": "canceled", "product_id": "ETH-USD", "price": "447.30000000", "remaining_size": "0.01000000", "sequence": 4179024277, "time": "2018-07-02T05:21:46.443000Z"}
{"type": "received", "order_id": "d33b504f-2a06-4839-ad48-204f4d21f804", "order_type": "limit", "size": "9.00000000", "price": "447.87000000", "side": "sell", "client_oid": "985b4897-e6b1-4a68-82d6-551eab36abfd", "product_id": "ETH-USD", "sequence": 4179024278, "time": "2018-07-02T05:21:46.446000Z"}
{"type": "open", "side": "sell", "price": "447.87000000", "order_id": "d33b504f-2a06-4839-ad48-204f4d21f804", "remaining_size": "9.00000000", "product_id": "ETH-USD", "sequence": 4179024279, "time": "2018-07-02T05:21:46.446000Z"}
{"type": "done", "side": "sell", "order_id": "d33b504f-2a06-4839-ad48-204f4d21f804", "reason": "canceled", "product_id": "ETH-USD", "price": "447.87000000", "remaining_size": "9.00000000", "sequence": 4179024280, "time": "2018-07-02T05:21:46.448000Z"}
{"type": "received", "order_id": "333c431c-d110-4011-bfe1-1f8d2cb3308d", "order_type": "limit", "size": "9.00000000", "price": "447.76000000", "side": "sell", "client_oid": "d86ced99-466c-4b1a-8df9-39881849d28d", "product_id": "ETH-USD", "sequence": 4179024281, "time": "2018-07-02T05:21:46.449000Z"}
{"type": "open", "side": "sell", "price": "447.76000000", "order_id": "333c431c-d110-4011-bfe1-1f8d2cb3308d", "remaining_size": "9.00000000", "product_id": "ETH-USD", "sequence": 4179024282, "time": "2018-07-02T05:21:46.449000Z"}
{"type": "done", "side": "sell", "order_id": "333c431c-d110-4011-bfe1-1f8d2cb3308d", "reason": "canceled", "product_id": "ETH-USD", "price": "447.76000000", "remaining_size": "9.00000000", "sequence": 4179024283, "time": "2018-07-02T05:21:46.452000Z"}
{"type": "received", "order_id": "786b0531-9b01-4733-9920-64e6b9e3066f", "order_type": "limit", "size": "9.00000000", "price": "447.94000000", "side": "sell", "client_oid": "5e30519c-ed89-48dd-931c-f417b4686d90", "product_id": "ETH-USD", "sequence": 4179024284, "time": "2018-07-02T05:21:46.456000Z"}
{"type": "open", "side": "sell", "price": "447.94000000", "order_id": "786b0531-9b01-4733-9920-64e6b9e3066f", "remaining_size": "9.00000000", "product_id": "ETH-USD", "sequence": 4179024285, "time": "2018-07-02T05:21:46.456000Z"}
{"type": "received", "order_id": "df830c12-475e-42d2-bafb-b4f41c50c8ad", "order_type": "limit", "size": "0.01000000", "price": "447.25000000", "side": "sell", "client_oid": "cbd42325-eea2-4656-8000-00ab83fb8b72", "product_id": "ETH-USD", "sequence": 4179024286, "time": "2018-07-02T05:21:46.468000Z"}
{"type": "open", "side": "sell", "price": "447.25000000", "order_id": "df830c12-475e-42d2-bafb-b4f41c50c8ad", "remaining_size": "0.01000000", "product_id": "ETH-USD", "sequence": 4179024287, "time": "2018-07-02T05:21:46.468000Z"}
{"type": "received", "order_id": "eb27f68c-4890-434c-bc76-e5973155bddf", "order_type": "limit", "size": "9.00000000", "price": "447.84000000", "side": "sell", "client_oid": "1b38fc19-b13b-4e6b-b1ed-99a3d03eb749", "product_id": "ETH-USD", "sequence": 4179024288, "time": "2018-07-02T05:21:46.470000Z"}
{"type": "open", "side": "sell", "price": "447.84000000", "order_id": "eb27f68c-4890-434c-bc76-e5973155bddf", "remaining_size": "9.00000000", "product_id": "ETH-USD", "sequence": 4179024289, "time": "2018-07-02T05:21:46.470000Z"}
{"type": "done", "side": "sell", "order_id": "ebc3b5b3-0dbf-4677-a506-0804ba2f7e0f", "reason": "canceled", "product_id": "ETH-USD", "price": "447.80000000", "remaining_size": "6.00000000", "sequence": 4179024290, "time": "2018-07-02T05:21:46.476000Z"}
{"type": "done", "side": "sell", "order_id": "4250e2c4-8095-44d2-b2a9-22d73424fd27", "reason": "canceled", "product_id": "ETH-USD", "price": "447.84000000", "remaining_size": "6.00000000", "sequence": 4179024291, "time": "2018-07-02T05:21:46.477000Z"}
{"type": "received", "order_id": "0f1a9ede-8147-4bb5-b518-1a8340f238fb", "order_type": "limit", "size": "6.00000000", "price": "447.76000000", "side": "sell", "client_oid": "2f419cda-8304-459e-a7f4-d7d3fafd1a83", "product_id": "ETH-USD", "sequence": 4179024292, "time": "2018-07-02T05:21:46.482000Z"}
{"type": "open", "side": "sell", "price": "447.76000000", "order_id": "0f1a9ede-8147-4bb5-b518-1a8340f238fb", "remaining_size": "6.00000000", "product_id": "ETH-USD", "sequence": 4179024293, "time": "2018-07-02T05:21:46.482000Z"}
{"type": "received", "order_id": "9827b88f-8bfa-470b-970f-b2a8ea4e07f8", "order_type": "limit", "size": "6.00000000", "price": "447.72000000", "side": "sell", "client_oid": "eccf8cc7-e82a-49cf-845f-0fa56eaf45a2", "product_id": "ETH-USD", "sequence": 4179024294, "time": "2018-07-02T05:21:46.485000Z"}
{"type": "open", "side": "sell", "price": "447.72000000", "order_id": "9827b88f-8bfa-470b-970f-b2a8ea4e07f8", "remaining_size": "6.00000000", "product_id": "ETH-USD", "sequence": 4179024295, "time": "2018-07-02T05:21:46.485000Z"}
{"type": "done", "side": "sell", "order_id": "0f1a9ede-8147-4bb5-b518-1a8340f238fb", "reason": "canceled", "product_id": "ETH-USD", "price": "447.76000000", "remaining_size": "6.00000000", "sequence": 4179024296, "time": "2018-07-02T05:21:46.485000Z"}
{"type": "done", "side": "sell", "order_id": "9827b88f-8bfa-470b-970f-b2a8ea4e07f8", "reason": "canceled", "product_id": "ETH-USD", "price": "447.72000000", "remaining_size": "6.00000000", "sequence": 4179024297, "time": "2018-07-02T05:21:46.489000Z"}
{"type": "done", "side": "buy", "order_id": "7ceb3255-2370-4e4f-955a-f39046937790", "reason": "canceled", "product_id": "ETH-USD", "price": "446.68000000", "remaining_size": "0.01000000", "sequence": 4179024298, "time": "2018-07-02T05:21:46.492000Z"}
{"type": "received", "order_id": "e0c240eb-83ec-490d-a095-f093d0fcacaa", "order_type": "limit", "size": "6.00000000", "price": "447.84000000", "side": "sell", "client_oid": "d9446db1-9921-4d7a-9711-1224656a2fd0", "product_id": "ETH-USD", "sequence": 4179024299, "time": "2018-07-02T05:21:46.494000Z"}
{"type": "open", "side": "sell", "price": "447.84000000", "order_id": "e0c240eb-83ec-490d-a095-f093d0fcacaa", "remaining_size": "6.00000000", "product_id": "ETH-USD", "sequence": 4179024300, "time": "2018-07-02T05:21:46.494000Z"}
{"type": "received", "order_id": "35ec6337-d514-4695-9ddc-ad906abdde77", "order_type": "limit", "size": "6.00000000", "price": "447.80000000", "side": "sell", "client_oid": "b96a7db0-911c-4412-ada2-76360359a559", "product_id": "ETH-USD", "sequence": 4179024301, "time": "2018-07-02T05:21:46.497000Z"}
{"type": "open", "side": "sell", "price": "447.80000000", "order_id": "35ec6337-d514-4695-9ddc-ad906abdde77", "remaining_size": "6.00000000", "product_id": "ETH-USD", "sequence": 4179024302, "time": "2018-07-02T05:21:46.497000Z"}
{"type": "done", "side": "buy", "order_id": "0cb14be9-6966-404a-b84c-a1d9354aa610", "reason": "canceled", "product_id": "ETH-USD", "price": "446.69000000", "remaining_size": "6.87320969", "sequence": 4179024303, "time": "2018-07-02T05:21:46.503000Z"}
{"type": "received", "order_id": "a1158a8e-ec1b-42a0-85ef-82f050fc68a9", "order_type": "limit", "size": "6.87320969", "price": "446.66000000", "side": "buy", "client_oid": "b7cf5d18-1db9-7f28-2abf-6f4e863dcecf", "product_id": "ETH-USD", "sequence": 4179024304, "time": "2018-07-02T05:21:46.508000Z"}
{"type": "open", "side": "buy", "price": "446.66000000", "order_id": "a1158a8e-ec1b-42a0-85ef-82f050fc68a9", "remaining_size": "6.87320969", "product_id": "ETH-USD", "sequence": 4179024305, "time": "2018-07-02T05:21:46.508000Z"}
{"type": "done", "side": "sell", "order_id": "786b0531-9b01-4733-9920-64e6b9e3066f", "reason": "canceled", "product_id": "ETH-USD", "price": "447.94000000", "remaining_size": "9.00000000", "sequence": 4179024306, "time": "2018-07-02T05:21:46.512000Z"}
{"type": "done", "side": "sell", "order_id": "eb27f68c-4890-434c-bc76-e5973155bddf", "reason": "canceled", "product_id": "ETH-USD", "price": "447.84000000", "remaining_size": "9.00000000", "sequence": 4179024307, "time": "2018-07-02T05:21:46.514000Z"}
{"type": "received", "order_id": "96f32b1e-09fb-44fd-bd8b-61319d143eab", "order_type": "limit", "size": "9.00000000", "price": "447.76000000", "side": "sell", "client_oid": "aa2f220e-ec43-4dbe-9955-2978e99b4091", "product_id": "ETH-USD", "sequence": 4179024308, "time": "2018-07-02T05:21:46.517000Z"}
{"type": "open", "side": "sell", "price": "447.76000000", "order_id": "96f32b1e-09fb-44fd-bd8b-61319d143eab", "remaining_size": "9.00000000", "product_id": "ETH-USD", "sequence": 4179024309, "time": "2018-07-02T05:21:46.517000Z"}
{"type": "done", "side": "sell", "order_id": "96f32b1e-09fb-44fd-bd8b-61319d143eab", "reason": "canceled", "product_id": "ETH-USD", "price": "447.76000000", "remaining_size": "9.00000000", "sequence": 4179024310, "time": "2018-07-02T05:21:46.520000Z"}
{"type": "received", "order_id": "e1bbc963-e6e9-4446-8196-d29a57fbfb1b", "order_type": "limit", "size": "9.00000000", "price": "447.87000000", "side": "sell", "client_oid": "c1efd305-85d4-40d4-9183-bcc6be3cdb94", "product_id": "ETH-USD", "sequence": 4179024311, "time": "2018-07-02T05:21:46.528000Z"}
{"type": "open", "side": "sell", "price": "447.87000000", "order_id": "e1bbc963-e6e9-4446-8196-d29a57fbfb1b", "remaining_size": "9.00000000", "product_id": "ETH-USD", "sequence": 4179024312, "time": "2018-07-02T05:21:46.528000Z"}
{"type": "received", "order_id": "9bc9139d-d629-44c4-9d15-fda4ca1af247", "order_type": "limit", "size": "9.00000000", "price": "447.84000000", "side": "sell", "client_oid": "b9deed8b-27fe-4049-9714-9fdee2553b62", "product_id": "ETH-USD", "sequence": 4179024313, "time": "2018-07-02T05:21:46.531000Z"}
{"type": "open", "side": "sell", "price": "447.84000000", "order_id": "9bc9139d-d629-44c4-9d15-fda4ca1af247", "remaining_size": "9.00000000", "product_id": "ETH-USD", "sequence": 4179024314, "time": "2018-07-02T05:21:46.531000Z"}
{"type": "done", "side": "sell", "order_id": "e1bbc963-e6e9-4446-8196-d29a57fbfb1b", "reason": "canceled", "product_id": "ETH-USD", "price": "447.87000000", "remaining_size": "9.00000000", "sequence": 4179024315, "time": "2018-07-02T05:21:46.531000Z"}
{"type": "received", "order_id": "d9b227c7-f952-49b8-91af-fcfac8e1b225", "order_type": "limit", "size": "9.00000000", "price": "447.94000000", "side": "sell", "client_oid": "87e3a336-97b8-4f41-a857-71d7621a2ae3", "product_id": "ETH-USD", "sequence": 4179024316, "time": "2018-07-02T05:21:46.538000Z"}
{"type": "open", "side": "sell", "price": "447.94000000", "order_id": "d9b227c7-f952-49b8-91af-fcfac8e1b225", "remaining_size": "9.00000000", "product_id": "ETH-USD", "sequence": 4179024317, "time": "2018-07-02T05:21:46.538000Z"}
{"type": "received", "order_id": "19ee8d24-5e0c-4391-af56-86d9a84b045a", "order_type": "limit", "size": "0.01000000", "price": "448.25000000", "side": "sell", "client_oid": "90f3988f-bc6f-4916-8000-007c9d5f638b", "product_id": "ETH-USD", "sequence": 4179024318, "time": "2018-07-02T05:21:46.596000Z"}
{"type": "open", "side": "sell", "price": "448.25000000", "order_id": "19ee8d24-5e0c-4391-af56-86d9a84b045a", "remaining_size": "0.01000000", "product_id": "ETH-USD", "sequence": 4179024319, "time": "2018-07-02T05:21:46.596000Z"}
{"type": "done", "side": "sell", "order_id": "94ee1f37-07eb-4733-81d7-ab3db63ffead", "reason": "canceled", "product_id": "ETH-USD", "price": "474.70000000", "remaining_size": "0.01000000", "sequence": 4179024320, "time": "2018-07-02T05:21:46.600000Z"}
{"type": "received", "order_id": "2d28f6c1-f0a6-41cc-b872-14f9b8bb8ca2", "order_type": "limit", "size": "0.01000000", "price": "470.67000000", "side": "sell", "client_oid": "5ea0aeeb-d3cb-4433-8000-00e1bc5a37a1", "product_id": "ETH-USD", "sequence": 4179024321, "time": "2018-07-02T05:21:46.629000Z"}
{"type": "open", "side": "sell", "price": "470.67000000", "order_id": "2d28f6c1-f0a6-41cc-b872-14f9b8bb8ca2", "remaining_size": "0.01000000", "product_id": "ETH-USD", "sequence": 4179024322, "time": "2018-07-02T05:21:46.629000Z"}
{"type": "done", "side": "sell", "order_id": "19ee8d24-5e0c-4391-af56-86d9a84b045a", "reason": "canceled", "product_id": "ETH-USD", "price": "448.25000000", "remaining_size": "0.01000000", "sequence": 4179024323, "time": "2018-07-02T05:21:46.667000Z"}
{"type": "done", "side": "buy", "order_id": "c4834fda-f64c-4e04-ab80-0b34958f2ae1", "reason": "canceled", "product_id": "BTC-USD", "price": "6051.91000000", "remaining_size": "0.00150000", "sequence": 6227075406, "time": "2018-07-02T05:21:46.647000Z"}
{"type": "received", "order_id": "4e76c4ac-8b2a-4ded-be1a-439535b3914b", "order_type": "limit", "size": "0.00150000", "price": "6020.01000000", "side": "buy", "client_oid": "ae0b6e8e-f87d-4ca1-8000-0739051a9b70", "product_id": "BTC-USD", "sequence": 6227075407, "time": "2018-07-02T05:21:46.671000Z"}
{"type": "open", "side": "buy", "price": "6020.01000000", "order_id": "4e76c4ac-8b2a-4ded-be1a-439535b3914b", "remaining_size": "0.00150000", "product_id": "BTC-USD", "sequence": 6227075408, "time": "2018-07-02T05:21:46.671000Z"}
{"type": "done", "side": "sell", "order_id": "df830c12-475e-42d2-bafb-b4f41c50c8ad", "reason": "canceled", "product_id": "ETH-USD", "price": "447.25000000", "remaining_size": "0.01000000", "sequence": 4179024324, "time": "2018-07-02T05:21:46.670000Z"}
{"type": "received", "order_id": "05a64a7b-36fc-478d-bdea-6e480210ceae", "order_type": "limit", "size": "0.01000000", "price": "449.25000000", "side": "sell", "client_oid": "0afcbdc4-d720-402b-8000-00109b6b7845", "product_id": "ETH-USD", "sequence": 4179024325, "time": "2018-07-02T05:21:46.674000Z"}
{"type": "open", "side": "sell", "price": "449.25000000", "order_id": "05a64a7b-36fc-478d-bdea-6e480210ceae", "remaining_size": "0.01000000", "product_id": "ETH-USD", "sequence": 4179024326, "time": "2018-07-02T05:21:46.674000Z"}
{"type": "done", "side": "buy", "order_id": "48e79a43-385e-4a20-a17c-0f037964c8b0", "reason": "canceled", "product_id": "BTC-USD", "price": "6298.26000000", "remaining_size": "0.00200000", "sequence": 6227075409, "time": "2018-07-02T05:21:46.704000Z"}
{"type": "done", "side": "buy", "order_id": "b0e85f8e-b535-4bf5-afcb-13afe8b4ee01", "reason": "canceled", "product_id": "ETH-USD", "price": "446.34000000", "remaining_size": "11.00000000", "sequence": 4179024327, "time": "2018-07-02T05:21:46.734000Z"}
{"type": "done", "side": "buy", "order_id": "e0bc9729-245c-475b-9fa7-7c06a0ddcb4a", "reason": "canceled", "product_id": "ETH-USD", "price": "445.48000000", "remaining_size": "2.60784800", "sequence": 4179024328, "time": "2018-07-02T05:21:46.738000Z"}
{"type": "done", "side": "buy", "order_id": "d9f319f4-07a2-4b20-aae7-bd7cd0b20e56", "reason": "canceled", "product_id": "ETH-USD", "price": "445.35000000", "remaining_size": "5.71932800", "sequence": 4179024329, "time": "2018-07-02T05:21:46.742000Z"}
{"type": "done", "side": "buy", "order_id": "c32e3433-43f8-4a99-97bb-29fc29b7da8f", "reason": "canceled", "product_id": "ETH-USD", "price": "445.09000000", "remaining_size": "3.55678700", "sequence": 4179024330, "time": "2018-07-02T05:21:46.744000Z"}
{"type": "done", "side": "buy", "order_id": "bf753b42-526b-49f3-b2ec-c7b383aca14a", "reason": "canceled", "product_id": "ETH-USD", "price": "444.31000000", "remaining_size": "2.76799400", "sequence": 4179024331, "time": "2018-07-02T05:21:46.747000Z"}
{"type": "done", "side": "buy", "order_id": "eb3fd8d5-1a54-4aea-af90-b8b53599c600", "reason": "canceled", "product_id": "ETH-USD", "price": "444.05000000", "remaining_size": "5.90497600", "sequence": 4179024332, "time": "2018-07-02T05:21:46.749000Z"}
{"type": "done", "side": "buy", "order_id": "8035b5b2-75ba-40b4-8230-d984c662e4ad", "reason": "canceled", "product_id": "ETH-USD", "price": "443.92000000", "remaining_size": "2.08347600", "sequence": 4179024333, "time": "2018-07-02T05:21:46.752000Z"}
{"type": "received", "order_id": "4d3e26d2-bb90-47b6-920e-41f4b8ef0fb6", "order_type": "limit", "size": "11.00000000", "price": "446.41000000", "side": "buy", "client_oid": "1cd067ea-637b-4c0f-9458-508d4370e874", "product_id": "ETH-USD", "sequence": 4179024334, "time": "2018-07-02T05:21:46.766000Z"}
{"type": "open", "side": "buy", "price": "446.41000000", "order_id": "4d3e26d2-bb90-47b6-920e-41f4b8ef0fb6", "remaining_size": "11.00000000", "product_id": "ETH-USD", "sequence": 4179024335, "time": "2018-07-02T05:21:46.766000Z"}
{"type": "received", "order_id": "e9570f69-6907-4681-b650-ca29dc3ce2a7", "order_type": "limit", "size": "0.12000000", "price": "446.68000000", "side": "buy", "client_oid": "61a31e3b-3217-455e-8e8c-74cabf369794", "product_id": "ETH-USD", "sequence": 4179024336, "time": "2018-07-02T05:21:46.770000Z"}
{"type": "open", "side": "buy", "price": "446.68000000", "order_id": "e9570f69-6907-4681-b650-ca29dc3ce2a7", "remaining_size": "0.12000000", "product_id": "ETH-USD", "sequence": 4179024337, "time": "2018-07-02T05:21:46.770000Z"}
{"type": "done", "side": "buy", "order_id": "a1158a8e-ec1b-42a0-85ef-82f050fc68a9", "reason": "canceled", "product_id": "ETH-USD", "price": "446.66000000", "remaining_size": "6.87320969", "sequence": 4179024338, "time": "2018-07-02T05:21:46.777000Z"}
{"type": "received", "order_id": "0930faa2-3288-4a14-98a7-1f89b6676f0c", "order_type": "limit", "size": "2.54857100", "price": "445.48000000", "side": "buy", "client_oid": "6754c2d7-e55f-4b52-a627-29098851aad9", "product_id": "ETH-USD", "sequence": 4179024339, "time": "2018-07-02T05:21:46.780000Z"}
{"type": "open", "side": "buy", "price": "445.48000000", "order_id": "0930faa2-3288-4a14-98a7-1f89b6676f0c", "remaining_size": "2.54857100", "product_id": "ETH-USD", "sequence": 4179024340, "time": "2018-07-02T05:21:46.780000Z"}
{"type": "received", "order_id": "bb06da01-8a7c-4172-b4ff-4bdcfa8ccb39", "order_type": "limit", "size": "6.87320969", "price": "446.69000000", "side": "buy", "client_oid": "7f72e3f1-5675-2989-0f94-58ecf425fb91", "product_id": "ETH-USD", "sequence": 4179024341, "time": "2018-07-02T05:21:46.783000Z"}
{"type": "open", "side": "buy", "price": "446.69000000", "order_id": "bb06da01-8a7c-4172-b4ff-4bdcfa8ccb39", "remaining_size": "6.87320969", "product_id": "ETH-USD", "sequence": 4179024342, "time": "2018-07-02T05:21:46.783000Z"}
{"type": "received", "order_id": "3b3a3d6c-5817-4ea8-ab97-1e0aaf7a182d", "order_type": "limit", "size": "5.54592100", "price": "445.35000000", "side": "buy", "client_oid": "86c1631d-30e4-48c5-b9fb-315893b73221", "product_id": "ETH-USD", "sequence": 4179024343, "time": "2018-07-02T05:21:46.789000Z"}
{"type": "open", "side": "buy", "price": "445.35000000", "order_id": "3b3a3d6c-5817-4ea8-ab97-1e0aaf7a182d", "remaining_size": "5.54592100", "product_id": "ETH-USD", "sequence": 4179024344, "time": "2018-07-02T05:21:46.789000Z"}
{"type": "received", "order_id": "36cafafb-50f9-4dac-adda-d5fd66de15a0", "order_type": "limit", "size": "3.43884700", "price": "445.09000000", "side": "buy", "client_oid": "5b54ae50-5dd7-4b5b-8076-0d97f719d03c", "product_id": "ETH-USD", "sequence": 4179024345, "time": "2018-07-02T05:21:46.805000Z"}
{"type": "open", "side": "buy", "price": "445.09000000", "order_id": "36cafafb-50f9-4dac-adda-d5fd66de15a0", "remaining_size": "3.43884700", "product_id": "ETH-USD", "sequence": 4179024346, "time": "2018-07-02T05:21:46.805000Z"}
{"type": "received", "order_id": "3dd010bc-c33e-4a73-bca5-7beee9261ca0", "order_type": "limit", "size": "0.01000000", "price": "450.25000000", "side": "sell", "client_oid": "017d89df-9033-45fc-8000-001b78ac87ff", "product_id": "ETH-USD", "sequence": 4179024347, "time": "2018-07-02T05:21:46.807000Z"}
{"type": "open", "side": "sell", "price": "450.25000000", "order_id": "3dd010bc-c33e-4a73-bca5-7beee9261ca0", "remaining_size": "0.01000000", "product_id": "ETH-USD", "sequence": 4179024348, "time": "2018-07-02T05:21:46.807000Z"}
{"type": "received", "order_id": "48fd0805-f2ea-49bd-9b8b-717b5a4be172", "order_type": "limit", "size": "2.68071200", "price": "444.31000000", "side": "buy", "client_oid": "2c09d5d9-faf7-4842-a9e5-4ab3f9071e3c", "product_id": "ETH-USD", "sequence": 4179024349, "time": "2018-07-02T05:21:46.814000Z"}
{"type": "open", "side": "buy", "price": "444.31000000", "order_id": "48fd0805-f2ea-49bd-9b8b-717b5a4be172", "remaining_size": "2.68071200", "product_id": "ETH-USD", "sequence": 4179024350, "time": "2018-07-02T05:21:46.814000Z"}
{"type": "done", "side": "buy", "order_id": "5e15b5ff-d2fa-47fe-8a19-cd8c1c0eef79", "reason": "canceled", "product_id": "ETH-USD", "price": "446.68000000", "remaining_size": "0.03000000", "sequence": 4179024351, "time": "2018-07-02T05:21:46.822000Z"}
{"type": "received", "order_id": "04e88b37-6c2c-4b2c-94c0-4accc290cfe4", "order_type": "limit", "size": "5.59378000", "price": "444.05000000", "side": "buy", "client_oid": "ed5b7308-77c7-4048-95cf-f5db32a38228", "product_id": "ETH-USD", "sequence": 4179024352, "time": "2018-07-02T05:21:46.823000Z"}
{"type": "open", "side": "buy", "price": "444.05000000", "order_id": "04e88b37-6c2c-4b2c-94c0-4accc290cfe4", "remaining_size": "5.59378000", "product_id": "ETH-USD", "sequence": 4179024353, "time": "2018-07-02T05:21:46.823000Z"}
{"type": "received", "order_id": "1853a209-2d01-43e9-b7fb-caf0195ad37a", "order_type": "limit", "size": "2.61217100", "price": "443.92000000", "side": "buy", "client_oid": "74a7e0a9-574b-40b6-bf58-52f778082f9e", "product_id": "ETH-USD", "sequence": 4179024354, "time": "2018-07-02T05:21:46.832000Z"}
{"type": "open", "side": "buy", "price": "443.92000000", "order_id": "1853a209-2d01-43e9-b7fb-caf0195ad37a", "remaining_size": "2.61217100", "product_id": "ETH-USD", "sequence": 4179024355, "time": "2018-07-02T05:21:46.832000Z"}
{"type": "done", "side": "sell", "order_id": "d9b227c7-f952-49b8-91af-fcfac8e1b225", "reason": "canceled", "product_id": "ETH-USD", "price": "447.94000000", "remaining_size": "9.00000000", "sequence": 4179024356, "time": "2018-07-02T05:21:46.835000Z"}
{"type": "done", "side": "sell", "order_id": "9bc9139d-d629-44c4-9d15-fda4ca1af247", "reason": "canceled", "product_id": "ETH-USD", "price": "447.84000000", "remaining_size": "9.00000000", "sequence": 4179024357, "time": "2018-07-02T05:21:46.836000Z"}
{"type": "received", "order_id": "23915451-71b7-4727-8070-7ea37c79cdeb", "order_type": "limit", "size": "0.22178100", "price": "443.66000000", "side": "buy", "client_oid": "2983c52f-e1b8-4dea-a2d1-2192ed3b7676", "product_id": "ETH-USD", "sequence": 4179024358, "time": "2018-07-02T05:21:46.839000Z"}
{"type": "open", "side": "buy", "price": "443.66000000", "order_id": "23915451-71b7-4727-8070-7ea37c79cdeb", "remaining_size": "0.22178100", "product_id": "ETH-USD", "sequence": 4179024359, "time": "2018-07-02T05:21:46.839000Z"}
{"type": "received", "order_id": "4a94e291-54fa-4c69-b4af-bf678a9589a9", "order_type": "limit", "size": "9.00000000", "price": "447.87000000", "side": "sell", "client_oid": "8a4002e5-13a0-462f-bcd5-1fa70f746ece", "product_id": "ETH-USD", "sequence": 4179024360, "time": "2018-07-02T05:21:46.842000Z"}
{"type": "open", "side": "sell", "price": "447.87000000", "order_id": "4a94e291-54fa-4c69-b4af-bf678a9589a9", "remaining_size": "9.00000000", "product_id": "ETH-USD", "sequence": 4179024361, "time": "2018-07-02T05:21:46.842000Z"}
{"type": "received", "order_id": "076bda13-ef0c-4829-94b1-7f1ca36bd246", "order_type": "limit", "size": "9.00000000", "price": "447.76000000", "side": "sell", "client_oid": "da0ce9b4-9c0a-4c4d-91e0-4f9198eecb2e", "product_id": "ETH-USD", "sequence": 4179024362, "time": "2018-07-02T05:21:46.845000Z"}
{"type": "open", "side": "sell", "price": "447.76000000", "order_id": "076bda13-ef0c-4829-94b1-7f1ca36bd246", "remaining_size": "9.00000000", "product_id": "ETH-USD", "sequence": 4179024363, "time": "2018-07-02T05:21:46.845000Z"}
{"type": "done", "side": "buy", "order_id": "e9570f69-6907-4681-b650-ca29dc3ce2a7", "reason": "canceled", "product_id": "ETH-USD", "price": "446.68000000", "remaining_size": "0.12000000", "sequence": 4179024364, "time": "2018-07-02T05:21:46.851000Z"}
{"type": "done", "side": "sell", "order_id": "22d3454e-cedf-4a21-8634-c615be664469", "reason": "canceled", "product_id": "ETH-USD", "price": "447.17000000", "remaining_size": "2.68391400", "sequence": 4179024365, "time": "2018-07-02T05:21:46.856000Z"}
{"type": "done", "side": "sell", "order_id": "05a64a7b-36fc-478d-bdea-6e480210ceae", "reason": "canceled", "product_id": "ETH-USD", "price": "449.25000000", "remaining_size": "0.01000000", "sequence": 4179024366, "time": "2018-07-02T05:21:46.873000Z"}
{"type": "received", "order_id": "222f8dd3-b7b6-4fe2-a39d-8744e93859d3", "order_type": "limit", "size": "52.84000000", "price": "446.50000000", "side": "buy", "client_oid": "8912889c-eeda-4016-a49c-829270ed1cba", "product_id": "ETH-USD", "sequence": 4179024367, "time": "2018-07-02T05:21:46.874000Z"}
{"type": "open", "side": "buy", "price": "446.50000000", "order_id": "222f8dd3-b7b6-4fe2-a39d-8744e93859d3", "remaining_size": "52.84000000", "product_id": "ETH-USD", "sequence": 4179024368, "time": "2018-07-02T05:21:46.874000Z"}
{"type": "done", "side": "sell", "order_id": "49c72dd5-296b-490c-b6b9-373152ad5c38", "reason": "canceled", "product_id": "ETH-USD", "price": "447.17000000", "remaining_size": "4.00000000", "sequence": 4179024369, "time": "2018-07-02T05:21:46.894000Z"}
{"type": "done", "side": "buy", "order_id": "222f8dd3-b7b6-4fe2-a39d-8744e93859d3", "reason": "canceled", "product_id": "ETH-USD", "price": "446.50000000", "remaining_size": "52.84000000", "sequence": 4179024370, "time": "2018-07-02T05:21:46.905000Z"}
{"type": "received", "order_id": "87fc5e2b-ef2e-4dd9-8ed2-912af95b281c", "order_type": "limit", "size": "0.01000000", "price": "451.25000000", "side": "sell", "client_oid": "a1ba3ded-86b0-4ba4-8000-00ffa6ded26a", "product_id": "ETH-USD", "sequence": 4179024371, "time": "2018-07-02T05:21:46.916000Z"}
{"type": "done", "side": "buy", "order_id": "35dd915f-6995-482e-b481-a896ff8f5e52", "reason": "canceled", "product_id": "BTC-USD", "price": "6292.00000000", "remaining_size": "1.90000000", "sequence": 6227075410, "time": "2018-07-02T05:21:46.920000Z"}
{"type": "open", "side": "sell", "price": "451.25000000", "order_id": "87fc5e2b-ef2e-4dd9-8ed2-912af95b281c", "remaining_size": "0.01000000", "product_id": "ETH-USD", "sequence": 4179024372, "time": "2018-07-02T05:21:46.916000Z"}
{"type": "received", "order_id": "79100103-1284-4ca7-85e8-1d212ff8f968", "order_type": "limit", "size": "1.90000000", "price": "6297.00000000", "side": "buy", "client_oid": "06560118-0165-48e5-b022-fedc76c8a884", "product_id": "BTC-USD", "sequence": 6227075411, "time": "2018-07-02T05:21:46.926000Z"}
{"type": "open", "side": "buy", "price": "6297.00000000", "order_id": "79100103-1284-4ca7-85e8-1d212ff8f968", "remaining_size": "1.90000000", "product_id": "BTC-USD", "sequence": 6227075412, "time": "2018-07-02T05:21:46.926000Z"}
{"type": "done", "side": "sell", "order_id": "4a94e291-54fa-4c69-b4af-bf678a9589a9", "reason": "canceled", "product_id": "ETH-USD", "price": "447.87000000", "remaining_size": "9.00000000", "sequence": 4179024373, "time": "2018-07-02T05:21:46.937000Z"}
{"type": "done", "side": "sell", "order_id": "076bda13-ef0c-4829-94b1-7f1ca36bd246", "reason": "canceled", "product_id": "ETH-USD", "price": "447.76000000", "remaining_size": "9.00000000", "sequence": 4179024374, "time": "2018-07-02T05:21:46.937000Z"}
{"type": "received", "order_id": "e92028c9-0fd2-4ada-96a7-f655f1de4fb6", "order_type": "limit", "size": "9.00000000", "price": "447.84000000", "side": "sell", "client_oid": "ba5f1e5a-cb5d-4dba-af8e-8b8137808e10", "product_id": "ETH-USD", "sequence": 4179024375, "time": "2018-07-02T05:21:46.944000Z"}
{"type": "open", "side": "sell", "price": "447.84000000", "order_id": "e92028c9-0fd2-4ada-96a7-f655f1de4fb6", "remaining_size": "9.00000000", "product_id": "ETH-USD", "sequence": 4179024376, "time": "2018-07-02T05:21:46.944000Z"}
{"type": "received", "order_id": "f38f3ca5-f6a6-4994-bd58-154dcb15a251", "order_type": "limit", "size": "9.00000000", "price": "447.94000000", "side": "sell", "client_oid": "53eddf2b-bdfc-4a57-9f6c-67207ce57f31", "product_id": "ETH-USD", "sequence": 4179024377, "time": "2018-07-02T05:21:46.946000Z"}
{"type": "open", "side": "sell", "price": "447.94000000", "order_id": "f38f3ca5-f6a6-4994-bd58-154dcb15a251", "remaining_size": "9.00000000", "product_id": "ETH-USD", "sequence": 4179024378, "time": "2018-07-02T05:21:46.946000Z"}
{"type": "done", "side": "buy", "order_id": "bb06da01-8a7c-4172-b4ff-4bdcfa8ccb39", "reason": "canceled", "product_id": "ETH-USD", "price": "446.69000000", "remaining_size": "6.87320969", "sequence": 4179024379, "time": "2018-07-02T05:21:46.948000Z"}
{"type": "received", "order_id": "a4b4a898-00b8-47a2-b1c1-16bf91aa3f6b", "order_type": "limit", "size": "6.87320969", "price": "446.66000000", "side": "buy", "client_oid": "7b5f798d-b6c6-5305-88ea-8849454ef49e", "product_id": "ETH-USD", "sequence": 4179024380, "time": "2018-07-02T05:21:46.955000Z"}
{"type": "open", "side": "buy", "price": "446.66000000", "order_id": "a4b4a898-00b8-47a2-b1c1-16bf91aa3f6b", "remaining_size": "6.87320969", "product_id": "ETH-USD", "sequence": 4179024381, "time": "2018-07-02T05:21:46.955000Z"}
{"type": "done", "side": "sell", "order_id": "35ec6337-d514-4695-9ddc-ad906abdde77", "reason": "canceled", "product_id": "ETH-USD", "price": "447.80000000", "remaining_size": "6.00000000", "sequence": 4179024382, "time": "2018-07-02T05:21:46.956000Z"}
{"type": "done", "side": "sell", "order_id": "e0c240eb-83ec-490d-a095-f093d0fcacaa", "reason": "canceled", "product_id": "ETH-USD", "price": "447.84000000", "remaining_size": "6.00000000", "sequence": 4179024383, "time": "2018-07-02T05:21:46.956000Z"}
{"type": "done", "side": "sell", "order_id": "8b654c83-e0b2-4c77-bd4d-448a89962fa1", "reason": "canceled", "product_id": "BTC-USD", "price": "6300.74000000", "remaining_size": "1.00000000", "sequence": 6227075413, "time": "2018-07-02T05:21:46.964000Z"}
{"type": "received", "order_id": "cc40dc15-4313-4d0d-872b-97321b0a5743", "order_type": "limit", "size": "0.00200000", "price": "6298.26000000", "side": "buy", "product_id": "BTC-USD", "sequence": 6227075414, "time": "2018-07-02T05:21:46.967000Z"}
{"type": "open", "side": "buy", "price": "6298.26000000", "order_id": "cc40dc15-4313-4d0d-872b-97321b0a5743", "remaining_size": "0.00200000", "product_id": "BTC-USD", "sequence": 6227075415, "time": "2018-07-02T05:21:46.967000Z"}
{"type": "received", "order_id": "f61ea1f2-8dfc-4b9c-8101-2dbabae31c21", "order_type": "limit", "size": "6.00000000", "price": "447.76000000", "side": "sell", "client_oid": "9232b368-e1de-4f7d-b977-cbde142b23dc", "product_id": "ETH-USD", "sequence": 4179024384, "time": "2018-07-02T05:21:46.966000Z"}
{"type": "open", "side": "sell", "price": "447.76000000", "order_id": "f61ea1f2-8dfc-4b9c-8101-2dbabae31c21", "remaining_size": "6.00000000", "product_id": "ETH-USD", "sequence": 4179024385, "time": "2018-07-02T05:21:46.966000Z"}
{"type": "received", "order_id": "4a8bd102-223c-4551-abf8-321998d0a936", "order_type": "limit", "size": "6.00000000", "price": "447.72000000", "side": "sell", "client_oid": "a04f4dba-6962-468b-a0ff-04f4020aa38c", "product_id": "ETH-USD", "sequence": 4179024386, "time": "2018-07-02T05:21:46.967000Z"}
{"type": "open", "side": "sell", "price": "447.72000000", "order_id": "4a8bd102-223c-4551-abf8-321998d0a936", "remaining_size": "6.00000000", "product_id": "ETH-USD", "sequence": 4179024387, "time": "2018-07-02T05:21:46.967000Z"}
{"type": "done", "side": "sell", "order_id": "f61ea1f2-8dfc-4b9c-8101-2dbabae31c21", "reason": "canceled", "product_id": "ETH-USD", "price": "447.76000000", "remaining_size": "6.00000000", "sequence": 4179024388, "time": "2018-07-02T05:21:46.970000Z"}
{"type": "done", "side": "sell", "order_id": "4a8bd102-223c-4551-abf8-321998d0a936", "reason": "canceled", "product_id": "ETH-USD", "price": "447.72000000", "remaining_size": "6.00000000", "sequence": 4179024389, "time": "2018-07-02T05:21:46.973000Z"}
{"type": "received", "order_id": "eb695187-c17e-40f7-9c35-6fe0410dd573", "order_type": "limit", "size": "6.00000000", "price": "447.84000000", "side": "sell", "client_oid": "daa2d333-0c28-45ce-bb0d-ec5026e6a7a9", "product_id": "ETH-USD", "sequence": 4179024390, "time": "2018-07-02T05:21:46.978000Z"}
{"type": "open", "side": "sell", "price": "447.84000000", "order_id": "eb695187-c17e-40f7-9c35-6fe0410dd573", "remaining_size": "6.00000000", "product_id": "ETH-USD", "sequence": 4179024391, "time": "2018-07-02T05:21:46.978000Z"}
{"type": "received", "order_id": "daee1c60-641b-46b5-a9af-2e0242f98377", "order_type": "limit", "size": "4.00000000", "price": "447.17000000", "side": "sell", "client_oid": "16b65682-0b6f-4026-8be4-1aad68ae1513", "product_id": "ETH-USD", "sequence": 4179024392, "time": "2018-07-02T05:21:46.979000Z"}
{"type": "open", "side": "sell", "price": "447.17000000", "order_id": "daee1c60-641b-46b5-a9af-2e0242f98377", "remaining_size": "4.00000000", "product_id": "ETH-USD", "sequence": 4179024393, "time": "2018-07-02T05:21:46.979000Z"}
{"type": "received", "order_id": "81c495f4-ea1b-4ac0-91fd-e0dbd162cc66", "order_type": "limit", "size": "6.00000000", "price": "447.80000000", "side": "sell", "client_oid": "f2472e2d-0292-490e-b4f0-46afca7d4070", "product_id": "ETH-USD", "sequence": 4179024394, "time": "2018-07-02T05:21:46.983000Z"}
{"type": "open", "side": "sell", "price": "447.80000000", "order_id": "81c495f4-ea1b-4ac0-91fd-e0dbd162cc66", "remaining_size": "6.00000000", "product_id": "ETH-USD", "sequence": 4179024395, "time": "2018-07-02T05:21:46.983000Z"}
{"type": "received", "order_id": "87f3a991-dac8-447d-8af9-726239bcbc6a", "order_type": "limit", "size": "1.00000000", "price": "6300.94000000", "side": "sell", "client_oid": "d853b7c8-48bd-406f-bb78-7d772bb63268", "product_id": "BTC-USD", "sequence": 6227075416, "time": "2018-07-02T05:21:46.998000Z"}
{"type": "open", "side": "sell", "price": "6300.94000000", "order_id": "87f3a991-dac8-447d-8af9-726239bcbc6a", "remaining_size": "1.00000000", "product_id": "BTC-USD", "sequence": 6227075417, "time": "2018-07-02T05:21:46.998000Z"}
{"type": "received", "order_id": "c82cc26e-96a4-4b1e-94c1-eabf7cf4715c", "order_type": "limit", "size": "0.07641477", "price": "18975.89000000", "side": "sell", "client_oid": "ce7a7860-7db7-11e8-b667-a9bd8c692f8b", "product_id": "BTC-USD", "sequence": 6227075418, "time": "2018-07-02T05:21:47.011000Z"}
{"type": "open", "side": "sell", "price": "18975.89000000", "order_id": "c82cc26e-96a4-4b1e-94c1-eabf7cf4715c", "remaining_size": "0.07641477", "product_id": "BTC-USD", "sequence": 6227075419, "time": "2018-07-02T05:21:47.011000Z"}
{"type": "received", "order_id": "709a05ab-899d-4379-8b77-f9026ad79b56", "order_type": "limit", "size": "0.00190000", "price": "16494.49000000", "side": "sell", "client_oid": "cdca8950-7db7-11e8-b667-a9bd8c692f8b", "product_id": "BTC-USD", "sequence": 6227075420, "time": "2018-07-02T05:21:47.013000Z"}
{"type": "open", "side": "sell", "price": "16494.49000000", "order_id": "709a05ab-899d-4379-8b77-f9026ad79b56", "remaining_size": "0.00190000", "product_id": "BTC-USD", "sequence": 6227075421, "time": "2018-07-02T05:21:47.013000Z"}
{"type": "done", "side": "buy", "order_id": "f20d2a3d-40c7-4025-b2b9-9ebbcda238a8", "reason": "canceled", "product_id": "ETH-USD", "price": "446.14000000", "remaining_size": "0.01000000", "sequence": 4179024396, "time": "2018-07-02T05:21:47.041000Z"}
{"type": "received", "order_id": "916577d6-ca98-43d2-93ab-d88272822406", "order_type": "limit", "size": "0.01000000", "price": "446.03000000", "side": "buy", "client_oid": "1f654300-0000-40e5-bbb0-000000e5fbb0", "product_id": "ETH-USD", "sequence": 4179024397, "time": "2018-07-02T05:21:47.051000Z"}
{"type": "open", "side": "buy", "price": "446.03000000", "order_id": "916577d6-ca98-43d2-93ab-d88272822406", "remaining_size": "0.01000000", "product_id": "ETH-USD", "sequence": 4179024398, "time": "2018-07-02T05:21:47.051000Z"}
{"type": "received", "order_id": "e2373a89-c82a-49ba-bc3d-38298c91f6cd", "order_type": "limit", "size": "50.07000000", "price": "446.50000000", "side": "buy", "client_oid": "4ad886dc-a5ef-4dc8-9f0b-5ce484a07843", "product_id": "ETH-USD", "sequence": 4179024399, "time": "2018-07-02T05:21:47.064000Z"}
{"type": "open", "side": "buy", "price": "446.50000000", "order_id": "e2373a89-c82a-49ba-bc3d-38298c91f6cd", "remaining_size": "50.07000000", "product_id": "ETH-USD", "sequence": 4179024400, "time": "2018-07-02T05:21:47.064000Z"}
{"type": "done", "side": "buy", "order_id": "bbe4f523-0c4b-4041-b385-769f768a5dc9", "reason": "canceled", "product_id": "BTC-USD", "price": "6285.26000000", "remaining_size": "0.42000000", "sequence": 6227075422, "time": "2018-07-02T05:21:47.082000Z"}
{"type": "done", "side": "sell", "order_id": "d32c45af-afbe-42dc-93b7-804d5e2bf7c0", "reason": "canceled", "product_id": "ETH-USD", "price": "447.92000000", "remaining_size": "11.74997000", "sequence": 4179024401, "time": "2018-07-02T05:21:47.091000Z"}
{"type": "received", "order_id": "6910577c-5590-46a5-9c40-39ec5c86dedc", "order_type": "limit", "size": "0.04000000", "price": "446.68000000", "side": "buy", "client_oid": "ad53474e-2214-4a66-b891-32a685526868", "product_id": "ETH-USD", "sequence": 4179024402, "time": "2018-07-02T05:21:47.116000Z"}
{"type": "open", "side": "buy", "price": "446.68000000", "order_id": "6910577c-5590-46a5-9c40-39ec5c86dedc", "remaining_size": "0.04000000", "product_id": "ETH-USD", "sequence": 4179024403, "time": "2018-07-02T05:21:47.116000Z"}
{"type": "done", "side": "buy", "order_id": "916577d6-ca98-43d2-93ab-d88272822406", "reason": "canceled", "product_id": "ETH-USD", "price": "446.03000000", "remaining_size": "0.01000000", "sequence": 4179024404, "time": "2018-07-02T05:21:47.136000Z"}
{"type": "received", "order_id": "5b27a420-4005-4f40-9787-5d4e904b3746", "order_type": "limit", "size": "0.01000000", "price": "446.03000000", "side": "buy", "client_oid": "fb632400-0000-4911-bc90-000009113c90", "product_id": "ETH-USD", "sequence": 4179024405, "time": "2018-07-02T05:21:47.143000Z"}
{"type": "open", "side": "buy", "price": "446.03000000", "order_id": "5b27a420-4005-4f40-9787-5d4e904b3746", "remaining_size": "0.01000000", "product_id": "ETH-USD", "sequence": 4179024406, "time": "2018-07-02T05:21:47.143000Z"}
{"type": "done", "side": "sell", "order_id": "09981548-8813-48d5-8b97-c0b1a42599ae", "reason": "canceled", "product_id": "ETH-USD", "price": "448.40000000", "remaining_size": "8.82388000", "sequence": 4179024407, "time": "2018-07-02T05:21:47.160000Z"}
{"type": "received", "order_id": "5376f435-e2e9-4f7e-a264-492bac8e8b4e", "order_type": "limit", "size": "0.00100000", "price": "6315.69000000", "side": "sell", "client_oid": "dc24abca-42f0-4a2a-a92f-d8b90a28853b", "product_id": "BTC-USD", "sequence": 6227075423, "time": "2018-07-02T05:21:47.164000Z"}
{"type": "open", "side": "sell", "price": "6315.69000000", "order_id": "5376f435-e2e9-4f7e-a264-492bac8e8b4e", "remaining_size": "0.00100000", "product_id": "BTC-USD", "sequence": 6227075424, "time": "2018-07-02T05:21:47.164000Z"}
{"type": "done", "side": "buy", "order_id": "a4b4a898-00b8-47a2-b1c1-16bf91aa3f6b", "reason": "canceled", "product_id": "ETH-USD", "price": "446.66000000", "remaining_size": "6.87320969", "sequence": 4179024408, "time": "2018-07-02T05:21:47.180000Z"}
{"type": "received", "order_id": "59a29e79-4d50-4d11-b687-c0524bae7ce5", "order_type": "limit", "size": "11.74997000", "price": "447.93000000", "side": "sell", "client_oid": "6ee73a43-280b-47fd-9ed5-2f0fddbcaa59", "product_id": "ETH-USD", "sequence": 4179024409, "time": "2018-07-02T05:21:47.187000Z"}
{"type": "open", "side": "sell", "price": "447.93000000", "order_id": "59a29e79-4d50-4d11-b687-c0524bae7ce5", "remaining_size": "11.74997000", "product_id": "ETH-USD", "sequence": 4179024410, "time": "2018-07-02T05:21:47.187000Z"}
{"type": "done", "side": "sell", "order_id": "f38f3ca5-f6a6-4994-bd58-154dcb15a251", "reason": "canceled", "product_id": "ETH-USD", "price": "447.94000000", "remaining_size": "9.00000000", "sequence": 4179024411, "time": "2018-07-02T05:21:47.193000Z"}
{"type": "done", "side": "sell", "order_id": "e92028c9-0fd2-4ada-96a7-f655f1de4fb6", "reason": "canceled", "product_id": "ETH-USD", "price": "447.84000000", "remaining_size": "9.00000000", "sequence": 4179024412, "time": "2018-07-02T05:21:47.195000Z"}
{"type": "received", "order_id": "50181372-f758-4f13-976a-4238a06a471a", "order_type": "limit", "size": "6.87320969", "price": "446.69000000", "side": "buy", "client_oid": "43cba196-5594-e777-c219-2d6ce108c62e", "product_id": "ETH-USD", "sequence": 4179024413, "time": "2018-07-02T05:21:47.197000Z"}
{"type": "open", "side": "buy", "price": "446.69000000", "order_id": "50181372-f758-4f13-976a-4238a06a471a", "remaining_size": "6.87320969", "product_id": "ETH-USD", "sequence": 4179024414, "time": "2018-07-02T05:21:47.197000Z"}
{"type": "received", "order_id": "2841c733-7ba3-44ff-b220-d0b3f9087f5d", "order_type": "limit", "size": "9.00000000", "price": "447.88000000", "side": "sell", "client_oid": "75deb508-1dcc-494b-be60-66e09713bab3", "product_id": "ETH-USD", "sequence": 4179024415, "time": "2018-07-02T05:21:47.198000Z"}
{"type": "open", "side": "sell", "price": "447.88000000", "order_id": "2841c733-7ba3-44ff-b220-d0b3f9087f5d", "remaining_size": "9.00000000", "product_id": "ETH-USD", "sequence": 4179024416, "time": "2018-07-02T05:21:47.198000Z"}
{"type": "done", "side": "sell", "order_id": "eb695187-c17e-40f7-9c35-6fe0410dd573", "reason": "canceled", "product_id": "ETH-USD", "price": "447.84000000", "remaining_size": "6.00000000", "sequence": 4179024417, "time": "2018-07-02T05:21:47.199000Z"}
{"type": "done", "side": "sell", "order_id": "81c495f4-ea1b-4ac0-91fd-e0dbd162cc66", "reason": "canceled", "product_id": "ETH-USD", "price": "447.80000000", "remaining_size": "6.00000000", "sequence": 4179024418, "time": "2018-07-02T05:21:47.199000Z"}
{"type": "received", "order_id": "9f25e6de-c273-444a-b595-549089a5fb8a", "order_type": "limit", "size": "9.00000000", "price": "447.77000000", "side": "sell", "client_oid": "5f2c5ca2-7fcd-49a4-94ad-dac0200e9ff2", "product_id": "ETH-USD", "sequence": 4179024419, "time": "2018-07-02T05:21:47.202000Z"}
{"type": "open", "side": "sell", "price": "447.77000000", "order_id": "9f25e6de-c273-444a-b595-549089a5fb8a", "remaining_size": "9.00000000", "product_id": "ETH-USD", "sequence": 4179024420, "time": "2018-07-02T05:21:47.202000Z"}
{"type": "received", "order_id": "36a31b37-5eda-4872-aea1-8f60d7ebca5e", "order_type": "limit", "size": "6.00000000", "price": "447.73000000", "side": "sell", "client_oid": "1892e929-56e4-47b9-91ae-0efdaec2eac1", "product_id": "ETH-USD", "sequence": 4179024421, "time": "2018-07-02T05:21:47.206000Z"}
{"type": "open", "side": "sell", "price": "447.73000000", "order_id": "36a31b37-5eda-4872-aea1-8f60d7ebca5e", "remaining_size": "6.00000000", "product_id": "ETH-USD", "sequence": 4179024422, "time": "2018-07-02T05:21:47.206000Z"}
{"type": "received", "order_id": "677f899b-5be3-455f-97e1-721dea62da25", "order_type": "limit", "size": "6.00000000", "price": "447.77000000", "side": "sell", "client_oid": "517a6bb2-c149-43f8-9fa2-5adab20660c3", "product_id": "ETH-USD", "sequence": 4179024423, "time": "2018-07-02T05:21:47.209000Z"}
{"type": "open", "side": "sell", "price": "447.77000000", "order_id": "677f899b-5be3-455f-97e1-721dea62da25", "remaining_size": "6.00000000", "product_id": "ETH-USD", "sequence": 4179024424, "time": "2018-07-02T05:21:47.209000Z"}
{"type": "done", "side": "sell", "order_id": "36a31b37-5eda-4872-aea1-8f60d7ebca5e", "reason": "canceled", "product_id": "ETH-USD", "price": "447.73000000", "remaining_size": "6.00000000", "sequence": 4179024425, "time": "2018-07-02T05:21:47.210000Z"}
{"type": "done", "side": "sell", "order_id": "677f899b-5be3-455f-97e1-721dea62da25", "reason": "canceled", "product_id": "ETH-USD", "price": "447.77000000", "remaining_size": "6.00000000", "sequence": 4179024426, "time": "2018-07-02T05:21:47.213000Z"}
{"type": "done", "side": "sell", "order_id": "2841c733-7ba3-44ff-b220-d0b3f9087f5d", "reason": "canceled", "product_id": "ETH-USD", "price": "447.88000000", "remaining_size": "9.00000000", "sequence": 4179024427, "time": "2018-07-02T05:21:47.215000Z"}
{"type": "done", "side": "sell", "order_id": "9f25e6de-c273-444a-b595-549089a5fb8a", "reason": "canceled", "product_id": "ETH-USD", "price": "447.77000000", "remaining_size": "9.00000000", "sequence": 4179024428, "time": "2018-07-02T05:21:47.216000Z"}
{"type": "done", "side": "sell", "order_id": "daee1c60-641b-46b5-a9af-2e0242f98377", "reason": "canceled", "product_id": "ETH-USD", "price": "447.17000000", "remaining_size": "4.00000000", "sequence": 4179024429, "time": "2018-07-02T05:21:47.219000Z"}
{"type": "received", "order_id": "2d741ee8-92f1-415a-afb1-bef588ab4907", "order_type": "limit", "size": "6.00000000", "price": "447.80000000", "side": "sell", "client_oid": "565ff14c-f586-4726-9959-bb5cac143a64", "product_id": "ETH-USD", "sequence": 4179024430, "time": "2018-07-02T05:21:47.219000Z"}
{"type": "open", "side": "sell", "price": "447.80000000", "order_id": "2d741ee8-92f1-415a-afb1-bef588ab4907", "remaining_size": "6.00000000", "product_id": "ETH-USD", "sequence": 4179024431, "time": "2018-07-02T05:21:47.219000Z"}
{"type": "received", "order_id": "a03442c9-1ee8-4a15-9b34-027189059be3", "order_type": "limit", "size": "9.00000000", "price": "447.84000000", "side": "sell", "client_oid": "0c87d433-6f0f-477c-b3fd-773c6b3bc37f", "product_id": "ETH-USD", "sequence": 4179024432, "time": "2018-07-02T05:21:47.221000Z"}
{"type": "open", "side": "sell", "price": "447.84000000", "order_id": "a03442c9-1ee8-4a15-9b34-027189059be3", "remaining_size": "9.00000000", "product_id": "ETH-USD", "sequence": 4179024433, "time": "2018-07-02T05:21:47.221000Z"}
{"type": "received", "order_id": "1977236d-eb7e-4c05-8dc1-970f4169e5da", "order_type": "limit", "size": "6.00000000", "price": "447.84000000", "side": "sell", "client_oid": "73a3e988-64c8-459f-8675-a4ed7b98a7f1", "product_id": "ETH-USD", "sequence": 4179024434, "time": "2018-07-02T05:21:47.224000Z"}
{"type": "open", "side": "sell", "price": "447.84000000", "order_id": "1977236d-eb7e-4c05-8dc1-970f4169e5da", "remaining_size": "6.00000000", "product_id": "ETH-USD", "sequence": 4179024435, "time": "2018-07-02T05:21:47.224000Z"}
{"type": "received", "order_id": "f02cc1b5-0c72-4c2c-ba01-fbc6ac7b44dd", "order_type": "limit", "size": "9.00000000", "price": "447.94000000", "side": "sell", "client_oid": "82fb2680-db6b-42d9-9298-ff90747e8613", "product_id": "ETH-USD", "sequence": 4179024436, "time": "2018-07-02T05:21:47.227000Z"}
{"type": "open", "side": "sell", "price": "447.94000000", "order_id": "f02cc1b5-0c72-4c2c-ba01-fbc6ac7b44dd", "remaining_size": "9.00000000", "product_id": "ETH-USD", "sequence": 4179024437, "time": "2018-07-02T05:21:47.227000Z"}
{"type": "done", "side": "buy", "order_id": "5b27a420-4005-4f40-9787-5d4e904b3746", "reason": "canceled", "product_id": "ETH-USD", "price": "446.03000000", "remaining_size": "0.01000000", "sequence": 4179024438, "time": "2018-07-02T05:21:47.229000Z"}
{"type": "done", "side": "buy", "order_id": "e2373a89-c82a-49ba-bc3d-38298c91f6cd", "reason": "canceled", "product_id": "ETH-USD", "price": "446.50000000", "remaining_size": "50.07000000", "sequence": 4179024439, "time": "2018-07-02T05:21:47.234000Z"}
{"type": "done", "side": "sell", "order_id": "c7b4e5d3-e6d9-420f-bf7b-2c59f61ff17b", "reason": "canceled", "product_id": "ETH-USD", "price": "447.83000000", "remaining_size": "14.24999000", "sequence": 4179024440, "time": "2018-07-02T05:21:47.235000Z"}
{"type": "done", "side": "sell", "order_id": "87f3a991-dac8-447d-8af9-726239bcbc6a", "reason": "canceled", "product_id": "BTC-USD", "price": "6300.94000000", "remaining_size": "1.00000000", "sequence": 6227075425, "time": "2018-07-02T05:21:47.243000Z"}
{"type": "done", "side": "buy", "order_id": "6910577c-5590-46a5-9c40-39ec5c86dedc", "reason": "canceled", "product_id": "ETH-USD", "price": "446.68000000", "remaining_size": "0.04000000", "sequence": 4179024441, "time": "2018-07-02T05:21:47.243000Z"}
{"type": "received", "order_id": "5e2adc1f-448a-45ed-a716-cb9181fe9f8d", "order_type": "limit", "size": "0.01000000", "price": "446.19000000", "side": "buy", "client_oid": "b461a000-0006-47b3-9c50-0000067b35c5", "product_id": "ETH-USD", "sequence": 4179024442, "time": "2018-07-02T05:21:47.243000Z"}
{"type": "open", "side": "buy", "price": "446.19000000", "order_id": "5e2adc1f-448a-45ed-a716-cb9181fe9f8d", "remaining_size": "0.01000000", "product_id": "ETH-USD", "sequence": 4179024443, "time": "2018-07-02T05:21:47.243000Z"}
{"type": "done", "side": "buy", "order_id": "50181372-f758-4f13-976a-4238a06a471a", "reason": "canceled", "product_id": "ETH-USD", "price": "446.69000000", "remaining_size": "6.87320969", "sequence": 4179024444, "time": "2018-07-02T05:21:47.248000Z"}
{"type": "done", "side": "sell", "order_id": "1977236d-eb7e-4c05-8dc1-970f4169e5da", "reason": "canceled", "product_id": "ETH-USD", "price": "447.84000000", "remaining_size": "6.00000000", "sequence": 4179024445, "time": "2018-07-02T05:21:47.254000Z"}
{"type": "done", "side": "sell", "order_id": "2d741ee8-92f1-415a-afb1-bef588ab4907", "reason": "canceled", "product_id": "ETH-USD", "price": "447.80000000", "remaining_size": "6.00000000", "sequence": 4179024446, "time": "2018-07-02T05:21:47.255000Z"}
{"type": "received", "order_id": "486cb0a4-5a9e-4d27-a477-30f18d16e90d", "order_type": "limit", "size": "6.87320969", "price": "446.66000000", "side": "buy", "client_oid": "89fdbc8d-bb8d-4f91-809f-86eba6a29ea9", "product_id": "ETH-USD", "sequence": 4179024447, "time": "2018-07-02T05:21:47.255000Z"}
{"type": "done", "side": "buy", "order_id": "5fb0faf5-76fd-42b2-8c1a-ca44b571f5e9", "reason": "canceled", "product_id": "BTC-USD", "price": "6298.26000000", "remaining_size": "0.01250000", "sequence": 6227078843, "time": "2018-07-02T05:24:03.709000Z"}
{"type": "received", "order_id": "bf5fee9c-f7a9-4587-a53c-8793a31cb8d9", "order_type": "limit", "size": "0.01000000", "price": "448.25000000", "side": "sell", "client_oid": "02e4c0cb-3d9c-49fa-8000-00ddc0f905f3", "product_id": "ETH-USD", "sequence": 4179035592, "time": "2018-07-02T05:24:03.718000Z"}
{"type": "open", "side": "sell", "price": "448.25000000", "order_id": "bf5fee9c-f7a9-4587-a53c-8793a31cb8d9", "remaining_size": "0.01000000", "product_id": "ETH-USD", "sequence": 4179035593, "time": "2018-07-02T05:24:03.718000Z"}
{"type": "done", "side": "buy", "order_id": "b66bdbce-2592-4937-b914-da34f8486a04", "reason": "canceled", "product_id": "BTC-USD", "price": "6298.26000000", "remaining_size": "0.00200000", "sequence": 6227078844, "time": "2018-07-02T05:24:03.856000Z"}
{"type": "done", "side": "buy", "order_id": "3cc464b0-39ec-4a6b-8bd6-b83296add1a9", "reason": "canceled", "product_id": "BTC-USD", "price": "6144.61000000", "remaining_size": "0.00150000", "sequence": 6227078845, "time": "2018-07-02T05:24:03.881000Z"}
{"type": "received", "order_id": "d4163133-09bf-4a59-bcac-8740019e9247", "order_type": "limit", "size": "0.00150000", "price": "6116.50000000", "side": "buy", "client_oid": "46dfe860-393c-476f-8000-0047598fbae3", "product_id": "BTC-USD", "sequence": 6227078846, "time": "2018-07-02T05:24:03.889000Z"}
{"type": "open", "side": "buy", "price": "6116.50000000", "order_id": "d4163133-09bf-4a59-bcac-8740019e9247", "remaining_size": "0.00150000", "product_id": "BTC-USD", "sequence": 6227078847, "time": "2018-07-02T05:24:03.889000Z"}
{"type": "done", "side": "sell", "order_id": "ffa8d8b9-c04a-4100-8e71-61f2da302e31", "reason": "canceled", "product_id": "ETH-USD", "price": "470.67000000", "remaining_size": "0.01000000", "sequence": 4179035594, "time": "2018-07-02T05:24:03.900000Z"}
{"type": "received", "order_id": "4cd624ca-e18c-4091-a2ea-6e08792bb4ce", "order_type": "limit", "size": "0.01000000", "price": "472.67000000", "side": "sell", "client_oid": "be5f5321-1930-4ac3-8000-00bd880cdbc8", "product_id": "ETH-USD", "sequence": 4179035595, "time": "2018-07-02T05:24:03.907000Z"}
{"type": "open", "side": "sell", "price": "472.67000000", "order_id": "4cd624ca-e18c-4091-a2ea-6e08792bb4ce", "remaining_size": "0.01000000", "product_id": "ETH-USD", "sequence": 4179035596, "time": "2018-07-02T05:24:03.907000Z"}
{"type": "received", "order_id": "61bd0730-2d54-467b-80bd-3abff1c7551a", "order_type": "limit", "size": "0.00100000", "price": "6300.46000000", "side": "sell", "client_oid": "bfe8f57a-91c8-4b60-8000-0db523573570", "product_id": "BTC-USD", "sequence": 6227078848, "time": "2018-07-02T05:24:03.922000Z"}
{"type": "open", "side": "sell", "price": "6300.46000000", "order_id": "61bd0730-2d54-467b-80bd-3abff1c7551a", "remaining_size": "0.00100000", "product_id": "BTC-USD", "sequence": 6227078849, "time": "2018-07-02T05:24:03.922000Z"}
{"type": "done", "side": "sell", "order_id": "317e34e7-b55a-41e2-9a1e-86590062b9b0", "reason": "canceled", "product_id": "ETH-USD", "price": "452.96000000", "remaining_size": "15.83043000", "sequence": 4179035597, "time": "2018-07-02T05:24:03.948000Z"}
{"type": "received", "order_id": "43af6ef5-f36e-443d-bbd0-f1728c3e3424", "order_type": "limit", "size": "15.25233000", "price": "454.83000000", "side": "sell", "product_id": "ETH-USD", "sequence": 4179035598, "time": "2018-07-02T05:24:03.948000Z"}
{"type": "open", "side": "sell", "price": "454.83000000", "order_id": "43af6ef5-f36e-443d-bbd0-f1728c3e3424", "remaining_size": "15.25233000", "product_id": "ETH-USD", "sequence": 4179035599, "time": "2018-07-02T05:24:03.948000Z"}
{"type": "done", "side": "sell", "order_id": "ca92fbe9-e5e7-4abd-ab21-acc264cdb2d8", "reason": "canceled", "product_id": "ETH-USD", "price": "447.17000000", "remaining_size": "2.68391400", "sequence": 4179035600, "time": "2018-07-02T05:24:04.000000Z"}
{"type": "received", "order_id": "b0ca3d0e-171a-41dc-a56b-a33529b0b0c3", "order_type": "limit", "size": "0.01000000", "price": "449.25000000", "side": "sell", "client_oid": "2c95394d-cf3e-45ed-8000-00d403e53cd1", "product_id": "ETH-USD", "sequence": 4179035601, "time": "2018-07-02T05:24:04.028000Z"}
{"type": "open", "side": "sell", "price": "449.25000000", "order_id": "b0ca3d0e-171a-41dc-a56b-a33529b0b0c3", "remaining_size": "0.01000000", "product_id": "ETH-USD", "sequence": 4179035602, "time": "2018-07-02T05:24:04.028000Z"}
{"type": "received", "order_id": "007653ac-c7bc-4732-a130-4edc0d2ccbc1", "order_type": "limit", "size": "0.00100000", "price": "6301.46000000", "side": "sell", "client_oid": "f85293e0-1341-45f9-8000-00e7737563eb", "product_id": "BTC-USD", "sequence": 6227078850, "time": "2018-07-02T05:24:04.086000Z"}
{"type": "open", "side": "sell", "price": "6301.46000000", "order_id": "007653ac-c7bc-4732-a130-4edc0d2ccbc1", "remaining_size": "0.00100000", "product_id": "BTC-USD", "sequence": 6227078851, "time": "2018-07-02T05:24:04.086000Z"}
{"type": "received", "order_id": "d431f994-24a2-403a-9695-ff6f88b46276", "order_type": "limit", "size": "0.00200000", "price": "6298.26000000", "side": "buy", "product_id": "BTC-USD", "sequence": 6227078852, "time": "2018-07-02T05:24:04.125000Z"}
{"type": "open", "side": "buy", "price": "6298.26000000", "order_id": "d431f994-24a2-403a-9695-ff6f88b46276", "remaining_size": "0.00200000", "product_id": "BTC-USD", "sequence": 6227078853, "time": "2018-07-02T05:24:04.125000Z"}
{"type": "received", "order_id": "b38179de-6fb6-45b9-b5b1-f1ee2e38b3c0", "order_type": "limit", "size": "0.01000000", "price": "450.25000000", "side": "sell", "client_oid": "70635703-17ce-4586-8000-00428bfb39fe", "product_id": "ETH-USD", "sequence": 4179035603, "time": "2018-07-02T05:24:04.250000Z"}
{"type": "open", "side": "sell", "price": "450.25000000", "order_id": "b38179de-6fb6-45b9-b5b1-f1ee2e38b3c0", "remaining_size": "0.01000000", "product_id": "ETH-USD", "sequence": 4179035604, "time": "2018-07-02T05:24:04.250000Z"}
{"type": "done", "side": "buy", "order_id": "c042d8e0-f129-4bc1-a195-d58ceb2022c3", "reason": "canceled", "product_id": "ETH-USD", "price": "445.35000000", "remaining_size": "2.85340800", "sequence": 4179035605, "time": "2018-07-02T05:24:04.253000Z"}
{"type": "done", "side": "buy", "order_id": "5c2eba47-2cfe-40ef-a6f9-d6ba2f225fbf", "reason": "canceled", "product_id": "ETH-USD", "price": "445.09000000", "remaining_size": "2.35891600", "sequence": 4179035606, "time": "2018-07-02T05:24:04.256000Z"}
{"type": "done", "side": "buy", "order_id": "0e388417-6674-4d19-aa05-0604cca6fef6", "reason": "canceled", "product_id": "ETH-USD", "price": "443.66000000", "remaining_size": "1.81476200", "sequence": 4179035607, "time": "2018-07-02T05:24:04.259000Z"}
{"type": "done", "side": "buy", "order_id": "dd850165-9780-4eda-a75e-72580386caac", "reason": "canceled", "product_id": "ETH-USD", "price": "443.14000000", "remaining_size": "1.66738700", "sequence": 4179035608, "time": "2018-07-02T05:24:04.262000Z"}
{"type": "done", "side": "buy", "order_id": "4d539c07-cc10-4b8b-8618-c7c805b900a6", "reason": "canceled", "product_id": "ETH-USD", "price": "443.01000000", "remaining_size": "14.00435200", "sequence": 4179035609, "time": "2018-07-02T05:24:04.264000Z"}
{"type": "received", "order_id": "f114903c-4027-4c47-961b-eb4039b40945", "order_type": "limit", "size": "2.85927600", "price": "445.35000000", "side": "buy", "client_oid": "306dc491-a71f-4337-ad34-407a87397db1", "product_id": "ETH-USD", "sequence": 4179035610, "time": "2018-07-02T05:24:04.294000Z"}
{"type": "open", "side": "buy", "price": "445.35000000", "order_id": "f114903c-4027-4c47-961b-eb4039b40945", "remaining_size": "2.85927600", "product_id": "ETH-USD", "sequence": 4179035611, "time": "2018-07-02T05:24:04.294000Z"}
{"type": "received", "order_id": "4e8a9687-61e1-4abe-b0c9-a6c740e5d1b9", "order_type": "limit", "size": "2.36054100", "price": "445.09000000", "side": "buy", "client_oid": "fbecc6c0-fbfe-4425-bea3-a184aeca2896", "product_id": "ETH-USD", "sequence": 4179035612, "time": "2018-07-02T05:24:04.303000Z"}
{"type": "open", "side": "buy", "price": "445.09000000", "order_id": "4e8a9687-61e1-4abe-b0c9-a6c740e5d1b9", "remaining_size": "2.36054100", "product_id": "ETH-USD", "sequence": 4179035613, "time": "2018-07-02T05:24:04.303000Z"}
{"type": "received", "order_id": "365ee84a-60f7-487f-b6fa-607ca4141adf", "order_type": "limit", "size": "1.81306400", "price": "443.66000000", "side": "buy", "client_oid": "8507c822-eb2e-475a-b00a-21db3c23077a", "product_id": "ETH-USD", "sequence": 4179035614, "time": "2018-07-02T05:24:04.311000Z"}
{"type": "open", "side": "buy", "price": "443.66000000", "order_id": "365ee84a-60f7-487f-b6fa-607ca4141adf", "remaining_size": "1.81306400", "product_id": "ETH-USD", "sequence": 4179035615, "time": "2018-07-02T05:24:04.311000Z"}
{"type": "done", "side": "buy", "order_id": "673d9820-fc65-4bc9-a98c-3dbb37b2fdbd", "reason": "canceled", "product_id": "BTC-USD", "price": "6298.26000000", "remaining_size": "0.01250000", "sequence": 6227078854, "time": "2018-07-02T05:24:04.321000Z"}
{"type": "received", "order_id": "c3cc1ac0-7327-45a6-b0a6-9e1f613b2d0a", "order_type": "limit", "size": "1.64992700", "price": "443.14000000", "side": "buy", "client_oid": "a39bcbbd-e3ba-4384-babd-e7573226412c", "product_id": "ETH-USD", "sequence": 4179035616, "time": "2018-07-02T05:24:04.319000Z"}
{"type": "open", "side": "buy", "price": "443.14000000", "order_id": "c3cc1ac0-7327-45a6-b0a6-9e1f613b2d0a", "remaining_size": "1.64992700", "product_id": "ETH-USD", "sequence": 4179035617, "time": "2018-07-02T05:24:04.319000Z"}
{"type": "received", "order_id": "b46ad814-668e-4d05-918b-6f2b08865832", "order_type": "limit", "size": "14.01598500", "price": "443.01000000", "side": "buy", "client_oid": "b698526e-1389-4256-99cc-d5255a90051f", "product_id": "ETH-USD", "sequence": 4179035618, "time": "2018-07-02T05:24:04.403000Z"}
{"type": "open", "side": "buy", "price": "443.01000000", "order_id": "b46ad814-668e-4d05-918b-6f2b08865832", "remaining_size": "14.01598500", "product_id": "ETH-USD", "sequence": 4179035619, "time": "2018-07-02T05:24:04.403000Z"}
{"type": "done", "side": "sell", "order_id": "49ddba83-82ab-4e39-a0b8-ed4573bfe39f", "reason": "canceled", "product_id": "ETH-USD", "price": "447.17000000", "remaining_size": "132.00000000", "sequence": 4179035620, "time": "2018-07-02T05:24:04.464000Z"}
{"type": "done", "side": "sell", "order_id": "e22474ca-88c7-4bf4-a9ad-5e20077fdade", "reason": "canceled", "product_id": "BTC-USD", "price": "6303.65000000", "remaining_size": "0.01500000", "sequence": 6227078855, "time": "2018-07-02T05:24:04.470000Z"}
{"type": "received", "order_id": "9b55612a-90aa-4803-807e-3ee6a0bc70e1", "order_type": "limit", "size": "0.01500000", "price": "6303.68000000", "side": "sell", "client_oid": "69f31f6e-43bc-4c72-92af-fad173709459", "product_id": "BTC-USD", "sequence": 6227078856, "time": "2018-07-02T05:24:04.475000Z"}
{"type": "open", "side": "sell", "price": "6303.68000000", "order_id": "9b55612a-90aa-4803-807e-3ee6a0bc70e1", "remaining_size": "0.01500000", "product_id": "BTC-USD", "sequence": 6227078857, "time": "2018-07-02T05:24:04.475000Z"}
{"type": "done", "side": "sell", "order_id": "3c3daadf-2d61-4606-a660-5f83f785d3ca", "reason": "canceled", "product_id": "ETH-USD", "price": "449.70000000", "remaining_size": "6.79438000", "sequence": 4179035621, "time": "2018-07-02T05:24:04.477000Z"}
{"type": "done", "side": "sell", "order_id": "11ba1c70-e0d0-4c9b-a017-fa8108c7d2b3", "reason": "canceled", "product_id": "ETH-USD", "price": "450.36000000", "remaining_size": "6.79438000", "sequence": 4179035622, "time": "2018-07-02T05:24:04.485000Z"}
{"type": "received", "order_id": "645f13d8-3d15-431e-a792-8656da77d6f6", "order_type": "limit", "size": "6.79438000", "price": "452.99000000", "side": "sell", "client_oid": "31cc578a-2f89-4c7a-8626-541bafd95321", "product_id": "ETH-USD", "sequence": 4179035623, "time": "2018-07-02T05:24:04.495000Z"}
{"type": "open", "side": "sell", "price": "452.99000000", "order_id": "645f13d8-3d15-431e-a792-8656da77d6f6", "remaining_size": "6.79438000", "product_id": "ETH-USD", "sequence": 4179035624, "time": "2018-07-02T05:24:04.495000Z"}
{"type": "received", "order_id": "609fb356-9597-487c-9845-42a5a3aa385d", "order_type": "limit", "size": "6.79438000", "price": "452.79000000", "side": "sell", "client_oid": "34dd7e15-58f4-4a1a-a800-c98aa55a286d", "product_id": "ETH-USD", "sequence": 4179035625, "time": "2018-07-02T05:24:04.497000Z"}
{"type": "open", "side": "sell", "price": "452.79000000", "order_id": "609fb356-9597-487c-9845-42a5a3aa385d", "remaining_size": "6.79438000", "product_id": "ETH-USD", "sequence": 4179035626, "time": "2018-07-02T05:24:04.497000Z"}
{"type": "done", "side": "buy", "order_id": "48082879-b2db-4b0d-b637-6cbbfb652ea7", "reason": "canceled", "product_id": "BTC-USD", "price": "6298.26000000", "remaining_size": "0.00200000", "sequence": 6227078858, "time": "2018-07-02T05:24:04.625000Z"}
{"type": "done", "side": "sell", "order_id": "b38179de-6fb6-45b9-b5b1-f1ee2e38b3c0", "reason": "canceled", "product_id": "ETH-USD", "price": "450.25000000", "remaining_size": "0.01000000", "sequence": 4179035627, "time": "2018-07-02T05:24:04.697000Z"}
{"type": "done", "side": "sell", "order_id": "9b5c3986-e802-4535-ad3a-96f4ebd1baa8", "reason": "canceled", "product_id": "ETH-USD", "price": "447.25000000", "remaining_size": "0.01000000", "sequence": 4179035628, "time": "2018-07-02T05:24:04.699000Z"}
{"type": "done", "side": "sell", "order_id": "ea8171da-07b7-4095-b952-990f72bc1e52", "reason": "canceled", "product_id": "ETH-USD", "price": "452.25000000", "remaining_size": "0.01000000", "sequence": 4179035629, "time": "2018-07-02T05:24:04.701000Z"}
{"type": "done", "side": "sell", "order_id": "497e73d8-7e78-4220-964a-48abecccc88e", "reason": "canceled", "product_id": "ETH-USD", "price": "451.25000000", "remaining_size": "0.01000000", "sequence": 4179035630, "time": "2018-07-02T05:24:04.703000Z"}
{"type": "done", "side": "sell", "order_id": "b0ca3d0e-171a-41dc-a56b-a33529b0b0c3", "reason": "canceled", "product_id": "ETH-USD", "price": "449.25000000", "remaining_size": "0.01000000", "sequence": 4179035631, "time": "2018-07-02T05:24:04.704000Z"}
{"type": "done", "side": "sell", "order_id": "b74f5834-89ba-4e11-acf4-bf97c70b6b5f", "reason": "canceled", "product_id": "ETH-USD", "price": "453.25000000", "remaining_size": "0.01000000", "sequence": 4179035632, "time": "2018-07-02T05:24:04.705000Z"}
{"type": "done", "side": "sell", "order_id": "bf5fee9c-f7a9-4587-a53c-8793a31cb8d9", "reason": "canceled", "product_id": "ETH-USD", "price": "448.25000000", "remaining_size": "0.01000000", "sequence": 4179035633, "time": "2018-07-02T05:24:04.733000Z"}
{"type": "received", "order_id": "5d5ee41d-99c4-47e8-8a1d-8e2f1be653a1", "order_type": "limit", "size": "15.11670000", "price": "453.99000000", "side": "sell", "product_id": "ETH-USD", "sequence": 4179035634, "time": "2018-07-02T05:24:04.781000Z"}
{"type": "open", "side": "sell", "price": "453.99000000", "order_id": "5d5ee41d-99c4-47e8-8a1d-8e2f1be653a1", "remaining_size": "15.11670000", "product_id": "ETH-USD", "sequence": 4179035635, "time": "2018-07-02T05:24:04.781000Z"}
{"type": "received", "order_id": "6de021de-b322-4082-b141-59692c4b384b", "order_type": "limit", "size": "0.01000000", "price": "454.25000000", "side": "sell", "client_oid": "315b09b6-ce8a-46b5-8000-0053156d0884", "product_id": "ETH-USD", "sequence": 4179035636, "time": "2018-07-02T05:24:04.790000Z"}
{"type": "open", "side": "sell", "price": "454.25000000", "order_id": "6de021de-b322-4082-b141-59692c4b384b", "remaining_size": "0.01000000", "product_id": "ETH-USD", "sequence": 4179035637, "time": "2018-07-02T05:24:04.790000Z"}
{"type": "done", "side": "sell", "order_id": "645f13d8-3d15-431e-a792-8656da77d6f6", "reason": "canceled", "product_id": "ETH-USD", "price": "452.99000000", "remaining_size": "6.79438000", "sequence": 4179035638, "time": "2018-07-02T05:24:04.830000Z"}
{"type": "done", "side": "sell", "order_id": "43af6ef5-f36e-443d-bbd0-f1728c3e3424", "reason": "canceled", "product_id": "ETH-USD", "price": "454.83000000", "remaining_size": "15.25233000", "sequence": 4179035639, "time": "2018-07-02T05:24:04.833000Z"}
{"type": "done", "side": "sell", "order_id": "609fb356-9597-487c-9845-42a5a3aa385d", "reason": "canceled", "product_id": "ETH-USD", "price": "452.79000000", "remaining_size": "6.79438000", "sequence": 4179035640, "time": "2018-07-02T05:24:04.834000Z"}
{"type": "received", "order_id": "07f7c5be-23ae-4454-986d-f0effde4df51", "order_type": "limit", "size": "6.79438000", "price": "450.36000000", "side": "sell", "client_oid": "22b0035f-4728-45ff-9277-457e1c3c9c62", "product_id": "ETH-USD", "sequence": 4179035641, "time": "2018-07-02T05:24:04.846000Z"}
{"type": "open", "side": "sell", "price": "450.36000000", "order_id": "07f7c5be-23ae-4454-986d-f0effde4df51", "remaining_size": "6.79438000", "product_id": "ETH-USD", "sequence": 4179035642, "time": "2018-07-02T05:24:04.846000Z"}
{"type": "received", "order_id": "388f78d4-8da1-4814-a4e3-d89595dc3993", "order_type": "limit", "size": "6.79438000", "price": "449.70000000", "side": "sell", "client_oid": "5162487f-ad1e-423a-87a2-917a77d762ed", "product_id": "ETH-USD", "sequence": 4179035643, "time": "2018-07-02T05:24:04.850000Z"}
{"type": "open", "side": "sell", "price": "449.70000000", "order_id": "388f78d4-8da1-4814-a4e3-d89595dc3993", "remaining_size": "6.79438000", "product_id": "ETH-USD", "sequence": 4179035644, "time": "2018-07-02T05:24:04.850000Z"}
{"type": "done", "side": "buy", "order_id": "d4163133-09bf-4a59-bcac-8740019e9247", "reason": "canceled", "product_id": "BTC-USD", "price": "6116.50000000", "remaining_size": "0.00150000", "sequence": 6227078859, "time": "2018-07-02T05:24:05.037000Z"}
{"type": "done", "side": "sell", "order_id": "364d7dfc-cc94-48d4-b6ad-5401d804fb91", "reason": "canceled", "product_id": "ETH-USD", "price": "449.31000000", "remaining_size": "0.01000000", "sequence": 4179035645, "time": "2018-07-02T05:24:05.056000Z"}
{"type": "done", "side": "sell", "order_id": "4cd624ca-e18c-4091-a2ea-6e08792bb4ce", "reason": "canceled", "product_id": "ETH-USD", "price": "472.67000000", "remaining_size": "0.01000000", "sequence": 4179035646, "time": "2018-07-02T05:24:05.056000Z"}
{"type": "received", "order_id": "6987c4eb-a639-4c50-902c-6e75c220f0b6", "order_type": "limit", "size": "2.68391400", "price": "447.17000000", "side": "sell", "product_id": "ETH-USD", "sequence": 4179035647, "time": "2018-07-02T05:24:05.103000Z"}
{"type": "open", "side": "sell", "price": "447.17000000", "order_id": "6987c4eb-a639-4c50-902c-6e75c220f0b6", "remaining_size": "2.68391400", "product_id": "ETH-USD", "sequence": 4179035648, "time": "2018-07-02T05:24:05.103000Z"}
{"type": "received", "order_id": "3a309566-1ec0-4b4b-8f62-883c34f2041a", "order_type": "limit", "size": "0.00150000", "price": "6085.89000000", "side": "buy", "client_oid": "9f706cfb-c8fb-4518-8000-00cda45ad5c6", "product_id": "BTC-USD", "sequence": 6227078860, "time": "2018-07-02T05:24:05.110000Z"}
{"type": "open", "side": "buy", "price": "6085.89000000", "order_id": "3a309566-1ec0-4b4b-8f62-883c34f2041a", "remaining_size": "0.00150000", "product_id": "BTC-USD", "sequence": 6227078861, "time": "2018-07-02T05:24:05.110000Z"}
{"type": "received", "order_id": "fe215288-4dc9-4ddc-9d14-117a63fedab0", "order_type": "limit", "size": "0.01000000", "price": "474.70000000", "side": "sell", "client_oid": "b52c50af-d012-489f-8000-00efe0c30454", "product_id": "ETH-USD", "sequence": 4179035649, "time": "2018-07-02T05:24:05.111000Z"}
{"type": "open", "side": "sell", "price": "474.70000000", "order_id": "fe215288-4dc9-4ddc-9d14-117a63fedab0", "remaining_size": "0.01000000", "product_id": "ETH-USD", "sequence": 4179035650, "time": "2018-07-02T05:24:05.111000Z"}
{"type": "done", "side": "sell", "order_id": "baa107a1-59b5-4e64-b89a-be5491bfb7a2", "reason": "canceled", "product_id": "ETH-USD", "price": "447.87000000", "remaining_size": "14.24999000", "sequence": 4179035651, "time": "2018-07-02T05:24:05.132000Z"}
{"type": "done", "side": "buy", "order_id": "5bfcb4d3-42a9-4d61-baa4-2425a6683e9d", "reason": "canceled", "product_id": "ETH-USD", "price": "446.40000000", "remaining_size": "13.00000000", "sequence": 4179035652, "time": "2018-07-02T05:24:05.141000Z"}
{"type": "done", "side": "sell", "order_id": "6de021de-b322-4082-b141-59692c4b384b", "reason": "canceled", "product_id": "ETH-USD", "price": "454.25000000", "remaining_size": "0.01000000", "sequence": 4179035653, "time": "2018-07-02T05:24:05.145000Z"}
{"type": "received", "order_id": "c0edd0a4-e5ed-4963-a488-f412cec30ad9", "order_type": "limit", "size": "0.00200000", "price": "6298.26000000", "side": "buy", "product_id": "BTC-USD", "sequence": 6227078862, "time": "2018-07-02T05:24:05.161000Z"}
{"type": "open", "side": "buy", "price": "6298.26000000", "order_id": "c0edd0a4-e5ed-4963-a488-f412cec30ad9", "remaining_size": "0.00200000", "product_id": "BTC-USD", "sequence": 6227078863, "time": "2018-07-02T05:24:05.161000Z"}
{"type": "received", "order_id": "7cf7cdd9-c9c8-4aeb-b300-63ee8fb29afb", "order_type": "limit", "size": "0.01000000", "price": "449.31000000", "side": "sell", "client_oid": "538d4e48-1618-47f9-bc47-1a6a1af6a020", "product_id": "ETH-USD", "sequence": 4179035654, "time": "2018-07-02T05:24:05.158000Z"}
{"type": "open", "side": "sell", "price": "449.31000000", "order_id": "7cf7cdd9-c9c8-4aeb-b300-63ee8fb29afb", "remaining_size": "0.01000000", "product_id": "ETH-USD", "sequence": 4179035655, "time": "2018-07-02T05:24:05.158000Z"}
{"type": "received", "order_id": "b61f3a37-d26f-4423-955a-e6f91ccc0e3a", "order_type": "limit", "size": "34.00000000", "price": "447.17000000", "side": "sell", "client_oid": "cea7044d-bbc3-4f66-8a34-9bf16e9ef06d", "product_id": "ETH-USD", "sequence": 4179035656, "time": "2018-07-02T05:24:05.193000Z"}
{"type": "open", "side": "sell", "price": "447.17000000", "order_id": "b61f3a37-d26f-4423-955a-e6f91ccc0e3a", "remaining_size": "34.00000000", "product_id": "ETH-USD", "sequence": 4179035657, "time": "2018-07-02T05:24:05.193000Z"}
{"type": "received", "order_id": "cb5d27e9-3688-4e57-863d-1c286ba026aa", "order_type": "limit", "size": "0.01000000", "price": "447.25000000", "side": "sell", "client_oid": "fe31f8f6-8d53-4277-8000-00c815e49ab3", "product_id": "ETH-USD", "sequence": 4179035658, "time": "2018-07-02T05:24:05.194000Z"}
{"type": "open", "side": "sell", "price": "447.25000000", "order_id": "cb5d27e9-3688-4e57-863d-1c286ba026aa", "remaining_size": "0.01000000", "product_id": "ETH-USD", "sequence": 4179035659, "time": "2018-07-02T05:24:05.194000Z"}
{"type": "received", "order_id": "9c90f190-d4da-4556-9b84-599461fc02e5", "order_type": "limit", "size": "13.00000000", "price": "446.41000000", "side": "buy", "client_oid": "ddaa7a8d-5c1d-4d77-add9-56cbe1cf9f69", "product_id": "ETH-USD", "sequence": 4179035660, "time": "2018-07-02T05:24:05.217000Z"}
{"type": "open", "side": "buy", "price": "446.41000000", "order_id": "9c90f190-d4da-4556-9b84-599461fc02e5", "remaining_size": "13.00000000", "product_id": "ETH-USD", "sequence": 4179035661, "time": "2018-07-02T05:24:05.217000Z"}
{"type": "done", "side": "buy", "order_id": "f114903c-4027-4c47-961b-eb4039b40945", "reason": "canceled", "product_id": "ETH-USD", "price": "445.35000000", "remaining_size": "2.85927600", "sequence": 4179035662, "time": "2018-07-02T05:24:05.273000Z"}
{"type": "done", "side": "buy", "order_id": "4e8a9687-61e1-4abe-b0c9-a6c740e5d1b9", "reason": "canceled", "product_id": "ETH-USD", "price": "445.09000000", "remaining_size": "2.36054100", "sequence": 4179035663, "time": "2018-07-02T05:24:05.275000Z"}
{"type": "done", "side": "buy", "order_id": "365ee84a-60f7-487f-b6fa-607ca4141adf", "reason": "canceled", "product_id": "ETH-USD", "price": "443.66000000", "remaining_size": "1.81306400", "sequence": 4179035664, "time": "2018-07-02T05:24:05.278000Z"}
{"type": "done", "side": "buy", "order_id": "c3cc1ac0-7327-45a6-b0a6-9e1f613b2d0a", "reason": "canceled", "product_id": "ETH-USD", "price": "443.14000000", "remaining_size": "1.64992700", "sequence": 4179035665, "time": "2018-07-02T05:24:05.282000Z"}
{"type": "done", "side": "buy", "order_id": "b46ad814-668e-4d05-918b-6f2b08865832", "reason": "canceled", "product_id": "ETH-USD", "price": "443.01000000", "remaining_size": "14.01598500", "sequence": 4179035666, "time": "2018-07-02T05:24:05.284000Z"}
{"type": "received", "order_id": "1fcbccc2-3429-44cb-bbea-f9d9fb284de7", "order_type": "limit", "size": "3.58036300", "price": "445.35000000", "side": "buy", "client_oid": "6ebeea39-b037-4a5e-96b4-3509ef1950a7", "product_id": "ETH-USD", "sequence": 4179035667, "time": "2018-07-02T05:24:05.313000Z"}
{"type": "open", "side": "buy", "price": "445.35000000", "order_id": "1fcbccc2-3429-44cb-bbea-f9d9fb284de7", "remaining_size": "3.58036300", "product_id": "ETH-USD", "sequence": 4179035668, "time": "2018-07-02T05:24:05.313000Z"}
{"type": "received", "order_id": "5bd8785c-d362-4bf2-8be3-5a4726eb3c02", "order_type": "limit", "size": "0.01000000", "price": "448.25000000", "side": "sell", "client_oid": "38eabc5a-56ec-45a5-8000-001cb7ccc1b8", "product_id": "ETH-USD", "sequence": 4179035669, "time": "2018-07-02T05:24:05.319000Z"}
{"type": "open", "side": "sell", "price": "448.25000000", "order_id": "5bd8785c-d362-4bf2-8be3-5a4726eb3c02", "remaining_size": "0.01000000", "product_id": "ETH-USD", "sequence": 4179035670, "time": "2018-07-02T05:24:05.319000Z"}
{"type": "received", "order_id": "a2031e06-99c9-4baa-a123-9147ed6b3198", "order_type": "limit", "size": "2.86779800", "price": "445.09000000", "side": "buy", "client_oid": "d1687af0-b8a6-4a56-bb3a-73534c731435", "product_id": "ETH-USD", "sequence": 4179035671, "time": "2018-07-02T05:24:05.323000Z"}
{"type": "open", "side": "buy", "price": "445.09000000", "order_id": "a2031e06-99c9-4baa-a123-9147ed6b3198", "remaining_size": "2.86779800", "product_id": "ETH-USD", "sequence": 4179035672, "time": "2018-07-02T05:24:05.323000Z"}
{"type": "done", "side": "sell", "order_id": "526d635a-ca57-46d2-8cb4-4a1074798065", "reason": "canceled", "product_id": "ETH-USD", "price": "447.17000000", "remaining_size": "0.01053000", "sequence": 4179035673, "time": "2018-07-02T05:24:05.327000Z"}
{"type": "done", "side": "buy", "order_id": "b6514db7-88e9-43d5-a573-d142f1f1bc15", "reason": "canceled", "product_id": "ETH-USD", "price": "443.15000000", "remaining_size": "1.50900000", "sequence": 4179035674, "time": "2018-07-02T05:24:05.330000Z"}
{"type": "received", "order_id": "bbe0bcce-1cc8-4307-83a0-9c02ce29c572", "order_type": "limit", "size": "2.06991400", "price": "443.66000000", "side": "buy", "client_oid": "12d1c620-acf1-45b2-8447-f84e380480bb", "product_id": "ETH-USD", "sequence": 4179035675, "time": "2018-07-02T05:24:05.331000Z"}
{"type": "open", "side": "buy", "price": "443.66000000", "order_id": "bbe0bcce-1cc8-4307-83a0-9c02ce29c572", "remaining_size": "2.06991400", "product_id": "ETH-USD", "sequence": 4179035676, "time": "2018-07-02T05:24:05.331000Z"}
{"type": "received", "order_id": "48994853-f4f8-4b11-85b3-0229a238f158", "order_type": "limit", "size": "14.24999000", "price": "447.85000000", "side": "sell", "client_oid": "83da97cc-ff4a-44e5-9578-685c17bab33c", "product_id": "ETH-USD", "sequence": 4179035677, "time": "2018-07-02T05:24:05.338000Z"}
{"type": "open", "side": "sell", "price": "447.85000000", "order_id": "48994853-f4f8-4b11-85b3-0229a238f158", "remaining_size": "14.24999000", "product_id": "ETH-USD", "sequence": 4179035678, "time": "2018-07-02T05:24:05.338000Z"}
{"type": "received", "order_id": "e748f854-06e5-47d3-afd2-8865715c08ab", "order_type": "limit", "size": "2.06792900", "price": "443.14000000", "side": "buy", "client_oid": "b35a6e6f-d3ba-48ed-8c6a-f69032ef54c1", "product_id": "ETH-USD", "sequence": 4179035679, "time": "2018-07-02T05:24:05.339000Z"}
{"type": "open", "side": "buy", "price": "443.14000000", "order_id": "e748f854-06e5-47d3-afd2-8865715c08ab", "remaining_size": "2.06792900", "product_id": "ETH-USD", "sequence": 4179035680, "time": "2018-07-02T05:24:05.339000Z"}
{"type": "received", "order_id": "b3c43302-3f1a-49f1-be55-a8b8e7da4162", "order_type": "limit", "size": "0.01067000", "price": "447.17000000", "side": "sell", "client_oid": "233a7a58-7db8-11e8-874f-16be7828d23e", "product_id": "ETH-USD", "sequence": 4179035681, "time": "2018-07-02T05:24:05.340000Z"}
{"type": "open", "side": "sell", "price": "447.17000000", "order_id": "b3c43302-3f1a-49f1-be55-a8b8e7da4162", "remaining_size": "0.01067000", "product_id": "ETH-USD", "sequence": 4179035682, "time": "2018-07-02T05:24:05.340000Z"}
{"type": "received", "order_id": "1ac39e78-a5b7-4505-8cce-2e12a7112aad", "order_type": "limit", "size": "12.10609900", "price": "443.01000000", "side": "buy", "client_oid": "6d1b107d-132d-4c3f-aaf0-211d0a4ef5f0", "product_id": "ETH-USD", "sequence": 4179035683, "time": "2018-07-02T05:24:05.347000Z"}
{"type": "open", "side": "buy", "price": "443.01000000", "order_id": "1ac39e78-a5b7-4505-8cce-2e12a7112aad", "remaining_size": "12.10609900", "product_id": "ETH-USD", "sequence": 4179035684, "time": "2018-07-02T05:24:05.347000Z"}
{"type": "received", "order_id": "47b8743a-5ff7-44bf-9ae8-5e9958e4e574", "order_type": "limit", "size": "1.50947000", "price": "443.01000000", "side": "buy", "client_oid": "d5d4e726-f96c-4380-8e39-5e62a9291d48", "product_id": "ETH-USD", "sequence": 4179035685, "time": "2018-07-02T05:24:05.348000Z"}
{"type": "open", "side": "buy", "price": "443.01000000", "order_id": "47b8743a-5ff7-44bf-9ae8-5e9958e4e574", "remaining_size": "1.50947000", "product_id": "ETH-USD", "sequence": 4179035686, "time": "2018-07-02T05:24:05.348000Z"}
{"type": "done", "side": "buy", "order_id": "47b8743a-5ff7-44bf-9ae8-5e9958e4e574", "reason": "canceled", "product_id": "ETH-USD", "price": "443.01000000", "remaining_size": "1.50947000", "sequence": 4179035687, "time": "2018-07-02T05:24:05.430000Z"}
{"type": "received", "order_id": "30948da3-d71e-475a-9fae-2c8cd7686a3f", "order_type": "limit", "size": "1.50900000", "price": "443.15000000", "side": "buy", "client_oid": "3c491950-3eaa-41ea-81e6-d5d98f5dc30f", "product_id": "ETH-USD", "sequence": 4179035688, "time": "2018-07-02T05:24:05.439000Z"}
{"type": "open", "side": "buy", "price": "443.15000000", "order_id": "30948da3-d71e-475a-9fae-2c8cd7686a3f", "remaining_size": "1.50900000", "product_id": "ETH-USD", "sequence": 4179035689, "time": "2018-07-02T05:24:05.439000Z"}
{"type": "done", "side": "sell", "order_id": "b61f3a37-d26f-4423-955a-e6f91ccc0e3a", "reason": "canceled", "product_id": "ETH-USD", "price": "447.17000000", "remaining_size": "34.00000000", "sequence": 4179035690, "time": "2018-07-02T05:24:05.463000Z"}
{"type": "done", "side": "sell", "order_id": "9b55612a-90aa-4803-807e-3ee6a0bc70e1", "reason": "canceled", "product_id": "BTC-USD", "price": "6303.68000000", "remaining_size": "0.01500000", "sequence": 6227078864, "time": "2018-07-02T05:24:05.471000Z"}
{"type": "done", "side": "sell", "order_id": "cb5d27e9-3688-4e57-863d-1c286ba026aa", "reason": "canceled", "product_id": "ETH-USD", "price": "447.25000000", "remaining_size": "0.01000000", "sequence": 4179035691, "time": "2018-07-02T05:24:05.516000Z"}
{"type": "received", "order_id": "ed3f2961-1a97-43cf-9b2f-28103b14b868", "order_type": "limit", "size": "0.01500000", "price": "6303.69000000", "side": "sell", "client_oid": "66dae35f-265c-44a1-a3ae-f0f239accfe6", "product_id": "BTC-USD", "sequence": 6227078865, "time": "2018-07-02T05:24:05.528000Z"}
{"type": "open", "side": "sell", "price": "6303.69000000", "order_id": "ed3f2961-1a97-43cf-9b2f-28103b14b868", "remaining_size": "0.01500000", "product_id": "BTC-USD", "sequence": 6227078866, "time": "2018-07-02T05:24:05.528000Z"}
{"type": "received", "order_id": "b55f8bb1-18ba-47a6-9230-27a1f7e496ef", "order_type": "limit", "size": "0.01000000", "price": "449.25000000", "side": "sell", "client_oid": "8f93b687-4fbf-4a86-8000-00cf7e013815", "product_id": "ETH-USD", "sequence": 4179035692, "time": "2018-07-02T05:24:05.570000Z"}
{"type": "open", "side": "sell", "price": "449.25000000", "order_id": "b55f8bb1-18ba-47a6-9230-27a1f7e496ef", "remaining_size": "0.01000000", "product_id": "ETH-USD", "sequence": 4179035693, "time": "2018-07-02T05:24:05.570000Z"}
{"type": "received", "order_id": "c9dbb5f5-77bc-4d53-a564-184a818c2b76", "order_type": "limit", "size": "0.01000000", "price": "450.25000000", "side": "sell", "client_oid": "cadd02a4-b086-434c-8000-00493fb1129f", "product_id": "ETH-USD", "sequence": 4179035694, "time": "2018-07-02T05:24:05.573000Z"}
{"type": "open", "side": "sell", "price": "450.25000000", "order_id": "c9dbb5f5-77bc-4d53-a564-184a818c2b76", "remaining_size": "0.01000000", "product_id": "ETH-USD", "sequence": 4179035695, "time": "2018-07-02T05:24:05.573000Z"}
{"type": "done", "side": "buy", "order_id": "0195c3a1-d441-4d19-9bfd-83f5219512b4", "reason": "canceled", "product_id": "BTC-USD", "price": "6298.26000000", "remaining_size": "0.00200000", "sequence": 6227078867, "time": "2018-07-02T05:24:05.612000Z"}
{"type": "done", "side": "sell", "order_id": "5bd8785c-d362-4bf2-8be3-5a4726eb3c02", "reason": "canceled", "product_id": "ETH-USD", "price": "448.25000000", "remaining_size": "0.01000000", "sequence": 4179035696, "time": "2018-07-02T05:24:05.679000Z"}
{"type": "done", "side": "sell", "order_id": "5d5ee41d-99c4-47e8-8a1d-8e2f1be653a1", "reason": "canceled", "product_id": "ETH-USD", "price": "453.99000000", "remaining_size": "15.11670000", "sequence": 4179035697, "time": "2018-07-02T05:24:05.689000Z"}
{"type": "received", "order_id": "f4288fe8-ccc0-45c5-a8e5-4bf87198ed01", "order_type": "limit", "size": "15.54951000", "price": "453.82000000", "side": "sell", "product_id": "ETH-USD", "sequence": 4179035698, "time": "2018-07-02T05:24:05.700000Z"}
{"type": "open", "side": "sell", "price": "453.82000000", "order_id": "f4288fe8-ccc0-45c5-a8e5-4bf87198ed01", "remaining_size": "15.54951000", "product_id": "ETH-USD", "sequence": 4179035699, "time": "2018-07-02T05:24:05.700000Z"}
{"type": "received", "order_id": "af0634a7-a780-4254-b15d-3ef71d8c82cf", "order_type": "limit", "size": "0.01000000", "price": "451.25000000", "side": "sell", "client_oid": "e1ea58f5-23f8-4305-8000-002eae4317ef", "product_id": "ETH-USD", "sequence": 4179035700, "time": "2018-07-02T05:24:05.723000Z"}
{"type": "open", "side": "sell", "price": "451.25000000", "order_id": "af0634a7-a780-4254-b15d-3ef71d8c82cf", "remaining_size": "0.01000000", "product_id": "ETH-USD", "sequence": 4179035701, "time": "2018-07-02T05:24:05.723000Z"}
{"type": "received", "order_id": "9148f83b-657b-4a81-b262-7d3c87cbb498", "order_type": "limit", "size": "0.00200000", "price": "6298.26000000", "side": "buy", "product_id": "BTC-USD", "sequence": 6227078868, "time": "2018-07-02T05:24:05.868000Z"}
{"type": "open", "side": "buy", "price": "6298.26000000", "order_id": "9148f83b-657b-4a81-b262-7d3c87cbb498", "remaining_size": "0.00200000", "product_id": "BTC-USD", "sequence": 6227078869, "time": "2018-07-02T05:24:05.868000Z"}
{"type": "done", "side": "sell", "order_id": "b55f8bb1-18ba-47a6-9230-27a1f7e496ef", "reason": "canceled", "product_id": "ETH-USD", "price": "449.25000000", "remaining_size": "0.01000000", "sequence": 4179035702, "time": "2018-07-02T05:24:05.926000Z"}
{"type": "done", "side": "sell", "order_id": "c9dbb5f5-77bc-4d53-a564-184a818c2b76", "reason": "canceled", "product_id": "ETH-USD", "price": "450.25000000", "remaining_size": "0.01000000", "sequence": 4179035703, "time": "2018-07-02T05:24:05.966000Z"}
{"type": "received", "order_id": "9d23babe-2423-4ee5-9143-b3ef697419cf", "order_type": "limit", "size": "0.01000000", "price": "452.25000000", "side": "sell", "client_oid": "da60290f-814f-4276-8000-00b5d594a689", "product_id": "ETH-USD", "sequence": 4179035704, "time": "2018-07-02T05:24:05.976000Z"}
{"type": "open", "side": "sell", "price": "452.25000000", "order_id": "9d23babe-2423-4ee5-9143-b3ef697419cf", "remaining_size": "0.01000000", "product_id": "ETH-USD", "sequence": 4179035705, "time": "2018-07-02T05:24:05.976000Z"}
{"type": "done", "side": "sell", "order_id": "af0634a7-a780-4254-b15d-3ef71d8c82cf", "reason": "canceled", "product_id": "ETH-USD", "price": "451.25000000", "remaining_size": "0.01000000", "sequence": 4179035706, "time": "2018-07-02T05:24:06.049000Z"}
{"type": "received", "order_id": "52bb46c1-913e-4d44-b669-118b66a7a28a", "order_type": "limit", "size": "0.01000000", "price": "453.25000000", "side": "sell", "client_oid": "1f8b24cf-2586-4637-8000-00648a0ec0b6", "product_id": "ETH-USD", "sequence": 4179035707, "time": "2018-07-02T05:24:06.055000Z"}
{"type": "open", "side": "sell", "price": "453.25000000", "order_id": "52bb46c1-913e-4d44-b669-118b66a7a28a", "remaining_size": "0.01000000", "product_id": "ETH-USD", "sequence": 4179035708, "time": "2018-07-02T05:24:06.055000Z"}
{"type": "done", "side": "sell", "order_id": "6987c4eb-a639-4c50-902c-6e75c220f0b6", "reason": "canceled", "product_id": "ETH-USD", "price": "447.17000000", "remaining_size": "2.68391400", "sequence": 4179035709, "time": "2018-07-02T05:24:06.088000Z"}
{"type": "done", "side": "sell", "order_id": "fe215288-4dc9-4ddc-9d14-117a63fedab0", "reason": "canceled", "product_id": "ETH-USD", "price": "474.70000000", "remaining_size": "0.01000000", "sequence": 4179035710, "time": "2018-07-02T05:24:06.172000Z"}
{"type": "received", "order_id": "0fdb61c6-0a6b-4050-a424-ea2dd97187d8", "order_type": "limit", "size": "0.01000000", "price": "470.67000000", "side": "sell", "client_oid": "5a26b58a-43cd-4f2d-8000-00bc8b7c0323", "product_id": "ETH-USD", "sequence": 4179035711, "time": "2018-07-02T05:24:06.179000Z"}
{"type": "open", "side": "sell", "price": "470.67000000", "order_id": "0fdb61c6-0a6b-4050-a424-ea2dd97187d8", "remaining_size": "0.01000000", "product_id": "ETH-USD", "sequence": 4179035712, "time": "2018-07-02T05:24:06.179000Z"}
{"type": "received", "order_id": "443fd7ab-1851-4325-9aeb-73410b971996", "order_type": "limit", "size": "54.00000000", "price": "447.17000000", "side": "sell", "client_oid": "abb4a253-ae1c-41c5-88ab-fd425d999f35", "product_id": "ETH-USD", "sequence": 4179035713, "time": "2018-07-02T05:24:06.183000Z"}
{"type": "open", "side": "sell", "price": "447.17000000", "order_id": "443fd7ab-1851-4325-9aeb-73410b971996", "remaining_size": "54.00000000", "product_id": "ETH-USD", "sequence": 4179035714, "time": "2018-07-02T05:24:06.183000Z"}
{"type": "done", "side": "sell", "order_id": "95db07e7-bd8a-48df-9586-7d1ea35e7ee6", "reason": "canceled", "product_id": "BTC-USD", "price": "6345.96000000", "remaining_size": "0.00200000", "sequence": 6227078870, "time": "2018-07-02T05:24:06.201000Z"}
{"type": "done", "side": "buy", "order_id": "3a309566-1ec0-4b4b-8f62-883c34f2041a", "reason": "canceled", "product_id": "BTC-USD", "price": "6085.89000000", "remaining_size": "0.00150000", "sequence": 6227078871, "time": "2018-07-02T05:24:06.201000Z"}
{"type": "received", "order_id": "c226878b-1816-4319-93cf-f66e5f66d7db", "order_type": "limit", "size": "0.00150000", "price": "6051.91000000", "side": "buy", "client_oid": "ae844d78-7aae-4efa-8000-00ff0c5a634b", "product_id": "BTC-USD", "sequence": 6227078872, "time": "2018-07-02T05:24:06.208000Z"}
{"type": "open", "side": "buy", "price": "6051.91000000", "order_id": "c226878b-1816-4319-93cf-f66e5f66d7db", "remaining_size": "0.00150000", "product_id": "BTC-USD", "sequence": 6227078873, "time": "2018-07-02T05:24:06.208000Z"}
{"type": "received", "order_id": "8344e204-43c8-425e-9013-bf75a0087241", "order_type": "limit", "size": "0.01000000", "price": "454.25000000", "side": "sell", "client_oid": "6504fe75-cbf4-4b99-8000-00f943becc87", "product_id": "ETH-USD", "sequence": 4179035715, "time": "2018-07-02T05:24:06.222000Z"}
{"type": "open", "side": "sell", "price": "454.25000000", "order_id": "8344e204-43c8-425e-9013-bf75a0087241", "remaining_size": "0.01000000", "product_id": "ETH-USD", "sequence": 4179035716, "time": "2018-07-02T05:24:06.222000Z"}
{"type": "done", "side": "sell", "order_id": "f1cf39a2-e81e-4c9b-a8a6-69f0937142df", "reason": "canceled", "product_id": "ETH-USD", "price": "448.05000000", "remaining_size": "6.00000000", "sequence": 4179035717, "time": "2018-07-02T05:24:06.248000Z"}
{"type": "done", "side": "sell", "order_id": "84e5d7bb-0ce0-45ae-a1ec-f859fc4b09aa", "reason": "canceled", "product_id": "ETH-USD", "price": "448.09000000", "remaining_size": "6.00000000", "sequence": 4179035718, "time": "2018-07-02T05:24:06.249000Z"}
{"type": "done", "side": "sell", "order_id": "01a62751-b3ed-4e8f-8c77-9eca040cf90b", "reason": "canceled", "product_id": "BTC-USD", "price": "6315.61000000", "remaining_size": "0.90000000", "sequence": 6227078874, "time": "2018-07-02T05:24:06.252000Z"}
{"type": "done", "side": "buy", "order_id": "798d3720-da61-4319-8d42-15915fed42b4", "reason": "canceled", "product_id": "BTC-USD", "price": "6287.25000000", "remaining_size": "0.90000000", "sequence": 6227078875, "time": "2018-07-02T05:24:06.253000Z"}
{"type": "received", "order_id": "f354bba5-3543-483b-8ed5-f50c4935cae8", "order_type": "limit", "size": "0.00200000", "price": "6345.96000000", "side": "sell", "client_oid": "a7f7a431-25b6-48f5-a285-5e51ed8c874a", "product_id": "BTC-USD", "sequence": 6227078876, "time": "2018-07-02T05:24:06.272000Z"}
{"type": "open", "side": "sell", "price": "6345.96000000", "order_id": "f354bba5-3543-483b-8ed5-f50c4935cae8", "remaining_size": "0.00200000", "product_id": "BTC-USD", "sequence": 6227078877, "time": "2018-07-02T05:24:06.272000Z"}
{"type": "received", "order_id": "009e320d-01d9-4bfc-af58-88444c4114eb", "order_type": "limit", "size": "6.00000000", "price": "448.05000000", "side": "sell", "client_oid": "6e563c3c-cd0f-4abe-b76d-f34f9baa7136", "product_id": "ETH-USD", "sequence": 4179035719, "time": "2018-07-02T05:24:06.274000Z"}
{"type": "open", "side": "sell", "price": "448.05000000", "order_id": "009e320d-01d9-4bfc-af58-88444c4114eb", "remaining_size": "6.00000000", "product_id": "ETH-USD", "sequence": 4179035720, "time": "2018-07-02T05:24:06.274000Z"}
{"type": "done", "side": "buy", "order_id": "1fcbccc2-3429-44cb-bbea-f9d9fb284de7", "reason": "canceled", "product_id": "ETH-USD", "price": "445.35000000", "remaining_size": "3.58036300", "sequence": 4179035721, "time": "2018-07-02T05:24:06.278000Z"}
{"type": "done", "side": "buy", "order_id": "a2031e06-99c9-4baa-a123-9147ed6b3198", "reason": "canceled", "product_id": "ETH-USD", "price": "445.09000000", "remaining_size": "2.86779800", "sequence": 4179035722, "time": "2018-07-02T05:24:06.281000Z"}
{"type": "received", "order_id": "b5ccf23e-9547-4382-8278-ca37a048180f", "order_type": "limit", "size": "6.00000000", "price": "448.09000000", "side": "sell", "client_oid": "9eb3c5b9-06b6-4008-8aa9-16abba43d26c", "product_id": "ETH-USD", "sequence": 4179035723, "time": "2018-07-02T05:24:06.281000Z"}
{"type": "open", "side": "sell", "price": "448.09000000", "order_id": "b5ccf23e-9547-4382-8278-ca37a048180f", "remaining_size": "6.00000000", "product_id": "ETH-USD", "sequence": 4179035724, "time": "2018-07-02T05:24:06.281000Z"}
{"type": "done", "side": "buy", "order_id": "bbe0bcce-1cc8-4307-83a0-9c02ce29c572", "reason": "canceled", "product_id": "ETH-USD", "price": "443.66000000", "remaining_size": "2.06991400", "sequence": 4179035725, "time": "2018-07-02T05:24:06.283000Z"}
{"type": "done", "side": "buy", "order_id": "e748f854-06e5-47d3-afd2-8865715c08ab", "reason": "canceled", "product_id": "ETH-USD", "price": "443.14000000", "remaining_size": "2.06792900", "sequence": 4179035726, "time": "2018-07-02T05:24:06.286000Z"}
{"type": "done", "side": "buy", "order_id": "1ac39e78-a5b7-4505-8cce-2e12a7112aad", "reason": "canceled", "product_id": "ETH-USD", "price": "443.01000000", "remaining_size": "12.10609900", "sequence": 4179035727, "time": "2018-07-02T05:24:06.289000Z"}
{"type": "received", "order_id": "6c811adb-1ac4-4b2c-b04e-c9075290c7ce", "order_type": "limit", "size": "0.90000000", "price": "6287.25000000", "side": "buy", "client_oid": "2811b4be-eb06-4c47-b589-c4149d3b08b9", "product_id": "BTC-USD", "sequence": 6227078878, "time": "2018-07-02T05:24:06.305000Z"}
{"type": "open", "side": "buy", "price": "6287.25000000", "order_id": "6c811adb-1ac4-4b2c-b04e-c9075290c7ce", "remaining_size": "0.90000000", "product_id": "BTC-USD", "sequence": 6227078879, "time": "2018-07-02T05:24:06.305000Z"}
{"type": "received", "order_id": "37b54af6-aba6-4ea0-8c13-31771f13b382", "order_type": "limit", "size": "0.90000000", "price": "6315.61000000", "side": "sell", "client_oid": "b141f7b0-109d-4279-9944-7151a503dbfe", "product_id": "BTC-USD", "sequence": 6227078880, "time": "2018-07-02T05:24:06.312000Z"}
{"type": "open", "side": "sell", "price": "6315.61000000", "order_id": "37b54af6-aba6-4ea0-8c13-31771f13b382", "remaining_size": "0.90000000", "product_id": "BTC-USD", "sequence": 6227078881, "time": "2018-07-02T05:24:06.312000Z"}
{"type": "received", "order_id": "5ccbab60-b66d-48c1-a668-413cbae0ae62", "order_type": "limit", "size": "3.57934300", "price": "445.35000000", "side": "buy", "client_oid": "1eab81a5-52c2-4a56-9d2e-2942757f7ec8", "product_id": "ETH-USD", "sequence": 4179035728, "time": "2018-07-02T05:24:06.320000Z"}
{"type": "open", "side": "buy", "price": "445.35000000", "order_id": "5ccbab60-b66d-48c1-a668-413cbae0ae62", "remaining_size": "3.57934300", "product_id": "ETH-USD", "sequence": 4179035729, "time": "2018-07-02T05:24:06.320000Z"}
{"type": "received", "order_id": "02685464-f32b-4a67-ad7c-ca9e0d382d28", "order_type": "limit", "size": "2.87725600", "price": "445.09000000", "side": "buy", "client_oid": "e2463e62-aa9b-4c18-b138-308565e00c69", "product_id": "ETH-USD", "sequence": 4179035730, "time": "2018-07-02T05:24:06.328000Z"}
{"type": "open", "side": "buy", "price": "445.09000000", "order_id": "02685464-f32b-4a67-ad7c-ca9e0d382d28", "remaining_size": "2.87725600", "product_id": "ETH-USD", "sequence": 4179035731, "time": "2018-07-02T05:24:06.328000Z"}
{"type": "received", "order_id": "9a7ca11a-bd92-485a-a765-53afcc9c7327", "order_type": "limit", "size": "2.10199100", "price": "443.66000000", "side": "buy", "client_oid": "1392ea06-909d-4739-8847-948a421a2ce5", "product_id": "ETH-USD", "sequence": 4179035732, "time": "2018-07-02T05:24:06.338000Z"}
{"type": "open", "side": "buy", "price": "443.66000000", "order_id": "9a7ca11a-bd92-485a-a765-53afcc9c7327", "remaining_size": "2.10199100", "product_id": "ETH-USD", "sequence": 4179035733, "time": "2018-07-02T05:24:06.338000Z"}
{"type": "received", "order_id": "197c611b-80a8-4e2e-bab2-d436012a2ca4", "order_type": "limit", "size": "1.77236600", "price": "443.14000000", "side": "buy", "client_oid": "648983c0-05d0-4e92-a52c-b4e3097cbc47", "product_id": "ETH-USD", "sequence": 4179035734, "time": "2018-07-02T05:24:06.346000Z"}
{"type": "open", "side": "buy", "price": "443.14000000", "order_id": "197c611b-80a8-4e2e-bab2-d436012a2ca4", "remaining_size": "1.77236600", "product_id": "ETH-USD", "sequence": 4179035735, "time": "2018-07-02T05:24:06.346000Z"}
{"type": "received", "order_id": "1997e166-027b-45d7-8bfd-4c25488696dd", "order_type": "limit", "size": "12.36114900", "price": "443.01000000", "side": "buy", "client_oid": "72e75d40-4c2d-4327-9d19-544cd370ede6", "product_id": "ETH-USD", "sequence": 4179035736, "time": "2018-07-02T05:24:06.356000Z"}
{"type": "open", "side": "buy", "price": "443.01000000", "order_id": "1997e166-027b-45d7-8bfd-4c25488696dd", "remaining_size": "12.36114900", "product_id": "ETH-USD", "sequence": 4179035737, "time": "2018-07-02T05:24:06.356000Z"}
{"type": "received", "order_id": "4cf6b07d-6d7b-4ece-b7ba-c9d0551a4bcf", "order_type": "limit", "size": "0.01000000", "price": "447.06000000", "side": "buy", "client_oid": "23e17e3e-7db8-11e8-874f-16be7828d23e", "product_id": "ETH-USD", "sequence": 4179035738, "time": "2018-07-02T05:24:06.427000Z"}
{"type": "done", "side": "buy", "order_id": "4cf6b07d-6d7b-4ece-b7ba-c9d0551a4bcf", "reason": "canceled", "product_id": "ETH-USD", "price": "447.06000000", "remaining_size": "0.01000000", "sequence": 4179035739, "time": "2018-07-02T05:24:06.427000Z"}
{"type": "done", "side": "sell", "order_id": "ed3f2961-1a97-43cf-9b2f-28103b14b868", "reason": "canceled", "product_id": "BTC-USD", "price": "6303.69000000", "remaining_size": "0.01500000", "sequence": 6227078882, "time": "2018-07-02T05:24:06.471000Z"}
{"type": "received", "order_id": "9f167aeb-713d-49fd-82eb-861d7b5d9bae", "order_type": "limit", "size": "0.01500000", "price": "6303.70000000", "side": "sell", "client_oid": "6f799019-1ced-4efe-a4e8-cec22ba6ce5c", "product_id": "BTC-USD", "sequence": 6227078883, "time": "2018-07-02T05:24:06.476000Z"}
{"type": "open", "side": "sell", "price": "6303.70000000", "order_id": "9f167aeb-713d-49fd-82eb-861d7b5d9bae", "remaining_size": "0.01500000", "product_id": "BTC-USD", "sequence": 6227078884, "time": "2018-07-02T05:24:06.476000Z"}
{"type": "done", "side": "sell", "order_id": "f1bb576e-7500-4a38-963a-20270df25cc6", "reason": "canceled", "product_id": "ETH-USD", "price": "448.20000000", "remaining_size": "9.00000000", "sequence": 4179035740, "time": "2018-07-02T05:24:06.498000Z"}
{"type": "done", "side": "sell", "order_id": "7dd35068-6452-4bc3-97ed-fcfd6d0403d8", "reason": "canceled", "product_id": "ETH-USD", "price": "448.09000000", "remaining_size": "9.00000000", "sequence": 4179035741, "time": "2018-07-02T05:24:06.498000Z"}
{"type": "done", "side": "buy", "order_id": "7a1684ec-e8a8-4a4d-a0a2-6b811b75300c", "reason": "canceled", "product_id": "BTC-USD", "price": "6287.25000000", "remaining_size": "0.90000000", "sequence": 6227078885, "time": "2018-07-02T05:24:06.502000Z"}
{"type": "done", "side": "buy", "order_id": "fcb53b94-c052-4748-a322-c9ba7e6277f8", "reason": "canceled", "product_id": "BTC-USD", "price": "6285.36000000", "remaining_size": "0.90000000", "sequence": 6227078886, "time": "2018-07-02T05:24:06.503000Z"}
{"type": "done", "side": "sell", "order_id": "b133ef98-a62e-4ddc-9707-465a3b774d7e", "reason": "canceled", "product_id": "BTC-USD", "price": "6314.35000000", "remaining_size": "0.90000000", "sequence": 6227078887, "time": "2018-07-02T05:24:06.503000Z"}
{"type": "received", "order_id": "e5ae7cc8-0859-4322-aa39-7d1a08cbf966", "order_type": "limit", "size": "9.00000000", "price": "448.20000000", "side": "sell", "client_oid": "66cbed85-76ab-4b80-b156-df84112a4910", "product_id": "ETH-USD", "sequence": 4179035742, "time": "2018-07-02T05:24:06.515000Z"}
{"type": "open", "side": "sell", "price": "448.20000000", "order_id": "e5ae7cc8-0859-4322-aa39-7d1a08cbf966", "remaining_size": "9.00000000", "product_id": "ETH-USD", "sequence": 4179035743, "time": "2018-07-02T05:24:06.515000Z"}
{"type": "received", "order_id": "221a5421-a5c0-48df-8807-622b6e5ae017", "order_type": "limit", "size": "0.90000000", "price": "6287.25000000", "side": "buy", "client_oid": "e3686a69-9782-4cfa-9f15-9d190b8b0d35", "product_id": "BTC-USD", "sequence": 6227078888, "time": "2018-07-02T05:24:06.522000Z"}
{"type": "open", "side": "buy", "price": "6287.25000000", "order_id": "221a5421-a5c0-48df-8807-622b6e5ae017", "remaining_size": "0.90000000", "product_id": "BTC-USD", "sequence": 6227078889, "time": "2018-07-02T05:24:06.522000Z"}
{"type": "received", "order_id": "8fb59d68-3f2a-4b8b-b902-75c516edb857", "order_type": "limit", "size": "0.90000000", "price": "6285.36000000", "side": "buy", "client_oid": "c4d8806f-aa64-4b13-b4dc-07e2d79225ed", "product_id": "BTC-USD", "sequence": 6227078890, "time": "2018-07-02T05:24:06.546000Z"}
{"type": "open", "side": "buy", "price": "6285.36000000", "order_id": "8fb59d68-3f2a-4b8b-b902-75c516edb857", "remaining_size": "0.90000000", "product_id": "BTC-USD", "sequence": 6227078891, "time": "2018-07-02T05:24:06.546000Z"}
{"type": "received", "order_id": "cdf41870-47c3-4791-9ab6-db1f3ad1688a", "order_type": "limit", "size": "0.90000000", "price": "6314.35000000", "side": "sell", "client_oid": "32b8e614-cfac-4ea8-8cf7-067841739d11", "product_id": "BTC-USD", "sequence": 6227078892, "time": "2018-07-02T05:24:06.571000Z"}
{"type": "open", "side": "sell", "price": "6314.35000000", "order_id": "cdf41870-47c3-4791-9ab6-db1f3ad1688a", "remaining_size": "0.90000000", "product_id": "BTC-USD", "sequence": 6227078893, "time": "2018-07-02T05:24:06.571000Z"}
{"type": "received", "order_id": "784fceed-d074-4ace-bfb2-a9c000c7ec5b", "order_type": "limit", "size": "9.00000000", "price": "448.09000000", "side": "sell", "client_oid": "02eaf19e-68a2-4ae4-9ecb-9a1db3cd2493", "product_id": "ETH-USD", "sequence": 4179035744, "time": "2018-07-02T05:24:06.594000Z"}
{"type": "open", "side": "sell", "price": "448.09000000", "order_id": "784fceed-d074-4ace-bfb2-a9c000c7ec5b", "remaining_size": "9.00000000", "product_id": "ETH-USD", "sequence": 4179035745, "time": "2018-07-02T05:24:06.594000Z"}
{"type": "done", "side": "sell", "order_id": "9d23babe-2423-4ee5-9143-b3ef697419cf", "reason": "canceled", "product_id": "ETH-USD", "price": "452.25000000", "remaining_size": "0.01000000", "sequence": 4179035746, "time": "2018-07-02T05:24:06.663000Z"}
{"type": "received", "order_id": "98e29ba7-128e-4b27-9299-64d542ad7dba", "order_type": "limit", "size": "0.01000000", "price": "447.25000000", "side": "sell", "client_oid": "9626e1e3-bb9e-467d-8000-00067afca16e", "product_id": "ETH-USD", "sequence": 4179035747, "time": "2018-07-02T05:24:06.716000Z"}
{"type": "open", "side": "sell", "price": "447.25000000", "order_id": "98e29ba7-128e-4b27-9299-64d542ad7dba", "remaining_size": "0.01000000", "product_id": "ETH-USD", "sequence": 4179035748, "time": "2018-07-02T05:24:06.716000Z"}
{"type": "done", "side": "sell", "order_id": "b3c43302-3f1a-49f1-be55-a8b8e7da4162", "reason": "canceled", "product_id": "ETH-USD", "price": "447.17000000", "remaining_size": "0.01067000", "sequence": 4179035749, "time": "2018-07-02T05:24:06.722000Z"}
{"type": "received", "order_id": "b5a9852a-9843-413d-ab75-166fec411375", "order_type": "limit", "size": "0.01006000", "price": "447.17000000", "side": "sell", "client_oid": "240f503e-7db8-11e8-874f-16be7828d23e", "product_id": "ETH-USD", "sequence": 4179035750, "time": "2018-07-02T05:24:06.728000Z"}
{"type": "open", "side": "sell", "price": "447.17000000", "order_id": "b5a9852a-9843-413d-ab75-166fec411375", "remaining_size": "0.01006000", "product_id": "ETH-USD", "sequence": 4179035751, "time": "2018-07-02T05:24:06.728000Z"}
{"type": "received", "order_id": "15ab17d9-2051-4339-9cd6-2f58ee165858", "order_type": "limit", "size": "0.01000000", "price": "448.25000000", "side": "sell", "client_oid": "db83edc8-5408-4f68-8000-00047bacf156", "product_id": "ETH-USD", "sequence": 4179035752, "time": "2018-07-02T05:24:06.873000Z"}
{"type": "open", "side": "sell", "price": "448.25000000", "order_id": "15ab17d9-2051-4339-9cd6-2f58ee165858", "remaining_size": "0.01000000", "product_id": "ETH-USD", "sequence": 4179035753, "time": "2018-07-02T05:24:06.873000Z"}
{"type": "done", "side": "sell", "order_id": "07f7c5be-23ae-4454-986d-f0effde4df51", "reason": "canceled", "product_id": "ETH-USD", "price": "450.36000000", "remaining_size": "6.79438000", "sequence": 4179035754, "time": "2018-07-02T05:24:06.980000Z"}
{"type": "done", "side": "sell", "order_id": "388f78d4-8da1-4814-a4e3-d89595dc3993", "reason": "canceled", "product_id": "ETH-USD", "price": "449.70000000", "remaining_size": "6.79438000", "sequence": 4179035755, "time": "2018-07-02T05:24:06.985000Z"}
{"type": "received", "order_id": "9d0c1e6f-dec1-4b9b-b462-d22dc6c544ca", "order_type": "limit", "size": "6.79438000", "price": "452.79000000", "side": "sell", "client_oid": "d68c4864-5d44-4b29-999e-536bb52bf25c", "product_id": "ETH-USD", "sequence": 4179035756, "time": "2018-07-02T05:24:06.993000Z"}
{"type": "open", "side": "sell", "price": "452.79000000", "order_id": "9d0c1e6f-dec1-4b9b-b462-d22dc6c544ca", "remaining_size": "6.79438000", "product_id": "ETH-USD", "sequence": 4179035757, "time": "2018-07-02T05:24:06.993000Z"}
{"type": "received", "order_id": "6847bcbb-1062-4772-b9f2-959c8f13f40c", "order_type": "limit", "size": "6.79438000", "price": "452.99000000", "side": "sell", "client_oid": "c4153d92-6a3e-4c9e-b6ff-0c9baf04526c", "product_id": "ETH-USD", "sequence": 4179035758, "time": "2018-07-02T05:24:06.997000Z"}
